
Friendly tracebacks - in Русский
==================================================

Friendly aims to provide friendlier feedback when an exception
is raised than what is done by Python.

Below, we can find some examples. SyntaxError cases, as well as TabError and
IndentationError cases, are shown in a separate page.
Not all cases handled by friendly are included here.

.. note::

     The content of this page is generated by running
     `trb_russian.py` located in the ``tests/`` directory.
     This needs to be done explicitly, independently of updating the
     documentation using Sphinx.

Friendly-traceback version: 0.6.0
Python version: 3.9.10



ArithmeticError
---------------


Generic
~~~~~~~

.. code-block:: none


    Traceback (most recent call last):
      File "TESTS:\runtime\test_arithmetic_error.py", line 9, in test_Generic
        raise ArithmeticError('error')
    ArithmeticError: error
    
    `ArithmeticError` является базовым классом для встроенных исключений,
    которые возникают при различных арифметических ошибках.
    Странно, что вы видите это исключение, обычно должно вызываться
    более конкретное исключение.
    
    Исключение возникло в строке 9 файла TESTS:\runtime\test_arithmetic_error.py.
    
        4| def test_Generic():
        5|     try:
        6|         # I am not aware of any way in which this error is raised directly
        7|         # Usually, a subclass such as ZeroDivisionError, etc., would
        8|         # likely be raised.
    --> 9|         raise ArithmeticError('error')
       10|     except ArithmeticError as e:

            ArithmeticError:  <class ArithmeticError>
        


AssertionError
--------------


Generic
~~~~~~~

.. code-block:: none


    Traceback (most recent call last):
      File "TESTS:\runtime\test_assertion_error.py", line 8, in test_Generic
        raise AssertionError("Fake message")
    AssertionError: Fake message
    
    В Python ключевое слово `assert` используется в утверждениях типа
    `assert condition`, чтобы подтвердить, что `condition` не является `False`,
    или эквивалентно `False`, например, пустой список и т.д.
    
    Если `condition` равно `False` или эквивалентно ему, возникает `AssertionError`.
    
    Исключение возникло в строке 8 файла TESTS:\runtime\test_assertion_error.py.
    
       4| def test_Generic():
       5|     try:
       6|         # We raise it explicitly, rather than with the keyword assert, since
       7|         # we don't want pytest to rewrite out test.
    -->8|         raise AssertionError("Fake message")
       9|     except AssertionError as e:

            AssertionError:  <class AssertionError>
        


AttributeError
--------------


Attribute from other module
~~~~~~~~~~~~~~~~~~~~~~~~~~~

.. code-block:: none


    Traceback (most recent call last):
      File "TESTS:\runtime\test_attribute_error.py", line 325, in test_Attribute_from_other_module
        keyword.pi
    AttributeError: module 'keyword' has no attribute 'pi'
    
        Вы имели в виду один из следующих модулей: `math, cmath`?
    `AttributeError` возникает, когда код содержит что-то вроде
        `object.x`
    где `x` не является методом или атрибутом (переменной), принадлежащим `object`.
    
    Возможно, вместо модуля `keyword`, следует использовать
    атрибут `pi` одного из следующих модулей:
    `math, cmath`.
    
    Исключение возникло в строке 325 файла TESTS:\runtime\test_attribute_error.py.
    
       321|     assert "Did you mean `math`?" in result
       322| 
       323| import cmath
       324| try:
    -->325|     keyword.pi
                ^^^^^^^^^^
       326| except AttributeError as e:

            keyword:  <module keyword> from PYTHON_LIB:\keyword.py
        


Builtin function
~~~~~~~~~~~~~~~~

.. code-block:: none


    Traceback (most recent call last):
      File "TESTS:\runtime\test_attribute_error.py", line 223, in test_Builtin_function
        len.text
    AttributeError: 'builtin_function_or_method' object has no attribute 'text'
    
        Вы имели в виду `len(text)`?
        
    `AttributeError` возникает, когда код содержит что-то вроде
        `object.x`
    где `x` не является методом или атрибутом (переменной), принадлежащим `object`.
    
    `len` является функцией. Возможно, вы хотели написать
    `len(text)`.
    
    Исключение возникло в строке 223 файла TESTS:\runtime\test_attribute_error.py.
    
       220| def test_Builtin_function():
       221|     text = 'Hello world!'
       222|     try:
    -->223|         len.text
                    ^^^^^^^^
       224|     except AttributeError as e:

            text:  'Hello world!'
            len:  <builtin function len>
        


Builtin module with no file
~~~~~~~~~~~~~~~~~~~~~~~~~~~

.. code-block:: none


    Traceback (most recent call last):
      File "TESTS:\runtime\test_attribute_error.py", line 240, in test_Builtin_module_with_no_file
        sys.foo
    AttributeError: module 'sys' has no attribute 'foo'
    
    `AttributeError` возникает, когда код содержит что-то вроде
        `object.x`
    где `x` не является методом или атрибутом (переменной), принадлежащим `object`.
    
    Python сообщает, что ни один объект с именем `foo`
    не найден в модуле `sys`.
    
    Исключение возникло в строке 240 файла TESTS:\runtime\test_attribute_error.py.
    
       236| """Issue 116"""
       237| import sys
       238| 
       239| try:
    -->240|     sys.foo
                ^^^^^^^
       241| except AttributeError as e:

            sys:  <module sys (builtin)>
        


Circular import
~~~~~~~~~~~~~~~

.. code-block:: none


    Traceback (most recent call last):
      File "TESTS:\runtime\test_attribute_error.py", line 359, in test_Circular_import
        import my_turtle1
      File "TESTS:\my_turtle1.py", line 4, in <module>
        a = my_turtle1.something
    AttributeError: partially initialized module 'my_turtle1' has no attribute 'something' (most likely due to a circular import)
    
        Давали ли вы своей программе то же имя, что и модулю Python?
        
    `AttributeError` возникает, когда код содержит что-то вроде
        `object.x`
    где `x` не является методом или атрибутом (переменной), принадлежащим `object`.
    
    Предположение: вы использовали имя `my_turtle1.py` для своей программы
    и что вы также хотели импортировать модуль с тем же именем
    из стандартной библиотеки Python.
    Если это так, то вы должны использовать другое имя для своей программы.
    
    Выполнение остановлено на строке 359 файла TESTS:\runtime\test_attribute_error.py.
    
       356| from friendly_traceback.runtime_errors import stdlib_modules
       357| stdlib_modules.names.append("my_turtle1")
       358| try:
    -->359|    import my_turtle1
       360| except AttributeError as e:

    Исключение возникло в строке 4 файла TESTS:\my_turtle1.py.
    
       1| """To test attribute error of partially initialized module."""
       2| import my_turtle1
       3| 
    -->4| a = my_turtle1.something
              ^^^^^^^^^^^^^^^^^^^^

            my_turtle1:  <module my_turtle1> from TESTS:\my_turtle1.py
        


Circular import b
~~~~~~~~~~~~~~~~~

.. code-block:: none


    Traceback (most recent call last):
      File "TESTS:\runtime\test_attribute_error.py", line 376, in test_Circular_import_b
        import circular_c
      File "TESTS:\circular_c.py", line 4, in <module>
        a = circular_c.something
    AttributeError: partially initialized module 'circular_c' has no attribute 'something' (most likely due to a circular import)
    
        У вас кольцевой импорт.
        
    `AttributeError` возникает, когда код содержит что-то вроде
        `object.x`
    где `x` не является методом или атрибутом (переменной), принадлежащим `object`.
    
    Python указал, что модуль `{module}` был импортирован не полностью.
    Это может произойти, если во время выполнения кода в модуле `circular_c`
    будет сделана попытка импортировать тот же модуль еще раз.
    
    Выполнение остановлено на строке 376 файла TESTS:\runtime\test_attribute_error.py.
    
       374| def test_Circular_import_b():
       375|     try:
    -->376|         import circular_c
       377|     except AttributeError as e:

    Исключение возникло в строке 4 файла TESTS:\circular_c.py.
    
       1| # Attribute error for partially initialize module
       2| import circular_c
       3| 
    -->4| a = circular_c.something
              ^^^^^^^^^^^^^^^^^^^^

            circular_c:  <module circular_c> from TESTS:\circular_c.py
        


Generic
~~~~~~~

.. code-block:: none


    Traceback (most recent call last):
      File "TESTS:\runtime\test_attribute_error.py", line 26, in test_Generic
        A.x  # testing type
    AttributeError: type object 'A' has no attribute 'x'
    
    `AttributeError` возникает, когда код содержит что-то вроде
        `object.x`
    где `x` не является методом или атрибутом (переменной), принадлежащим `object`.
    
    У объекта `A` нет атрибута с именем `x`.
    
    Исключение возникло в строке 26 файла TESTS:\runtime\test_attribute_error.py.
    
       22| class A:
       23|     pass
       24| 
       25| try:
    -->26|     A.x  # testing type
               ^^^
       27| except AttributeError as e:

            A:  <class A> defined in <function test_attribute_error.test_Generic>
        


Generic different frame
~~~~~~~~~~~~~~~~~~~~~~~

.. code-block:: none


    Traceback (most recent call last):
      File "TESTS:\runtime\test_attribute_error.py", line 49, in test_Generic_different_frame
        a.attr
    AttributeError: 'A' object has no attribute 'attr'
    
        Вы имели в виду `attr2`?
        
    `AttributeError` возникает, когда код содержит что-то вроде
        `object.x`
    где `x` не является методом или атрибутом (переменной), принадлежащим `object`.
    
    У объекта `a` нет атрибута с именем `attr`.
    Возможно, вы хотели написать `a.attr2` вместо `a.attr`.
    
    Исключение возникло в строке 49 файла TESTS:\runtime\test_attribute_error.py.
    
       45|     return A()
       46| 
       47| a = f()
       48| try:
    -->49|     a.attr
               ^^^^^^
       50| except AttributeError as e:

            a:  <A object>
                defined in <function test_attribute_error.test_Generic_different_frame.<locals>.f>
        


Generic instance
~~~~~~~~~~~~~~~~

.. code-block:: none


    Traceback (most recent call last):
      File "TESTS:\runtime\test_attribute_error.py", line 67, in test_Generic_instance
        a.x
    AttributeError: 'A' object has no attribute 'x'
    
    `AttributeError` возникает, когда код содержит что-то вроде
        `object.x`
    где `x` не является методом или атрибутом (переменной), принадлежащим `object`.
    
    У объекта `a` нет атрибута с именем `x`.
    
    Исключение возникло в строке 67 файла TESTS:\runtime\test_attribute_error.py.
    
       64|     pass
       65| a = A()
       66| try:
    -->67|     a.x
               ^^^
       68| except AttributeError as e:

            a:  <A object>
                defined in <function test_attribute_error.test_Generic_instance>
        


Module attribute typo
~~~~~~~~~~~~~~~~~~~~~

.. code-block:: none


    Traceback (most recent call last):
      File "TESTS:\runtime\test_attribute_error.py", line 144, in test_Module_attribute_typo
        math.cost
    AttributeError: module 'math' has no attribute 'cost'
    
        Вы имели в виду `cos`?
        
    `AttributeError` возникает, когда код содержит что-то вроде
        `object.x`
    где `x` не является методом или атрибутом (переменной), принадлежащим `object`.
    
    Вместо того, чтобы написать `math.cost`, возможно, вы хотели написать
     одно из следующих имен, которые являются атрибутами модуля `math`:
    `cos, cosh`
    
    Исключение возникло в строке 144 файла TESTS:\runtime\test_attribute_error.py.
    
       139|     assert "Did you mean `ascii_lowercase`" in result
       140| 
       141| import math
       142| 
       143| try:
    -->144|     math.cost
                ^^^^^^^^^
       145| except AttributeError as e:

            math:  <module math (builtin)>
        


Nonetype
~~~~~~~~

.. code-block:: none


    Traceback (most recent call last):
      File "TESTS:\runtime\test_attribute_error.py", line 183, in test_Nonetype
        a.b
    AttributeError: 'NoneType' object has no attribute 'b'
    
    `AttributeError` возникает, когда код содержит что-то вроде
        `object.x`
    где `x` не является методом или атрибутом (переменной), принадлежащим `object`.
    
    Вы пытаетесь получить доступ к атрибуту `b`
    для переменной, значение которой `None`.
    Исключение возникло в строке 183 файла TESTS:\runtime\test_attribute_error.py.
    
       180| def test_Nonetype():
       181|     a = None
       182|     try:
    -->183|         a.b
                    ^^^
       184|     except AttributeError as e:

            a:  None
        


Object attribute typo
~~~~~~~~~~~~~~~~~~~~~

.. code-block:: none


    Traceback (most recent call last):
      File "TESTS:\runtime\test_attribute_error.py", line 83, in test_Object_attribute_typo
        a.appendh(4)
    AttributeError: 'list' object has no attribute 'appendh'
    
        Вы имели в виду `append`?
        
    `AttributeError` возникает, когда код содержит что-то вроде
        `object.x`
    где `x` не является методом или атрибутом (переменной), принадлежащим `object`.
    
    У объекта `a` нет атрибута с именем `appendh`.
    Возможно, вы хотели написать `a.append` вместо `a.appendh`.
    
    Исключение возникло в строке 83 файла TESTS:\runtime\test_attribute_error.py.
    
       79| def test_Object_attribute_typo():
       80|     #
       81|     try:
       82|         a = [1, 2, 3]
    -->83|         a.appendh(4)
                   ^^^^^^^^^
       84|     except AttributeError as e:

            a:  [1, 2, 3]
        


Perhaps comma
~~~~~~~~~~~~~

.. code-block:: none


    Traceback (most recent call last):
      File "TESTS:\runtime\test_attribute_error.py", line 203, in test_Perhaps_comma
        a = [abcd
    AttributeError: 'str' object has no attribute 'defg'
    
        Вы хотели разделить имена объектов запятой?
        
    `AttributeError` возникает, когда код содержит что-то вроде
        `object.x`
    где `x` не является методом или атрибутом (переменной), принадлежащим `object`.
    
    `defg` не является атрибутом `abcd`.
    Однако и `abcd`, и `defg` являются известными объектами.
    Возможно, вы написали точку, чтобы разделить эти два объекта, 
    вместо запятой.
    
    Исключение возникло в строке 203 файла TESTS:\runtime\test_attribute_error.py.
    
       199| defg = "world"
       200| 
       201| # fmt: off
       202| try:
    -->203|     a = [abcd
                     ^^^^
       204|     .defg]
                ^^^^^
       205| # fmt: on

            abcd:  'hello'
            defg:  'world'
        


Read only
~~~~~~~~~

.. code-block:: none


    Traceback (most recent call last):
      File "TESTS:\runtime\test_attribute_error.py", line 280, in test_Read_only
        f.b = 1
    AttributeError: 'F' object attribute 'b' is read-only
    
    `AttributeError` возникает, когда код содержит что-то вроде
        `object.x`
    где `x` не является методом или атрибутом (переменной), принадлежащим `object`.
    
    Объект `f` использует `__slots__` чтобы указать, какие атрибуты могут
    быть изменены. Значение атрибута `f.b`
    не может быть изменено.
    The only attribute of `f` whose value can be changed is`a`.
    
    Исключение возникло в строке 280 файла TESTS:\runtime\test_attribute_error.py.
    
       276|     b = 2
       277| 
       278| f = F()
       279| try:
    -->280|     f.b = 1
                ^^^
       281| except AttributeError as e:

            f:  <F object>
                defined in <function test_attribute_error.test_Read_only>
            f.b:  2
        


Shadow stdlib module
~~~~~~~~~~~~~~~~~~~~

.. code-block:: none


    Traceback (most recent call last):
      File "TESTS:\runtime\test_attribute_error.py", line 165, in test_Shadow_stdlib_module
        turtle.Pen
    AttributeError: module 'turtle' has no attribute 'Pen'
    
        Давали ли вы своей программе то же имя, что и модулю Python?
        
    `AttributeError` возникает, когда код содержит что-то вроде
        `object.x`
    где `x` не является методом или атрибутом (переменной), принадлежащим `object`.
    
    Вы импортировали модуль с именем `turtle` из `TESTS:\turtle.py`.
    В стандартной библиотеке Python также есть модуль с именем `turtle`.
    Возможно, вам нужно переименовать ваш модуль.
    
    Исключение возникло в строке 165 файла TESTS:\runtime\test_attribute_error.py.
    
       161| def test_Shadow_stdlib_module():
       162|     import turtle
       163| 
       164|     try:
    -->165|         turtle.Pen
                    ^^^^^^^^^^
       166|     except AttributeError as e:

            turtle:  <module turtle> from TESTS:\turtle.py
        


Tuple by accident
~~~~~~~~~~~~~~~~~

.. code-block:: none


    Traceback (most recent call last):
      File "TESTS:\runtime\test_attribute_error.py", line 295, in test_Tuple_by_accident
        something.upper()
    AttributeError: 'tuple' object has no attribute 'upper'
    
        Вы поставили запятую по ошибке?
        
    `AttributeError` возникает, когда код содержит что-то вроде
        `object.x`
    где `x` не является методом или атрибутом (переменной), принадлежащим `object`.
    
    `something` -- это кортеж, который содержит единственный элемент,
    имеющий `'upper` в качестве атрибута.
    Возможно, вы по ошибке добавили запятую в конце строки
    в которой вы определили `something`.
    
    Исключение возникло в строке 295 файла TESTS:\runtime\test_attribute_error.py.
    
       292| def test_Tuple_by_accident():
       293|     something = "abc",  # note trailing comma
       294|     try:
    -->295|         something.upper()
                    ^^^^^^^^^^^^^^^
       296|     except AttributeError as e:

            something:  ('abc',)
        


Use builtin
~~~~~~~~~~~

.. code-block:: none


    Traceback (most recent call last):
      File "TESTS:\runtime\test_attribute_error.py", line 99, in test_Use_builtin
        a.length()
    AttributeError: 'list' object has no attribute 'length'
    
        Вы имели в виду `len(a)`?
        
    `AttributeError` возникает, когда код содержит что-то вроде
        `object.x`
    где `x` не является методом или атрибутом (переменной), принадлежащим `object`.
    
    У объекта `a` нет атрибута с именем `length`.
    Возможно, вместо этого следует использовать встроенную функцию Python `len`:
    `len(a)`.
    Исключение возникло в строке 99 файла TESTS:\runtime\test_attribute_error.py.
    
        95| def test_Use_builtin():
        96|     #
        97|     try:
        98|         a = [1, 2, 3]
    --> 99|         a.length()
                    ^^^^^^^^
       100|     except AttributeError as e:

            a:  [1, 2, 3]
        


Use join with str
~~~~~~~~~~~~~~~~~

.. code-block:: none


    Traceback (most recent call last):
      File "TESTS:\runtime\test_attribute_error.py", line 339, in test_Use_join_with_str
        a = ['a', '2'].join('abc') + ['b', '3'].join('\n')
    AttributeError: 'list' object has no attribute 'join'
    
        Вы имели в виду `'abc'.join(['a', '2'])`?
        
    `AttributeError` возникает, когда код содержит что-то вроде
        `object.x`
    где `x` не является методом или атрибутом (переменной), принадлежащим `object`.
    
    У объекта `['a', '2']` нет атрибута с именем `join`.
    Возможно, вы хотели получить что-то вроде `'abc'.join(['a', '2'])`.
    
    Исключение возникло в строке 339 файла TESTS:\runtime\test_attribute_error.py.
    
       337| def test_Use_join_with_str():
       338|     try:
    -->339|         a = ['a', '2'].join('abc') + ['b', '3'].join('\n')
                        ^^^^^^^^^^^^^^^
       340|     except AttributeError as e:


Use synonym
~~~~~~~~~~~

.. code-block:: none


    Traceback (most recent call last):
      File "TESTS:\runtime\test_attribute_error.py", line 115, in test_Use_synonym
        a.add(4)
    AttributeError: 'list' object has no attribute 'add'
    
        Вы имели в виду `append`?
        
    `AttributeError` возникает, когда код содержит что-то вроде
        `object.x`
    где `x` не является методом или атрибутом (переменной), принадлежащим `object`.
    
    У объекта `a` нет атрибута с именем `add`.
    Однако `a` имеет следующие атрибуты с аналогичными значениями:
    `append, extend, insert`.
    
    Исключение возникло в строке 115 файла TESTS:\runtime\test_attribute_error.py.
    
       111| def test_Use_synonym():
       112|     #
       113|     try:
       114|         a = [1, 2, 3]
    -->115|         a.add(4)
                    ^^^^^
       116|     except AttributeError as e:

            a:  [1, 2, 3]
        


Using slots
~~~~~~~~~~~

.. code-block:: none


    Traceback (most recent call last):
      File "TESTS:\runtime\test_attribute_error.py", line 260, in test_Using_slots
        f.b = 1
    AttributeError: 'F' object has no attribute 'b'
    
    `AttributeError` возникает, когда код содержит что-то вроде
        `object.x`
    где `x` не является методом или атрибутом (переменной), принадлежащим `object`.
    
    У объекта `f` нет атрибута с именем `b`.
    Обратите внимание, что объект `f` использует `__slots__`,
    что предотвращает создание новых атрибутов.
    Ниже перечислены некоторые из его известных атрибутов:
    `a`.
    Исключение возникло в строке 260 файла TESTS:\runtime\test_attribute_error.py.
    
       256|     __slots__ = ["a"]
       257| 
       258| f = F()
       259| try:
    -->260|     f.b = 1
                ^^^
       261| except AttributeError as e:

            f:  <F object>
                defined in <function test_attribute_error.test_Using_slots>
        


FileNotFoundError
-----------------


Directory not found
~~~~~~~~~~~~~~~~~~~

.. code-block:: none


    Traceback (most recent call last):
      File "TESTS:\runtime\test_file_not_found_error.py", line 70, in test_Directory_not_found
        open("does_not_exist/file.txt")
    FileNotFoundError: [Errno 2] No such file or directory: 'does_not_exist/file.txt'
    
    `FileNotFoundError` указывает на то, что вы пытаетесь открыть файл,
    который не может быть найден Python.
    Это может быть связано с тем, что вы неправильно написали имя файла.
    
    В вашей программе имя файла,
    который не может быть найден, будет `file.txt`.
    does_not_exist не является допустимой.
    
    Исключение возникло в строке 70 файла TESTS:\runtime\test_file_not_found_error.py.
    
       68| def test_Directory_not_found():
       69|     try:
    -->70|         open("does_not_exist/file.txt")
                   ^^^^^^^^^^^^^^^^^^^^^^^^^^^^^^^
       71|     except FileNotFoundError as e:

            open:  <builtin function open>
        


Filename not found
~~~~~~~~~~~~~~~~~~

.. code-block:: none


    Traceback (most recent call last):
      File "TESTS:\runtime\test_file_not_found_error.py", line 7, in test_Filename_not_found
        open("does_not_exist")
    FileNotFoundError: [Errno 2] No such file or directory: 'does_not_exist'
    
    `FileNotFoundError` указывает на то, что вы пытаетесь открыть файл,
    который не может быть найден Python.
    Это может быть связано с тем, что вы неправильно написали имя файла.
    
    В вашей программе имя файла,
    который не может быть найден, будет `does_not_exist`.
    Ожидалось, что он будет найден в
    директории `C:\Users\Andre\github\friendly-traceback\tests`.
    Дополнительной информации нет.
    
    Исключение возникло в строке 7 файла TESTS:\runtime\test_file_not_found_error.py.
    
       5| def test_Filename_not_found():
       6|     try:
    -->7|         open("does_not_exist")
                  ^^^^^^^^^^^^^^^^^^^^^^
       8|     except FileNotFoundError as e:

            open:  <builtin function open>
        


Filename not found 2
~~~~~~~~~~~~~~~~~~~~

.. code-block:: none


    Traceback (most recent call last):
      File "TESTS:\runtime\test_file_not_found_error.py", line 30, in test_Filename_not_found_2
        open("setupp.py")
    FileNotFoundError: [Errno 2] No such file or directory: 'setupp.py'
    
        Вы имели в виду `setup.py`?
        
    `FileNotFoundError` указывает на то, что вы пытаетесь открыть файл,
    который не может быть найден Python.
    Это может быть связано с тем, что вы неправильно написали имя файла.
    
    В вашей программе имя файла,
    который не может быть найден, будет `setupp.py`.
    Ожидалось, что он будет найден в
    директории `C:\Users\Andre\github\friendly-traceback`.
    Файл `setup.py` имеет похожее имя.
    
    Исключение возникло в строке 30 файла TESTS:\runtime\test_file_not_found_error.py.
    
       26| if chdir:
       27|     os.chdir("..")
       28| 
       29| try:
    -->30|     open("setupp.py")
               ^^^^^^^^^^^^^^^^^
       31| except FileNotFoundError as e:

            open:  <builtin function open>
        


Filename not found 3
~~~~~~~~~~~~~~~~~~~~

.. code-block:: none


    Traceback (most recent call last):
      File "TESTS:\runtime\test_file_not_found_error.py", line 52, in test_Filename_not_found_3
        open("setup.pyg")
    FileNotFoundError: [Errno 2] No such file or directory: 'setup.pyg'
    
        Вы имели в виду `setup.py`?
        
    `FileNotFoundError` указывает на то, что вы пытаетесь открыть файл,
    который не может быть найден Python.
    Это может быть связано с тем, что вы неправильно написали имя файла.
    
    В вашей программе имя файла,
    который не может быть найден, будет `setup.pyg`.
    Ожидалось, что он будет найден в
    директории `C:\Users\Andre\github\friendly-traceback`.
    Возможно, вы имели в виду один из следующих файлов с похожими именами:
    `setup.py`, `setup.cfg`
    
    Исключение возникло в строке 52 файла TESTS:\runtime\test_file_not_found_error.py.
    
       49| if chdir:
       50|     os.chdir("..")
       51| try:
    -->52|     open("setup.pyg")
               ^^^^^^^^^^^^^^^^^
       53| except FileNotFoundError as e:

            open:  <builtin function open>
        


ImportError
-----------


Simple import error
~~~~~~~~~~~~~~~~~~~

.. code-block:: none


    Traceback (most recent call last):
      File "TESTS:\runtime\test_import_error.py", line 56, in test_Simple_import_error
        from math import Pi
    ImportError: cannot import name 'Pi' from 'math' (unknown location)
    
        Вы имели в виду `pi`?
        
    `ImportError` указывает на то, что определенный объект не может быть
    импортирован из модуля или пакета. Чаще всего это происходит
    из-за того, что имя объекта написано неправильно.
    
    Возможно, вместо `Pi` вы хотели импортировать `pi` из `math`
    
    Исключение возникло в строке 56 файла TESTS:\runtime\test_import_error.py.
    
       52| multiple_import_on_same_line()
       53| wrong_case()
       54| 
       55| try:
    -->56|     from math import Pi
       57| except ImportError as e:


IndexError
----------


Assignment
~~~~~~~~~~

.. code-block:: none


    Traceback (most recent call last):
      File "TESTS:\runtime\test_index_error.py", line 93, in test_Assignment
        a[13] = 1
    IndexError: list assignment index out of range
    
    `IndexError` возникает, когда вы пытаетесь получить элемент из списка,
    кортежа или аналогичного объекта (последовательности) и используете индекс, который
    не существует. Обычно это происходит потому, что указанный вами индекс
    больше, чем длина последовательности.
    
    Вы попытались присвоить значение индексу `13` из `a`,
    список `list` длины `10`.
    Допустимыми значениями индекса `a` являются целые числа в диапазоне
    от `-10` до `9`.
    
    Исключение возникло в строке 93 файла TESTS:\runtime\test_index_error.py.
    
       89|     assert "You have tried to assign a value to index `1` of `b`," in result
       90|     assert "a `list` which contains no item." in result
       91| 
       92| try:
    -->93|     a[13] = 1
               ^^^^^
       94| except IndexError as e:

            a:  [0, 1, 2, 3, 4, 5, 6, 7, 8, 9]
        


Empty
~~~~~

.. code-block:: none


    Traceback (most recent call last):
      File "TESTS:\runtime\test_index_error.py", line 46, in test_Empty
        c = a[1]
    IndexError: list index out of range
    
        `a` не содержит ни одного элемента.
        
    `IndexError` возникает, когда вы пытаетесь получить элемент из списка,
    кортежа или аналогичного объекта (последовательности) и используете индекс, который
    не существует. Обычно это происходит потому, что указанный вами индекс
    больше, чем длина последовательности.
    
    Вы пытались получить элемент с индексом `1` из `a`,
    список `list`, который не содержит ни одного элемента.
    
    Исключение возникло в строке 46 файла TESTS:\runtime\test_index_error.py.
    
       43| def test_Empty():
       44|     a = []
       45|     try:
    -->46|         c = a[1]
                       ^^^^
       47|     except IndexError as e:

            a:  []
        


Long list
~~~~~~~~~

.. code-block:: none


    Traceback (most recent call last):
      File "TESTS:\runtime\test_index_error.py", line 29, in test_Long_list
        print(a[60], b[0])
    IndexError: list index out of range
    
    `IndexError` возникает, когда вы пытаетесь получить элемент из списка,
    кортежа или аналогичного объекта (последовательности) и используете индекс, который
    не существует. Обычно это происходит потому, что указанный вами индекс
    больше, чем длина последовательности.
    
    Вы пытались получить элемент с индексом `60` из `a`,
    список `list` длиной `40`.
    Допустимыми значениями индекса `a` являются целые числа в диапазоне
    от `-40` до `39`.
    
    Исключение возникло в строке 29 файла TESTS:\runtime\test_index_error.py.
    
       26| a = list(range(40))
       27| b = tuple(range(50))
       28| try:
    -->29|     print(a[60], b[0])
                     ^^^^^
       30| except IndexError as e:

            a:  [0, 1, 2, 3, 4, 5, 6, 7, 8, 9, 10, 11, 12, 13, 14, 15, 16, 17, 18, ...]
                len(a): 40
        
        


Short tuple
~~~~~~~~~~~

.. code-block:: none


    Traceback (most recent call last):
      File "TESTS:\runtime\test_index_error.py", line 10, in test_Short_tuple
        print(a[3], b[2])
    IndexError: tuple index out of range
    
        Помните: первый элемент кортеж `tuple` имеет индекс не 1, а 0.
        
    `IndexError` возникает, когда вы пытаетесь получить элемент из списка,
    кортежа или аналогичного объекта (последовательности) и используете индекс, который
    не существует. Обычно это происходит потому, что указанный вами индекс
    больше, чем длина последовательности.
    
    Вы пытались получить элемент с индексом `3` из `a`,
    кортеж `tuple` длиной `3`.
    Допустимыми значениями индекса `a` являются целые числа в диапазоне
    от `-3` до `2`.
    
    Исключение возникло в строке 10 файла TESTS:\runtime\test_index_error.py.
    
        7| a = (1, 2, 3)
        8| b = [1, 2, 3]
        9| try:
    -->10|     print(a[3], b[2])
                     ^^^^
       11| except IndexError as e:

            a:  (1, 2, 3)
        


KeyError
--------


ChainMap
~~~~~~~~

.. code-block:: none


    Traceback (most recent call last):
      File "PYTHON_LIB:\collections\__init__.py", line 1008, in pop
        return self.maps[0].pop(key, *args)
    KeyError: 42
    
        During handling of the above exception, another exception occurred:
    
    Traceback (most recent call last):
      File "TESTS:\runtime\test_key_error.py", line 62, in test_ChainMap
        d.pop(42)
    KeyError: 'Key not found in the first mapping: 42'
    
    `KeyError` возникает, когда значение не найдено в качестве
    ключа в словаре или аналогичном объекте.
    
    Ключ `42` не найден в `d`, объекте типа `ChainMap`.
    
    Исключение возникло в строке 62 файла TESTS:\runtime\test_key_error.py.
    
       59| from collections import ChainMap
       60| d = ChainMap({}, {})
       61| try:
    -->62|     d.pop(42)
               ^^^^^^^^^
       63| except KeyError as e:

            d:  ChainMap({}, {})
            d.pop:  <bound method ChainMap.pop> of ChainMap({}, {})
        


Forgot to convert to string
~~~~~~~~~~~~~~~~~~~~~~~~~~~

.. code-block:: none


    Traceback (most recent call last):
      File "TESTS:\runtime\test_key_error.py", line 115, in test_Forgot_to_convert_to_string
        print(squares[2])
    KeyError: 2
    
        Вы забыли преобразовать `2` в строку?
        
    `KeyError` возникает, когда значение не найдено в качестве
    ключа в словаре или аналогичном объекте.
    
    В словаре `squares` не найден ключ `2`.
    `squares` содержит строковый ключ, который идентичен `str(2)`.
    Возможно, вы забыли преобразовать ключ в строку.
    
    Исключение возникло в строке 115 файла TESTS:\runtime\test_key_error.py.
    
       112| def test_Forgot_to_convert_to_string():
       113|     squares = {"1": 1, "2": 4, "3": 9}
       114|     try:
    -->115|         print(squares[2])
                          ^^^^^^^^^^
       116|     except KeyError as e:

            squares:  {'1': 1, '2': 4, '3': 9}
        


Generic key error
~~~~~~~~~~~~~~~~~

.. code-block:: none


    Traceback (most recent call last):
      File "TESTS:\runtime\test_key_error.py", line 44, in test_Generic_key_error
        d["c"]
    KeyError: 'c'
    
    `KeyError` возникает, когда значение не найдено в качестве
    ключа в словаре или аналогичном объекте.
    
    В словаре `d` не найден ключ `'c'`.
    
    Исключение возникло в строке 44 файла TESTS:\runtime\test_key_error.py.
    
       41| def test_Generic_key_error():
       42|     d = {"a": 1, "b": 2}
       43|     try:
    -->44|         d["c"]
                   ^^^^^^
       45|     except KeyError as e:

            d:  {'a': 1, 'b': 2}
        


Popitem empty ChainMap
~~~~~~~~~~~~~~~~~~~~~~

.. code-block:: none


    Traceback (most recent call last):
      File "PYTHON_LIB:\collections\__init__.py", line 1001, in popitem
        return self.maps[0].popitem()
    KeyError: 'popitem(): dictionary is empty'
    
        During handling of the above exception, another exception occurred:
    
    Traceback (most recent call last):
      File "TESTS:\runtime\test_key_error.py", line 26, in test_Popitem_empty_ChainMap
        alpha.popitem()
    KeyError: 'No keys found in the first mapping.'
    
        `alpha` -- это пустой `ChainMap`.
        
    `KeyError` возникает, когда значение не найдено в качестве
    ключа в словаре или аналогичном объекте.
    
    Вы попытались получить элемент из `alpha`, который является пустым `ChainMap`.
    
    Исключение возникло в строке 26 файла TESTS:\runtime\test_key_error.py.
    
       23| from collections import ChainMap
       24| alpha = ChainMap({}, {})
       25| try:
    -->26|     alpha.popitem()
               ^^^^^^^^^^^^^^^
       27| except KeyError as e:

            alpha:  ChainMap({}, {})
            alpha.popitem:  <bound method ChainMap.popitem> of ChainMap({}, {})
        


Popitem empty dict
~~~~~~~~~~~~~~~~~~

.. code-block:: none


    Traceback (most recent call last):
      File "TESTS:\runtime\test_key_error.py", line 8, in test_Popitem_empty_dict
        d.popitem()
    KeyError: 'popitem(): dictionary is empty'
    
        `d` -- пустой словарь `dict`.
        
    `KeyError` возникает, когда значение не найдено в качестве
    ключа в словаре или аналогичном объекте.
    
    Вы попытались получить элемент из `d`, который является пустым словарём `dict`.
    
    Исключение возникло в строке 8 файла TESTS:\runtime\test_key_error.py.
    
       5| def test_Popitem_empty_dict():
       6|     d = {}
       7|     try:
    -->8|         d.popitem()
                  ^^^^^^^^^^^
       9|     except KeyError as e:

            d:  {}
            d.popitem:  <builtin method popitem of dict object>
        


Similar names
~~~~~~~~~~~~~

.. code-block:: none


    Traceback (most recent call last):
      File "TESTS:\runtime\test_key_error.py", line 145, in test_Similar_names
        a = second["alpha"]
    KeyError: 'alpha'
    
        Вы имели в виду `'alpha0'`?
        
    `KeyError` возникает, когда значение не найдено в качестве
    ключа в словаре или аналогичном объекте.
    
    В словаре `second` не найден ключ `'alpha'`.
    `second` имеет несколько ключей, похожих на `'alpha'`, включая:
    `'alpha0', 'alpha11', 'alpha12'`.
    
    Исключение возникло в строке 145 файла TESTS:\runtime\test_key_error.py.
    
       141|     assert ok, diff
       142| 
       143| second = {"alpha0": 1, "alpha11": 2, "alpha12": 3}
       144| try:
    -->145|     a = second["alpha"]
                    ^^^^^^^^^^^^^^^
       146| except KeyError as e:

            second:  {'alpha0': 1, 'alpha11': 2, 'alpha12': 3}
        


String by mistake
~~~~~~~~~~~~~~~~~

.. code-block:: none


    Traceback (most recent call last):
      File "TESTS:\runtime\test_key_error.py", line 98, in test_String_by_mistake
        d["(0, 0)"]
    KeyError: '(0, 0)'
    
        Вы ошибочно преобразовали `(0, 0)` в строку.
        
    `KeyError` возникает, когда значение не найдено в качестве
    ключа в словаре или аналогичном объекте.
    
    В словаре `d` не найден ключ `'(0, 0)'`.
    `'(0, 0)'` -- это строка.
    Существует ключ `d`, строковое представление которого
    идентично `'(0, 0)'`.
    
    Исключение возникло в строке 98 файла TESTS:\runtime\test_key_error.py.
    
       94| chain_map_string_by_mistake()  # do not show in docs
       95| 
       96| d = {(0, 0): "origin"}
       97| try:
    -->98|     d["(0, 0)"]
               ^^^^^^^^^^^
       99| except KeyError as e:

            d:  {(0, 0): 'origin'}
        


LookupError
-----------


Generic
~~~~~~~

.. code-block:: none


    Traceback (most recent call last):
      File "TESTS:\runtime\test_lookup_error.py", line 10, in test_Generic
        raise LookupError("Fake message")
    LookupError: Fake message
    
    `LookupError` является базовым классом для исключений, возникающих
    когда ключ или индекс, используемый в связке или последовательности, недействителен.
    Он также может быть вызван непосредственно функцией codecs.lookup().
    
    
    Исключение возникло в строке 10 файла TESTS:\runtime\test_lookup_error.py.
    
        4| def test_Generic():
        5|     try:
        6|         # LookupError is the base class for KeyError and IndexError.
        7|         # It should normally not be raised by user code,
        8|         # other than possibly codecs.lookup(), which is why we raise
        9|         # it directly here for our example.
    -->10|         raise LookupError("Fake message")
       11|     except LookupError as e:

            LookupError:  <class LookupError>
        


ModuleNotFoundError
-------------------


Need to install module
~~~~~~~~~~~~~~~~~~~~~~

.. code-block:: none


    Traceback (most recent call last):
      File "TESTS:\runtime\test_module_not_found_error.py", line 76, in test_Need_to_install_module
        import alphabet
    ModuleNotFoundError: No module named 'alphabet'
    
    `ModuleNotFoundError` указывает на то, что вы
    пытаетесь импортировать модуль, который не может быть найден Python.
    Это может быть связано с тем, что вы неправильно написали имя модуля
    или потому, что он не установлен на вашем компьютере.
    
    Модуль с именем `alphabet` не может быть импортирован.
    Возможно, вам необходимо установить его.
    
    Исключение возникло в строке 76 файла TESTS:\runtime\test_module_not_found_error.py.
    
       74| def test_Need_to_install_module():
       75|     try:
    -->76|         import alphabet
       77|     except ModuleNotFoundError as e:


Not a package
~~~~~~~~~~~~~

.. code-block:: none


    Traceback (most recent call last):
      File "TESTS:\runtime\test_module_not_found_error.py", line 22, in test_Not_a_package
        import os.xxx
    ModuleNotFoundError: No module named 'os.xxx'; 'os' is not a package
    
    `ModuleNotFoundError` указывает на то, что вы
    пытаетесь импортировать модуль, который не может быть найден Python.
    Это может быть связано с тем, что вы неправильно написали имя модуля
    или потому, что он не установлен на вашем компьютере.
    
    `xxx` не может быть импортирован из `os`.
    
    Исключение возникло в строке 22 файла TESTS:\runtime\test_module_not_found_error.py.
    
       19| def test_Not_a_package():
       20| 
       21|     try:
    -->22|         import os.xxx
       23|     except ModuleNotFoundError as e:


Not a package similar name
~~~~~~~~~~~~~~~~~~~~~~~~~~

.. code-block:: none


    Traceback (most recent call last):
      File "TESTS:\runtime\test_module_not_found_error.py", line 36, in test_Not_a_package_similar_name
        import os.pathh
    ModuleNotFoundError: No module named 'os.pathh'; 'os' is not a package
    
        Вы имели в виду `import os.path`?
        
    `ModuleNotFoundError` указывает на то, что вы
    пытаетесь импортировать модуль, который не может быть найден Python.
    Это может быть связано с тем, что вы неправильно написали имя модуля
    или потому, что он не установлен на вашем компьютере.
    
    Возможно, вы имели в виду `import os.path`.
    `path` -- это имя, похожее на `pathh`, и это модуль, который
    может быть импортирован из `os`.
    
    Исключение возникло в строке 36 файла TESTS:\runtime\test_module_not_found_error.py.
    
       34| def test_Not_a_package_similar_name():
       35|     try:
    -->36|         import os.pathh
       37|     except ModuleNotFoundError as e:


Object not module
~~~~~~~~~~~~~~~~~

.. code-block:: none


    Traceback (most recent call last):
      File "TESTS:\runtime\test_module_not_found_error.py", line 49, in test_Object_not_module
        import os.open
    ModuleNotFoundError: No module named 'os.open'; 'os' is not a package
    
        Вы имели в виду `from os import open`?
        
    `ModuleNotFoundError` указывает на то, что вы
    пытаетесь импортировать модуль, который не может быть найден Python.
    Это может быть связано с тем, что вы неправильно написали имя модуля
    или потому, что он не установлен на вашем компьютере.
    
    `open` -- это не отдельный модуль, а объект, который является частью `os`.
    
    
    Исключение возникло в строке 49 файла TESTS:\runtime\test_module_not_found_error.py.
    
       47| def test_Object_not_module():
       48|     try:
    -->49|         import os.open
       50|     except ModuleNotFoundError as e:

            open:  <builtin function open>
        


Similar object not module
~~~~~~~~~~~~~~~~~~~~~~~~~

.. code-block:: none


    Traceback (most recent call last):
      File "TESTS:\runtime\test_module_not_found_error.py", line 62, in test_Similar_object_not_module
        import os.opend
    ModuleNotFoundError: No module named 'os.opend'; 'os' is not a package
    
        Вы имели в виду `from os import open`?
        
    `ModuleNotFoundError` указывает на то, что вы
    пытаетесь импортировать модуль, который не может быть найден Python.
    Это может быть связано с тем, что вы неправильно написали имя модуля
    или потому, что он не установлен на вашем компьютере.
    
    Возможно, вы имели в виду `from os import open`.
    `open` -- это имя, похожее на `opend` и являющееся объектом,
    который может быть импортирован из `os`.
    Другие объекты с похожими именами, которые являются частью
     `os`, включают `popen`.
    
    Исключение возникло в строке 62 файла TESTS:\runtime\test_module_not_found_error.py.
    
       60| def test_Similar_object_not_module():
       61|     try:
    -->62|         import os.opend
       63|     except ModuleNotFoundError as e:


Standard library module
~~~~~~~~~~~~~~~~~~~~~~~

.. code-block:: none


    Traceback (most recent call last):
      File "TESTS:\runtime\test_module_not_found_error.py", line 7, in test_Standard_library_module
        import Tkinter
    ModuleNotFoundError: No module named 'Tkinter'
    
        Вы имели в виду `tkinter`?
        
    `ModuleNotFoundError` указывает на то, что вы
    пытаетесь импортировать модуль, который не может быть найден Python.
    Это может быть связано с тем, что вы неправильно написали имя модуля
    или потому, что он не установлен на вашем компьютере.
    
    Модуль с именем `Tkinter` не может быть импортирован.
    Возможно, вам необходимо установить его.
    `tkinter` -- существующий модуль с похожим именем.
    
    Исключение возникло в строке 7 файла TESTS:\runtime\test_module_not_found_error.py.
    
       5| def test_Standard_library_module():
       6|     try:
    -->7|         import Tkinter
       8|     except ModuleNotFoundError as e:


no curses
~~~~~~~~~

.. code-block:: none


    Traceback (most recent call last):
      File "TESTS:\runtime\test_module_not_found_error.py", line 92, in test_no_curses
        import curses
    ModuleNotFoundError: No module named '_curses'
    
        Модуль curses редко устанавливается вместе с Python в Windows.
        
    `ModuleNotFoundError` указывает на то, что вы
    пытаетесь импортировать модуль, который не может быть найден Python.
    Это может быть связано с тем, что вы неправильно написали имя модуля
    или потому, что он не установлен на вашем компьютере.
    
    Вы попытались импортировать модуль curses.
    Модуль curses редко устанавливается вместе с Python в Windows.
    
    Исключение возникло в строке 92 файла TESTS:\runtime\test_module_not_found_error.py.
    
       90| def test_no_curses():
       91|     try:
    -->92|         import curses
       93|     except ModuleNotFoundError as e:


NameError
---------


Annotated variable
~~~~~~~~~~~~~~~~~~

.. code-block:: none


    Traceback (most recent call last):
      File "TESTS:\runtime\test_name_error.py", line 30, in test_Annotated_variable
        y = x
    NameError: name 'x' is not defined
    
        Вы использовали двоеточие вместо знака равенства?
        
    `NameError` указывает на то, что переменная или
    имя переменной либо функции неизвестно Python.
    Чаще всего это происходит из-за орфографической ошибки.
    Однако иногда это происходит потому, что имя используется
    до того, как оно было обьявлено или инициализировано.
    
    В вашей программе не существует объекта с именем `x`.
    Найдена подсказка типа для `x` в области видимости global.
    Возможно, вы использовали двоеточие вместо знака равенства и написали
    
        x : 3
    
    вместо
    
        x = 3
    
    Исключение возникло в строке 30 файла TESTS:\runtime\test_name_error.py.
    
       28| def test_Annotated_variable():
       29|     try:
    -->30|         y = x
                       ^
       31|     except NameError as e:


Custom name
~~~~~~~~~~~

.. code-block:: none


    Traceback (most recent call last):
      File "TESTS:\runtime\test_name_error.py", line 198, in test_Custom_name
        python
    NameError: name 'python' is not defined
    
        Вы уже используете Python!
    `NameError` указывает на то, что переменная или
    имя переменной либо функции неизвестно Python.
    Чаще всего это происходит из-за орфографической ошибки.
    Однако иногда это происходит потому, что имя используется
    до того, как оно было обьявлено или инициализировано.
    
    Вы уже используете Python!
    Исключение возникло в строке 198 файла TESTS:\runtime\test_name_error.py.
    
       196| def test_Custom_name():
       197|     try:
    -->198|         python
                    ^^^^^^
       199|     except NameError as e:


Free variable referenced
~~~~~~~~~~~~~~~~~~~~~~~~

.. code-block:: none


    Traceback (most recent call last):
      File "TESTS:\runtime\test_name_error.py", line 182, in test_Free_variable_referenced
        outer()
      File "TESTS:\runtime\test_name_error.py", line 178, in outer
        inner()
      File "TESTS:\runtime\test_name_error.py", line 177, in inner
        return var
    NameError: free variable 'var' referenced before assignment in enclosing scope
    
    `NameError` указывает на то, что переменная или
    имя переменной либо функции неизвестно Python.
    Чаще всего это происходит из-за орфографической ошибки.
    Однако иногда это происходит потому, что имя используется
    до того, как оно было обьявлено или инициализировано.
    
    В вашей программе `var` -- это неизвестное имя,
    которому еще не присвоено значение.
    
    Выполнение остановлено на строке 182 файла TESTS:\runtime\test_name_error.py.
    
       178|     inner()
       179|     var = 4
       180| 
       181| try:
    -->182|     outer()
                ^^^^^^^
       183| except NameError as e:

            outer:  <function outer>
                defined in <function test_Free_variable_referenced>
        
    Исключение возникло в строке 177 файла TESTS:\runtime\test_name_error.py.
    
       176| def inner():
    -->177|     return var
                       ^^^


Generic
~~~~~~~

.. code-block:: none


    Traceback (most recent call last):
      File "TESTS:\runtime\test_name_error.py", line 15, in test_Generic
        this = something
    NameError: name 'something' is not defined
    
    `NameError` указывает на то, что переменная или
    имя переменной либо функции неизвестно Python.
    Чаще всего это происходит из-за орфографической ошибки.
    Однако иногда это происходит потому, что имя используется
    до того, как оно было обьявлено или инициализировано.
    
    В вашей программе не существует объекта с именем `something`.
    Дополнительной информации нет.
    
    Исключение возникло в строке 15 файла TESTS:\runtime\test_name_error.py.
    
       13| def test_Generic():
       14|     try:
    -->15|         this = something
                          ^^^^^^^^^
       16|     except NameError as e:


Missing import
~~~~~~~~~~~~~~

.. code-block:: none


    Traceback (most recent call last):
      File "TESTS:\runtime\test_name_error.py", line 135, in test_Missing_import
        unicodedata.something
    NameError: name 'unicodedata' is not defined
    
        Вы забыли импортировать `unicodedata`?
        
    `NameError` указывает на то, что переменная или
    имя переменной либо функции неизвестно Python.
    Чаще всего это происходит из-за орфографической ошибки.
    Однако иногда это происходит потому, что имя используется
    до того, как оно было обьявлено или инициализировано.
    
    
    Имя `unicodedata` не определено в вашей программе.
    Возможно, вы забыли импортировать `unicodedata`, которое находится
    в стандартной библиотеке Python.
    
    `unicodedata` -- это имя, найденное в модуле `stringprep`.
    Возможно, вы забыли написать
    
        from stringprep import unicodedata
    
    Исключение возникло в строке 135 файла TESTS:\runtime\test_name_error.py.
    
       131| if friendly_traceback.get_lang() == "en":
       132|     assert "I have no additional information for you." in result
       133| 
       134| try:
    -->135|     unicodedata.something
                ^^^^^^^^^^^
       136| except NameError as e:


Missing module name
~~~~~~~~~~~~~~~~~~~

.. code-block:: none


    Traceback (most recent call last):
      File "TESTS:\runtime\test_name_error.py", line 281, in test_Missing_module_name
        frame = Frame()
    NameError: name 'Frame' is not defined
    
        Вы забыли добавить `tkinter.`?
        
    `NameError` указывает на то, что переменная или
    имя переменной либо функции неизвестно Python.
    Чаще всего это происходит из-за орфографической ошибки.
    Однако иногда это происходит потому, что имя используется
    до того, как оно было обьявлено или инициализировано.
    
    В вашей программе не существует объекта с именем `Frame`.
    
    Объект global `tkinter`
    имеет атрибут с именем `Frame`.
    Возможно, вам следовало написать `tkinter.Frame`
    вместо `Frame`.
    
    `Frame` - это имя, встречающееся в следующих модулях из стандартной библиотеки:
    tkinter, tracemalloc.
    Возможно, вы забыли импортировать `Frame` из одного из этих модулей.
    
    Исключение возникло в строке 281 файла TESTS:\runtime\test_name_error.py.
    
       278| @pytest.mark.skipif(not tkinter, reason="tkinter not present; likely MacOS")
       279| def test_Missing_module_name():
       280|     try:
    -->281|         frame = Frame()
                            ^^^^^
       282|     except NameError as e:


Missing self 1
~~~~~~~~~~~~~~

.. code-block:: none


    Traceback (most recent call last):
      File "TESTS:\runtime\test_name_error.py", line 233, in test_Missing_self_1
        str(a)
      File "TESTS:\runtime\test_name_error.py", line 224, in __str__
        toys_list = add_toy(  # ensure that it can see 'self' on following line
    NameError: name 'add_toy' is not defined
    
        Вы написали `self` не в том месте?
        
    `NameError` указывает на то, что переменная или
    имя переменной либо функции неизвестно Python.
    Чаще всего это происходит из-за орфографической ошибки.
    Однако иногда это происходит потому, что имя используется
    до того, как оно было обьявлено или инициализировано.
    
    В вашей программе не существует объекта с именем `add_toy`.
    
    Объект local `<Pet object> defined in <function test_name_error.test_Missing_self_1>`
    имеет атрибут с именем `add_toy`.
    Возможно, вам следовало написать `self.add_toy(...`
    вместо `add_toy(self, ...`.
    
    Выполнение остановлено на строке 233 файла TESTS:\runtime\test_name_error.py.
    
       229|             return "{} has no toys".format(self.name)
       230| 
       231| a = Pet('Fido')
       232| try:
    -->233|     str(a)
                ^^^^^^
       234| except NameError as e:

            a:  <Pet object>
                defined in <function test_name_error.test_Missing_self_1>
            str:  <class str>
        
    Исключение возникло в строке 224 файла TESTS:\runtime\test_name_error.py.
    
       222| def __str__(self):
       223|     # self at the wrong place
    -->224|     toys_list = add_toy(  # ensure that it can see 'self' on following line
                            ^^^^^^^
       225|                         self, 'something')
       226|     if self.toys:


Missing self 2
~~~~~~~~~~~~~~

.. code-block:: none


    Traceback (most recent call last):
      File "TESTS:\runtime\test_name_error.py", line 267, in test_Missing_self_2
        str(a)
      File "TESTS:\runtime\test_name_error.py", line 259, in __str__
        toys_list = add_toy('something')
    NameError: name 'add_toy' is not defined
    
        Вы забыли добавить `self.`?
        
    `NameError` указывает на то, что переменная или
    имя переменной либо функции неизвестно Python.
    Чаще всего это происходит из-за орфографической ошибки.
    Однако иногда это происходит потому, что имя используется
    до того, как оно было обьявлено или инициализировано.
    
    В вашей программе не существует объекта с именем `add_toy`.
    
    Объект local, `<Pet object> defined in <function test_name_error.test_Missing_self_2>`,
    имеет атрибут с именем `add_toy`.
    Возможно, вам следовало написать `self.add_toy`
    вместо `add_toy`.
    
    Выполнение остановлено на строке 267 файла TESTS:\runtime\test_name_error.py.
    
       263|             return "{} has no toys".format(self.name)
       264| 
       265| a = Pet('Fido')
       266| try:
    -->267|     str(a)
                ^^^^^^
       268| except NameError as e:

            a:  <Pet object>
                defined in <function test_name_error.test_Missing_self_2>
            str:  <class str>
        
    Исключение возникло в строке 259 файла TESTS:\runtime\test_name_error.py.
    
       257| def __str__(self):
       258|     # Missing self.
    -->259|     toys_list = add_toy('something')
                            ^^^^^^^
       260|     if self.toys:


Synonym
~~~~~~~

.. code-block:: none


    Traceback (most recent call last):
      File "TESTS:\runtime\test_name_error.py", line 95, in test_Synonym
        cost  # wrote from math import * above
    NameError: name 'cost' is not defined
    
        Вы имели в виду `cos`?
        
    `NameError` указывает на то, что переменная или
    имя переменной либо функции неизвестно Python.
    Чаще всего это происходит из-за орфографической ошибки.
    Однако иногда это происходит потому, что имя используется
    до того, как оно было обьявлено или инициализировано.
    
    В вашей программе не существует объекта с именем `cost`.
    Вместо того, чтобы написать `cost`, возможно, вы имели в виду следующее:
    *  Глобальная область видимости: `cos`, `cosh`
    
    Исключение возникло в строке 95 файла TESTS:\runtime\test_name_error.py.
    
       91| if friendly_traceback.get_lang() == "en":
       92|     assert "The Python builtin `chr` has a similar name." in result
       93| 
       94| try:
    -->95|     cost  # wrote from math import * above
               ^^^^
       96| except NameError as e:


missing import2
~~~~~~~~~~~~~~~

.. code-block:: none


    Traceback (most recent call last):
      File "TESTS:\runtime\test_name_error.py", line 149, in test_missing_import2
        ABCMeta
    NameError: name 'ABCMeta' is not defined
    
    `NameError` указывает на то, что переменная или
    имя переменной либо функции неизвестно Python.
    Чаще всего это происходит из-за орфографической ошибки.
    Однако иногда это происходит потому, что имя используется
    до того, как оно было обьявлено или инициализировано.
    
    В вашей программе не существует объекта с именем `ABCMeta`.
    `ABCMeta` - это имя, встречающееся в следующих модулях из стандартной библиотеки:
    abc, numbers, selectors, typing.
    Возможно, вы забыли импортировать `ABCMeta` из одного из этих модулей.
    
    Исключение возникло в строке 149 файла TESTS:\runtime\test_name_error.py.
    
       147| def test_missing_import2():
       148|     try:
    -->149|         ABCMeta
                    ^^^^^^^
       150|     except NameError as e:


missing import3
~~~~~~~~~~~~~~~

.. code-block:: none


    Traceback (most recent call last):
      File "TESTS:\runtime\test_name_error.py", line 163, in test_missing_import3
        AF_APPLETALK
    NameError: name 'AF_APPLETALK' is not defined
    
    `NameError` указывает на то, что переменная или
    имя переменной либо функции неизвестно Python.
    Чаще всего это происходит из-за орфографической ошибки.
    Однако иногда это происходит потому, что имя используется
    до того, как оно было обьявлено или инициализировано.
    
    В вашей программе не существует объекта с именем `AF_APPLETALK`.
    `AF_APPLETALK` -- это имя, найденное в модуле `socket`.
    Возможно, вы забыли написать
    
        from socket import AF_APPLETALK
    
    Исключение возникло в строке 163 файла TESTS:\runtime\test_name_error.py.
    
       161| def test_missing_import3():
       162|     try:
    -->163|         AF_APPLETALK
                    ^^^^^^^^^^^^
       164|     except NameError as e:


special keyword
~~~~~~~~~~~~~~~

.. code-block:: none


    Traceback (most recent call last):
      File "TESTS:\runtime\test_name_error.py", line 312, in test_special_keyword
        brek
    NameError: name 'brek' is not defined
    
        Вы имели в виду `break`?
        
    `NameError` указывает на то, что переменная или
    имя переменной либо функции неизвестно Python.
    Чаще всего это происходит из-за орфографической ошибки.
    Однако иногда это происходит потому, что имя используется
    до того, как оно было обьявлено или инициализировано.
    
    Подозреваю, что ключевое слово `break` вы написали по ошибке.
    
    Исключение возникло в строке 312 файла TESTS:\runtime\test_name_error.py.
    
       309| if friendly_traceback.get_lang() == "en":
       310|     assert "Did you mean `continue`" in result
       311| try:
    -->312|     brek
                ^^^^
       313| except NameError as e:


OsError
-------


Urllib error
~~~~~~~~~~~~

.. code-block:: none


    Traceback (most recent call last):
      File "PYTHON_LIB:\urllib\request.py", line 1346, in do_open
           ... Другие строки не показаны. ...
      File "PYTHON_LIB:\socket.py", line 823, in create_connection
        for res in getaddrinfo(host, port, 0, SOCK_STREAM):
      File "PYTHON_LIB:\socket.py", line 954, in getaddrinfo
        for res in _socket.getaddrinfo(host, port, family, type, proto, flags):
    socket.gaierror: [Errno 11001] getaddrinfo failed
    
        During handling of the above exception, another exception occurred:
    
    Traceback (most recent call last):
      File "TESTS:\runtime\test_os_error.py", line 10, in test_Urllib_error
        request.urlopen("http://does_not_exist")
    URLError: <urlopen error [Errno 11001] getaddrinfo failed>
    
    Исключение типа `URLError` является наследником `OSError`.
    
    `OSError` обычно вызывается операционной системой чтобы указать,
    что операция не разрешена или что ресурс недоступен.
    
    Предполагаю, что вы пытаетесь подключиться к серверу
    и что соединение не может быть установлено.
    Если это так, проверьте, нет ли опечаток в URL-адресе
    и проверьте подключение к Интернету.
    
    Исключение возникло в строке 10 файла TESTS:\runtime\test_os_error.py.
    
        6| @pytest.mark.skipif(random.randint(0, 50) < 59, reason="very long test")
        7| def test_Urllib_error():
        8|     from urllib import request, error
        9|     try:
    -->10|         request.urlopen("http://does_not_exist")
                   ^^^^^^^^^^^^^^^^^^^^^^^^^^^^^^^^^^^^^^^^
       11|     except error.URLError as e:

            request:  <module urllib.request> from PYTHON_LIB:\urllib\request.py
            request.urlopen:  <function urlopen>
        


invalid argument
~~~~~~~~~~~~~~~~

.. code-block:: none


    Traceback (most recent call last):
      File "TESTS:\runtime\test_os_error.py", line 48, in test_invalid_argument
        open("c:\test.txt")
    OSError: [Errno 22] Invalid argument: 'c:\test.txt'
    
        Возможно, вам нужно удвоить символы обратной косой черты.
        
    `OSError` обычно вызывается операционной системой чтобы указать,
    что операция не разрешена или что ресурс недоступен.
    
    Предполагаю, что вы написали имя файла или путь, который содержит
    по крайней мере один символ обратной косой черты, `\`.
    Python, вероятно, интерпретировал это как начало того,
    что известно как последовательность экранирования.
    Чтобы решить эту проблему, либо напишите так называемую 'необработанную строку', добавив букву `r` в качестве префикса перед
    именем файла или путем, либо замените все одинарные символы обратной косой черты `\` на двойные: `\\`.
    
    Исключение возникло в строке 48 файла TESTS:\runtime\test_os_error.py.
    
       45| if os.name != "nt":
       46|     return "Windows test only", "No result"
       47| try:
    -->48|     open("c:\test.txt")
               ^^^^^^^^^^^^^^^^^^^
       49| except OSError as e:

            open:  <builtin function open>
        


no information
~~~~~~~~~~~~~~

.. code-block:: none


    Traceback (most recent call last):
      File "TESTS:\runtime\test_os_error.py", line 29, in test_no_information
        raise OSError("Some unknown message")
    OSError: Some unknown message
    
        Friendly-traceback не определил причину возникновения этой ошибки.
        
        
    `OSError` обычно вызывается операционной системой чтобы указать,
    что операция не разрешена или что ресурс недоступен.
    
    По этому исключению информации нет.
    Пожалуйста, сообщите об этом примере по адресу
    https://github.com/friendly-traceback/friendly-traceback/issues/new
    Если вы используете REPL, используйте для этого `www('bug')`.
    
    Если вы используете консоль Friendly, используйте `www()`, чтобы
    выполнить поиск в Интернете для этого конкретного случая.
    
    Исключение возникло в строке 29 файла TESTS:\runtime\test_os_error.py.
    
       26| old_debug = friendly_traceback.debug_helper.DEBUG
       27| friendly_traceback.debug_helper.DEBUG = False
       28| try:
    -->29|     raise OSError("Some unknown message")
       30| except OSError as e:

            OSError:  <class OSError>
        


OverflowError
-------------


Generic
~~~~~~~

.. code-block:: none


    Traceback (most recent call last):
      File "TESTS:\runtime\test_overflow_error.py", line 6, in test_Generic
        2.0 ** 1600
    OverflowError: (34, 'Result too large')
    
    `OverflowError` возникает, когда результат арифметической операции слишком велик
    для того, чтобы его мог обработать процессор компьютера.
    
    Исключение возникло в строке 6 файла TESTS:\runtime\test_overflow_error.py.
    
       4| def test_Generic():
       5|     try:
    -->6|         2.0 ** 1600
                  ^^^^^^^^^^^
       7|     except OverflowError as e:


Huge lenght
~~~~~~~~~~~

.. code-block:: none


    Traceback (most recent call last):
      File "TESTS:\runtime\test_overflow_error.py", line 24, in test_Huge_lenght
        len(huge)
    OverflowError: Python int too large to convert to C ssize_t
    
    `OverflowError` возникает, когда результат арифметической операции слишком велик
    для того, чтобы его мог обработать процессор компьютера.
    
    Исключение возникло в строке 24 файла TESTS:\runtime\test_overflow_error.py.
    
       21| def test_Huge_lenght():
       22|     huge = range(1<<10000)
       23|     try:
    -->24|         len(huge)
                   ^^^^^^^^^
       25|     except OverflowError as e:

            huge:  range(0, ...)
                   len(huge): Объект слишком велик для обработки Python.
        
            len:  <builtin function len>
        


RecursionError
--------------


Generic
~~~~~~~

.. code-block:: none


    Traceback (most recent call last):
      File "TESTS:\runtime\test_recursion_error.py", line 8, in test_Generic
        a()
           ... Другие строки не показаны. ...
      File "TESTS:\runtime\test_recursion_error.py", line 6, in a
        return a()
      File "TESTS:\runtime\test_recursion_error.py", line 6, in a
        return a()
    RecursionError: maximum recursion depth exceeded
    
    `RecursionError` возникает, когда функция вызывает сама себя
    прямо или косвенно, слишком много раз.
    Это почти всегда указывает на то, что вы допустили ошибку в своем коде
    и что ваша программа никогда не завершится.
    
    Выполнение остановлено на строке 8 файла TESTS:\runtime\test_recursion_error.py.
    
       5| def a():
       6|     return a()
       7| try:
    -->8|     a()
              ^^^
       9| except RecursionError as e:

            a:  <function a> defined in <function test_Generic>
        
    Исключение возникло в строке 6 файла TESTS:\runtime\test_recursion_error.py.
    
       5| def a():
    -->6|     return a()
                     ^^^

            a:  <function a> defined in <function test_Generic>
        


TypeError
---------


Argument of object is not iterable
~~~~~~~~~~~~~~~~~~~~~~~~~~~~~~~~~~

.. code-block:: none


    Traceback (most recent call last):
      File "TESTS:\runtime\test_type_error.py", line 804, in test_Argument_of_object_is_not_iterable
        a in b
    TypeError: argument of type 'object' is not iterable
    
    `TypeError` обычно возникает при попытке
    объединить два несовместимых типа объектов,
    вызовом функции с объектом неправильного типа,
    или при попытке выполнить операцию, недопустимую для данного типа объекта.
    
    Итерабельность - это объект, способный возвращать свои члены по одному за раз.
    Контейнеры Python (`list, tuple, dict` и т.д.) являются итерабельными.
    'b' не является контейнером. Здесь требуется контейнер.
    
    Исключение возникло в строке 804 файла TESTS:\runtime\test_type_error.py.
    
       801| a = object()
       802| b = object()
       803| try:
    -->804|     a in b
                ^^^^^^
       805| except TypeError as e:

            a:  <object object>
            b:  <object object>
        


Bad type for unary operator
~~~~~~~~~~~~~~~~~~~~~~~~~~~

.. code-block:: none


    Traceback (most recent call last):
      File "TESTS:\runtime\test_type_error.py", line 398, in test_Bad_type_for_unary_operator
        a =+ "def"
    TypeError: bad operand type for unary +: 'str'
    
        Возможно, вы хотели написать `+=` вместо `=+`
    `TypeError` обычно возникает при попытке
    объединить два несовместимых типа объектов,
    вызовом функции с объектом неправильного типа,
    или при попытке выполнить операцию, недопустимую для данного типа объекта.
    
    Вы попытались использовать унарный оператор '+'
    со следующим типом объекта: строка (`str`).
    Эта операция не определена для данного типа объекта.
    
    Возможно, вы хотели написать `+=` вместо `=+`
    
    Исключение возникло в строке 398 файла TESTS:\runtime\test_type_error.py.
    
       393|     assert "You tried to use the unary operator '~'" in result
       394| 
       395| try:
       396|     # fmt: off
       397|     a = "abc"
    -->398|     a =+ "def"
                   ^^^^^^^
       399|     # fmt: on


Builtin has no len
~~~~~~~~~~~~~~~~~~

.. code-block:: none


    Traceback (most recent call last):
      File "TESTS:\runtime\test_type_error.py", line 859, in test_Builtin_has_no_len
        len("Hello world".split)
    TypeError: object of type 'builtin_function_or_method' has no len()
    
        Вы забыли вызвать `"Hello world".split`?
        
    `TypeError` обычно возникает при попытке
    объединить два несовместимых типа объектов,
    вызовом функции с объектом неправильного типа,
    или при попытке выполнить операцию, недопустимую для данного типа объекта.
    
    Предполагаю, что вы забыли добавить круглые скобки для вызова `"Hello world".split`.
    Возможно, вы хотели написать:
    `len("Hello world".split())`.
    
    Исключение возникло в строке 859 файла TESTS:\runtime\test_type_error.py.
    
       857| def test_Builtin_has_no_len():
       858|     try:
    -->859|         len("Hello world".split)
                    ^^^^^^^^^^^^^^^^^^^^^^^^
       860|     except TypeError as e:

            len:  <builtin function len>
            "Hello world".split:  <builtin method split of str object>
        


Can only concatenate
~~~~~~~~~~~~~~~~~~~~

.. code-block:: none


    Traceback (most recent call last):
      File "TESTS:\runtime\test_type_error.py", line 39, in test_Can_only_concatenate
        result = a_tuple + a_list
    TypeError: can only concatenate tuple (not "list") to tuple
    
    `TypeError` обычно возникает при попытке
    объединить два несовместимых типа объектов,
    вызовом функции с объектом неправильного типа,
    или при попытке выполнить операцию, недопустимую для данного типа объекта.
    
    Вы попытались обьединить (сложить) два разных типа объектов:
    кортеж `tuple` и список `list`.
    
    Исключение возникло в строке 39 файла TESTS:\runtime\test_type_error.py.
    
       36| try:
       37|     a_tuple = (1, 2, 3)
       38|     a_list = [1, 2, 3]
    -->39|     result = a_tuple + a_list
                        ^^^^^^^^^^^^^^^^
       40| except TypeError as e:

            a_list:  [1, 2, 3]
            a_tuple:  (1, 2, 3)
        


Cannot convert dictionary update sequence
~~~~~~~~~~~~~~~~~~~~~~~~~~~~~~~~~~~~~~~~~

.. code-block:: none


    Traceback (most recent call last):
      File "TESTS:\runtime\test_type_error.py", line 845, in test_Cannot_convert_dictionary_update_sequence
        dd.update([1, 2, 3])
    TypeError: cannot convert dictionary update sequence element #0 to a sequence
    
        Возможно, вам следует использовать метод `dict.fromkeys()`.
        
    `TypeError` обычно возникает при попытке
    объединить два несовместимых типа объектов,
    вызовом функции с объектом неправильного типа,
    или при попытке выполнить операцию, недопустимую для данного типа объекта.
    
    `dict.update()` не принимает последовательность в качестве аргумента.
    Вместо того, чтобы писать `dd.update([1, 2, 3])`
    возможно, следует использовать метод `dict.fromkeys()`: `dd.update( dict.fromkeys([1, 2, 3]) )`.
    
    Исключение возникло в строке 845 файла TESTS:\runtime\test_type_error.py.
    
       841|     assert "you should use the `dict.fromkeys()`" in result
       842| 
       843| dd = {"a": "a"}
       844| try:
    -->845|     dd.update([1, 2, 3])
                ^^^^^^^^^^^^^^^^^^^^
       846| except TypeError as e:

            dd:  {'a': 'a'}
            dd.update:  <builtin method update of dict object>
        


Cannot multiply by non int
~~~~~~~~~~~~~~~~~~~~~~~~~~

.. code-block:: none


    Traceback (most recent call last):
      File "TESTS:\runtime\test_type_error.py", line 614, in test_Cannot_multiply_by_non_int
        "a" * "2"
    TypeError: can't multiply sequence by non-int of type 'str'
    
        Вы забыли преобразовать `"2"` в целое число?
        
    `TypeError` обычно возникает при попытке
    объединить два несовместимых типа объектов,
    вызовом функции с объектом неправильного типа,
    или при попытке выполнить операцию, недопустимую для данного типа объекта.
    
    Вы можете умножать только последовательности, такие как список, кортежи,
    строки и т.д., на целые числа.
    Возможно, вы забыли преобразовать `"2"` в целое число.
    
    Исключение возникло в строке 614 файла TESTS:\runtime\test_type_error.py.
    
       610| if friendly_traceback.get_lang() == "en":
       611|     assert "Did you forget to convert `c` into an integer?" in result
       612| 
       613| try:
    -->614|     "a" * "2"
                ^^^^^^^^^
       615| except TypeError as e:


Cannot unpack non iterable object
~~~~~~~~~~~~~~~~~~~~~~~~~~~~~~~~~

.. code-block:: none


    Traceback (most recent call last):
      File "TESTS:\runtime\test_type_error.py", line 817, in test_Cannot_unpack_non_iterable_object
        a, b = 42.0
    TypeError: cannot unpack non-iterable float object
    
    `TypeError` обычно возникает при попытке
    объединить два несовместимых типа объектов,
    вызовом функции с объектом неправильного типа,
    или при попытке выполнить операцию, недопустимую для данного типа объекта.
    
    Распаковка является удобным способом присвоить имя
    каждому элементу итерирумого обьекта.
    Итерабельным является объект, способный возвращать свои элементы по одному за раз.
    Контейнеры Python (`list, tuple, dict` и т.д.) являются итерабельными,
    но не объекты типа `float`.
    
    Исключение возникло в строке 817 файла TESTS:\runtime\test_type_error.py.
    
       815| def test_Cannot_unpack_non_iterable_object():
       816|     try:
    -->817|         a, b = 42.0
       818|     except TypeError as e:


Comparison not supported
~~~~~~~~~~~~~~~~~~~~~~~~

.. code-block:: none


    Traceback (most recent call last):
      File "TESTS:\runtime\test_type_error.py", line 347, in test_Comparison_not_supported
        b >= a
    TypeError: '>=' not supported between instances of 'int' and 'str'
    
        Вы забыли преобразовать строку `a` в целое число (`int`)?
        
    `TypeError` обычно возникает при попытке
    объединить два несовместимых типа объектов,
    вызовом функции с объектом неправильного типа,
    или при попытке выполнить операцию, недопустимую для данного типа объекта.
    
    Вы попытались выполнить порядковое сравнение (>=)
    двух несовместимых типов объектов:
    целое число (`int`) и строка (`str`).
    Возможно, вы забыли преобразовать строку `a` в целое число (`int`).
    
    Исключение возникло в строке 347 файла TESTS:\runtime\test_type_error.py.
    
       344| try:
       345|     a = "2"
       346|     b = 42
    -->347|     b >= a
                ^^^^^^
       348| except TypeError as e:

            a:  '2'
            b:  42
        


Derive from BaseException
~~~~~~~~~~~~~~~~~~~~~~~~~

.. code-block:: none


    Traceback (most recent call last):
      File "TESTS:\runtime\test_type_error.py", line 557, in test_Derive_from_BaseException
        raise "exception"  # noqa
    TypeError: exceptions must derive from BaseException
    
    `TypeError` обычно возникает при попытке
    объединить два несовместимых типа объектов,
    вызовом функции с объектом неправильного типа,
    или при попытке выполнить операцию, недопустимую для данного типа объекта.
    
    В Python 3 исключения должны быть производными от BaseException.
    
    Исключение возникло в строке 557 файла TESTS:\runtime\test_type_error.py.
    
       555| def test_Derive_from_BaseException():
       556|     try:
    -->557|         raise "exception"  # noqa
       558|     except TypeError as e:


Generator has no len
~~~~~~~~~~~~~~~~~~~~

.. code-block:: none


    Traceback (most recent call last):
      File "TESTS:\runtime\test_type_error.py", line 1014, in test_Generator_has_no_len
        nb = len(letter
    TypeError: object of type 'generator' has no len()
    
        You likely need to build a list first.
        
    `TypeError` обычно возникает при попытке
    объединить два несовместимых типа объектов,
    вызовом функции с объектом неправильного типа,
    или при попытке выполнить операцию, недопустимую для данного типа объекта.
    
    I am guessing that you were trying to count the number of elements
    produced by a generator expression. You first need to capture them
    in a list:
    
        len([letter for letter in "word"])
    
    Исключение возникло в строке 1014 файла TESTS:\runtime\test_type_error.py.
    
       1012| def test_Generator_has_no_len():
       1013|     try:
    -->1014|         nb = len(letter
                          ^^^^^^^^^^
       1015|                  for letter in "word")
                              ^^^^^^^^^^^^^^^^^^^^^
       1016|     except TypeError as e:

            len:  <builtin function len>
        


Indices must be integers or slices
~~~~~~~~~~~~~~~~~~~~~~~~~~~~~~~~~~

.. code-block:: none


    Traceback (most recent call last):
      File "TESTS:\runtime\test_type_error.py", line 696, in test_Indices_must_be_integers_or_slices
        [1, 2, 3]["2"]
    TypeError: list indices must be integers or slices, not str
    
        Вы забыли преобразовать `"2"` в целое число?
        
    `TypeError` обычно возникает при попытке
    объединить два несовместимых типа объектов,
    вызовом функции с объектом неправильного типа,
    или при попытке выполнить операцию, недопустимую для данного типа объекта.
    
    В выражении `[1, 2, 3]["2"]`
    то, что включено между квадратными скобками, `[...]`,
    должно быть либо целым числом, либо фрагментом
    (`start:stop` или `start:stop:step`) 
    а вы вместо этого использовали строка (`str`).
    
    Возможно, вы забыли преобразовать `"2"` в целое число.
    
    Исключение возникло в строке 696 файла TESTS:\runtime\test_type_error.py.
    
       692| if friendly_traceback.get_lang() == "en":
       693|     assert "Perhaps you forgot to convert `2.0` into an integer." in result
       694| 
       695| try:
    -->696|     [1, 2, 3]["2"]
                ^^^^^^^^^^^^^^
       697| except TypeError as e:


Not an integer
~~~~~~~~~~~~~~

.. code-block:: none


    Traceback (most recent call last):
      File "TESTS:\runtime\test_type_error.py", line 659, in test_Not_an_integer
        range(c, d)
    TypeError: 'str' object cannot be interpreted as an integer
    
        Вы забыли преобразовать `c, d` в целые числа?
        
    `TypeError` обычно возникает при попытке
    объединить два несовместимых типа объектов,
    вызовом функции с объектом неправильного типа,
    или при попытке выполнить операцию, недопустимую для данного типа объекта.
    
    Вы записали объект типа `str`, где ожидалось целочисленное значение.
    Возможно, вы забыли преобразовать `c, d` в целые числа.
    Исключение возникло в строке 659 файла TESTS:\runtime\test_type_error.py.
    
       655|     assert "Perhaps you forgot to convert `1.0" in result
       656| 
       657| c, d = "2", "3"
       658| try:
    -->659|     range(c, d)
                ^^^^^^^^^^^
       660| except TypeError as e:

            c:  '2'
            d:  '3'
            range:  <class range>
        


Not callable
~~~~~~~~~~~~

.. code-block:: none


    Traceback (most recent call last):
      File "TESTS:\runtime\test_type_error.py", line 541, in test_Not_callable
        _ = [1, 2](a + b)
    TypeError: 'list' object is not callable
    
        Вы имели в виду `[1, 2][a + b]`?
        
    `TypeError` обычно возникает при попытке
    объединить два несовместимых типа объектов,
    вызовом функции с объектом неправильного типа,
    или при попытке выполнить операцию, недопустимую для данного типа объекта.
    
    Из-за окружающих скобок, `(a + b)` 
    интерпретируется Python как вызов функции для 
    `[1, 2]`, которая является объектом типа `list`
    который не может быть вызван.
    
    `[1, 2]` -- это последовательность.
    Возможно, вы хотели использовать `[]` вместо `()` и написать
    `[1, 2][a + b]`
    
    Исключение возникло в строке 541 файла TESTS:\runtime\test_type_error.py.
    
       537|     assert "b.a_list[3]" in result
       538| 
       539| try:
       540|     a, b = 3, 7
    -->541|     _ = [1, 2](a + b)
                    ^^^^^^^^^^^^^
       542| except TypeError as e:

            a:  3
            b:  7
            a + b:  10
        


Object is not iterable
~~~~~~~~~~~~~~~~~~~~~~

.. code-block:: none


    Traceback (most recent call last):
      File "TESTS:\runtime\test_type_error.py", line 788, in test_Object_is_not_iterable
        list(42)
    TypeError: 'int' object is not iterable
    
    `TypeError` обычно возникает при попытке
    объединить два несовместимых типа объектов,
    вызовом функции с объектом неправильного типа,
    или при попытке выполнить операцию, недопустимую для данного типа объекта.
    
    Итерабельным является обьект, способный возвращать свои элементы по одному за раз.
    Контейнеры Python (`list, tuple, dict` и т.д.) являются итерабельными.
    
    Исключение возникло в строке 788 файла TESTS:\runtime\test_type_error.py.
    
       786| def test_Object_is_not_iterable():
       787|     try:
    -->788|         list(42)
                    ^^^^^^^^
       789|     except TypeError as e:

            list:  <class list>
        


Object is not subscriptable
~~~~~~~~~~~~~~~~~~~~~~~~~~~

.. code-block:: none


    Traceback (most recent call last):
      File "TESTS:\runtime\test_type_error.py", line 771, in test_Object_is_not_subscriptable
        a = f[1]
    TypeError: 'function' object is not subscriptable
    
        Вы имели в виду `f(1)`?
        
    `TypeError` обычно возникает при попытке
    объединить два несовместимых типа объектов,
    вызовом функции с объектом неправильного типа,
    или при попытке выполнить операцию, недопустимую для данного типа объекта.
    
    Subscriptable objects обычно являются контейнерами, из которых
    вы можете получить элемент, используя нотацию `[...]`.
    
    Возможно, вы хотели написать `f(1)`.
    
    Исключение возникло в строке 771 файла TESTS:\runtime\test_type_error.py.
    
       767| def f():
       768|     pass
       769| 
       770| try:
    -->771|     a = f[1]
                    ^^^^
       772| except TypeError as e:

            f:  <function f>
                defined in <function test_Object_is_not_subscriptable>
        


Slice indices must be integers or None
~~~~~~~~~~~~~~~~~~~~~~~~~~~~~~~~~~~~~~

.. code-block:: none


    Traceback (most recent call last):
      File "TESTS:\runtime\test_type_error.py", line 710, in test_Slice_indices_must_be_integers_or_None
        [1, 2, 3][1.0:2.0]
    TypeError: slice indices must be integers or None or have an __index__ method
    
    `TypeError` обычно возникает при попытке
    объединить два несовместимых типа объектов,
    вызовом функции с объектом неправильного типа,
    или при попытке выполнить операцию, недопустимую для данного типа объекта.
    
    При использовании среза для извлечения диапазона элементов
    из последовательности, то есть что-то вроде
    `[start:stop]` или `[start:stop:step]`.
    каждый из `start`, `stop`, `step` должен быть либо целым числом, либо `None`,
    либо каким-то другим объектом, имеющим метод `__index__`.
    
    Исключение возникло в строке 710 файла TESTS:\runtime\test_type_error.py.
    
       708| def test_Slice_indices_must_be_integers_or_None():
       709|     try:
    -->710|         [1, 2, 3][1.0:2.0]
                    ^^^^^^^^^^^^^^^^^^
       711|     except TypeError as e:


Too few positional argument
~~~~~~~~~~~~~~~~~~~~~~~~~~~

.. code-block:: none


    Traceback (most recent call last):
      File "TESTS:\runtime\test_type_error.py", line 471, in test_Too_few_positional_argument
        fn(1)
    TypeError: fn() missing 2 required positional arguments: 'b' and 'c'
    
    `TypeError` обычно возникает при попытке
    объединить два несовместимых типа объектов,
    вызовом функции с объектом неправильного типа,
    или при попытке выполнить операцию, недопустимую для данного типа объекта.
    
    Видимо, вы вызвали функцию 'fn()' с
    меньшим количеством позиционных аргументов, чем требуется (2 missing).
    
    Исключение возникло в строке 471 файла TESTS:\runtime\test_type_error.py.
    
       467| def fn(a, b, c):
       468|     pass
       469| 
       470| try:
    -->471|     fn(1)
                ^^^^^
       472| except TypeError as e:

            fn:  <function fn>
                defined in <function test_Too_few_positional_argument>
        


Too many positional argument
~~~~~~~~~~~~~~~~~~~~~~~~~~~~

.. code-block:: none


    Traceback (most recent call last):
      File "TESTS:\runtime\test_type_error.py", line 452, in test_Too_many_positional_argument
        A().f(1)
    TypeError: f() takes 1 positional argument but 2 were given
    
        Возможно, вы забыли `self` при обьявлении `f`.
        
    `TypeError` обычно возникает при попытке
    объединить два несовместимых типа объектов,
    вызовом функции с объектом неправильного типа,
    или при попытке выполнить операцию, недопустимую для данного типа объекта.
    
    Вы, очевидно, вызвали функцию `f` с
    2 позиционным аргументом(ами), в то время как она требует
    позиционный(е) аргумент(ы) 1
    Возможно, вы забыли `self` при обьявлении `f`.
    
    Исключение возникло в строке 452 файла TESTS:\runtime\test_type_error.py.
    
       448|     def f(x):
       449|         pass
       450| 
       451| try:
    -->452|     A().f(1)
                ^^^^^^^^
       453| except TypeError as e:

            A:  <class A>
                defined in <function test_type_error.test_Too_many_positional_argument>
        


Tuple no item assignment
~~~~~~~~~~~~~~~~~~~~~~~~

.. code-block:: none


    Traceback (most recent call last):
      File "TESTS:\runtime\test_type_error.py", line 419, in test_Tuple_no_item_assignment
        a[0] = 0
    TypeError: 'tuple' object does not support item assignment
    
        Вы хотели использовать список?
        
    `TypeError` обычно возникает при попытке
    объединить два несовместимых типа объектов,
    вызовом функции с объектом неправильного типа,
    или при попытке выполнить операцию, недопустимую для данного типа объекта.
    
    В Python некоторые объекты известны как неизменяемые,
    после определения их значение не может быть изменено.
    Вы можете изменить часть такого неизменяемого объекта: кортеж `tuple`,
    скорее всего, с помощью операции индексирования
    Возможно, вы хотели использовать список.
    
    Исключение возникло в строке 419 файла TESTS:\runtime\test_type_error.py.
    
       416| def test_Tuple_no_item_assignment():
       417|     a = (1, 2, 3)
       418|     try:
    -->419|         a[0] = 0
                    ^^^^
       420|     except TypeError as e:

            a:  (1, 2, 3)
            a[0]:  1
        


Unhachable type
~~~~~~~~~~~~~~~

.. code-block:: none


    Traceback (most recent call last):
      File "TESTS:\runtime\test_type_error.py", line 727, in test_Unhachable_type
        {[1, 2]: 1}
    TypeError: unhashable type: 'list'
    
    `TypeError` обычно возникает при попытке
    объединить два несовместимых типа объектов,
    вызовом функции с объектом неправильного типа,
    или при попытке выполнить операцию, недопустимую для данного типа объекта.
    
    Только хешируемые объекты могут быть использованы
    в качестве элементов `set` или ключей `dict`.
    Хешируемые объекты - это объекты, которые не меняют своего значения после их создания.Вместо список `list` используйте кортеж `tuple`.
    
    Исключение возникло в строке 727 файла TESTS:\runtime\test_type_error.py.
    
       725| def test_Unhachable_type():
       726|     try:
    -->727|         {[1, 2]: 1}
       728|     except TypeError as e:


Unsupported operand types
~~~~~~~~~~~~~~~~~~~~~~~~~

.. code-block:: none


    Traceback (most recent call last):
      File "TESTS:\runtime\test_type_error.py", line 310, in test_Unsupported_operand_types
        a @= b
    TypeError: unsupported operand type(s) for @=: 'str' and 'int'
    
    `TypeError` обычно возникает при попытке
    объединить два несовместимых типа объектов,
    вызовом функции с объектом неправильного типа,
    или при попытке выполнить операцию, недопустимую для данного типа объекта.
    
    Вы попытались использовать оператор @=
    используя два несовместимых типа объектов:
    строка (`str`) и целое число (`int`).
    Этот оператор обычно используется только
    для умножения матриц.
    
    Исключение возникло в строке 310 файла TESTS:\runtime\test_type_error.py.
    
       307| try:
       308|     a = "a"
       309|     b = 2
    -->310|     a @= b
       311| except TypeError as e:

            a:  'a'
            b:  2
        


divmod
~~~~~~

.. code-block:: none


    Traceback (most recent call last):
      File "TESTS:\runtime\test_type_error.py", line 55, in test_divmod
        result = divmod(a, b)
    TypeError: can't take floor or mod of complex number.
    
    `TypeError` обычно возникает при попытке
    объединить два несовместимых типа объектов,
    вызовом функции с объектом неправильного типа,
    или при попытке выполнить операцию, недопустимую для данного типа объекта.
    
    Аргументы `divmod` должны быть целыми (`int`) или вещественными (`float`) числами.
    По крайней мере один из аргументов был комплексным числом.
    
    Исключение возникло в строке 55 файла TESTS:\runtime\test_type_error.py.
    
       52| a = 2
       53| b = 3 + 2j
       54| try:
    -->55|     result = divmod(a, b)
                        ^^^^^^^^^^^^
       56| except TypeError as e:

            a:  2
            b:  (3+2j)
            divmod:  <builtin function divmod>
        


function got multiple argument
~~~~~~~~~~~~~~~~~~~~~~~~~~~~~~

.. code-block:: none


    Traceback (most recent call last):
      File "TESTS:\runtime\test_type_error.py", line 951, in test_function_got_multiple_argument
        fn2(0, a=1)
    TypeError: fn2() got multiple values for argument 'a'
    
    `TypeError` обычно возникает при попытке
    объединить два несовместимых типа объектов,
    вызовом функции с объектом неправильного типа,
    или при попытке выполнить операцию, недопустимую для данного типа объекта.
    
    Вы указали значение аргумента `a` более одного раза
    при вызове функции с именем `fn2`.
    Эта функция принимает следующие аргументы:
    `a, b=1`
    
    Исключение возникло в строке 951 файла TESTS:\runtime\test_type_error.py.
    
       947| def fn2(a, b=1):
       948|     pass
       949| 
       950| try:
    -->951|     fn2(0, a=1)
                ^^^^^^^^^^^
       952| except TypeError as e:

            fn2:  <function fn2>
                defined in <function test_function_got_multiple_argument>
        


function has no len
~~~~~~~~~~~~~~~~~~~

.. code-block:: none


    Traceback (most recent call last):
      File "TESTS:\runtime\test_type_error.py", line 876, in test_function_has_no_len
        len(bad)
    TypeError: object of type 'function' has no len()
    
        Вы забыли вызвать `bad`?
        
    `TypeError` обычно возникает при попытке
    объединить два несовместимых типа объектов,
    вызовом функции с объектом неправильного типа,
    или при попытке выполнить операцию, недопустимую для данного типа объекта.
    
    Предполагаю, что вы забыли добавить круглые скобки для вызова `bad`.
    Возможно, вы хотели написать:
    `len(bad())`.
    
    Исключение возникло в строке 876 файла TESTS:\runtime\test_type_error.py.
    
       872| def bad():
       873|     pass
       874| 
       875| try:
    -->876|     len(bad)
                ^^^^^^^^
       877| except TypeError as e:

            bad:  <function bad> defined in <function test_function_has_no_len>
            len:  <builtin function len>
        


getattr attribute name must be string
~~~~~~~~~~~~~~~~~~~~~~~~~~~~~~~~~~~~~

.. code-block:: none


    Traceback (most recent call last):
      File "TESTS:\runtime\test_type_error.py", line 997, in test_getattr_attribute_name_must_be_string
        getattr("__repr__", 1)  # as reported in issue #77
    TypeError: getattr(): attribute name must be string
    
    `TypeError` обычно возникает при попытке
    объединить два несовместимых типа объектов,
    вызовом функции с объектом неправильного типа,
    или при попытке выполнить операцию, недопустимую для данного типа объекта.
    
    Второй аргумент функции `getattr()` должен быть строкой.
    
    Исключение возникло в строке 997 файла TESTS:\runtime\test_type_error.py.
    
       990| if friendly_traceback.get_lang() == "en":
       991|     assert (
       992|         "The second argument of the function `hasattr()` must be a string."
       993|         in result
       994|     )
       995| 
       996| try:
    -->997|     getattr("__repr__", 1)  # as reported in issue #77
                ^^^^^^^^^^^^^^^^^^^^^^
       998| except TypeError as e:

            getattr:  <builtin function getattr>
        


method got multiple argument
~~~~~~~~~~~~~~~~~~~~~~~~~~~~

.. code-block:: none


    Traceback (most recent call last):
      File "TESTS:\runtime\test_type_error.py", line 970, in test_method_got_multiple_argument
        t.some_method(0, a=1)
    TypeError: some_method() got multiple values for argument 'a'
    
    `TypeError` обычно возникает при попытке
    объединить два несовместимых типа объектов,
    вызовом функции с объектом неправильного типа,
    или при попытке выполнить операцию, недопустимую для данного типа объекта.
    
    Вы указали значение аргумента `a` более одного раза
    при вызове функции с именем `t.some_method`.
    Эта функция принимает только один аргумент: `a`.
    
    Исключение возникло в строке 970 файла TESTS:\runtime\test_type_error.py.
    
       966|         pass
       967| 
       968| t = T()
       969| try:
    -->970|     t.some_method(0, a=1)
                ^^^^^^^^^^^^^^^^^^^^^
       971| except TypeError as e:

            t:  <T object>
                defined in <function test_type_error.test_method_got_multiple_argument>
            t.some_method:  <bound method T.some_method>
                of <T object>
                defined in <function test_type_error.test_method_got_multiple_argument>
        


vars arg must have dict
~~~~~~~~~~~~~~~~~~~~~~~

.. code-block:: none


    Traceback (most recent call last):
      File "TESTS:\runtime\test_type_error.py", line 920, in test_vars_arg_must_have_dict
        vars(f)
    TypeError: vars() argument must have __dict__ attribute
    
    `TypeError` обычно возникает при попытке
    объединить два несовместимых типа объектов,
    вызовом функции с объектом неправильного типа,
    или при попытке выполнить операцию, недопустимую для данного типа объекта.
    
    Функция `vars` используется для перечисления содержимого атрибута
    `__dict__` объекта.
    Объект `f` использует `__slots__` вместо `__dict__`.
    
    Исключение возникло в строке 920 файла TESTS:\runtime\test_type_error.py.
    
       916|     assert no_slots not in result
       917|     assert use_slots not in result
       918| 
       919| try:
    -->920|     vars(f)
                ^^^^^^^
       921| except TypeError as e:

            f:  <F object>
                defined in <function test_type_error.test_vars_arg_must_have_dict>
            vars:  <builtin function vars>
        


UnboundLocalError
-----------------


Missing both
~~~~~~~~~~~~

.. code-block:: none


    Traceback (most recent call last):
      File "TESTS:\runtime\test_unbound_local_error.py", line 63, in test_Missing_both
        outer_missing_both()
      File "TESTS:\runtime\test_unbound_local_error.py", line 22, in outer_missing_both
        inner()
      File "TESTS:\runtime\test_unbound_local_error.py", line 21, in inner
        spam_missing_both += 1
    UnboundLocalError: local variable 'spam_missing_both' referenced before assignment
    
        Вы забыли добавить
            `global spam_missing_both`
        или
            `nonlocal spam_missing_both`?
        
    В Python переменные, которые используются внутри функции, называются 
    локальными переменными. Перед использованием им должно быть присвоено значение.
    Переменная, которая используется до присвоения ей значения, считается
    определена вне этой функции; она известна как `global`
    (или иногда `nonlocal`) переменной. Вы не можете присвоить значение такой
    глобальной переменной внутри функции, не указав предварительно
    Python, что это глобальная переменная, иначе вы словите
    `UnboundLocalError`.
    
    Вы пытаетесь использовать имя `spam_missing_both`, идентифицированное Python как находящееся
    в локальной области видимости функции, прежде чем присвоить ему значение.
    
    Имя `spam_missing_both` существует как в глобальной, так и в нелокальной областях видимости. Это может привести к путанице и не рекомендуется.
    В зависимости от того, на какую переменную вы хотите сослаться, вам нужно добавить либо
        global spam_missing_both
    либо
        nonlocal spam_missing_both
    в качестве первой строки внутри вашей функции.
    
    Выполнение остановлено на строке 63 файла TESTS:\runtime\test_unbound_local_error.py.
    
       61| def test_Missing_both():
       62|     try:
    -->63|         outer_missing_both()
                   ^^^^^^^^^^^^^^^^^^^^
       64|     except UnboundLocalError as e:

            global outer_missing_both:  <function outer_missing_both>
        
    Исключение возникло в строке 21 файла TESTS:\runtime\test_unbound_local_error.py.
    
       20| def inner():
    -->21|     spam_missing_both += 1

            global spam_missing_both:  1
        


Missing global
~~~~~~~~~~~~~~

.. code-block:: none


    Traceback (most recent call last):
      File "TESTS:\runtime\test_unbound_local_error.py", line 27, in test_Missing_global
        outer_missing_global()
      File "TESTS:\runtime\test_unbound_local_error.py", line 10, in outer_missing_global
        inner()
      File "TESTS:\runtime\test_unbound_local_error.py", line 9, in inner
        spam_missing_global += 1
    UnboundLocalError: local variable 'spam_missing_global' referenced before assignment
    
        Вы забыли добавить `global spam_missing_global`?
        
    В Python переменные, которые используются внутри функции, называются 
    локальными переменными. Перед использованием им должно быть присвоено значение.
    Переменная, которая используется до присвоения ей значения, считается
    определена вне этой функции; она известна как `global`
    (или иногда `nonlocal`) переменной. Вы не можете присвоить значение такой
    глобальной переменной внутри функции, не указав предварительно
    Python, что это глобальная переменная, иначе вы словите
    `UnboundLocalError`.
    
    Вы пытаетесь использовать имя `spam_missing_global`, идентифицированное Python как находящееся
    в локальной области видимости функции, прежде чем присвоить ему значение.
    
    Имя `spam_missing_global` существует в области видимости global.
    Возможно,обьявление
    
        global spam_missing_global
    
    должно быть включено в качестве первой строки внутри вашей функции.
    
    Выполнение остановлено на строке 27 файла TESTS:\runtime\test_unbound_local_error.py.
    
       25| def test_Missing_global():
       26|     try:
    -->27|         outer_missing_global()
                   ^^^^^^^^^^^^^^^^^^^^^^
       28|     except UnboundLocalError as e:

            global outer_missing_global:  <function outer_missing_global>
        
    Исключение возникло в строке 9 файла TESTS:\runtime\test_unbound_local_error.py.
    
       8| def inner():
    -->9|     spam_missing_global += 1

            global spam_missing_global:  1
        


Missing nonlocal
~~~~~~~~~~~~~~~~

.. code-block:: none


    Traceback (most recent call last):
      File "TESTS:\runtime\test_unbound_local_error.py", line 45, in test_Missing_nonlocal
        outer_missing_nonlocal()
      File "TESTS:\runtime\test_unbound_local_error.py", line 16, in outer_missing_nonlocal
        inner()
      File "TESTS:\runtime\test_unbound_local_error.py", line 15, in inner
        spam_missing_nonlocal += 1
    UnboundLocalError: local variable 'spam_missing_nonlocal' referenced before assignment
    
        Вы забыли добавить `nonlocal spam_missing_nonlocal`?
        
    В Python переменные, которые используются внутри функции, называются 
    локальными переменными. Перед использованием им должно быть присвоено значение.
    Переменная, которая используется до присвоения ей значения, считается
    определена вне этой функции; она известна как `global`
    (или иногда `nonlocal`) переменной. Вы не можете присвоить значение такой
    глобальной переменной внутри функции, не указав предварительно
    Python, что это глобальная переменная, иначе вы словите
    `UnboundLocalError`.
    
    Вы пытаетесь использовать имя `spam_missing_nonlocal`, идентифицированное Python как находящееся
    в локальной области видимости функции, прежде чем присвоить ему значение.
    
    Имя `spam_missing_nonlocal` существует в области видимости nonlocal.
    Возможно,обьявление
    
        nonlocal spam_missing_nonlocal
    
    должно быть включено в качестве первой строки внутри вашей функции.
    
    Выполнение остановлено на строке 45 файла TESTS:\runtime\test_unbound_local_error.py.
    
       43| def test_Missing_nonlocal():
       44|     try:
    -->45|         outer_missing_nonlocal()
                   ^^^^^^^^^^^^^^^^^^^^^^^^
       46|     except UnboundLocalError as e:

            global outer_missing_nonlocal:  <function outer_missing_nonlocal>
        
    Исключение возникло в строке 15 файла TESTS:\runtime\test_unbound_local_error.py.
    
       14| def inner():
    -->15|     spam_missing_nonlocal += 1


Typo in local
~~~~~~~~~~~~~

.. code-block:: none


    Traceback (most recent call last):
      File "TESTS:\runtime\test_unbound_local_error.py", line 101, in test_Typo_in_local
        test2()
      File "TESTS:\runtime\test_unbound_local_error.py", line 98, in test2
        alpha3 += 1
    UnboundLocalError: local variable 'alpha3' referenced before assignment
    
        Вы имели в виду `alpha1`?
        
    В Python переменные, которые используются внутри функции, называются 
    локальными переменными. Перед использованием им должно быть присвоено значение.
    Переменная, которая используется до присвоения ей значения, считается
    определена вне этой функции; она известна как `global`
    (или иногда `nonlocal`) переменной. Вы не можете присвоить значение такой
    глобальной переменной внутри функции, не указав предварительно
    Python, что это глобальная переменная, иначе вы словите
    `UnboundLocalError`.
    
    Вместо того, чтобы написать `alpha3`, возможно, вы имели в виду следующее:
    *  Локальная область видимости: `alpha1`, `alpha2`
    
    Выполнение остановлено на строке 101 файла TESTS:\runtime\test_unbound_local_error.py.
    
        97|     alpha2 = 1
        98|     alpha3 += 1
        99| 
       100| try:
    -->101|     test2()
                ^^^^^^^
       102| except UnboundLocalError as e:

            test2:  <function test2> defined in <function test_Typo_in_local>
        
    Исключение возникло в строке 98 файла TESTS:\runtime\test_unbound_local_error.py.
    
       95| def test2():
       96|     alpha1 = 1
       97|     alpha2 = 1
    -->98|     alpha3 += 1


Using name of builtin
~~~~~~~~~~~~~~~~~~~~~

.. code-block:: none


    Traceback (most recent call last):
      File "TESTS:\runtime\test_unbound_local_error.py", line 121, in test_Using_name_of_builtin
        dist([])
      File "TESTS:\runtime\test_unbound_local_error.py", line 117, in dist
        max = max(points)
    UnboundLocalError: local variable 'max' referenced before assignment
    
    В Python переменные, которые используются внутри функции, называются 
    локальными переменными. Перед использованием им должно быть присвоено значение.
    Переменная, которая используется до присвоения ей значения, считается
    определена вне этой функции; она известна как `global`
    (или иногда `nonlocal`) переменной. Вы не можете присвоить значение такой
    глобальной переменной внутри функции, не указав предварительно
    Python, что это глобальная переменная, иначе вы словите
    `UnboundLocalError`.
    
    `max` -- это встроенная функция Python.
    Вы попытались присвоить значение `max` внутри функции
    при этом используя ее исходное значение в функции.
    
    Обратите внимание, что обычно не стоит давать локальной переменной
    то же имя, что и встроенной функции Python (например, `max`).
    
    Выполнение остановлено на строке 121 файла TESTS:\runtime\test_unbound_local_error.py.
    
       118|     min = min(points)
       119|     return max - min
       120| try:
    -->121|     dist([])
                ^^^^^^^^
       122| except UnboundLocalError as e:

            dist:  <function dist> defined in <function test_Using_name_of_builtin>
        
    Исключение возникло в строке 117 файла TESTS:\runtime\test_unbound_local_error.py.
    
       116| def dist(points):
    -->117|     max = max(points)
                      ^^^
       118|     min = min(points)

            max:  <builtin function max>
        


UnknownError
------------


Generic
~~~~~~~

.. code-block:: none


    Traceback (most recent call last):
      File "TESTS:\runtime\test_unknown_error.py", line 12, in test_Generic
        raise UnknownException("Some informative message about an unknown exception.")
    UnknownException: Some informative message about an unknown exception.
    
    По этому исключению информации нет.
    Пожалуйста, сообщите об этом примере по адресу
    https://github.com/friendly-traceback/friendly-traceback/issues/new
    Если вы используете REPL, используйте для этого `www('bug')`.
    
    Если вы используете консоль Friendly, используйте `www()`, чтобы
    выполнить поиск в Интернете для этого конкретного случая.
    
    Исключение возникло в строке 12 файла TESTS:\runtime\test_unknown_error.py.
    
        9| old_debug = friendly_traceback.debug_helper.DEBUG
       10| friendly_traceback.debug_helper.DEBUG = False
       11| try:
    -->12|     raise UnknownException("Some informative message about an unknown exception.")
       13| except Exception as e:

            global UnknownException:  <class test_unknown_error.UnknownException>
        


ValueError
----------


Convert to int
~~~~~~~~~~~~~~

.. code-block:: none


    Traceback (most recent call last):
      File "TESTS:\runtime\test_value_error.py", line 187, in test_Convert_to_int
        int('13a')
    ValueError: invalid literal for int() with base 10: '13a'
    
    `ValueError` указывает на то, что функция или операция
    получила аргумент правильного типа, но несоответствующего значения.
    
    `'13a'` является недопустимым аргументом для `int()` в базе `10`.
    В базе `10`, `int()` чаще всего используется для преобразования строки,
    содержащей цифры от `0` до `9` в целое число.
    Недопустимы следующие символы: `a`.
    
    Исключение возникло в строке 187 файла TESTS:\runtime\test_value_error.py.
    
       183| if english:
       184|     assert "needs to be first converted using `float()`" in result
       185| 
       186| try:
    -->187|     int('13a')
                ^^^^^^^^^^
       188| except ValueError as e:

            int:  <class int>
        


Could not convert to float
~~~~~~~~~~~~~~~~~~~~~~~~~~

.. code-block:: none


    Traceback (most recent call last):
      File "TESTS:\runtime\test_value_error.py", line 88, in test_Could_not_convert_to_float
        float("42b")
    ValueError: could not convert string to float: '42b'
    
    `ValueError` указывает на то, что функция или операция
    получила аргумент правильного типа, но несоответствующего значения.
    
    Строка `42b` не может быть преобразована во `float`.
    
    Исключение возникло в строке 88 файла TESTS:\runtime\test_value_error.py.
    
       86| def test_Could_not_convert_to_float():
       87|     try:
    -->88|         float("42b")
                   ^^^^^^^^^^^^
       89|     except ValueError as e:

            float:  <class float>
        


Date invalid month
~~~~~~~~~~~~~~~~~~

.. code-block:: none


    Traceback (most recent call last):
      File "TESTS:\runtime\test_value_error.py", line 58, in test_Date_invalid_month
        d = date(2021, 13, 1)
    ValueError: month must be in 1..12
    
        Вы указали неправильный месяц?
        
    `ValueError` указывает на то, что функция или операция
    получила аргумент правильного типа, но несоответствующего значения.
    
    Предполагаю, что вы указали недопустимое значение для месяца
    в объекте `date`. Допустимыми значениями являются целые числа от 1 до 12.
    
    Исключение возникло в строке 58 файла TESTS:\runtime\test_value_error.py.
    
       55| def test_Date_invalid_month():
       56|     from datetime import date
       57|     try:
    -->58|         d = date(2021, 13, 1)
                       ^^^^^^^^^^^^^^^^^
       59|     except ValueError as e:

            date:  <class datetime.date>
        


Not enough values to unpack
~~~~~~~~~~~~~~~~~~~~~~~~~~~

.. code-block:: none


    Traceback (most recent call last):
      File "TESTS:\runtime\test_value_error.py", line 28, in test_Not_enough_values_to_unpack
        a, b, c = d
    ValueError: not enough values to unpack (expected 3, got 2)
    
    `ValueError` указывает на то, что функция или операция
    получила аргумент правильного типа, но несоответствующего значения.
    
    Распаковка является удобным способом присвоить имя
    каждому элементу итерирумого обьекта.
    В данном случае количество имен (3) больше,
    чем длина итерируемого объекта, строка (`str`) длиной 2.
    
    Исключение возникло в строке 28 файла TESTS:\runtime\test_value_error.py.
    
       24| assert "ValueError: not enough values to unpack (expected 3, got 2)" in result
       25| 
       26| d = "ab"
       27| try:
    -->28|     a, b, c = d
       29| except ValueError as e:

            d:  'ab'
        


Pow third arg cannot be zero
~~~~~~~~~~~~~~~~~~~~~~~~~~~~

.. code-block:: none


    Traceback (most recent call last):
      File "TESTS:\runtime\test_value_error.py", line 103, in test_Pow_third_arg_cannot_be_zero
        pow(2, 4, a)
    ValueError: pow() 3rd argument cannot be 0
    
    `ValueError` указывает на то, что функция или операция
    получила аргумент правильного типа, но несоответствующего значения.
    
    Третий аргумент функции `pow()` не может быть нулём.
    
    Исключение возникло в строке 103 файла TESTS:\runtime\test_value_error.py.
    
       100| def test_Pow_third_arg_cannot_be_zero():
       101|     a = 0
       102|     try:
    -->103|         pow(2, 4, a)
                    ^^^^^^^^^^^^
       104|     except ValueError as e:

            a:  0
            pow:  <builtin function pow>
        


Slots conflicts with class variable
~~~~~~~~~~~~~~~~~~~~~~~~~~~~~~~~~~~

.. code-block:: none


    Traceback (most recent call last):
      File "TESTS:\runtime\test_value_error.py", line 72, in test_Slots_conflicts_with_class_variable
        class F:
    ValueError: 'a' in __slots__ conflicts with class variable
    
    `ValueError` указывает на то, что функция или операция
    получила аргумент правильного типа, но несоответствующего значения.
    
    Имя `a` используется и как имя переменной класса,
    и как строковый элемент в классе `__slots__`. Это недопустимо.
    
    Исключение возникло в строке 72 файла TESTS:\runtime\test_value_error.py.
    
       70| def test_Slots_conflicts_with_class_variable():
       71|     try:
    -->72|         class F:
       73|             __slots__ = ["a", "b"]


Too many values to unpack
~~~~~~~~~~~~~~~~~~~~~~~~~

.. code-block:: none


    Traceback (most recent call last):
      File "TESTS:\runtime\test_value_error.py", line 43, in test_Too_many_values_to_unpack
        a, b = c
    ValueError: too many values to unpack (expected 2)
    
    `ValueError` указывает на то, что функция или операция
    получила аргумент правильного типа, но несоответствующего значения.
    
    Распаковка является удобным способом присвоить имя
    каждому элементу итерирумого обьекта.
    В данном случае имен (2) меньше,
    чем длина итерируемого объекта, список `list` длиной 3.
    
    Исключение возникло в строке 43 файла TESTS:\runtime\test_value_error.py.
    
       40| def test_Too_many_values_to_unpack():
       41|     c = [1, 2, 3]
       42|     try:
    -->43|         a, b = c
       44|     except ValueError as e:

            c:  [1, 2, 3]
        


int base not in range
~~~~~~~~~~~~~~~~~~~~~

.. code-block:: none


    Traceback (most recent call last):
      File "TESTS:\runtime\test_value_error.py", line 201, in test_int_base_not_in_range
        int('18', base=37)
    ValueError: int() base must be >= 2 and <= 36, or 0
    
    `ValueError` указывает на то, что функция или операция
    получила аргумент правильного типа, но несоответствующего значения.
    
    Аргумент `base` функции `int()` должен быть либо нулем
    или любым целым числом от 2 до 36.
    Вы написали 37, что недопустимо.
    
    Исключение возникло в строке 201 файла TESTS:\runtime\test_value_error.py.
    
       199| def test_int_base_not_in_range():
       200|     try:
    -->201|         int('18', base=37)
                    ^^^^^^^^^^^^^^^^^^
       202|     except ValueError as e:

            int:  <class int>
        


time strptime incorrect format
~~~~~~~~~~~~~~~~~~~~~~~~~~~~~~

.. code-block:: none


    Traceback (most recent call last):
      File "TESTS:\runtime\test_value_error.py", line 127, in test_time_strptime_incorrect_format
        time.strptime("2020-01-01", "%d %m %Y")
    ValueError: time data '2020-01-01' does not match format '%d %m %Y'
    
    `ValueError` указывает на то, что функция или операция
    получила аргумент правильного типа, но несоответствующего значения.
    
    Значение, которое вы указали для времени, не соответствует указанному формату.
    Убедитесь, что между элементами используется одинаковый разделитель
    (например, между днем и месяцем) и соблюдайте одинаковый порядок
    как в предоставленных данных, так и в указанном вами формате.
    Следующая таблица может оказаться полезной:
    https://docs.python.org/3/library/time.html#time.strftime
    Следующий сайт также может быть полезен: https://www.strfti.me/
    
    Исключение возникло в строке 127 файла TESTS:\runtime\test_value_error.py.
    
       123|     return
       124| 
       125| import time
       126| try:
    -->127|     time.strptime("2020-01-01", "%d %m %Y")
                ^^^^^^^^^^^^^^^^^^^^^^^^^^^^^^^^^^^^^^^
       128| except ValueError as e:

            time:  <module time (builtin)>
            time.strptime:  <builtin function strptime>
        


ZeroDivisionError
-----------------


Complex division
~~~~~~~~~~~~~~~~

.. code-block:: none


    Traceback (most recent call last):
      File "TESTS:\runtime\test_zero_division_error.py", line 173, in test_Complex_division
        1 / zero
    ZeroDivisionError: complex division by zero
    
    `ZeroDivisionError` возникает, когда вы пытаетесь разделить значение
    на ноль либо напрямую, либо с помощью другой математической операции.
    
    Вы делите на следующее выражение
    
         zero
    
    которое равно нулю.
    
    Исключение возникло в строке 173 файла TESTS:\runtime\test_zero_division_error.py.
    
       170| def test_Complex_division():
       171|     zero = 0j
       172|     try:
    -->173|         1 / zero
                    ^^^^^^^^
       174|     except ZeroDivisionError as e:

            zero:  0j
        


Division by zero literal
~~~~~~~~~~~~~~~~~~~~~~~~

.. code-block:: none


    Traceback (most recent call last):
      File "TESTS:\runtime\test_zero_division_error.py", line 220, in test_Division_by_zero_literal
        1.0 / 0
    ZeroDivisionError: float division by zero
    
    `ZeroDivisionError` возникает, когда вы пытаетесь разделить значение
    на ноль либо напрямую, либо с помощью другой математической операции.
    
    Вы делите на ноль.
    
    Исключение возникло в строке 220 файла TESTS:\runtime\test_zero_division_error.py.
    
       216| if friendly_traceback.get_lang() == "en":
       217|     assert "Using the modulo operator, you are dividing by zero" in result
       218| 
       219| try:
    -->220|     1.0 / 0
                ^^^^^^^
       221| except ZeroDivisionError as e:


Division operator
~~~~~~~~~~~~~~~~~

.. code-block:: none


    Traceback (most recent call last):
      File "TESTS:\runtime\test_zero_division_error.py", line 20, in test_Division_operator
        1 / zero
    ZeroDivisionError: division by zero
    
    `ZeroDivisionError` возникает, когда вы пытаетесь разделить значение
    на ноль либо напрямую, либо с помощью другой математической операции.
    
    Вы делите на следующее выражение
    
         zero
    
    которое равно нулю.
    
    Исключение возникло в строке 20 файла TESTS:\runtime\test_zero_division_error.py.
    
       13| if friendly_traceback.get_lang() == "en":
       14|     assert (
       15|         "The following mathematical expression includes a division by zero"
       16|         in result
       17|     )
       18| 
       19| try:
    -->20|     1 / zero
               ^^^^^^^^
       21| except ZeroDivisionError as e:

            zero:  0
        


Divmod
~~~~~~

.. code-block:: none


    Traceback (most recent call last):
      File "TESTS:\runtime\test_zero_division_error.py", line 97, in test_Divmod
        divmod(1, zero)
    ZeroDivisionError: integer division or modulo by zero
    
    `ZeroDivisionError` возникает, когда вы пытаетесь разделить значение
    на ноль либо напрямую, либо с помощью другой математической операции.
    
    Второй аргумент функции `divmod()` равен нулю.
    
    Исключение возникло в строке 97 файла TESTS:\runtime\test_zero_division_error.py.
    
       94| def test_Divmod():
       95|     zero = 0
       96|     try:
    -->97|         divmod(1, zero)
                   ^^^^^^^^^^^^^^^
       98|     except ZeroDivisionError as e:

            zero:  0
            divmod:  <builtin function divmod>
        


Float division
~~~~~~~~~~~~~~

.. code-block:: none


    Traceback (most recent call last):
      File "TESTS:\runtime\test_zero_division_error.py", line 143, in test_Float_division
        1 / zero
    ZeroDivisionError: float division by zero
    
    `ZeroDivisionError` возникает, когда вы пытаетесь разделить значение
    на ноль либо напрямую, либо с помощью другой математической операции.
    
    Вы делите на следующее выражение
    
         zero
    
    которое равно нулю.
    
    Исключение возникло в строке 143 файла TESTS:\runtime\test_zero_division_error.py.
    
       140| def test_Float_division():
       141|     zero = 0.0
       142|     try:
    -->143|         1 / zero
                    ^^^^^^^^
       144|     except ZeroDivisionError as e:

            zero:  0.0
        


Float divmod
~~~~~~~~~~~~

.. code-block:: none


    Traceback (most recent call last):
      File "TESTS:\runtime\test_zero_division_error.py", line 158, in test_Float_divmod
        divmod(1, zero)
    ZeroDivisionError: float divmod()
    
    `ZeroDivisionError` возникает, когда вы пытаетесь разделить значение
    на ноль либо напрямую, либо с помощью другой математической операции.
    
    Второй аргумент функции `divmod()` равен нулю.
    
    Исключение возникло в строке 158 файла TESTS:\runtime\test_zero_division_error.py.
    
       155| def test_Float_divmod():
       156|     zero = 0.0
       157|     try:
    -->158|         divmod(1, zero)
                    ^^^^^^^^^^^^^^^
       159|     except ZeroDivisionError as e:

            zero:  0.0
            divmod:  <builtin function divmod>
        


Float modulo
~~~~~~~~~~~~

.. code-block:: none


    Traceback (most recent call last):
      File "TESTS:\runtime\test_zero_division_error.py", line 128, in test_Float_modulo
        1 % zero
    ZeroDivisionError: float modulo
    
    `ZeroDivisionError` возникает, когда вы пытаетесь разделить значение
    на ноль либо напрямую, либо с помощью другой математической операции.
    
    Используя оператор modulo, вы делите на следующий член
    
         zero
    
    равный нулю.
    
    Исключение возникло в строке 128 файла TESTS:\runtime\test_zero_division_error.py.
    
       121|     assert (
       122|         "The following mathematical expression includes a division by zero"
       123|         in result
       124|     )
       125|     assert "done using the modulo operator" in result
       126| 
       127| try:
    -->128|     1 % zero
                ^^^^^^^^
       129| except ZeroDivisionError as e:

            zero:  0.0
        


Integer division operator
~~~~~~~~~~~~~~~~~~~~~~~~~

.. code-block:: none


    Traceback (most recent call last):
      File "TESTS:\runtime\test_zero_division_error.py", line 48, in test_Integer_division_operator
        1 // zero
    ZeroDivisionError: integer division or modulo by zero
    
    `ZeroDivisionError` возникает, когда вы пытаетесь разделить значение
    на ноль либо напрямую, либо с помощью другой математической операции.
    
    Вы делите на следующее выражение
    
         zero
    
    которое равно нулю.
    
    Исключение возникло в строке 48 файла TESTS:\runtime\test_zero_division_error.py.
    
       41| if friendly_traceback.get_lang() == "en":
       42|     assert (
       43|         "The following mathematical expression includes a division by zero"
       44|         in result
       45|     )
       46| 
       47| try:
    -->48|     1 // zero
               ^^^^^^^^^
       49| except ZeroDivisionError as e:

            zero:  0
        


Mixed operations
~~~~~~~~~~~~~~~~

.. code-block:: none


    Traceback (most recent call last):
      File "TESTS:\runtime\test_zero_division_error.py", line 233, in test_Mixed_operations
        a = divmod(8, 1 // 2)
    ZeroDivisionError: integer division or modulo by zero
    
    `ZeroDivisionError` возникает, когда вы пытаетесь разделить значение
    на ноль либо напрямую, либо с помощью другой математической операции.
    
    Следующее математическое выражение включает в себя деление на ноль:
    
        divmod(8, 1 // 2)
    
    Исключение возникло в строке 233 файла TESTS:\runtime\test_zero_division_error.py.
    
       231| def test_Mixed_operations():
       232|     try:
    -->233|         a = divmod(8, 1 // 2)
                        ^^^^^^^^^^^^^^^^^
       234|     except ZeroDivisionError as e:

            divmod:  <builtin function divmod>
            1 // 2:  0
        


Modulo operator
~~~~~~~~~~~~~~~

.. code-block:: none


    Traceback (most recent call last):
      File "TESTS:\runtime\test_zero_division_error.py", line 79, in test_Modulo_operator
        1 % zero
    ZeroDivisionError: integer division or modulo by zero
    
    `ZeroDivisionError` возникает, когда вы пытаетесь разделить значение
    на ноль либо напрямую, либо с помощью другой математической операции.
    
    Используя оператор modulo, вы делите на следующий член
    
         zero
    
    равный нулю.
    
    Исключение возникло в строке 79 файла TESTS:\runtime\test_zero_division_error.py.
    
       72| if friendly_traceback.get_lang() == "en":
       73|     assert (
       74|         "The following mathematical expression includes a division by zero"
       75|         in result
       76|     )
       77| 
       78| try:
    -->79|     1 % zero
               ^^^^^^^^
       80| except ZeroDivisionError as e:

            zero:  0
        


Raise zero negative power
~~~~~~~~~~~~~~~~~~~~~~~~~

.. code-block:: none


    Traceback (most recent call last):
      File "TESTS:\runtime\test_zero_division_error.py", line 188, in test_Raise_zero_negative_power
        zero**-1
    ZeroDivisionError: 0.0 cannot be raised to a negative power
    
    `ZeroDivisionError` возникает, когда вы пытаетесь разделить значение
    на ноль либо напрямую, либо с помощью другой математической операции.
    
    Вы пытаетесь возвести число 0 в отрицательную степень.
    что эквивалентно делению на ноль.
    
    Исключение возникло в строке 188 файла TESTS:\runtime\test_zero_division_error.py.
    
       185| def test_Raise_zero_negative_power():
       186|     zero = 0
       187|     try:
    -->188|         zero**-1
                    ^^^^^^^^
       189|     except ZeroDivisionError as e:

            zero:  0
        

