<!doctype html>
<html class="no-js">
  <head><meta charset="utf-8"/>
    <meta name="viewport" content="width=device-width,initial-scale=1"/>
    <meta name="color-scheme" content="light dark"><meta name="generator" content="Docutils 0.17.1: http://docutils.sourceforge.net/" />
<link rel="index" title="Index" href="genindex.html" /><link rel="search" title="Search" href="search.html" /><link rel="next" title="Friendly SyntaxError tracebacks - en Français" href="syntax_tracebacks_fr.html" /><link rel="prev" title="Friendly SyntaxError tracebacks - en español" href="syntax_tracebacks_es.html" />

    <meta name="generator" content="sphinx-4.3.2, furo 2021.11.23"/>
        <title>Friendly tracebacks - en Français - friendly-traceback 0.5.1</title>
      <link rel="stylesheet" type="text/css" href="_static/pygments.css" />
    <link rel="stylesheet" type="text/css" href="_static/styles/furo.css?digest=7f0192ddeb2adecfbaa87ffbcf67d16358b30bc1" />
    <link rel="stylesheet" type="text/css" href="_static/tabs.css" />
    <link rel="stylesheet" type="text/css" href="_static/copybutton.css" />
    <link rel="stylesheet" type="text/css" href="_static/styles/furo-extensions.css?digest=0af69da206d614734f649b27d4cdc2dd6c31f41d" />
    <link rel="stylesheet" type="text/css" href="_static/custom.css" />
    
    


<style>
  body {
    --color-code-background: #FFFFFF;
  --color-code-foreground: #101010;
  
  }
  body[data-theme="dark"] {
    --color-code-background: #101010;
  --color-code-foreground: #F4F0EC;
  
  }
  @media (prefers-color-scheme: dark) {
    body:not([data-theme="light"]) {
      --color-code-background: #101010;
  --color-code-foreground: #F4F0EC;
  
    }
  }
</style></head>
  <body>
    <script>
      document.body.dataset.theme = localStorage.getItem("theme") || "auto";
    </script>
    
<svg xmlns="http://www.w3.org/2000/svg" style="display: none;">
  <symbol id="svg-toc" viewBox="0 0 24 24">
    <title>Contents</title>
    <svg xmlns="http://www.w3.org/2000/svg" width="24" height="24" viewBox="0 0 24 24" fill="none" stroke="currentColor"
      stroke-width="1.5" stroke-linecap="round" stroke-linejoin="round">
      <path stroke="none" d="M0 0h24v24H0z" />
      <line x1="4" y1="6" x2="20" y2="6" />
      <line x1="10" y1="12" x2="20" y2="12" />
      <line x1="6" y1="18" x2="20" y2="18" />
    </svg>
  </symbol>
  <symbol id="svg-menu" viewBox="0 0 24 24">
    <title>Menu</title>
    <svg xmlns="http://www.w3.org/2000/svg" width="24" height="24" viewBox="0 0 24 24" fill="none" stroke="currentColor"
      stroke-width="2" stroke-linecap="round" stroke-linejoin="round" class="feather-menu">
      <line x1="3" y1="12" x2="21" y2="12"></line>
      <line x1="3" y1="6" x2="21" y2="6"></line>
      <line x1="3" y1="18" x2="21" y2="18"></line>
    </svg>
  </symbol>
  <symbol id="svg-arrow-right" viewBox="0 0 24 24">
    <title>Expand</title>
    <svg xmlns="http://www.w3.org/2000/svg" width="24" height="24" viewBox="0 0 24 24" fill="none" stroke="currentColor"
      stroke-width="2" stroke-linecap="round" stroke-linejoin="round" class="feather-chevron-right">
      <polyline points="9 18 15 12 9 6"></polyline>
    </svg>
  </symbol>
  <symbol id="svg-sun" viewBox="0 0 24 24">
    <title>Light mode</title>
    <svg xmlns="http://www.w3.org/2000/svg" width="24" height="24" viewBox="0 0 24 24" fill="none" stroke="currentColor"
      stroke-width="1.5" stroke-linecap="round" stroke-linejoin="round" class="feather-sun">
      <circle cx="12" cy="12" r="5"></circle>
      <line x1="12" y1="1" x2="12" y2="3"></line>
      <line x1="12" y1="21" x2="12" y2="23"></line>
      <line x1="4.22" y1="4.22" x2="5.64" y2="5.64"></line>
      <line x1="18.36" y1="18.36" x2="19.78" y2="19.78"></line>
      <line x1="1" y1="12" x2="3" y2="12"></line>
      <line x1="21" y1="12" x2="23" y2="12"></line>
      <line x1="4.22" y1="19.78" x2="5.64" y2="18.36"></line>
      <line x1="18.36" y1="5.64" x2="19.78" y2="4.22"></line>
    </svg>
  </symbol>
  <symbol id="svg-moon" viewBox="0 0 24 24">
    <title>Dark mode</title>
    <svg xmlns="http://www.w3.org/2000/svg" width="24" height="24" viewBox="0 0 24 24" fill="none" stroke="currentColor"
      stroke-width="1.5" stroke-linecap="round" stroke-linejoin="round" class="icon-tabler-moon">
      <path stroke="none" d="M0 0h24v24H0z" fill="none" />
      <path d="M12 3c.132 0 .263 0 .393 0a7.5 7.5 0 0 0 7.92 12.446a9 9 0 1 1 -8.313 -12.454z" />
    </svg>
  </symbol>
  <symbol id="svg-sun-half" viewBox="0 0 24 24">
    <title>Auto light/dark mode</title>
    <svg xmlns="http://www.w3.org/2000/svg" width="24" height="24" viewBox="0 0 24 24" fill="none" stroke="currentColor"
      stroke-width="1.5" stroke-linecap="round" stroke-linejoin="round" class="icon-tabler-shadow">
      <path stroke="none" d="M0 0h24v24H0z" fill="none"/>
      <circle cx="12" cy="12" r="9" />
      <path d="M13 12h5" />
      <path d="M13 15h4" />
      <path d="M13 18h1" />
      <path d="M13 9h4" />
      <path d="M13 6h1" />
    </svg>
  </symbol>
</svg>

<input type="checkbox" class="sidebar-toggle" name="__navigation" id="__navigation">
<input type="checkbox" class="sidebar-toggle" name="__toc" id="__toc">
<label class="overlay sidebar-overlay" for="__navigation">
  <div class="visually-hidden">Hide navigation sidebar</div>
</label>
<label class="overlay toc-overlay" for="__toc">
  <div class="visually-hidden">Hide table of contents sidebar</div>
</label>



<div class="page">
  <header class="mobile-header">
    <div class="header-left">
      <label class="nav-overlay-icon" for="__navigation">
        <div class="visually-hidden">Toggle site navigation sidebar</div>
        <i class="icon"><svg><use href="#svg-menu"></use></svg></i>
      </label>
    </div>
    <div class="header-center">
      <a href="index.html"><div class="brand">friendly-traceback 0.5.1</div></a>
    </div>
    <div class="header-right">
      <div class="theme-toggle-container theme-toggle-header">
        <button class="theme-toggle">
          <div class="visually-hidden">Toggle Light / Dark / Auto color theme</div>
          <svg class="theme-icon-when-auto"><use href="#svg-sun-half"></use></svg>
          <svg class="theme-icon-when-dark"><use href="#svg-moon"></use></svg>
          <svg class="theme-icon-when-light"><use href="#svg-sun"></use></svg>
        </button>
      </div>
      <label class="toc-overlay-icon toc-header-icon" for="__toc">
        <div class="visually-hidden">Toggle table of contents sidebar</div>
        <i class="icon"><svg><use href="#svg-toc"></use></svg></i>
      </label>
    </div>
  </header>
  <aside class="sidebar-drawer">
    <div class="sidebar-container">
      
      <div class="sidebar-sticky"><a class="sidebar-brand centered" href="index.html">
  
  <div class="sidebar-logo-container">
    <img class="sidebar-logo" src="_static/friendly_logo.png" alt="Logo"/>
  </div>
  
  <span class="sidebar-brand-text">friendly-traceback 0.5.1</span>
  
</a><form class="sidebar-search-container" method="get" action="search.html" role="search">
  <input class="sidebar-search" placeholder=Search name="q" aria-label="Search">
  <input type="hidden" name="check_keywords" value="yes">
  <input type="hidden" name="area" value="default">
</form>
<div id="searchbox"></div><div class="sidebar-scroll"><div class="sidebar-tree">
  <p class="caption" role="heading"><span class="caption-text">Begin here</span></p>
<ul>
<li class="toctree-l1"><a class="reference internal" href="beginner.html">Useful information for beginners</a></li>
<li class="toctree-l1"><a class="reference internal" href="install.html">Getting Friendly</a></li>
<li class="toctree-l1"><a class="reference internal" href="usage.html">Basic usage</a></li>
<li class="toctree-l1"><a class="reference internal" href="usage_adv.html">Other details for advanced users</a></li>
</ul>
<p class="caption" role="heading"><span class="caption-text">friendly console</span></p>
<ul>
<li class="toctree-l1"><a class="reference internal" href="repl.html">Console basics</a></li>
<li class="toctree-l1"><a class="reference internal" href="why.html">why()</a></li>
<li class="toctree-l1"><a class="reference internal" href="what.html">what()</a></li>
<li class="toctree-l1"><a class="reference internal" href="where.html">where()</a></li>
<li class="toctree-l1"><a class="reference internal" href="explain.html">explain()</a></li>
<li class="toctree-l1"><a class="reference internal" href="www.html">www()</a></li>
<li class="toctree-l1"><a class="reference internal" href="history.html">history() and back()</a></li>
<li class="toctree-l1"><a class="reference internal" href="friendly_object.html">Friendly object</a></li>
<li class="toctree-l1"><a class="reference internal" href="repl_api.html">Everything about the friendly console</a></li>
<li class="toctree-l1"><a class="reference internal" href="about_warnings.html">One last thing</a></li>
</ul>
<p class="caption" role="heading"><span class="caption-text">Why import *?</span></p>
<ul>
<li class="toctree-l1"><a class="reference internal" href="import_all.html">Why <code class="docutils literal notranslate"><span class="pre">import</span> <span class="pre">*</span></code>?</a></li>
</ul>
<p class="caption" role="heading"><span class="caption-text">IDLE</span></p>
<ul>
<li class="toctree-l1"><a class="reference internal" href="idle.html">About IDLE</a></li>
<li class="toctree-l1"><a class="reference internal" href="idle_repl.html">IDLE’s shell</a></li>
<li class="toctree-l1"><a class="reference internal" href="idle_run.html">IDLE: using the editor</a></li>
</ul>
<p class="caption" role="heading"><span class="caption-text">Mu</span></p>
<ul>
<li class="toctree-l1"><a class="reference internal" href="mu_about.html">About Mu</a></li>
<li class="toctree-l1"><a class="reference internal" href="mu_install.html">Using with Mu: installation</a></li>
<li class="toctree-l1"><a class="reference internal" href="mu_repl.html">Mu’s REPL</a></li>
<li class="toctree-l1"><a class="reference internal" href="mu_run.html">Mu: executing a program</a></li>
</ul>
<p class="caption" role="heading"><span class="caption-text">Other consoles</span></p>
<ul>
<li class="toctree-l1"><a class="reference internal" href="pyrepl.html">Using another REPL</a></li>
<li class="toctree-l1"><a class="reference internal" href="vs_code_repl.html">Visual Studio Code’s terminal</a></li>
<li class="toctree-l1"><a class="reference internal" href="ipython_repl.html">IPython’s console</a></li>
<li class="toctree-l1"><a class="reference internal" href="other_repl.html">Other repl</a></li>
</ul>
<p class="caption" role="heading"><span class="caption-text">Editors and Notebooks</span></p>
<ul>
<li class="toctree-l1"><a class="reference internal" href="install_thonny.html">Information for Thonny</a></li>
<li class="toctree-l1"><a class="reference internal" href="editor.html">Using with an editor or IDE</a></li>
<li class="toctree-l1"><a class="reference internal" href="jupyter.html">Jupyter notebooks and JupyterLab</a></li>
<li class="toctree-l1"><a class="reference internal" href="vs_code.html">Visual Studio Code</a></li>
<li class="toctree-l1"><a class="reference internal" href="colab.html">Google’s colab</a></li>
</ul>
<p class="caption" role="heading"><span class="caption-text">Thoughts on design</span></p>
<ul>
<li class="toctree-l1"><a class="reference internal" href="design.html">Some thoughts on the design of friendly</a></li>
<li class="toctree-l1"><a class="reference internal" href="themes.html">Themes, Styles, and Colours</a></li>
<li class="toctree-l1"><a class="reference internal" href="multiple_tracebacks.html">Multiple tracebacks</a></li>
<li class="toctree-l1"><a class="reference internal" href="friendly_tb.html">friendly tracebacks</a></li>
<li class="toctree-l1"><a class="reference internal" href="ipython_tb.html">IPython tracebacks</a></li>
<li class="toctree-l1"><a class="reference internal" href="jupyter_tb.html">Jupyter tracebacks</a></li>
<li class="toctree-l1"><a class="reference internal" href="numbered_prompt.html">Numbered prompt</a></li>
<li class="toctree-l1"><a class="reference internal" href="idle_colours.html">IDLE’s colours</a></li>
</ul>
<p class="caption" role="heading"><span class="caption-text">Use in your project</span></p>
<ul>
<li class="toctree-l1"><a class="reference internal" href="api.html">Public API</a></li>
<li class="toctree-l1"><a class="reference internal" href="formatter.html">Custom formatter</a></li>
<li class="toctree-l1"><a class="reference internal" href="custom_errors.html">Registering custom error types</a></li>
<li class="toctree-l1"><a class="reference internal" href="plugins.html">Editor plugins</a></li>
</ul>
<p class="caption" role="heading"><span class="caption-text">All the tracebacks!</span></p>
<ul>
<li class="toctree-l1"><a class="reference internal" href="tracebacks_en_3.9.html">Friendly tracebacks - Python 3.9</a></li>
<li class="toctree-l1"><a class="reference internal" href="syntax_tracebacks_en_3.9.html">SyntaxError - Python 3.9</a></li>
</ul>
<p class="caption" role="heading"><span class="caption-text">En español</span></p>
<ul>
<li class="toctree-l1"><a class="reference internal" href="tracebacks_es.html">Friendly tracebacks - en español</a></li>
<li class="toctree-l1"><a class="reference internal" href="syntax_tracebacks_es.html">Friendly SyntaxError tracebacks - en español</a></li>
</ul>
<p class="caption" role="heading"><span class="caption-text">En français</span></p>
<ul class="current">
<li class="toctree-l1 current current-page"><a class="current reference internal" href="#"> Friendly tracebacks - en Français</a></li>
<li class="toctree-l1"><a class="reference internal" href="syntax_tracebacks_fr.html"> Friendly SyntaxError tracebacks - en Français</a></li>
</ul>
<p class="caption" role="heading"><span class="caption-text">In italiano</span></p>
<ul>
<li class="toctree-l1"><a class="reference internal" href="tracebacks_it.html">Friendly tracebacks - in italiano</a></li>
<li class="toctree-l1"><a class="reference internal" href="syntax_tracebacks_it.html">Friendly SyntaxError tracebacks - in italiano</a></li>
</ul>
<p class="caption" role="heading"><span class="caption-text">More tracebacks</span></p>
<ul>
<li class="toctree-l1"><a class="reference internal" href="known.html">Generic information about various exceptions</a></li>
<li class="toctree-l1"><a class="reference internal" href="tracebacks_en_3.6.html">Friendly tracebacks - Python 3.6 in English</a></li>
<li class="toctree-l1"><a class="reference internal" href="syntax_tracebacks_en_3.6.html">SyntaxError - Python 3.6 in English</a></li>
<li class="toctree-l1"><a class="reference internal" href="tracebacks_en_3.7.html">Friendly tracebacks - Python 3.7 in English</a></li>
<li class="toctree-l1"><a class="reference internal" href="syntax_tracebacks_en_3.7.html">SyntaxError - Python 3.7 in English</a></li>
<li class="toctree-l1"><a class="reference internal" href="tracebacks_en_3.8.html">Friendly tracebacks - Python 3.8 in English</a></li>
<li class="toctree-l1"><a class="reference internal" href="syntax_tracebacks_en_3.8.html">SyntaxError - Python 3.8 in English</a></li>
<li class="toctree-l1"><a class="reference internal" href="tracebacks_en_3.10.html">Friendly tracebacks - Python 3.10 in English</a></li>
<li class="toctree-l1"><a class="reference internal" href="syntax_tracebacks_en_3.10.html">SyntaxError - Python 3.10 in English</a></li>
<li class="toctree-l1"><a class="reference internal" href="tracebacks_en_3.11.html">Friendly tracebacks - Python 3.11 in English</a></li>
<li class="toctree-l1"><a class="reference internal" href="syntax_tracebacks_en_3.11.html">SyntaxError - Python 3.11 in English</a></li>
<li class="toctree-l1"><a class="reference internal" href="compare_exceptions.html">Comparing Exception messages between Python versions</a></li>
<li class="toctree-l1"><a class="reference internal" href="compare.html">Comparison between Python versions: SyntaxErrors</a></li>
</ul>
<p class="caption" role="heading"><span class="caption-text">Contribute</span></p>
<ul>
<li class="toctree-l1"><a class="reference internal" href="suggest.html">Suggest an addition</a></li>
<li class="toctree-l1"><a class="reference internal" href="translation_notes.html">Notes on translations - using gettext</a></li>
</ul>

</div>
</div>
      </div>
      
    </div>
  </aside>
  <div class="main">
    <div class="content">
      <div class="article-container">
        <div class="content-icon-container">
          <div class="theme-toggle-container theme-toggle-content">
            <button class="theme-toggle">
              <div class="visually-hidden">Toggle Light / Dark / Auto color theme</div>
              <svg class="theme-icon-when-auto"><use href="#svg-sun-half"></use></svg>
              <svg class="theme-icon-when-dark"><use href="#svg-moon"></use></svg>
              <svg class="theme-icon-when-light"><use href="#svg-sun"></use></svg>
            </button>
          </div>
          <label class="toc-overlay-icon toc-content-icon" for="__toc">
            <div class="visually-hidden">Toggle table of contents sidebar</div>
            <i class="icon"><svg><use href="#svg-toc"></use></svg></i>
          </label>
        </div>
        <article role="main">
          <section id="france-friendly-tracebacks-en-francais">
<h1><img alt="france" src="_images/france.png"/> Friendly tracebacks - en Français<a class="headerlink" href="#france-friendly-tracebacks-en-francais" title="Permalink to this headline">¶</a></h1>
<p>Le but principal de friendly est de fournir des rétroactions plus
conviviales que les fameux <strong>tracebacks</strong> de Python lorsqu’une exception survient.</p>
<div class="admonition note">
<p class="admonition-title">Note</p>
<p>Le contenu de cette page a été généré par l’exécution de
<cite>trb_french.py</cite> situé dans le répertoire <code class="docutils literal notranslate"><span class="pre">tests/</span></code>.
Ceci a besoin d’être fait de manière explicite lorsqu’on veut
faire des corrections ou des ajouts, avant de faire la mise
à jour du reste de la documentation avec Sphinx.</p>
</div>
<p>Friendly-traceback version: 0.5.1
Python version: 3.9.9</p>
<section id="arithmeticerror">
<h2>ArithmeticError<a class="headerlink" href="#arithmeticerror" title="Permalink to this headline">¶</a></h2>
<section id="generic">
<h3>Generic<a class="headerlink" href="#generic" title="Permalink to this headline">¶</a></h3>
<div class="highlight-none notranslate"><div class="highlight"><pre><span></span>Traceback (most recent call last):
  File "TESTS:\runtime\test_arithmetic_error.py", line 9, in test_Generic
    raise ArithmeticError('error')
ArithmeticError: error

`ArithmeticError` est la classe de base pour les exceptions
qui sont soulevées pour diverses erreurs arithmétiques.
Il est inhabituel que vous voyiez cette exception;
normalement, une exception plus spécifique aurait dû être soulevée.

Exception levée à la ligne 9 du fichier TESTS:\runtime\test_arithmetic_error.py.

    4: def test_Generic():
    5:     try:
    6:         # I am not aware of any way in which this error is raised directly
    7:         # Usually, a subclass such as ZeroDivisionError, etc., would
    8:         # likely be raised.
--&gt; 9:         raise ArithmeticError('error')
   10:     except ArithmeticError as e:

        ArithmeticError:  &lt;class ArithmeticError&gt;
</pre></div>
</div>
</section>
</section>
<section id="assertionerror">
<h2>AssertionError<a class="headerlink" href="#assertionerror" title="Permalink to this headline">¶</a></h2>
<section id="id1">
<h3>Generic<a class="headerlink" href="#id1" title="Permalink to this headline">¶</a></h3>
<div class="highlight-none notranslate"><div class="highlight"><pre><span></span>Traceback (most recent call last):
  File "TESTS:\runtime\test_assertion_error.py", line 8, in test_Generic
    raise AssertionError("Fake message")
AssertionError: Fake message

Dans Python, le mot clé `assert` est utilisé dans des énoncés ayant la forme
`assert condition`, pour confirmer que `condition` n’est pas `False`;
ni équivalente à `False` comme une liste vide, etc.

Si `condition` est `False` ou son équivalent, une exception de type `AssertionError` est levée.

Exception levée à la ligne 8 du fichier TESTS:\runtime\test_assertion_error.py.

   4: def test_Generic():
   5:     try:
   6:         # We raise it explicitly, rather than with the keyword assert, since
   7:         # we don't want pytest to rewrite out test.
--&gt;8:         raise AssertionError("Fake message")
   9:     except AssertionError as e:

        AssertionError:  &lt;class AssertionError&gt;
</pre></div>
</div>
</section>
</section>
<section id="attributeerror">
<h2>AttributeError<a class="headerlink" href="#attributeerror" title="Permalink to this headline">¶</a></h2>
<section id="attribute-from-other-module">
<h3>Attribute from other module<a class="headerlink" href="#attribute-from-other-module" title="Permalink to this headline">¶</a></h3>
<div class="highlight-none notranslate"><div class="highlight"><pre><span></span>Traceback (most recent call last):
  File "TESTS:\runtime\test_attribute_error.py", line 325, in test_Attribute_from_other_module
    keyword.pi
AttributeError: module 'keyword' has no attribute 'pi'

    Vouliez-vous dire l’un des modules suivants: `math, cmath` ?
Une exception `AttributeError` se produit lorsque le code contient quelque chose comme
    `object.x`
et `x` n’est pas une méthode ou un attribut (variable) appartenant à `objet`.

Au lieu du module `keyword`, peut-être vouliez-vous utiliser l’attribut `pi` de
l'un des modules suivants:
`math, cmath` .

Exception levée à la ligne 325 du fichier TESTS:\runtime\test_attribute_error.py.

   321:         assert "Did you mean `math`?" in result
   323:     import cmath
   324:     try:
--&gt;325:         keyword.pi
                ^^^^^^^^^^
   326:     except AttributeError as e:

        keyword:  &lt;module keyword&gt; from PYTHON_LIB:\keyword.py
</pre></div>
</div>
</section>
<section id="builtin-function">
<h3>Builtin function<a class="headerlink" href="#builtin-function" title="Permalink to this headline">¶</a></h3>
<div class="highlight-none notranslate"><div class="highlight"><pre><span></span>Traceback (most recent call last):
  File "TESTS:\runtime\test_attribute_error.py", line 223, in test_Builtin_function
    len.text
AttributeError: 'builtin_function_or_method' object has no attribute 'text'

    Vouliez-vous dire `len(text)` ?

Une exception `AttributeError` se produit lorsque le code contient quelque chose comme
    `object.x`
et `x` n’est pas une méthode ou un attribut (variable) appartenant à `objet`.

`len` est une fonction. Peut-être que vous vouliez écrire
`len(text)`

Exception levée à la ligne 223 du fichier TESTS:\runtime\test_attribute_error.py.

   220: def test_Builtin_function():
   221:     text = 'Hello world!'
   222:     try:
--&gt;223:         len.text
                ^^^^^^^^
   224:     except AttributeError as e:

        text:  'Hello world!'
        len:  &lt;builtin function len&gt;
</pre></div>
</div>
</section>
<section id="builtin-module-with-no-file">
<h3>Builtin module with no file<a class="headerlink" href="#builtin-module-with-no-file" title="Permalink to this headline">¶</a></h3>
<div class="highlight-none notranslate"><div class="highlight"><pre><span></span>Traceback (most recent call last):
  File "TESTS:\runtime\test_attribute_error.py", line 240, in test_Builtin_module_with_no_file
    sys.foo
AttributeError: module 'sys' has no attribute 'foo'

Une exception `AttributeError` se produit lorsque le code contient quelque chose comme
    `object.x`
et `x` n’est pas une méthode ou un attribut (variable) appartenant à `objet`.

Python nous dit qu’aucun objet avec le nom `foo` n’est
dans le module `sys`.

Exception levée à la ligne 240 du fichier TESTS:\runtime\test_attribute_error.py.

   236:     """Issue 116"""
   237:     import sys
   239:     try:
--&gt;240:         sys.foo
                ^^^^^^^
   241:     except AttributeError as e:

        sys:  &lt;module sys (builtin)&gt;
</pre></div>
</div>
</section>
<section id="circular-import">
<h3>Circular import<a class="headerlink" href="#circular-import" title="Permalink to this headline">¶</a></h3>
<div class="highlight-none notranslate"><div class="highlight"><pre><span></span>Traceback (most recent call last):
  File "TESTS:\runtime\test_attribute_error.py", line 359, in test_Circular_import
    import my_turtle1
  File "TESTS:\my_turtle1.py", line 4, in &lt;module&gt;
    a = my_turtle1.something
AttributeError: partially initialized module 'my_turtle1' has no attribute 'something' (most likely due to a circular import)

    Avez-vous donné à votre programme le même nom qu’un module Python ?

Une exception `AttributeError` se produit lorsque le code contient quelque chose comme
    `object.x`
et `x` n’est pas une méthode ou un attribut (variable) appartenant à `objet`.

Je soupçonne que vous avez utilisé le nom `my_turtle1.py` pour votre programme
et que vous vouliez aussi importer un module du même nom
de la bibliothèque standard de Python.
Si c’est le cas, vous devriez utiliser un nom différent pour votre programme.

L'exécution s'est arrêtée à la ligne 359 du fichier TESTS:\runtime\test_attribute_error.py

   356:     from friendly_traceback.runtime_errors import stdlib_modules
   357:     stdlib_modules.names.append("my_turtle1")
   358:     try:
--&gt;359:        import my_turtle1
   360:     except AttributeError as e:

Exception levée à la ligne 4 du fichier TESTS:\my_turtle1.py.

   1: """To test attribute error of partially initialized module."""
   2: import my_turtle1
--&gt;4: a = my_turtle1.something
          ^^^^^^^^^^^^^^^^^^^^

        my_turtle1:  &lt;module my_turtle1&gt; from TESTS:\my_turtle1.py
</pre></div>
</div>
</section>
<section id="circular-import-b">
<h3>Circular import b<a class="headerlink" href="#circular-import-b" title="Permalink to this headline">¶</a></h3>
<div class="highlight-none notranslate"><div class="highlight"><pre><span></span>Traceback (most recent call last):
  File "TESTS:\runtime\test_attribute_error.py", line 376, in test_Circular_import_b
    import circular_c
  File "TESTS:\circular_c.py", line 4, in &lt;module&gt;
    a = circular_c.something
AttributeError: partially initialized module 'circular_c' has no attribute 'something' (most likely due to a circular import)

    Vous avez une importation circulaire.

Une exception `AttributeError` se produit lorsque le code contient quelque chose comme
    `object.x`
et `x` n’est pas une méthode ou un attribut (variable) appartenant à `objet`.

Python a indiqué que le module `{module}` n'était pas complètement importé.
Cela peut se produire si, pendant l'exécution du code du module `circular_c`
une tentative est faite d'importer à nouveau le même module.

L'exécution s'est arrêtée à la ligne 376 du fichier TESTS:\runtime\test_attribute_error.py

   374: def test_Circular_import_b():
   375:     try:
--&gt;376:         import circular_c
   377:     except AttributeError as e:

Exception levée à la ligne 4 du fichier TESTS:\circular_c.py.

   1: # Attribute error for partially initialize module
   2: import circular_c
--&gt;4: a = circular_c.something
          ^^^^^^^^^^^^^^^^^^^^

        circular_c:  &lt;module circular_c&gt; from TESTS:\circular_c.py
</pre></div>
</div>
</section>
<section id="id2">
<h3>Generic<a class="headerlink" href="#id2" title="Permalink to this headline">¶</a></h3>
<div class="highlight-none notranslate"><div class="highlight"><pre><span></span>Traceback (most recent call last):
  File "TESTS:\runtime\test_attribute_error.py", line 26, in test_Generic
    A.x  # testing type
AttributeError: type object 'A' has no attribute 'x'

Une exception `AttributeError` se produit lorsque le code contient quelque chose comme
    `object.x`
et `x` n’est pas une méthode ou un attribut (variable) appartenant à `objet`.

L’objet `A` n’a pas d’attribut nommé `x`.

Exception levée à la ligne 26 du fichier TESTS:\runtime\test_attribute_error.py.

   22:     class A:
   23:         pass
   25:     try:
--&gt;26:         A.x  # testing type
               ^^^
   27:     except AttributeError as e:

        A:  &lt;class A&gt; defined in &lt;function test_attribute_error.test_Generic&gt;
</pre></div>
</div>
</section>
<section id="generic-different-frame">
<h3>Generic different frame<a class="headerlink" href="#generic-different-frame" title="Permalink to this headline">¶</a></h3>
<div class="highlight-none notranslate"><div class="highlight"><pre><span></span>Traceback (most recent call last):
  File "TESTS:\runtime\test_attribute_error.py", line 49, in test_Generic_different_frame
    a.attr
AttributeError: 'A' object has no attribute 'attr'

    Vouliez-vous dire `attr2` ?

Une exception `AttributeError` se produit lorsque le code contient quelque chose comme
    `object.x`
et `x` n’est pas une méthode ou un attribut (variable) appartenant à `objet`.

L’objet `a` n’a pas d’attribut nommé `attr`.
Peut-être que vous vouliez plutôt écrire : `a.attr2` au lieu de `a.attr`.

Exception levée à la ligne 49 du fichier TESTS:\runtime\test_attribute_error.py.

   45:         return A()
   47:     a = f()
   48:     try:
--&gt;49:         a.attr
               ^^^^^^
   50:     except AttributeError as e:

        a:  &lt;A object&gt;
            defined in &lt;function test_attribute_error.test_Generic_different_frame.&lt;locals&gt;.f&gt;
</pre></div>
</div>
</section>
<section id="generic-instance">
<h3>Generic instance<a class="headerlink" href="#generic-instance" title="Permalink to this headline">¶</a></h3>
<div class="highlight-none notranslate"><div class="highlight"><pre><span></span>Traceback (most recent call last):
  File "TESTS:\runtime\test_attribute_error.py", line 67, in test_Generic_instance
    a.x
AttributeError: 'A' object has no attribute 'x'

Une exception `AttributeError` se produit lorsque le code contient quelque chose comme
    `object.x`
et `x` n’est pas une méthode ou un attribut (variable) appartenant à `objet`.

L’objet `a` n’a pas d’attribut nommé `x`.

Exception levée à la ligne 67 du fichier TESTS:\runtime\test_attribute_error.py.

   64:         pass
   65:     a = A()
   66:     try:
--&gt;67:         a.x
               ^^^
   68:     except AttributeError as e:

        a:  &lt;A object&gt;
            defined in &lt;function test_attribute_error.test_Generic_instance&gt;
</pre></div>
</div>
</section>
<section id="module-attribute-typo">
<h3>Module attribute typo<a class="headerlink" href="#module-attribute-typo" title="Permalink to this headline">¶</a></h3>
<div class="highlight-none notranslate"><div class="highlight"><pre><span></span>Traceback (most recent call last):
  File "TESTS:\runtime\test_attribute_error.py", line 144, in test_Module_attribute_typo
    math.cost
AttributeError: module 'math' has no attribute 'cost'

    Vouliez-vous dire `cos` ?

Une exception `AttributeError` se produit lorsque le code contient quelque chose comme
    `object.x`
et `x` n’est pas une méthode ou un attribut (variable) appartenant à `objet`.

Au lieu d’écrire `math.cost`, peut-être que vous vouliez écrire
l'un des attributs suivants du module `math` :
cos, cosh

Exception levée à la ligne 144 du fichier TESTS:\runtime\test_attribute_error.py.

   139:         assert "Did you mean `ascii_lowercase`" in result
   141:     import math
   143:     try:
--&gt;144:         math.cost
                ^^^^^^^^^
   145:     except AttributeError as e:

        math:  &lt;module math (builtin)&gt;
</pre></div>
</div>
</section>
<section id="nonetype">
<h3>Nonetype<a class="headerlink" href="#nonetype" title="Permalink to this headline">¶</a></h3>
<div class="highlight-none notranslate"><div class="highlight"><pre><span></span>Traceback (most recent call last):
  File "TESTS:\runtime\test_attribute_error.py", line 183, in test_Nonetype
    a.b
AttributeError: 'NoneType' object has no attribute 'b'

Une exception `AttributeError` se produit lorsque le code contient quelque chose comme
    `object.x`
et `x` n’est pas une méthode ou un attribut (variable) appartenant à `objet`.

Vous tentez d’accéder à l’attribut `b`
pour une variable dont la valeur est `None`.
Exception levée à la ligne 183 du fichier TESTS:\runtime\test_attribute_error.py.

   180: def test_Nonetype():
   181:     a = None
   182:     try:
--&gt;183:         a.b
                ^^^
   184:     except AttributeError as e:

        a:  None
</pre></div>
</div>
</section>
<section id="object-attribute-typo">
<h3>Object attribute typo<a class="headerlink" href="#object-attribute-typo" title="Permalink to this headline">¶</a></h3>
<div class="highlight-none notranslate"><div class="highlight"><pre><span></span>Traceback (most recent call last):
  File "TESTS:\runtime\test_attribute_error.py", line 83, in test_Object_attribute_typo
    a.appendh(4)
AttributeError: 'list' object has no attribute 'appendh'

    Vouliez-vous dire `append` ?

Une exception `AttributeError` se produit lorsque le code contient quelque chose comme
    `object.x`
et `x` n’est pas une méthode ou un attribut (variable) appartenant à `objet`.

L’objet `a` n’a pas d’attribut nommé `appendh`.
Peut-être que vous vouliez plutôt écrire : `a.append` au lieu de `a.appendh`.

Exception levée à la ligne 83 du fichier TESTS:\runtime\test_attribute_error.py.

   79: def test_Object_attribute_typo():
   80:     #
   81:     try:
   82:         a = [1, 2, 3]
--&gt;83:         a.appendh(4)
               ^^^^^^^^^
   84:     except AttributeError as e:

        a:  [1, 2, 3]
</pre></div>
</div>
</section>
<section id="perhaps-comma">
<h3>Perhaps comma<a class="headerlink" href="#perhaps-comma" title="Permalink to this headline">¶</a></h3>
<div class="highlight-none notranslate"><div class="highlight"><pre><span></span>Traceback (most recent call last):
  File "TESTS:\runtime\test_attribute_error.py", line 203, in test_Perhaps_comma
    a = [abcd
AttributeError: 'str' object has no attribute 'defg'

    Vouliez-vous séparer les noms d’objets par une virgule ?

Une exception `AttributeError` se produit lorsque le code contient quelque chose comme
    `object.x`
et `x` n’est pas une méthode ou un attribut (variable) appartenant à `objet`.

`defg` n’est pas un attribut de `abcd`.
Cependant, les objets `abcd` et `defg` sont des objets connus.
Peut-être avez-vous écrit une période pour séparer ces deux objets,
au lieu d’utiliser une virgule.

Exception levée à la ligne 203 du fichier TESTS:\runtime\test_attribute_error.py.

   199:     defg = "world"
   201:     # fmt: off
   202:     try:
--&gt;203:         a = [abcd
   204:         .defg]
   205:     # fmt: on

        abcd:  'hello'
        defg:  'world'
</pre></div>
</div>
</section>
<section id="read-only">
<h3>Read only<a class="headerlink" href="#read-only" title="Permalink to this headline">¶</a></h3>
<div class="highlight-none notranslate"><div class="highlight"><pre><span></span>Traceback (most recent call last):
  File "TESTS:\runtime\test_attribute_error.py", line 280, in test_Read_only
    f.b = 1
AttributeError: 'F' object attribute 'b' is read-only

Une exception `AttributeError` se produit lorsque le code contient quelque chose comme
    `object.x`
et `x` n’est pas une méthode ou un attribut (variable) appartenant à `objet`.

L'objet `f` utilise `__slots__` pour spécifier quels attributs peuvent être
être modifiés. La valeur de l'attribut `f.b` ne peut pas être modifiée.
The only attribute of `f` whose value can be changed is`a`.

Exception levée à la ligne 280 du fichier TESTS:\runtime\test_attribute_error.py.

   276:         b = 2
   278:     f = F()
   279:     try:
--&gt;280:         f.b = 1
   281:     except AttributeError as e:

        f:  &lt;F object&gt;
            defined in &lt;function test_attribute_error.test_Read_only&gt;
        f.b:  2
</pre></div>
</div>
</section>
<section id="shadow-stdlib-module">
<h3>Shadow stdlib module<a class="headerlink" href="#shadow-stdlib-module" title="Permalink to this headline">¶</a></h3>
<div class="highlight-none notranslate"><div class="highlight"><pre><span></span>Traceback (most recent call last):
  File "TESTS:\runtime\test_attribute_error.py", line 165, in test_Shadow_stdlib_module
    turtle.Pen
AttributeError: module 'turtle' has no attribute 'Pen'

    Avez-vous donné à votre programme le même nom qu’un module Python ?

Une exception `AttributeError` se produit lorsque le code contient quelque chose comme
    `object.x`
et `x` n’est pas une méthode ou un attribut (variable) appartenant à `objet`.

Vous avez importé un module nommé `turtle` de `TESTS:\turtle.py`.
Il y a aussi un module nommé `turtle` dans la bibliothèque standard de Python.
Peut-être avez-vous besoin de renommer votre module.

Exception levée à la ligne 165 du fichier TESTS:\runtime\test_attribute_error.py.

   161: def test_Shadow_stdlib_module():
   162:     import turtle
   164:     try:
--&gt;165:         turtle.Pen
                ^^^^^^^^^^
   166:     except AttributeError as e:

        turtle:  &lt;module turtle&gt; from TESTS:\turtle.py
</pre></div>
</div>
</section>
<section id="tuple-by-accident">
<h3>Tuple by accident<a class="headerlink" href="#tuple-by-accident" title="Permalink to this headline">¶</a></h3>
<div class="highlight-none notranslate"><div class="highlight"><pre><span></span>Traceback (most recent call last):
  File "TESTS:\runtime\test_attribute_error.py", line 295, in test_Tuple_by_accident
    something.upper()
AttributeError: 'tuple' object has no attribute 'upper'

    Avez-vous écrit une virgule par erreur ?

Une exception `AttributeError` se produit lorsque le code contient quelque chose comme
    `object.x`
et `x` n’est pas une méthode ou un attribut (variable) appartenant à `objet`.

`something` est un tuple qui contient un seul élément
ayant `upper` comme attribut.
Peut-être avez-vous ajouté une virgule par erreur à la fin de la ligne
lorsque vous avez défini `something`.

Exception levée à la ligne 295 du fichier TESTS:\runtime\test_attribute_error.py.

   292: def test_Tuple_by_accident():
   293:     something = "abc",  # note trailing comma
   294:     try:
--&gt;295:         something.upper()
                ^^^^^^^^^^^^^^^
   296:     except AttributeError as e:

        something:  ('abc',)
</pre></div>
</div>
</section>
<section id="use-builtin">
<h3>Use builtin<a class="headerlink" href="#use-builtin" title="Permalink to this headline">¶</a></h3>
<div class="highlight-none notranslate"><div class="highlight"><pre><span></span>Traceback (most recent call last):
  File "TESTS:\runtime\test_attribute_error.py", line 99, in test_Use_builtin
    a.length()
AttributeError: 'list' object has no attribute 'length'

    Vouliez-vous utiliser `len(a)` ?

Une exception `AttributeError` se produit lorsque le code contient quelque chose comme
    `object.x`
et `x` n’est pas une méthode ou un attribut (variable) appartenant à `objet`.

L’objet `a` n’a pas d’attribut nommé `length`.
Peut-être pouvez-vous utiliser la fonction Python builtin `len` à la place:
`len(a)`.
Exception levée à la ligne 99 du fichier TESTS:\runtime\test_attribute_error.py.

    95: def test_Use_builtin():
    96:     #
    97:     try:
    98:         a = [1, 2, 3]
--&gt; 99:         a.length()
                ^^^^^^^^
   100:     except AttributeError as e:

        a:  [1, 2, 3]
</pre></div>
</div>
</section>
<section id="use-join-with-str">
<h3>Use join with str<a class="headerlink" href="#use-join-with-str" title="Permalink to this headline">¶</a></h3>
<div class="highlight-none notranslate"><div class="highlight"><pre><span></span>Traceback (most recent call last):
  File "TESTS:\runtime\test_attribute_error.py", line 339, in test_Use_join_with_str
    a = ['a', '2'].join('abc') + ['b', '3'].join('\n')
AttributeError: 'list' object has no attribute 'join'

    Voulez-vous dire `'abc'.join(['a', '2'])` ?

Une exception `AttributeError` se produit lorsque le code contient quelque chose comme
    `object.x`
et `x` n’est pas une méthode ou un attribut (variable) appartenant à `objet`.

L’objet `['a', '2']` n’a pas d’attribut nommé `join`.
Vous vouliez peut-être plutôt écrire quelque chose comme `'...'.join(['a', '2'])`.

Exception levée à la ligne 339 du fichier TESTS:\runtime\test_attribute_error.py.

   337: def test_Use_join_with_str():
   338:     try:
--&gt;339:         a = ['a', '2'].join('abc') + ['b', '3'].join('\n')
                    ^^^^^^^^^^^^^^^
   340:     except AttributeError as e:
</pre></div>
</div>
</section>
<section id="use-synonym">
<h3>Use synonym<a class="headerlink" href="#use-synonym" title="Permalink to this headline">¶</a></h3>
<div class="highlight-none notranslate"><div class="highlight"><pre><span></span>Traceback (most recent call last):
  File "TESTS:\runtime\test_attribute_error.py", line 115, in test_Use_synonym
    a.add(4)
AttributeError: 'list' object has no attribute 'add'

    Vouliez-vous dire `append` ?

Une exception `AttributeError` se produit lorsque le code contient quelque chose comme
    `object.x`
et `x` n’est pas une méthode ou un attribut (variable) appartenant à `objet`.

L’objet `a` n’a pas d’attribut nommé `add`.
Toutefois, `a` a les attributs suivants avec des sens similaires:
'append, extend, insert'.

Exception levée à la ligne 115 du fichier TESTS:\runtime\test_attribute_error.py.

   111: def test_Use_synonym():
   112:     #
   113:     try:
   114:         a = [1, 2, 3]
--&gt;115:         a.add(4)
                ^^^^^
   116:     except AttributeError as e:

        a:  [1, 2, 3]
</pre></div>
</div>
</section>
<section id="using-slots">
<h3>Using slots<a class="headerlink" href="#using-slots" title="Permalink to this headline">¶</a></h3>
<div class="highlight-none notranslate"><div class="highlight"><pre><span></span>Traceback (most recent call last):
  File "TESTS:\runtime\test_attribute_error.py", line 260, in test_Using_slots
    f.b = 1
AttributeError: 'F' object has no attribute 'b'

Une exception `AttributeError` se produit lorsque le code contient quelque chose comme
    `object.x`
et `x` n’est pas une méthode ou un attribut (variable) appartenant à `objet`.

L’objet `f` n’a pas d’attribut nommé `b`.
Notez que l’objet `f` utilise `__slots__` qui empêche
la création de nouveaux attributs.
Voici quelques-uns de ses attributs connus :
`a`.
Exception levée à la ligne 260 du fichier TESTS:\runtime\test_attribute_error.py.

   256:         __slots__ = ["a"]
   258:     f = F()
   259:     try:
--&gt;260:         f.b = 1
   261:     except AttributeError as e:

        f:  &lt;F object&gt;
            defined in &lt;function test_attribute_error.test_Using_slots&gt;
</pre></div>
</div>
</section>
</section>
<section id="filenotfounderror">
<h2>FileNotFoundError<a class="headerlink" href="#filenotfounderror" title="Permalink to this headline">¶</a></h2>
<section id="directory-not-found">
<h3>Directory not found<a class="headerlink" href="#directory-not-found" title="Permalink to this headline">¶</a></h3>
<div class="highlight-none notranslate"><div class="highlight"><pre><span></span>Traceback (most recent call last):
  File "TESTS:\runtime\test_file_not_found_error.py", line 70, in test_Directory_not_found
    open("does_not_exist/file.txt")
FileNotFoundError: [Errno 2] No such file or directory: 'does_not_exist/file.txt'

Une exception `FileNotFoundError` indique que vous
essayez d’importer un module qui ne peut pas être trouvé par Python.
Cela pourrait être parce que vous fait une faute d'orthographe en
écrivant le nom du fichier.

Dans votre programme, le nom du fichier inconnu est `file.txt`.
does_not_exist
n'est pas un répertoire valide.

Exception levée à la ligne 70 du fichier TESTS:\runtime\test_file_not_found_error.py.

   68: def test_Directory_not_found():
   69:     try:
--&gt;70:         open("does_not_exist/file.txt")
               ^^^^^^^^^^^^^^^^^^^^^^^^^^^^^^^
   71:     except FileNotFoundError as e:

        open:  &lt;builtin function open&gt;
</pre></div>
</div>
</section>
<section id="filename-not-found">
<h3>Filename not found<a class="headerlink" href="#filename-not-found" title="Permalink to this headline">¶</a></h3>
<div class="highlight-none notranslate"><div class="highlight"><pre><span></span>Traceback (most recent call last):
  File "TESTS:\runtime\test_file_not_found_error.py", line 7, in test_Filename_not_found
    open("does_not_exist")
FileNotFoundError: [Errno 2] No such file or directory: 'does_not_exist'

Une exception `FileNotFoundError` indique que vous
essayez d’importer un module qui ne peut pas être trouvé par Python.
Cela pourrait être parce que vous fait une faute d'orthographe en
écrivant le nom du fichier.

Dans votre programme, le nom du fichier inconnu est `does_not_exist`.
On s'attendait à ce qu'il soit trouvé dans le répertoire
`C:\Users\Andre\github\friendly-traceback\tests`.
Je n’ai pas d’informations supplémentaires pour vous.

Exception levée à la ligne 7 du fichier TESTS:\runtime\test_file_not_found_error.py.

   5: def test_Filename_not_found():
   6:     try:
--&gt;7:         open("does_not_exist")
              ^^^^^^^^^^^^^^^^^^^^^^
   8:     except FileNotFoundError as e:

        open:  &lt;builtin function open&gt;
</pre></div>
</div>
</section>
<section id="filename-not-found-2">
<h3>Filename not found 2<a class="headerlink" href="#filename-not-found-2" title="Permalink to this headline">¶</a></h3>
<div class="highlight-none notranslate"><div class="highlight"><pre><span></span>Traceback (most recent call last):
  File "TESTS:\runtime\test_file_not_found_error.py", line 30, in test_Filename_not_found_2
    open("setupp.py")
FileNotFoundError: [Errno 2] No such file or directory: 'setupp.py'

    Vouliez-vous dire `setup.py` ?

Une exception `FileNotFoundError` indique que vous
essayez d’importer un module qui ne peut pas être trouvé par Python.
Cela pourrait être parce que vous fait une faute d'orthographe en
écrivant le nom du fichier.

Dans votre programme, le nom du fichier inconnu est `setupp.py`.
On s'attendait à ce qu'il soit trouvé dans le répertoire
`C:\Users\Andre\github\friendly-traceback`.
Le fichier `setup.py` a un nom semblable.

Exception levée à la ligne 30 du fichier TESTS:\runtime\test_file_not_found_error.py.

   26:     if chdir:
   27:         os.chdir("..")
   29:     try:
--&gt;30:         open("setupp.py")
               ^^^^^^^^^^^^^^^^^
   31:     except FileNotFoundError as e:

        open:  &lt;builtin function open&gt;
</pre></div>
</div>
</section>
<section id="filename-not-found-3">
<h3>Filename not found 3<a class="headerlink" href="#filename-not-found-3" title="Permalink to this headline">¶</a></h3>
<div class="highlight-none notranslate"><div class="highlight"><pre><span></span>Traceback (most recent call last):
  File "TESTS:\runtime\test_file_not_found_error.py", line 52, in test_Filename_not_found_3
    open("setup.pyg")
FileNotFoundError: [Errno 2] No such file or directory: 'setup.pyg'

    Vouliez-vous dire `setup.py` ?

Une exception `FileNotFoundError` indique que vous
essayez d’importer un module qui ne peut pas être trouvé par Python.
Cela pourrait être parce que vous fait une faute d'orthographe en
écrivant le nom du fichier.

Dans votre programme, le nom du fichier inconnu est `setup.pyg`.
On s'attendait à ce qu'il soit trouvé dans le répertoire
`C:\Users\Andre\github\friendly-traceback`.
Vous vouliez peut-être un des fichiers suivants ayant des noms semblables :
`setup.py`, `setup.cfg`

Exception levée à la ligne 52 du fichier TESTS:\runtime\test_file_not_found_error.py.

   49:     if chdir:
   50:         os.chdir("..")
   51:     try:
--&gt;52:         open("setup.pyg")
               ^^^^^^^^^^^^^^^^^
   53:     except FileNotFoundError as e:

        open:  &lt;builtin function open&gt;
</pre></div>
</div>
</section>
</section>
<section id="importerror">
<h2>ImportError<a class="headerlink" href="#importerror" title="Permalink to this headline">¶</a></h2>
<section id="id3">
<h3>Circular import<a class="headerlink" href="#id3" title="Permalink to this headline">¶</a></h3>
<div class="highlight-none notranslate"><div class="highlight"><pre><span></span>Traceback (most recent call last):
  File "TESTS:\runtime\test_import_error.py", line 70, in test_Circular_import
    import circular_a
  File "TESTS:\circular_a.py", line 2, in &lt;module&gt;
    import circular_b
  File "TESTS:\circular_b.py", line 2, in &lt;module&gt;
    from circular_a import a
ImportError: cannot import name 'a' from partially initialized module 'circular_a' (most likely due to a circular import) (C:\Users\Andre\github\friendly-traceback\tests\circular_a.py)

L'exception `ImportError` indique qu’un certain objet n’a pas pu
être importé à partir d’un module ou d’un paquet. Très souvent, c’est
parce que le nom de l’objet n’est pas écrit correctement.

L’objet qui n’a pas pu être importé est `a`.
Le module ou le paquet d'où il devait être importé est `circular_a`.

Le problème a probablement été causé par ce qu’on appelle une « importation circulaire ».
Tout d’abord, Python a importé et a commencé à exécuter le code dans le fichier
   'TESTS:\runtime\test_import_error.py'.
qui importe le module `circular_a`.
Au cours de ce processus, le code d’un autre fichier,
   'TESTS:\circular_b.py'
a été exécuté. Toutefois, dans ce dernier dossier, une tentative a été
pour importer le module d’origine `circular_a`
une deuxième fois, avant que Python n’ait terminé la première importation.

L'exécution s'est arrêtée à la ligne 70 du fichier TESTS:\runtime\test_import_error.py

   68: def test_Circular_import():
   69:     try:
--&gt;70:         import circular_a
   71:     except ImportError as e:

Exception levée à la ligne 2 du fichier TESTS:\circular_b.py.

   1: """File used in for test_circular_import() in test_import_error.py"""
--&gt;2: from circular_a import a
                 ^
</pre></div>
</div>
</section>
<section id="simple-import-error">
<h3>Simple import error<a class="headerlink" href="#simple-import-error" title="Permalink to this headline">¶</a></h3>
<div class="highlight-none notranslate"><div class="highlight"><pre><span></span>Traceback (most recent call last):
  File "TESTS:\runtime\test_import_error.py", line 56, in test_Simple_import_error
    from math import Pi
ImportError: cannot import name 'Pi' from 'math' (unknown location)

    Vouliez-vous dire `pi` ?

L'exception `ImportError` indique qu’un certain objet n’a pas pu
être importé à partir d’un module ou d’un paquet. Très souvent, c’est
parce que le nom de l’objet n’est pas écrit correctement.

Peut-être que vous vouliez importer `pi` (de `math`) au lieu de `Pi`.

Exception levée à la ligne 56 du fichier TESTS:\runtime\test_import_error.py.

   52:     multiple_import_on_same_line()
   53:     wrong_case()
   55:     try:
--&gt;56:         from math import Pi
   57:     except ImportError as e:
</pre></div>
</div>
</section>
</section>
<section id="indexerror">
<h2>IndexError<a class="headerlink" href="#indexerror" title="Permalink to this headline">¶</a></h2>
<section id="assignment">
<h3>Assignment<a class="headerlink" href="#assignment" title="Permalink to this headline">¶</a></h3>
<div class="highlight-none notranslate"><div class="highlight"><pre><span></span>Traceback (most recent call last):
  File "TESTS:\runtime\test_index_error.py", line 87, in test_Assignment
    a[13] = 1
IndexError: list assignment index out of range

Une exception `IndexError` se produit lorsque vous essayez d’obtenir un élément
d'une liste, d'un tuple, ou d'un objet similaire (séquence), à l’aide d’un indice qui
n’existe pas; typiquement, c’est parce que l’indice que vous donnez
est plus grand que la longueur de la séquence.

Vous avez essayé d'assigner une valeur à l'indice `13` de `a`,
une liste (`list`) de longueur `10`.
Les indices valides de `a` sont les entiers allant de `-10` à `9`.

Exception levée à la ligne 87 du fichier TESTS:\runtime\test_index_error.py.

   83:         assert "You have tried to assign a value to index `1` of `b`," in result
   84:         assert "a `list` which contains no item." in result
   86:     try:
--&gt;87:         a[13] = 1
   88:     except IndexError as e:

        a:  [0, 1, 2, 3, 4, 5, 6, 7, 8, 9]
</pre></div>
</div>
</section>
<section id="empty">
<h3>Empty<a class="headerlink" href="#empty" title="Permalink to this headline">¶</a></h3>
<div class="highlight-none notranslate"><div class="highlight"><pre><span></span>Traceback (most recent call last):
  File "TESTS:\runtime\test_index_error.py", line 46, in test_Empty
    c = a[1]
IndexError: list index out of range

    `a` ne contient aucun élément.

Une exception `IndexError` se produit lorsque vous essayez d’obtenir un élément
d'une liste, d'un tuple, ou d'un objet similaire (séquence), à l’aide d’un indice qui
n’existe pas; typiquement, c’est parce que l’indice que vous donnez
est plus grand que la longueur de la séquence.

Vous avez essayé d’obtenir l’élément avec l’indice `1` de `a`,
une liste (`list`) qui ne contient aucun élément.

Exception levée à la ligne 46 du fichier TESTS:\runtime\test_index_error.py.

   43: def test_Empty():
   44:     a = []
   45:     try:
--&gt;46:         c = a[1]
                   ^^^^
   47:     except IndexError as e:

        a:  []
</pre></div>
</div>
</section>
<section id="long-list">
<h3>Long list<a class="headerlink" href="#long-list" title="Permalink to this headline">¶</a></h3>
<div class="highlight-none notranslate"><div class="highlight"><pre><span></span>Traceback (most recent call last):
  File "TESTS:\runtime\test_index_error.py", line 29, in test_Long_list
    print(a[60], b[0])
IndexError: list index out of range

Une exception `IndexError` se produit lorsque vous essayez d’obtenir un élément
d'une liste, d'un tuple, ou d'un objet similaire (séquence), à l’aide d’un indice qui
n’existe pas; typiquement, c’est parce que l’indice que vous donnez
est plus grand que la longueur de la séquence.

Vous avez essayé d’obtenir l’élément avec l’indice `60` de `a`,
une liste (`list`) de longueur `40`.
Les indices valides de `a` sont les entiers allant de `-40` à `39`.

Exception levée à la ligne 29 du fichier TESTS:\runtime\test_index_error.py.

   26:     a = list(range(40))
   27:     b = tuple(range(50))
   28:     try:
--&gt;29:         print(a[60], b[0])
                     ^^^^^
   30:     except IndexError as e:

        a:  [0, 1, 2, 3, 4, 5, 6, 7, 8, 9, 10, 11, 12, 13, 14, 15, 16, 17, 18, ...]
            len(a): 40
</pre></div>
</div>
</section>
<section id="short-tuple">
<h3>Short tuple<a class="headerlink" href="#short-tuple" title="Permalink to this headline">¶</a></h3>
<div class="highlight-none notranslate"><div class="highlight"><pre><span></span>Traceback (most recent call last):
  File "TESTS:\runtime\test_index_error.py", line 10, in test_Short_tuple
    print(a[3], b[2])
IndexError: tuple index out of range

    N’oubliez pas : le premier élément d'un objet de type `un `tuple`` est à l’indice 0
    et non pas à l'indice 1.

Une exception `IndexError` se produit lorsque vous essayez d’obtenir un élément
d'une liste, d'un tuple, ou d'un objet similaire (séquence), à l’aide d’un indice qui
n’existe pas; typiquement, c’est parce que l’indice que vous donnez
est plus grand que la longueur de la séquence.

Vous avez essayé d’obtenir l’élément avec l’indice `3` de `a`,
un `tuple` de longueur `3`.
Les indices valides de `a` sont les entiers allant de `-3` à `2`.

Exception levée à la ligne 10 du fichier TESTS:\runtime\test_index_error.py.

    7:     a = (1, 2, 3)
    8:     b = [1, 2, 3]
    9:     try:
--&gt;10:         print(a[3], b[2])
                     ^^^^
   11:     except IndexError as e:

        a:  (1, 2, 3)
</pre></div>
</div>
</section>
</section>
<section id="keyerror">
<h2>KeyError<a class="headerlink" href="#keyerror" title="Permalink to this headline">¶</a></h2>
<section id="chainmap">
<h3>ChainMap<a class="headerlink" href="#chainmap" title="Permalink to this headline">¶</a></h3>
<div class="highlight-none notranslate"><div class="highlight"><pre><span></span>Traceback (most recent call last):
  File "PYTHON_LIB:\collections\__init__.py", line 1008, in pop
    return self.maps[0].pop(key, *args)
KeyError: 42

    During handling of the above exception, another exception occurred:

Traceback (most recent call last):
  File "TESTS:\runtime\test_key_error.py", line 62, in test_ChainMap
    d.pop(42)
KeyError: 'Key not found in the first mapping: 42'

Une `KeyError` est levée lorsqu'une valeur n'est pas trouvée en tant que
clé dans un dict Python ou dans un objet similaire.

La clé `42` est introuvable dans `d`, un objet de type `ChainMap`.

Exception levée à la ligne 62 du fichier TESTS:\runtime\test_key_error.py.

   59:     from collections import ChainMap
   60:     d = ChainMap({}, {})
   61:     try:
--&gt;62:         d.pop(42)
               ^^^^^^^^^
   63:     except KeyError as e:

        d:  ChainMap({}, {})
        d.pop:  &lt;bound method ChainMap.pop&gt; of ChainMap({}, {})
</pre></div>
</div>
</section>
<section id="forgot-to-convert-to-string">
<h3>Forgot to convert to string<a class="headerlink" href="#forgot-to-convert-to-string" title="Permalink to this headline">¶</a></h3>
<div class="highlight-none notranslate"><div class="highlight"><pre><span></span>Traceback (most recent call last):
  File "TESTS:\runtime\test_key_error.py", line 115, in test_Forgot_to_convert_to_string
    print(squares[2])
KeyError: 2

    Avez-vous oublié de convertir `2` en une chaîne ?

Une `KeyError` est levée lorsqu'une valeur n'est pas trouvée en tant que
clé dans un dict Python ou dans un objet similaire.

La clé `2` est introuvable dans le dict `squares`.
`squares` contient une clé identique à `str(2)`.
Peut-être avez-vous oublié de convertir la clé en une chaîne.

Exception levée à la ligne 115 du fichier TESTS:\runtime\test_key_error.py.

   112: def test_Forgot_to_convert_to_string():
   113:     squares = {"1": 1, "2": 4, "3": 9}
   114:     try:
--&gt;115:         print(squares[2])
                      ^^^^^^^^^^
   116:     except KeyError as e:

        squares:  {'1': 1, '2': 4, '3': 9}
</pre></div>
</div>
</section>
<section id="generic-key-error">
<h3>Generic key error<a class="headerlink" href="#generic-key-error" title="Permalink to this headline">¶</a></h3>
<div class="highlight-none notranslate"><div class="highlight"><pre><span></span>Traceback (most recent call last):
  File "TESTS:\runtime\test_key_error.py", line 44, in test_Generic_key_error
    d["c"]
KeyError: 'c'

Une `KeyError` est levée lorsqu'une valeur n'est pas trouvée en tant que
clé dans un dict Python ou dans un objet similaire.

La clé `'c'` est introuvable dans le dict `d`.

Exception levée à la ligne 44 du fichier TESTS:\runtime\test_key_error.py.

   41: def test_Generic_key_error():
   42:     d = {"a": 1, "b": 2}
   43:     try:
--&gt;44:         d["c"]
               ^^^^^^
   45:     except KeyError as e:

        d:  {'a': 1, 'b': 2}
</pre></div>
</div>
</section>
<section id="popitem-empty-chainmap">
<h3>Popitem empty ChainMap<a class="headerlink" href="#popitem-empty-chainmap" title="Permalink to this headline">¶</a></h3>
<div class="highlight-none notranslate"><div class="highlight"><pre><span></span>Traceback (most recent call last):
  File "PYTHON_LIB:\collections\__init__.py", line 1001, in popitem
    return self.maps[0].popitem()
KeyError: 'popitem(): dictionary is empty'

    During handling of the above exception, another exception occurred:

Traceback (most recent call last):
  File "TESTS:\runtime\test_key_error.py", line 26, in test_Popitem_empty_ChainMap
    alpha.popitem()
KeyError: 'No keys found in the first mapping.'

    `alpha` est une `ChainMap` vide.

Une `KeyError` est levée lorsqu'une valeur n'est pas trouvée en tant que
clé dans un dict Python ou dans un objet similaire.

Vous avez essayé de récupérer un élément de `alpha` qui est une `ChainMap` vide.

Exception levée à la ligne 26 du fichier TESTS:\runtime\test_key_error.py.

   23:     from collections import ChainMap
   24:     alpha = ChainMap({}, {})
   25:     try:
--&gt;26:         alpha.popitem()
               ^^^^^^^^^^^^^^^
   27:     except KeyError as e:

        alpha:  ChainMap({}, {})
        alpha.popitem:  &lt;bound method ChainMap.popitem&gt; of ChainMap({}, {})
</pre></div>
</div>
</section>
<section id="popitem-empty-dict">
<h3>Popitem empty dict<a class="headerlink" href="#popitem-empty-dict" title="Permalink to this headline">¶</a></h3>
<div class="highlight-none notranslate"><div class="highlight"><pre><span></span>Traceback (most recent call last):
  File "TESTS:\runtime\test_key_error.py", line 8, in test_Popitem_empty_dict
    d.popitem()
KeyError: 'popitem(): dictionary is empty'

    `d` est un `dict` vide.

Une `KeyError` est levée lorsqu'une valeur n'est pas trouvée en tant que
clé dans un dict Python ou dans un objet similaire.

Vous avez essayé de récupérer un élément de `d` qui est un `dict` vide.

Exception levée à la ligne 8 du fichier TESTS:\runtime\test_key_error.py.

   5: def test_Popitem_empty_dict():
   6:     d = {}
   7:     try:
--&gt;8:         d.popitem()
              ^^^^^^^^^^^
   9:     except KeyError as e:

        d:  {}
        d.popitem:  &lt;builtin method popitem of dict object&gt;
</pre></div>
</div>
</section>
<section id="similar-names">
<h3>Similar names<a class="headerlink" href="#similar-names" title="Permalink to this headline">¶</a></h3>
<div class="highlight-none notranslate"><div class="highlight"><pre><span></span>Traceback (most recent call last):
  File "TESTS:\runtime\test_key_error.py", line 145, in test_Similar_names
    a = second["alpha"]
KeyError: 'alpha'

    Vouliez-vous dire `'alpha0'` ?

Une `KeyError` est levée lorsqu'une valeur n'est pas trouvée en tant que
clé dans un dict Python ou dans un objet similaire.

La clé `'alpha'` est introuvable dans le dict `second`.
`second` a quelques clés similaires à `'alpha'` dont :
`'alpha0', 'alpha11', 'alpha12'`.

Exception levée à la ligne 145 du fichier TESTS:\runtime\test_key_error.py.

   141:         assert ok, diff
   143:     second = {"alpha0": 1, "alpha11": 2, "alpha12": 3}
   144:     try:
--&gt;145:         a = second["alpha"]
                    ^^^^^^^^^^^^^^^
   146:     except KeyError as e:

        second:  {'alpha0': 1, 'alpha11': 2, 'alpha12': 3}
</pre></div>
</div>
</section>
<section id="string-by-mistake">
<h3>String by mistake<a class="headerlink" href="#string-by-mistake" title="Permalink to this headline">¶</a></h3>
<div class="highlight-none notranslate"><div class="highlight"><pre><span></span>Traceback (most recent call last):
  File "TESTS:\runtime\test_key_error.py", line 98, in test_String_by_mistake
    d["(0, 0)"]
KeyError: '(0, 0)'

    Avez-vous converti `(0, 0)` en une chaîne par erreur ?

Une `KeyError` est levée lorsqu'une valeur n'est pas trouvée en tant que
clé dans un dict Python ou dans un objet similaire.

La clé `'(0, 0)'` est introuvable dans le dict `d`.
`'(0, 0)'` est une chaîne de caractères.
Il y a une clé de `d` dont la représentation en une chaîne
est identique à `'(0, 0)'`.

Exception levée à la ligne 98 du fichier TESTS:\runtime\test_key_error.py.

   94:     chain_map_string_by_mistake()  # do not show in docs
   96:     d = {(0, 0): "origin"}
   97:     try:
--&gt;98:         d["(0, 0)"]
               ^^^^^^^^^^^
   99:     except KeyError as e:

        d:  {(0, 0): 'origin'}
</pre></div>
</div>
</section>
</section>
<section id="lookuperror">
<h2>LookupError<a class="headerlink" href="#lookuperror" title="Permalink to this headline">¶</a></h2>
<section id="id4">
<h3>Generic<a class="headerlink" href="#id4" title="Permalink to this headline">¶</a></h3>
<div class="highlight-none notranslate"><div class="highlight"><pre><span></span>Traceback (most recent call last):
  File "TESTS:\runtime\test_lookup_error.py", line 10, in test_Generic
    raise LookupError("Fake message")
LookupError: Fake message

`LookupError` est la classe de base pour les exceptions qui sont levées
lorsqu’une clé ou un indice utilisé sur un tableau de correspondance ou une séquence est invalide.
Elle peut également être levée directement par codecs.lookup().

Exception levée à la ligne 10 du fichier TESTS:\runtime\test_lookup_error.py.

    4: def test_Generic():
    5:     try:
    6:         # LookupError is the base class for KeyError and IndexError.
    7:         # It should normally not be raised by user code,
    8:         # other than possibly codecs.lookup(), which is why we raise
    9:         # it directly here for our example.
--&gt;10:         raise LookupError("Fake message")
   11:     except LookupError as e:

        LookupError:  &lt;class LookupError&gt;
</pre></div>
</div>
</section>
</section>
<section id="modulenotfounderror">
<h2>ModuleNotFoundError<a class="headerlink" href="#modulenotfounderror" title="Permalink to this headline">¶</a></h2>
<section id="need-to-install-module">
<h3>Need to install module<a class="headerlink" href="#need-to-install-module" title="Permalink to this headline">¶</a></h3>
<div class="highlight-none notranslate"><div class="highlight"><pre><span></span>Traceback (most recent call last):
  File "TESTS:\runtime\test_module_not_found_error.py", line 76, in test_Need_to_install_module
    import alphabet
ModuleNotFoundError: No module named 'alphabet'

Une exception `ModuleNotFoundError` indique que vous
essayez d’importer un module qui ne peut pas être trouvé par Python.
Cela pourrait être parce que vous fait une faute d'orthographe en
écrivant le nom du module, ou parce qu’il n’est pas installé sur votre ordinateur.

Aucun module nommé `alphabet` ne peut être importé.
Vous devez peut-être l'installer.

Exception levée à la ligne 76 du fichier TESTS:\runtime\test_module_not_found_error.py.

   74: def test_Need_to_install_module():
   75:     try:
--&gt;76:         import alphabet
   77:     except ModuleNotFoundError as e:
</pre></div>
</div>
</section>
<section id="not-a-package">
<h3>Not a package<a class="headerlink" href="#not-a-package" title="Permalink to this headline">¶</a></h3>
<div class="highlight-none notranslate"><div class="highlight"><pre><span></span>Traceback (most recent call last):
  File "TESTS:\runtime\test_module_not_found_error.py", line 22, in test_Not_a_package
    import os.xxx
ModuleNotFoundError: No module named 'os.xxx'; 'os' is not a package

Une exception `ModuleNotFoundError` indique que vous
essayez d’importer un module qui ne peut pas être trouvé par Python.
Cela pourrait être parce que vous fait une faute d'orthographe en
écrivant le nom du module, ou parce qu’il n’est pas installé sur votre ordinateur.

`xxx` ne peut pas être importé de `os`.


Exception levée à la ligne 22 du fichier TESTS:\runtime\test_module_not_found_error.py.

   19: def test_Not_a_package():
   21:     try:
--&gt;22:         import os.xxx
   23:     except ModuleNotFoundError as e:
</pre></div>
</div>
</section>
<section id="not-a-package-similar-name">
<h3>Not a package similar name<a class="headerlink" href="#not-a-package-similar-name" title="Permalink to this headline">¶</a></h3>
<div class="highlight-none notranslate"><div class="highlight"><pre><span></span>Traceback (most recent call last):
  File "TESTS:\runtime\test_module_not_found_error.py", line 36, in test_Not_a_package_similar_name
    import os.pathh
ModuleNotFoundError: No module named 'os.pathh'; 'os' is not a package

    Vouliez-vous dire `import os.path` ?

Une exception `ModuleNotFoundError` indique que vous
essayez d’importer un module qui ne peut pas être trouvé par Python.
Cela pourrait être parce que vous fait une faute d'orthographe en
écrivant le nom du module, ou parce qu’il n’est pas installé sur votre ordinateur.

Peut-être que vous vouliez dire `import os.path`.
`path` est un nom semblable à `pathh` et est un module qui
peut être importé de `os`.

Exception levée à la ligne 36 du fichier TESTS:\runtime\test_module_not_found_error.py.

   34: def test_Not_a_package_similar_name():
   35:     try:
--&gt;36:         import os.pathh
   37:     except ModuleNotFoundError as e:
</pre></div>
</div>
</section>
<section id="object-not-module">
<h3>Object not module<a class="headerlink" href="#object-not-module" title="Permalink to this headline">¶</a></h3>
<div class="highlight-none notranslate"><div class="highlight"><pre><span></span>Traceback (most recent call last):
  File "TESTS:\runtime\test_module_not_found_error.py", line 49, in test_Object_not_module
    import os.open
ModuleNotFoundError: No module named 'os.open'; 'os' is not a package

    Vouliez-vous dire `from os import open` ?

Une exception `ModuleNotFoundError` indique que vous
essayez d’importer un module qui ne peut pas être trouvé par Python.
Cela pourrait être parce que vous fait une faute d'orthographe en
écrivant le nom du module, ou parce qu’il n’est pas installé sur votre ordinateur.

`open` n’est pas un module distinct, mais un objet qui fait partie de `os`.

Exception levée à la ligne 49 du fichier TESTS:\runtime\test_module_not_found_error.py.

   47: def test_Object_not_module():
   48:     try:
--&gt;49:         import os.open
   50:     except ModuleNotFoundError as e:

        open:  &lt;builtin function open&gt;
</pre></div>
</div>
</section>
<section id="similar-object-not-module">
<h3>Similar object not module<a class="headerlink" href="#similar-object-not-module" title="Permalink to this headline">¶</a></h3>
<div class="highlight-none notranslate"><div class="highlight"><pre><span></span>Traceback (most recent call last):
  File "TESTS:\runtime\test_module_not_found_error.py", line 62, in test_Similar_object_not_module
    import os.opend
ModuleNotFoundError: No module named 'os.opend'; 'os' is not a package

    Vouliez-vous dire `from os import open` ?

Une exception `ModuleNotFoundError` indique que vous
essayez d’importer un module qui ne peut pas être trouvé par Python.
Cela pourrait être parce que vous fait une faute d'orthographe en
écrivant le nom du module, ou parce qu’il n’est pas installé sur votre ordinateur.

Peut-être vouliez-vous dire `from os import open`.
`open` est un nom similaire à `opend` et est un objet qui
peut être importé de `os`.
D’autres objets avec des noms similaires qui font partie de
`os` comprennent `popen`.

Exception levée à la ligne 62 du fichier TESTS:\runtime\test_module_not_found_error.py.

   60: def test_Similar_object_not_module():
   61:     try:
--&gt;62:         import os.opend
   63:     except ModuleNotFoundError as e:
</pre></div>
</div>
</section>
<section id="standard-library-module">
<h3>Standard library module<a class="headerlink" href="#standard-library-module" title="Permalink to this headline">¶</a></h3>
<div class="highlight-none notranslate"><div class="highlight"><pre><span></span>Traceback (most recent call last):
  File "TESTS:\runtime\test_module_not_found_error.py", line 7, in test_Standard_library_module
    import Tkinter
ModuleNotFoundError: No module named 'Tkinter'

    Vouliez-vous dire `tkinter` ?

Une exception `ModuleNotFoundError` indique que vous
essayez d’importer un module qui ne peut pas être trouvé par Python.
Cela pourrait être parce que vous fait une faute d'orthographe en
écrivant le nom du module, ou parce qu’il n’est pas installé sur votre ordinateur.

Aucun module nommé `Tkinter` ne peut être importé.
Vous devez peut-être l'installer.
`tkinter` est un module existant qui a un nom similaire.

Exception levée à la ligne 7 du fichier TESTS:\runtime\test_module_not_found_error.py.

   5: def test_Standard_library_module():
   6:     try:
--&gt;7:         import Tkinter
   8:     except ModuleNotFoundError as e:
</pre></div>
</div>
</section>
<section id="no-curses">
<h3>no curses<a class="headerlink" href="#no-curses" title="Permalink to this headline">¶</a></h3>
<div class="highlight-none notranslate"><div class="highlight"><pre><span></span>Traceback (most recent call last):
  File "TESTS:\runtime\test_module_not_found_error.py", line 92, in test_no_curses
    import curses
ModuleNotFoundError: No module named '_curses'

    Le module curses est rarement installé avec Python sur Windows.

Une exception `ModuleNotFoundError` indique que vous
essayez d’importer un module qui ne peut pas être trouvé par Python.
Cela pourrait être parce que vous fait une faute d'orthographe en
écrivant le nom du module, ou parce qu’il n’est pas installé sur votre ordinateur.

Vous avez essayé d’importer le module curses.
Le module curses est rarement installé avec Python sur Windows.

Exception levée à la ligne 92 du fichier TESTS:\runtime\test_module_not_found_error.py.

   90:     def test_no_curses():
   91:         try:
--&gt;92:             import curses
   93:         except ModuleNotFoundError as e:
</pre></div>
</div>
</section>
</section>
<section id="nameerror">
<h2>NameError<a class="headerlink" href="#nameerror" title="Permalink to this headline">¶</a></h2>
<section id="annotated-variable">
<h3>Annotated variable<a class="headerlink" href="#annotated-variable" title="Permalink to this headline">¶</a></h3>
<div class="highlight-none notranslate"><div class="highlight"><pre><span></span>Traceback (most recent call last):
  File "TESTS:\runtime\test_name_error.py", line 25, in test_Annotated_variable
    y = x
NameError: name 'x' is not defined

    Avez-vous utilisé deux points au lieu d’un signe égal ?

Une exception `NameError` indique que le nom d'une variable
ou d'une fonction n'est pas connue par Python.
Habituellement, ceci indique une simple faute d'orthographe.
Cependant, cela peut également indiquer que le nom a été
utilisé avant qu'on ne lui ait associé une valeur.

Dans votre programme, aucun objet portant le nom `x` n'existe.
Une annotation de type a été trouvée pour `x` dans la portée 'global'
Peut-être que vous aviez utilisé deux points au lieu d’un signe égal et écrit

    x : 3

au lieu de

    x = 3

Exception levée à la ligne 25 du fichier TESTS:\runtime\test_name_error.py.

   23: def test_Annotated_variable():
   24:     try:
--&gt;25:         y = x
                   ^
   26:     except NameError as e:
</pre></div>
</div>
</section>
<section id="custom-name">
<h3>Custom name<a class="headerlink" href="#custom-name" title="Permalink to this headline">¶</a></h3>
<div class="highlight-none notranslate"><div class="highlight"><pre><span></span>Traceback (most recent call last):
  File "TESTS:\runtime\test_name_error.py", line 193, in test_Custom_name
    python
NameError: name 'python' is not defined

    Vous utilisez déjà Python!
Une exception `NameError` indique que le nom d'une variable
ou d'une fonction n'est pas connue par Python.
Habituellement, ceci indique une simple faute d'orthographe.
Cependant, cela peut également indiquer que le nom a été
utilisé avant qu'on ne lui ait associé une valeur.

Vous utilisez déjà Python!
Exception levée à la ligne 193 du fichier TESTS:\runtime\test_name_error.py.

   191: def test_Custom_name():
   192:     try:
--&gt;193:         python
                ^^^^^^
   194:     except NameError as e:
</pre></div>
</div>
</section>
<section id="free-variable-referenced">
<h3>Free variable referenced<a class="headerlink" href="#free-variable-referenced" title="Permalink to this headline">¶</a></h3>
<div class="highlight-none notranslate"><div class="highlight"><pre><span></span>Traceback (most recent call last):
  File "TESTS:\runtime\test_name_error.py", line 177, in test_Free_variable_referenced
    outer()
  File "TESTS:\runtime\test_name_error.py", line 173, in outer
    inner()
  File "TESTS:\runtime\test_name_error.py", line 172, in inner
    return var
NameError: free variable 'var' referenced before assignment in enclosing scope

Une exception `NameError` indique que le nom d'une variable
ou d'une fonction n'est pas connue par Python.
Habituellement, ceci indique une simple faute d'orthographe.
Cependant, cela peut également indiquer que le nom a été
utilisé avant qu'on ne lui ait associé une valeur.

Dans votre programme, `var` est un nom inconnu
qui existe dans une portée englobante,
mais qui n'a pas encore reçu de valeur.

L'exécution s'est arrêtée à la ligne 177 du fichier TESTS:\runtime\test_name_error.py

   173:         inner()
   174:         var = 4
   176:     try:
--&gt;177:         outer()
                ^^^^^^^
   178:     except NameError as e:

        outer:  &lt;function outer&gt;
            defined in &lt;function test_Free_variable_referenced&gt;

Exception levée à la ligne 172 du fichier TESTS:\runtime\test_name_error.py.

   171:         def inner():
--&gt;172:             return var
                           ^^^
</pre></div>
</div>
</section>
<section id="id5">
<h3>Generic<a class="headerlink" href="#id5" title="Permalink to this headline">¶</a></h3>
<div class="highlight-none notranslate"><div class="highlight"><pre><span></span>Traceback (most recent call last):
  File "TESTS:\runtime\test_name_error.py", line 10, in test_Generic
    this = something
NameError: name 'something' is not defined

Une exception `NameError` indique que le nom d'une variable
ou d'une fonction n'est pas connue par Python.
Habituellement, ceci indique une simple faute d'orthographe.
Cependant, cela peut également indiquer que le nom a été
utilisé avant qu'on ne lui ait associé une valeur.

Dans votre programme, aucun objet portant le nom `something` n'existe.
Je n’ai pas d’informations supplémentaires pour vous.

Exception levée à la ligne 10 du fichier TESTS:\runtime\test_name_error.py.

    8: def test_Generic():
    9:     try:
--&gt;10:         this = something
                      ^^^^^^^^^
   11:     except NameError as e:
</pre></div>
</div>
</section>
<section id="missing-import">
<h3>Missing import<a class="headerlink" href="#missing-import" title="Permalink to this headline">¶</a></h3>
<div class="highlight-none notranslate"><div class="highlight"><pre><span></span>Traceback (most recent call last):
  File "TESTS:\runtime\test_name_error.py", line 130, in test_Missing_import
    unicodedata.something
NameError: name 'unicodedata' is not defined

    Avez-vous oublié d’importer `unicodedata` ?

Une exception `NameError` indique que le nom d'une variable
ou d'une fonction n'est pas connue par Python.
Habituellement, ceci indique une simple faute d'orthographe.
Cependant, cela peut également indiquer que le nom a été
utilisé avant qu'on ne lui ait associé une valeur.


Le nom `unicodedata` n’est pas défini dans votre programme.
Peut-être avez-vous oublié d’importer `unicodedata` qui se trouve
dans la bibliothèque standard de Python.

`unicodedata` est un nom trouvé dans le module `stringprep`.
Vous avez peut-être oublié d'écrire

    from stringprep import unicodedata

Exception levée à la ligne 130 du fichier TESTS:\runtime\test_name_error.py.

   126:     if friendly_traceback.get_lang() == "en":
   127:         assert "I have no additional information for you." in result
   129:     try:
--&gt;130:         unicodedata.something
                ^^^^^^^^^^^
   131:     except NameError as e:
</pre></div>
</div>
</section>
<section id="missing-module-name">
<h3>Missing module name<a class="headerlink" href="#missing-module-name" title="Permalink to this headline">¶</a></h3>
<div class="highlight-none notranslate"><div class="highlight"><pre><span></span>Traceback (most recent call last):
  File "TESTS:\runtime\test_name_error.py", line 277, in test_Missing_module_name
    frame = Frame()
NameError: name 'Frame' is not defined

    Avez-vous oublié d’ajouter `tkinter.` ?

Une exception `NameError` indique que le nom d'une variable
ou d'une fonction n'est pas connue par Python.
Habituellement, ceci indique une simple faute d'orthographe.
Cependant, cela peut également indiquer que le nom a été
utilisé avant qu'on ne lui ait associé une valeur.

Dans votre programme, aucun objet portant le nom `Frame` n'existe.

L’objet local `tkinter`
a un attribut nommé `Frame`.
Peut-être que vous auriez dû écrire `tkinter.Frame`
au lieu de `Frame`.

`Frame` est un nom trouvé dans les modules suivants de la bibliothèque standard :
tkinter, tracemalloc.
Vous avez peut-être oublié d'importer `Frame` de l'un de ces modules.

Exception levée à la ligne 277 du fichier TESTS:\runtime\test_name_error.py.

   274: def test_Missing_module_name():
   275:     import tkinter
   276:     try:
--&gt;277:         frame = Frame()
                        ^^^^^
   278:     except NameError as e:
</pre></div>
</div>
</section>
<section id="missing-self-1">
<h3>Missing self 1<a class="headerlink" href="#missing-self-1" title="Permalink to this headline">¶</a></h3>
<div class="highlight-none notranslate"><div class="highlight"><pre><span></span>Traceback (most recent call last):
  File "TESTS:\runtime\test_name_error.py", line 228, in test_Missing_self_1
    str(a)
  File "TESTS:\runtime\test_name_error.py", line 219, in __str__
    toys_list = add_toy(  # ensure that it can see 'self' on following line
NameError: name 'add_toy' is not defined

    Avez-vous écrit `self` au mauvais endroit ?

Une exception `NameError` indique que le nom d'une variable
ou d'une fonction n'est pas connue par Python.
Habituellement, ceci indique une simple faute d'orthographe.
Cependant, cela peut également indiquer que le nom a été
utilisé avant qu'on ne lui ait associé une valeur.

Dans votre programme, aucun objet portant le nom `add_toy` n'existe.

L’objet local `&lt;Pet object&gt; defined in &lt;function test_name_error.test_Missing_self_1&gt;` a un attribut nommé `add_toy`.
Peut-être que vous auriez dû écrire `self.add_toy(...`
au lieu de `add_toy(self, ...`.

L'exécution s'est arrêtée à la ligne 228 du fichier TESTS:\runtime\test_name_error.py

   224:                 return "{} has no toys".format(self.name)
   226:     a = Pet('Fido')
   227:     try:
--&gt;228:         str(a)
                ^^^^^^
   229:     except NameError as e:

        a:  &lt;Pet object&gt;
            defined in &lt;function test_name_error.test_Missing_self_1&gt;
        str:  &lt;class str&gt;

Exception levée à la ligne 219 du fichier TESTS:\runtime\test_name_error.py.

   217:         def __str__(self):
   218:             # self at the wrong place
--&gt;219:             toys_list = add_toy(  # ensure that it can see 'self' on following line
                                ^^^^^^^
   220:                                 self, 'something')
   221:             if self.toys:
</pre></div>
</div>
</section>
<section id="missing-self-2">
<h3>Missing self 2<a class="headerlink" href="#missing-self-2" title="Permalink to this headline">¶</a></h3>
<div class="highlight-none notranslate"><div class="highlight"><pre><span></span>Traceback (most recent call last):
  File "TESTS:\runtime\test_name_error.py", line 262, in test_Missing_self_2
    str(a)
  File "TESTS:\runtime\test_name_error.py", line 254, in __str__
    toys_list = add_toy('something')
NameError: name 'add_toy' is not defined

    Avez-vous oublié d’ajouter `self.` ?

Une exception `NameError` indique que le nom d'une variable
ou d'une fonction n'est pas connue par Python.
Habituellement, ceci indique une simple faute d'orthographe.
Cependant, cela peut également indiquer que le nom a été
utilisé avant qu'on ne lui ait associé une valeur.

Dans votre programme, aucun objet portant le nom `add_toy` n'existe.

Un objet local, `&lt;Pet object&gt; defined in &lt;function test_name_error.test_Missing_self_2&gt;`,
a un attribut nommé `add_toy`.
Peut-être que vous auriez dû écrire `self.add_toy`
au lieu de `add_toy`.

L'exécution s'est arrêtée à la ligne 262 du fichier TESTS:\runtime\test_name_error.py

   258:                 return "{} has no toys".format(self.name)
   260:     a = Pet('Fido')
   261:     try:
--&gt;262:         str(a)
                ^^^^^^
   263:     except NameError as e:

        a:  &lt;Pet object&gt;
            defined in &lt;function test_name_error.test_Missing_self_2&gt;
        str:  &lt;class str&gt;

Exception levée à la ligne 254 du fichier TESTS:\runtime\test_name_error.py.

   252:         def __str__(self):
   253:             # Missing self.
--&gt;254:             toys_list = add_toy('something')
                                ^^^^^^^
   255:             if self.toys:
</pre></div>
</div>
</section>
<section id="synonym">
<h3>Synonym<a class="headerlink" href="#synonym" title="Permalink to this headline">¶</a></h3>
<div class="highlight-none notranslate"><div class="highlight"><pre><span></span>Traceback (most recent call last):
  File "TESTS:\runtime\test_name_error.py", line 90, in test_Synonym
    cost  # wrote from math import * above
NameError: name 'cost' is not defined

    Vouliez-vous dire `cos` ?

Une exception `NameError` indique que le nom d'une variable
ou d'une fonction n'est pas connue par Python.
Habituellement, ceci indique une simple faute d'orthographe.
Cependant, cela peut également indiquer que le nom a été
utilisé avant qu'on ne lui ait associé une valeur.

Dans votre programme, aucun objet portant le nom `cost` n'existe.
Au lieu d’écrire `cost`, peut-être que vous vouliez écrire l'un des noms suivants :
*    Portée globale : `cos`, `cosh`

Exception levée à la ligne 90 du fichier TESTS:\runtime\test_name_error.py.

   86:     if friendly_traceback.get_lang() == "en":
   87:         assert "The Python builtin `chr` has a similar name." in result
   89:     try:
--&gt;90:         cost  # wrote from math import * above
               ^^^^
   91:     except NameError as e:
</pre></div>
</div>
</section>
<section id="missing-import2">
<h3>missing import2<a class="headerlink" href="#missing-import2" title="Permalink to this headline">¶</a></h3>
<div class="highlight-none notranslate"><div class="highlight"><pre><span></span>Traceback (most recent call last):
  File "TESTS:\runtime\test_name_error.py", line 144, in test_missing_import2
    ABCMeta
NameError: name 'ABCMeta' is not defined

Une exception `NameError` indique que le nom d'une variable
ou d'une fonction n'est pas connue par Python.
Habituellement, ceci indique une simple faute d'orthographe.
Cependant, cela peut également indiquer que le nom a été
utilisé avant qu'on ne lui ait associé une valeur.

Dans votre programme, aucun objet portant le nom `ABCMeta` n'existe.
`ABCMeta` est un nom trouvé dans les modules suivants de la bibliothèque standard :
abc, numbers, selectors, typing.
Vous avez peut-être oublié d'importer `ABCMeta` de l'un de ces modules.

Exception levée à la ligne 144 du fichier TESTS:\runtime\test_name_error.py.

   142: def test_missing_import2():
   143:     try:
--&gt;144:         ABCMeta
                ^^^^^^^
   145:     except NameError as e:
</pre></div>
</div>
</section>
<section id="missing-import3">
<h3>missing import3<a class="headerlink" href="#missing-import3" title="Permalink to this headline">¶</a></h3>
<div class="highlight-none notranslate"><div class="highlight"><pre><span></span>Traceback (most recent call last):
  File "TESTS:\runtime\test_name_error.py", line 158, in test_missing_import3
    AF_APPLETALK
NameError: name 'AF_APPLETALK' is not defined

Une exception `NameError` indique que le nom d'une variable
ou d'une fonction n'est pas connue par Python.
Habituellement, ceci indique une simple faute d'orthographe.
Cependant, cela peut également indiquer que le nom a été
utilisé avant qu'on ne lui ait associé une valeur.

Dans votre programme, aucun objet portant le nom `AF_APPLETALK` n'existe.
`AF_APPLETALK` est un nom trouvé dans le module `socket`.
Vous avez peut-être oublié d'écrire

    from socket import AF_APPLETALK

Exception levée à la ligne 158 du fichier TESTS:\runtime\test_name_error.py.

   156: def test_missing_import3():
   157:     try:
--&gt;158:         AF_APPLETALK
                ^^^^^^^^^^^^
   159:     except NameError as e:
</pre></div>
</div>
</section>
</section>
<section id="oserror">
<h2>OsError<a class="headerlink" href="#oserror" title="Permalink to this headline">¶</a></h2>
<section id="urllib-error">
<h3>Urllib error<a class="headerlink" href="#urllib-error" title="Permalink to this headline">¶</a></h3>
<div class="highlight-none notranslate"><div class="highlight"><pre><span></span>Traceback (most recent call last):
  File "PYTHON_LIB:\urllib\request.py", line 1346, in do_open
       ... Plus de lignes non affichées. ...
  File "PYTHON_LIB:\socket.py", line 823, in create_connection
    for res in getaddrinfo(host, port, 0, SOCK_STREAM):
  File "PYTHON_LIB:\socket.py", line 954, in getaddrinfo
    for res in _socket.getaddrinfo(host, port, family, type, proto, flags):
socket.gaierror: [Errno 11001] getaddrinfo failed

    During handling of the above exception, another exception occurred:

Traceback (most recent call last):
  File "TESTS:\runtime\test_os_error.py", line 8, in test_Urllib_error
    request.urlopen("http://does_not_exist")
URLError: &lt;urlopen error [Errno 11001] getaddrinfo failed&gt;

Une exception de type `URLError` est une sous-classe de `OSError`.
Une exception `OSError` est généralement levée par le système d’exploitation
pour indiquer qu’une opération n’est pas autorisée ou
qu'une ressource n’est pas disponible.

Je soupçonne que vous essayez de vous connecter à un serveur et
qu’une connexion ne peut être faite.

Si c’est le cas, vérifiez les fautes de frappe dans l’URL
et vérifiez votre connectivité Internet.

Exception levée à la ligne 8 du fichier TESTS:\runtime\test_os_error.py.

   5: def test_Urllib_error():
   6:     from urllib import request, error
   7:     try:
--&gt;8:         request.urlopen("http://does_not_exist")
              ^^^^^^^^^^^^^^^^^^^^^^^^^^^^^^^^^^^^^^^^
   9:     except error.URLError as e:

        request:  &lt;module urllib.request&gt; from PYTHON_LIB:\urllib\request.py
        request.urlopen:  &lt;function urlopen&gt;
</pre></div>
</div>
</section>
<section id="invalid-argument">
<h3>invalid argument<a class="headerlink" href="#invalid-argument" title="Permalink to this headline">¶</a></h3>
<div class="highlight-none notranslate"><div class="highlight"><pre><span></span>Traceback (most recent call last):
  File "TESTS:\runtime\test_os_error.py", line 46, in test_invalid_argument
    open("c:\test.txt")
OSError: [Errno 22] Invalid argument: 'c:\test.txt'

    Il faut peut-être doubler les caractères barres obliques inversées.

Une exception `OSError` est généralement levée par le système d’exploitation
pour indiquer qu’une opération n’est pas autorisée ou
qu'une ressource n’est pas disponible.

Je soupçonne que vous avez écrit un nom de fichier ou un chemin qui contient
au moins un caractère Barre oblique inversée, `\`.
Python a probablement interprété ce caractère comme indiquant le début de
ce que l'on appelle une séquence d'échappement.
Pour résoudre ce problème, écrivez une "chaîne brute" (raw string)
en ajoutant la lettre `r` comme préfixe devant le nom de
fichier ou du chemin d'accès, ou remplacer tous les caractères
simples, `\`, par des caractères doubles : `\\`.

Exception levée à la ligne 46 du fichier TESTS:\runtime\test_os_error.py.

   43:     if os.name != "nt":
   44:         return "Windows test only", "No result"
   45:     try:
--&gt;46:         open("c:\test.txt")
               ^^^^^^^^^^^^^^^^^^^
   47:     except OSError as e:

        open:  &lt;builtin function open&gt;
</pre></div>
</div>
</section>
<section id="no-information">
<h3>no information<a class="headerlink" href="#no-information" title="Permalink to this headline">¶</a></h3>
<div class="highlight-none notranslate"><div class="highlight"><pre><span></span>Traceback (most recent call last):
  File "TESTS:\runtime\test_os_error.py", line 27, in test_no_information
    raise OSError("Some unknown message")
OSError: Some unknown message

    Friendly-traceback ne connaît pas la cause de cette erreur.

Une exception `OSError` est généralement levée par le système d’exploitation
pour indiquer qu’une opération n’est pas autorisée ou
qu'une ressource n’est pas disponible.

Aucune information n’est disponible au sujet de cette exception.
Veuillez signaler cet exemple à
https://github.com/friendly-traceback/friendly-traceback/issues/new
Si vous utilisez un REPL, utilisez `www('bug')` pour le faire.

Si vous utilisez la console Friendly, utilisez `www()` pour
faire une recherche sur Internet pour ce cas particulier.

Exception levée à la ligne 27 du fichier TESTS:\runtime\test_os_error.py.

   24:     old_debug = friendly_traceback.debug_helper.DEBUG
   25:     friendly_traceback.debug_helper.DEBUG = False
   26:     try:
--&gt;27:         raise OSError("Some unknown message")
   28:     except OSError as e:

        OSError:  &lt;class OSError&gt;
</pre></div>
</div>
</section>
</section>
<section id="overflowerror">
<h2>OverflowError<a class="headerlink" href="#overflowerror" title="Permalink to this headline">¶</a></h2>
<section id="id6">
<h3>Generic<a class="headerlink" href="#id6" title="Permalink to this headline">¶</a></h3>
<div class="highlight-none notranslate"><div class="highlight"><pre><span></span>Traceback (most recent call last):
  File "TESTS:\runtime\test_overflow_error.py", line 6, in test_Generic
    2.0 ** 1600
OverflowError: (34, 'Result too large')

Une exception de type `OverflowError` est levée lorsque le résultat d’une opération arithmétique
est trop grand pour être manipulé par le processeur de l’ordinateur.

Exception levée à la ligne 6 du fichier TESTS:\runtime\test_overflow_error.py.

   4: def test_Generic():
   5:     try:
--&gt;6:         2.0 ** 1600
              ^^^^^^^^^^^
   7:     except OverflowError as e:
</pre></div>
</div>
</section>
</section>
<section id="recursionerror">
<h2>RecursionError<a class="headerlink" href="#recursionerror" title="Permalink to this headline">¶</a></h2>
<section id="id7">
<h3>Generic<a class="headerlink" href="#id7" title="Permalink to this headline">¶</a></h3>
<div class="highlight-none notranslate"><div class="highlight"><pre><span></span>Traceback (most recent call last):
  File "TESTS:\runtime\test_recursion_error.py", line 8, in test_Generic
    a()
       ... Plus de lignes non affichées. ...
  File "TESTS:\runtime\test_recursion_error.py", line 6, in a
    return a()
  File "TESTS:\runtime\test_recursion_error.py", line 6, in a
    return a()
RecursionError: maximum recursion depth exceeded

Une exception de type `RecursionError` est levée lorsqu’une fonction s'invoque elle-même,
directement ou indirectement, trop de fois.
Cette exception indique presque toujours que vous avez fait une erreur dans votre code
et que votre programme ne terminerait jamais.

L'exécution s'est arrêtée à la ligne 8 du fichier TESTS:\runtime\test_recursion_error.py

   5:     def a():
   6:         return a()
   7:     try:
--&gt;8:         a()
              ^^^
   9:     except RecursionError as e:

        a:  &lt;function a&gt; defined in &lt;function test_Generic&gt;

Exception levée à la ligne 6 du fichier TESTS:\runtime\test_recursion_error.py.

   5:     def a():
--&gt;6:         return a()
                     ^^^

        a:  &lt;function a&gt; defined in &lt;function test_Generic&gt;
</pre></div>
</div>
</section>
</section>
<section id="typeerror">
<h2>TypeError<a class="headerlink" href="#typeerror" title="Permalink to this headline">¶</a></h2>
<section id="bad-type-for-unary-operator">
<h3>Bad type for unary operator<a class="headerlink" href="#bad-type-for-unary-operator" title="Permalink to this headline">¶</a></h3>
<div class="highlight-none notranslate"><div class="highlight"><pre><span></span>Traceback (most recent call last):
  File "TESTS:\runtime\test_type_error.py", line 376, in test_Bad_type_for_unary_operator
    a =+ "def"
TypeError: bad operand type for unary +: 'str'

    Peut-être que vous vouliez plutôt écrire `+=` au lieu de `=+`
Une exception `TypeError` est généralement causée par une tentative
de combiner deux types d’objets incompatibles,
en invoquant une fonction avec le mauvais type d’objet,
ou en tentant d'effectuer une opération non permise sur un type d'objet donné.

Vous avez essayé d’utiliser l’opérateur unaire '+'
avec le type d’objet suivant: une chaîne de caractères (`str`).
Cette opération n’est pas définie pour ce type d’objet.

Peut-être que vous vouliez plutôt écrire `+=` au lieu de `=+`

Exception levée à la ligne 376 du fichier TESTS:\runtime\test_type_error.py.

   371:         assert "You tried to use the unary operator '~'" in result
   373:     try:
   374:         # fmt: off
   375:         a = "abc"
--&gt;376:         a =+ "def"
                   ^^^^^^^
   377:         # fmt: on
</pre></div>
</div>
</section>
<section id="builtin-has-no-len">
<h3>Builtin has no len<a class="headerlink" href="#builtin-has-no-len" title="Permalink to this headline">¶</a></h3>
<div class="highlight-none notranslate"><div class="highlight"><pre><span></span>Traceback (most recent call last):
  File "TESTS:\runtime\test_type_error.py", line 808, in test_Builtin_has_no_len
    len("Hello world".split)
TypeError: object of type 'builtin_function_or_method' has no len()

    Avez-vous oublié d’invoquer `"Hello world".split` ?

Une exception `TypeError` est généralement causée par une tentative
de combiner deux types d’objets incompatibles,
en invoquant une fonction avec le mauvais type d’objet,
ou en tentant d'effectuer une opération non permise sur un type d'objet donné.

Je soupçonne que vous avez oublié d’ajouter des parenthèses pour invoquer `"Hello world".split`.
Vous avez peut-être voulu écrire :
`len("Hello world".split())`

Exception levée à la ligne 808 du fichier TESTS:\runtime\test_type_error.py.

   806: def test_Builtin_has_no_len():
   807:     try:
--&gt;808:         len("Hello world".split)
                ^^^^^^^^^^^^^^^^^^^^^^^^
   809:     except TypeError as e:

        len:  &lt;builtin function len&gt;
        "Hello world".split:  &lt;builtin method split of str object&gt;
</pre></div>
</div>
</section>
<section id="can-only-concatenate">
<h3>Can only concatenate<a class="headerlink" href="#can-only-concatenate" title="Permalink to this headline">¶</a></h3>
<div class="highlight-none notranslate"><div class="highlight"><pre><span></span>Traceback (most recent call last):
  File "TESTS:\runtime\test_type_error.py", line 39, in test_Can_only_concatenate
    result = a_tuple + a_list
TypeError: can only concatenate tuple (not "list") to tuple

Une exception `TypeError` est généralement causée par une tentative
de combiner deux types d’objets incompatibles,
en invoquant une fonction avec le mauvais type d’objet,
ou en tentant d'effectuer une opération non permise sur un type d'objet donné.

Vous avez essayé de concaténer (additionner) deux types d’objets différents:
un `tuple` et une liste (`list`).

Exception levée à la ligne 39 du fichier TESTS:\runtime\test_type_error.py.

   36:     try:
   37:         a_tuple = (1, 2, 3)
   38:         a_list = [1, 2, 3]
--&gt;39:         result = a_tuple + a_list
                        ^^^^^^^^^^^^^^^^
   40:     except TypeError as e:

        a_list:  [1, 2, 3]
        a_tuple:  (1, 2, 3)
</pre></div>
</div>
</section>
<section id="cannot-convert-dictionary-update-sequence">
<h3>Cannot convert dictionary update sequence<a class="headerlink" href="#cannot-convert-dictionary-update-sequence" title="Permalink to this headline">¶</a></h3>
<div class="highlight-none notranslate"><div class="highlight"><pre><span></span>Traceback (most recent call last):
  File "TESTS:\runtime\test_type_error.py", line 794, in test_Cannot_convert_dictionary_update_sequence
    dd.update([1, 2, 3])
TypeError: cannot convert dictionary update sequence element #0 to a sequence

    Peut-être que vous vouliez plutôt utiliser la méthode `dict.fromkeys()`.

Une exception `TypeError` est généralement causée par une tentative
de combiner deux types d’objets incompatibles,
en invoquant une fonction avec le mauvais type d’objet,
ou en tentant d'effectuer une opération non permise sur un type d'objet donné.

`dict.update()` n’accepte pas une séquence comme argument.
Au lieu d’écrire `dd.update([1, 2, 3])`
peut-être devriez-vous utiliser la méthode `dict.fromkeys()` : `dd.update( dict.fromkeys([1, 2, 3]) )`.

Exception levée à la ligne 794 du fichier TESTS:\runtime\test_type_error.py.

   790:         assert "you should use the `dict.fromkeys()`" in result
   792:     dd = {"a": "a"}
   793:     try:
--&gt;794:         dd.update([1, 2, 3])
                ^^^^^^^^^^^^^^^^^^^^
   795:     except TypeError as e:

        dd:  {'a': 'a'}
        dd.update:  &lt;builtin method update of dict object&gt;
</pre></div>
</div>
</section>
<section id="cannot-multiply-by-non-int">
<h3>Cannot multiply by non int<a class="headerlink" href="#cannot-multiply-by-non-int" title="Permalink to this headline">¶</a></h3>
<div class="highlight-none notranslate"><div class="highlight"><pre><span></span>Traceback (most recent call last):
  File "TESTS:\runtime\test_type_error.py", line 592, in test_Cannot_multiply_by_non_int
    "a" * "2"
TypeError: can't multiply sequence by non-int of type 'str'

    Avez-vous oublié de convertir `"2"` en un entier ?

Une exception `TypeError` est généralement causée par une tentative
de combiner deux types d’objets incompatibles,
en invoquant une fonction avec le mauvais type d’objet,
ou en tentant d'effectuer une opération non permise sur un type d'objet donné.

Vous ne pouvez multiplier les séquences, telles que
les listes, les tuples, les chaînes, etc., que par des entiers.
Peut-être avez-vous oublié de convertir `"2"` en un entier.

Exception levée à la ligne 592 du fichier TESTS:\runtime\test_type_error.py.

   588:     if friendly_traceback.get_lang() == "en":
   589:         assert "Did you forget to convert `c` into an integer?" in result
   591:     try:
--&gt;592:         "a" * "2"
                ^^^^^^^^^
   593:     except TypeError as e:
</pre></div>
</div>
</section>
<section id="cannot-unpack-non-iterable-object">
<h3>Cannot unpack non iterable object<a class="headerlink" href="#cannot-unpack-non-iterable-object" title="Permalink to this headline">¶</a></h3>
<div class="highlight-none notranslate"><div class="highlight"><pre><span></span>Traceback (most recent call last):
  File "TESTS:\runtime\test_type_error.py", line 766, in test_Cannot_unpack_non_iterable_object
    a, b = 42.0
TypeError: cannot unpack non-iterable float object

Une exception `TypeError` est généralement causée par une tentative
de combiner deux types d’objets incompatibles,
en invoquant une fonction avec le mauvais type d’objet,
ou en tentant d'effectuer une opération non permise sur un type d'objet donné.

Le dépaquetage ('unpack') est un moyen pratique d’attribuer un nom
à chaque élément d’un itérable.
Un itérable est un objet capable de renvoyer ses membres un à la fois.
Les contenants python (`list, tuple, dict`, etc.) sont itérables,
mais pas les objets de type `float`.

Exception levée à la ligne 766 du fichier TESTS:\runtime\test_type_error.py.

   764: def test_Cannot_unpack_non_iterable_object():
   765:     try:
--&gt;766:         a, b = 42.0
   767:     except TypeError as e:
</pre></div>
</div>
</section>
<section id="comparison-not-supported">
<h3>Comparison not supported<a class="headerlink" href="#comparison-not-supported" title="Permalink to this headline">¶</a></h3>
<div class="highlight-none notranslate"><div class="highlight"><pre><span></span>Traceback (most recent call last):
  File "TESTS:\runtime\test_type_error.py", line 325, in test_Comparison_not_supported
    b &gt;= a
TypeError: '&gt;=' not supported between instances of 'int' and 'str'

    Avez-vous oublié de convertir `a` en un entier (`int`) ?

Une exception `TypeError` est généralement causée par une tentative
de combiner deux types d’objets incompatibles,
en invoquant une fonction avec le mauvais type d’objet,
ou en tentant d'effectuer une opération non permise sur un type d'objet donné.

En utilisant &gt;=, vous avez tenté de comparer
deux types d’objets incompatibles:
un entier (`int`) et une chaîne de caractères (`str`).
Peut-être avez-vous oublié de convertir `a` en un entier (`int`).

Exception levée à la ligne 325 du fichier TESTS:\runtime\test_type_error.py.

   322:     try:
   323:         a = "2"
   324:         b = 42
--&gt;325:         b &gt;= a
                ^^^^^^
   326:     except TypeError as e:

        a:  '2'
        b:  42
</pre></div>
</div>
</section>
<section id="derive-from-baseexception">
<h3>Derive from BaseException<a class="headerlink" href="#derive-from-baseexception" title="Permalink to this headline">¶</a></h3>
<div class="highlight-none notranslate"><div class="highlight"><pre><span></span>Traceback (most recent call last):
  File "TESTS:\runtime\test_type_error.py", line 535, in test_Derive_from_BaseException
    raise "exception"  # noqa
TypeError: exceptions must derive from BaseException

Une exception `TypeError` est généralement causée par une tentative
de combiner deux types d’objets incompatibles,
en invoquant une fonction avec le mauvais type d’objet,
ou en tentant d'effectuer une opération non permise sur un type d'objet donné.

Dans Python 3, les exceptions doivent être dérivées de BaseException.

Exception levée à la ligne 535 du fichier TESTS:\runtime\test_type_error.py.

   533: def test_Derive_from_BaseException():
   534:     try:
--&gt;535:         raise "exception"  # noqa
   536:     except TypeError as e:
</pre></div>
</div>
</section>
<section id="indices-must-be-integers-or-slices">
<h3>Indices must be integers or slices<a class="headerlink" href="#indices-must-be-integers-or-slices" title="Permalink to this headline">¶</a></h3>
<div class="highlight-none notranslate"><div class="highlight"><pre><span></span>Traceback (most recent call last):
  File "TESTS:\runtime\test_type_error.py", line 674, in test_Indices_must_be_integers_or_slices
    [1, 2, 3]["2"]
TypeError: list indices must be integers or slices, not str

    Avez-vous oublié de convertir `"2"` en un entier ?

Une exception `TypeError` est généralement causée par une tentative
de combiner deux types d’objets incompatibles,
en invoquant une fonction avec le mauvais type d’objet,
ou en tentant d'effectuer une opération non permise sur un type d'objet donné.

Dans l’expression `[1, 2, 3]["2"]`
ce qui est inclus entre les crochets, `[...]`,
doit être soit un entier ou une tranche
(`start:stop` ou `start:stop:step`)
et vous l’avez utilisé une chaîne de caractères (`str`) la place.

Peut-être avez-vous oublié de convertir `"2"` en un entier.

Exception levée à la ligne 674 du fichier TESTS:\runtime\test_type_error.py.

   670:     if friendly_traceback.get_lang() == "en":
   671:         assert "Perhaps you forgot to convert `2.0` into an integer." in result
   673:     try:
--&gt;674:         [1, 2, 3]["2"]
                ^^^^^^^^^^^^^^
   675:     except TypeError as e:
</pre></div>
</div>
</section>
<section id="not-an-integer">
<h3>Not an integer<a class="headerlink" href="#not-an-integer" title="Permalink to this headline">¶</a></h3>
<div class="highlight-none notranslate"><div class="highlight"><pre><span></span>Traceback (most recent call last):
  File "TESTS:\runtime\test_type_error.py", line 637, in test_Not_an_integer
    range(c, d)
TypeError: 'str' object cannot be interpreted as an integer

    Avez-vous oublié de convertir `c, d` en entiers ?

Une exception `TypeError` est généralement causée par une tentative
de combiner deux types d’objets incompatibles,
en invoquant une fonction avec le mauvais type d’objet,
ou en tentant d'effectuer une opération non permise sur un type d'objet donné.

Vous avez écrit un objet de type `str` là où un entier était attendu.
Peut-être avez-vous oublié de convertir `c, d` en entiers.
Exception levée à la ligne 637 du fichier TESTS:\runtime\test_type_error.py.

   633:         assert "Perhaps you forgot to convert `1.0" in result
   635:     c, d = "2", "3"
   636:     try:
--&gt;637:         range(c, d)
                ^^^^^^^^^^^
   638:     except TypeError as e:

        c:  '2'
        d:  '3'
        range:  &lt;class range&gt;
</pre></div>
</div>
</section>
<section id="not-callable">
<h3>Not callable<a class="headerlink" href="#not-callable" title="Permalink to this headline">¶</a></h3>
<div class="highlight-none notranslate"><div class="highlight"><pre><span></span>Traceback (most recent call last):
  File "TESTS:\runtime\test_type_error.py", line 519, in test_Not_callable
    _ = [1, 2](a + b)
TypeError: 'list' object is not callable

    Vouliez-vous dire `[1, 2][a + b]` ?

Une exception `TypeError` est généralement causée par une tentative
de combiner deux types d’objets incompatibles,
en invoquant une fonction avec le mauvais type d’objet,
ou en tentant d'effectuer une opération non permise sur un type d'objet donné.

En raison des parenthees, `(a + b)` est interprété par Python
comme indiquant une invocation de fonction pour
`[1, 2]`, qui est un objet de type `list`
ne pouvant pas être invoqué.

Cependant, `[1, 2]` est une séquence.
Peut-être que vous vouliez utiliser `[]` au lieu de `()` et écrire
`[1, 2][a + b]`

Exception levée à la ligne 519 du fichier TESTS:\runtime\test_type_error.py.

   515:         assert "b.a_list[3]" in result
   517:     try:
   518:         a, b = 3, 7
--&gt;519:         _ = [1, 2](a + b)
                    ^^^^^^^^^^^^^
   520:     except TypeError as e:

        a:  3
        b:  7
        a + b:  10
</pre></div>
</div>
</section>
<section id="object-is-not-iterable">
<h3>Object is not iterable<a class="headerlink" href="#object-is-not-iterable" title="Permalink to this headline">¶</a></h3>
<div class="highlight-none notranslate"><div class="highlight"><pre><span></span>Traceback (most recent call last):
  File "TESTS:\runtime\test_type_error.py", line 752, in test_Object_is_not_iterable
    list(42)
TypeError: 'int' object is not iterable

Une exception `TypeError` est généralement causée par une tentative
de combiner deux types d’objets incompatibles,
en invoquant une fonction avec le mauvais type d’objet,
ou en tentant d'effectuer une opération non permise sur un type d'objet donné.

Un itérable est un objet capable de renvoyer ses membres un à la fois.
Les contenants python (`list, tuple, dict`, etc.) sont itérables.
Une itérable est requis ici.

Exception levée à la ligne 752 du fichier TESTS:\runtime\test_type_error.py.

   750: def test_Object_is_not_iterable():
   751:     try:
--&gt;752:         list(42)
                ^^^^^^^^
   753:     except TypeError as e:

        list:  &lt;class list&gt;
</pre></div>
</div>
</section>
<section id="object-is-not-subscriptable">
<h3>Object is not subscriptable<a class="headerlink" href="#object-is-not-subscriptable" title="Permalink to this headline">¶</a></h3>
<div class="highlight-none notranslate"><div class="highlight"><pre><span></span>Traceback (most recent call last):
  File "TESTS:\runtime\test_type_error.py", line 735, in test_Object_is_not_subscriptable
    a = f[1]
TypeError: 'function' object is not subscriptable

    Vouliez-vous dire `f(1)` ?

Une exception `TypeError` est généralement causée par une tentative
de combiner deux types d’objets incompatibles,
en invoquant une fonction avec le mauvais type d’objet,
ou en tentant d'effectuer une opération non permise sur un type d'objet donné.

Les objets subscriptibles sont généralement des conteneurs à partir
desquels on peut tirer des éléments en utilisant la notation `[...]`.

Peut-être que vous vouliez plutôt écrire `f(1)`.

Exception levée à la ligne 735 du fichier TESTS:\runtime\test_type_error.py.

   731:     def f():
   732:         pass
   734:     try:
--&gt;735:         a = f[1]
                    ^^^^
   736:     except TypeError as e:

        f:  &lt;function f&gt;
            defined in &lt;function test_Object_is_not_subscriptable&gt;
</pre></div>
</div>
</section>
<section id="slice-indices-must-be-integers-or-none">
<h3>Slice indices must be integers or None<a class="headerlink" href="#slice-indices-must-be-integers-or-none" title="Permalink to this headline">¶</a></h3>
<div class="highlight-none notranslate"><div class="highlight"><pre><span></span>Traceback (most recent call last):
  File "TESTS:\runtime\test_type_error.py", line 688, in test_Slice_indices_must_be_integers_or_None
    [1, 2, 3][1.0:2.0]
TypeError: slice indices must be integers or None or have an __index__ method

Une exception `TypeError` est généralement causée par une tentative
de combiner deux types d’objets incompatibles,
en invoquant une fonction avec le mauvais type d’objet,
ou en tentant d'effectuer une opération non permise sur un type d'objet donné.

Lors de l’utilisation d’une tranche pour extraire une gamme d’éléments
d’une séquence, c’est-à-dire quelque chose comme
`[start:stop]` ou `[start:stop:step]`
chacune des variables `start`, `stop`, et `step` doit être soit un entier, soit `None`,
ou possiblement un autre objet ayant une méthode `__index__`.

Exception levée à la ligne 688 du fichier TESTS:\runtime\test_type_error.py.

   686: def test_Slice_indices_must_be_integers_or_None():
   687:     try:
--&gt;688:         [1, 2, 3][1.0:2.0]
                ^^^^^^^^^^^^^^^^^^
   689:     except TypeError as e:
</pre></div>
</div>
</section>
<section id="too-few-positional-argument">
<h3>Too few positional argument<a class="headerlink" href="#too-few-positional-argument" title="Permalink to this headline">¶</a></h3>
<div class="highlight-none notranslate"><div class="highlight"><pre><span></span>Traceback (most recent call last):
  File "TESTS:\runtime\test_type_error.py", line 449, in test_Too_few_positional_argument
    fn(1)
TypeError: fn() missing 2 required positional arguments: 'b' and 'c'

Une exception `TypeError` est généralement causée par une tentative
de combiner deux types d’objets incompatibles,
en invoquant une fonction avec le mauvais type d’objet,
ou en tentant d'effectuer une opération non permise sur un type d'objet donné.

Vous avez apparemment invoqué la fonction 'fn()' avec
moins d'arguments positionnels qu'il n'en faut (2 manquent).

Exception levée à la ligne 449 du fichier TESTS:\runtime\test_type_error.py.

   445:     def fn(a, b, c):
   446:         pass
   448:     try:
--&gt;449:         fn(1)
                ^^^^^
   450:     except TypeError as e:

        fn:  &lt;function fn&gt;
            defined in &lt;function test_Too_few_positional_argument&gt;
</pre></div>
</div>
</section>
<section id="too-many-positional-argument">
<h3>Too many positional argument<a class="headerlink" href="#too-many-positional-argument" title="Permalink to this headline">¶</a></h3>
<div class="highlight-none notranslate"><div class="highlight"><pre><span></span>Traceback (most recent call last):
  File "TESTS:\runtime\test_type_error.py", line 430, in test_Too_many_positional_argument
    A().f(1)
TypeError: f() takes 1 positional argument but 2 were given

    Peut-être avez-vous oublié `self` lors de la définition de `f`.

Une exception `TypeError` est généralement causée par une tentative
de combiner deux types d’objets incompatibles,
en invoquant une fonction avec le mauvais type d’objet,
ou en tentant d'effectuer une opération non permise sur un type d'objet donné.

Vous avez apparemment invoqué la fonction `f` avec
2 arguments positionnels alors qu'elle en requiert 1.
Peut-être avez-vous oublié `self` lors de la définition de `f`.

Exception levée à la ligne 430 du fichier TESTS:\runtime\test_type_error.py.

   426:         def f(x):
   427:             pass
   429:     try:
--&gt;430:         A().f(1)
                ^^^^^^^^
   431:     except TypeError as e:

        A:  &lt;class A&gt;
            defined in &lt;function test_type_error.test_Too_many_positional_argument&gt;
</pre></div>
</div>
</section>
<section id="tuple-no-item-assignment">
<h3>Tuple no item assignment<a class="headerlink" href="#tuple-no-item-assignment" title="Permalink to this headline">¶</a></h3>
<div class="highlight-none notranslate"><div class="highlight"><pre><span></span>Traceback (most recent call last):
  File "TESTS:\runtime\test_type_error.py", line 397, in test_Tuple_no_item_assignment
    a[0] = 0
TypeError: 'tuple' object does not support item assignment

    Voulez-vous utiliser une liste?

Une exception `TypeError` est généralement causée par une tentative
de combiner deux types d’objets incompatibles,
en invoquant une fonction avec le mauvais type d’objet,
ou en tentant d'effectuer une opération non permise sur un type d'objet donné.

Dans Python, certains objets sont connus comme immuables:
une fois définis, leur valeur ne peut pas être modifiée.
Vous avez essayé de modifier une partie d’un tel objet immuable: un `tuple`,
probablement en utilisant une opération d’indexation.
Peut-être que vous vouliez plutôt utiliser une liste.

Exception levée à la ligne 397 du fichier TESTS:\runtime\test_type_error.py.

   394: def test_Tuple_no_item_assignment():
   395:     a = (1, 2, 3)
   396:     try:
--&gt;397:         a[0] = 0
   398:     except TypeError as e:

        a:  (1, 2, 3)
        a[0]:  1
</pre></div>
</div>
</section>
<section id="unhachable-type">
<h3>Unhachable type<a class="headerlink" href="#unhachable-type" title="Permalink to this headline">¶</a></h3>
<div class="highlight-none notranslate"><div class="highlight"><pre><span></span>Traceback (most recent call last):
  File "TESTS:\runtime\test_type_error.py", line 705, in test_Unhachable_type
    {[1, 2]: 1}
TypeError: unhashable type: 'list'

Une exception `TypeError` est généralement causée par une tentative
de combiner deux types d’objets incompatibles,
en invoquant une fonction avec le mauvais type d’objet,
ou en tentant d'effectuer une opération non permise sur un type d'objet donné.

Seuls les objets hachables peuvent être utilisés
comme éléments de `set` ou des clés de `dict`.
Les objets hachables sont des objets qui ne changent pas de valeur
une fois qu’ils ont été créés.Au lieu d’utiliser une liste (`list`), envisagez d’utiliser un `tuple`.

Exception levée à la ligne 705 du fichier TESTS:\runtime\test_type_error.py.

   703: def test_Unhachable_type():
   704:     try:
--&gt;705:         {[1, 2]: 1}
   706:     except TypeError as e:
</pre></div>
</div>
</section>
<section id="unsupported-operand-types">
<h3>Unsupported operand types<a class="headerlink" href="#unsupported-operand-types" title="Permalink to this headline">¶</a></h3>
<div class="highlight-none notranslate"><div class="highlight"><pre><span></span>Traceback (most recent call last):
  File "TESTS:\runtime\test_type_error.py", line 288, in test_Unsupported_operand_types
    a @= b
TypeError: unsupported operand type(s) for @=: 'str' and 'int'

Une exception `TypeError` est généralement causée par une tentative
de combiner deux types d’objets incompatibles,
en invoquant une fonction avec le mauvais type d’objet,
ou en tentant d'effectuer une opération non permise sur un type d'objet donné.

Vous avez essayé d’utiliser l’opérateur @=
à l’aide de deux types d’objets incompatibles:
une chaîne de caractères (`str`) et un entier (`int`).
Cet opérateur est normalement utilisé uniquement
pour la multiplication des matrices.

Exception levée à la ligne 288 du fichier TESTS:\runtime\test_type_error.py.

   285:     try:
   286:         a = "a"
   287:         b = 2
--&gt;288:         a @= b
   289:     except TypeError as e:

        a:  'a'
        b:  2
</pre></div>
</div>
</section>
<section id="function-got-multiple-argument">
<h3>function got multiple argument<a class="headerlink" href="#function-got-multiple-argument" title="Permalink to this headline">¶</a></h3>
<div class="highlight-none notranslate"><div class="highlight"><pre><span></span>Traceback (most recent call last):
  File "TESTS:\runtime\test_type_error.py", line 900, in test_function_got_multiple_argument
    fn2(0, a=1)
TypeError: fn2() got multiple values for argument 'a'

Une exception `TypeError` est généralement causée par une tentative
de combiner deux types d’objets incompatibles,
en invoquant une fonction avec le mauvais type d’objet,
ou en tentant d'effectuer une opération non permise sur un type d'objet donné.

Vous avez spécifié la valeur de l'argument `a` plus d'une fois
lors de l'appel de la fonction nommée `fn2`.
Cette fonction a les arguments suivants :
`a, b=1`

Exception levée à la ligne 900 du fichier TESTS:\runtime\test_type_error.py.

   896:     def fn2(a, b=1):
   897:         pass
   899:     try:
--&gt;900:         fn2(0, a=1)
                ^^^^^^^^^^^
   901:     except TypeError as e:

        fn2:  &lt;function fn2&gt;
            defined in &lt;function test_function_got_multiple_argument&gt;
</pre></div>
</div>
</section>
<section id="function-has-no-len">
<h3>function has no len<a class="headerlink" href="#function-has-no-len" title="Permalink to this headline">¶</a></h3>
<div class="highlight-none notranslate"><div class="highlight"><pre><span></span>Traceback (most recent call last):
  File "TESTS:\runtime\test_type_error.py", line 825, in test_function_has_no_len
    len(bad)
TypeError: object of type 'function' has no len()

    Avez-vous oublié d’invoquer `bad` ?

Une exception `TypeError` est généralement causée par une tentative
de combiner deux types d’objets incompatibles,
en invoquant une fonction avec le mauvais type d’objet,
ou en tentant d'effectuer une opération non permise sur un type d'objet donné.

Je soupçonne que vous avez oublié d’ajouter des parenthèses pour invoquer `bad`.
Vous avez peut-être voulu écrire :
`len(bad())`

Exception levée à la ligne 825 du fichier TESTS:\runtime\test_type_error.py.

   821:     def bad():
   822:         pass
   824:     try:
--&gt;825:         len(bad)
                ^^^^^^^^
   826:     except TypeError as e:

        bad:  &lt;function bad&gt; defined in &lt;function test_function_has_no_len&gt;
        len:  &lt;builtin function len&gt;
</pre></div>
</div>
</section>
<section id="getattr-attribute-name-must-be-string">
<h3>getattr attribute name must be string<a class="headerlink" href="#getattr-attribute-name-must-be-string" title="Permalink to this headline">¶</a></h3>
<div class="highlight-none notranslate"><div class="highlight"><pre><span></span>Traceback (most recent call last):
  File "TESTS:\runtime\test_type_error.py", line 946, in test_getattr_attribute_name_must_be_string
    getattr("__repr__", 1)  # as reported in issue #77
TypeError: getattr(): attribute name must be string

Une exception `TypeError` est généralement causée par une tentative
de combiner deux types d’objets incompatibles,
en invoquant une fonction avec le mauvais type d’objet,
ou en tentant d'effectuer une opération non permise sur un type d'objet donné.

Le deuxième argument de la fonction `getattr()` doit être une chaîne de caractères.

Exception levée à la ligne 946 du fichier TESTS:\runtime\test_type_error.py.

   939:     if friendly_traceback.get_lang() == "en":
   940:         assert (
   941:             "The second argument of the function `hasattr()` must be a string."
   942:             in result
   943:         )
   945:     try:
--&gt;946:         getattr("__repr__", 1)  # as reported in issue #77
                ^^^^^^^^^^^^^^^^^^^^^^
   947:     except TypeError as e:

        getattr:  &lt;builtin function getattr&gt;
</pre></div>
</div>
</section>
<section id="method-got-multiple-argument">
<h3>method got multiple argument<a class="headerlink" href="#method-got-multiple-argument" title="Permalink to this headline">¶</a></h3>
<div class="highlight-none notranslate"><div class="highlight"><pre><span></span>Traceback (most recent call last):
  File "TESTS:\runtime\test_type_error.py", line 919, in test_method_got_multiple_argument
    t.some_method(0, a=1)
TypeError: some_method() got multiple values for argument 'a'

Une exception `TypeError` est généralement causée par une tentative
de combiner deux types d’objets incompatibles,
en invoquant une fonction avec le mauvais type d’objet,
ou en tentant d'effectuer une opération non permise sur un type d'objet donné.

Vous avez spécifié la valeur de l'argument `a` plus d'une fois
lors de l'appel de la fonction nommée `t.some_method`.
Cette fonction n'a qu'un seul argument : `a`

Exception levée à la ligne 919 du fichier TESTS:\runtime\test_type_error.py.

   915:             pass
   917:     t = T()
   918:     try:
--&gt;919:         t.some_method(0, a=1)
                ^^^^^^^^^^^^^^^^^^^^^
   920:     except TypeError as e:

        t:  &lt;T object&gt;
            defined in &lt;function test_type_error.test_method_got_multiple_argument&gt;
        t.some_method:  &lt;bound method T.some_method&gt;
            of &lt;T object&gt;
            defined in &lt;function test_type_error.test_method_got_multiple_argument&gt;
</pre></div>
</div>
</section>
<section id="vars-arg-must-have-dict">
<h3>vars arg must have dict<a class="headerlink" href="#vars-arg-must-have-dict" title="Permalink to this headline">¶</a></h3>
<div class="highlight-none notranslate"><div class="highlight"><pre><span></span>Traceback (most recent call last):
  File "TESTS:\runtime\test_type_error.py", line 869, in test_vars_arg_must_have_dict
    vars(f)
TypeError: vars() argument must have __dict__ attribute

Une exception `TypeError` est généralement causée par une tentative
de combiner deux types d’objets incompatibles,
en invoquant une fonction avec le mauvais type d’objet,
ou en tentant d'effectuer une opération non permise sur un type d'objet donné.

La fonction `vars` est utilisée pour lister le contenu
de l'attribut `__dict__` d'un objet.
L'objet `f` utilise `__slots__` au lieu de `__dict__`.

Exception levée à la ligne 869 du fichier TESTS:\runtime\test_type_error.py.

   865:         assert no_slots not in result
   866:         assert use_slots not in result
   868:     try:
--&gt;869:         vars(f)
                ^^^^^^^
   870:     except TypeError as e:

        f:  &lt;F object&gt;
            defined in &lt;function test_type_error.test_vars_arg_must_have_dict&gt;
        vars:  &lt;builtin function vars&gt;
</pre></div>
</div>
</section>
</section>
<section id="unboundlocalerror">
<h2>UnboundLocalError<a class="headerlink" href="#unboundlocalerror" title="Permalink to this headline">¶</a></h2>
<section id="missing-both">
<h3>Missing both<a class="headerlink" href="#missing-both" title="Permalink to this headline">¶</a></h3>
<div class="highlight-none notranslate"><div class="highlight"><pre><span></span>Traceback (most recent call last):
  File "TESTS:\runtime\test_unbound_local_error.py", line 63, in test_Missing_both
    outer_missing_both()
  File "TESTS:\runtime\test_unbound_local_error.py", line 22, in outer_missing_both
    inner()
  File "TESTS:\runtime\test_unbound_local_error.py", line 21, in inner
    spam_missing_both += 1
UnboundLocalError: local variable 'spam_missing_both' referenced before assignment

    Avez-vous oublié d’ajouter soit `global spam_missing_both` ou
    `nonlocal spam_missing_both` ?

En Python, les variables utilisées à l’intérieur d’une fonction sont appelées
variables «locales».
Avant d’utiliser une variable locale, une valeur doit lui être attribuée.
Une variable utilisée avant l’attribution d’une valeur est supposée
être définie en dehors de cette fonction;
elle est connu comme une variable «globale» (`global` ou parfois `nonlocal`).
Vous ne pouvez pas assigner une valeur à une telle variable globale
à l’intérieur d’une fonction sans d’abord confirmer à python
qu’il s’agit d’une variable globale, sinon vous verrez une exception `UnboundLocalError`.

Vous essayez d'utiliser le nom `spam_missing_both` identifié par Python comme se trouvant
dans la portée locale d'une fonction avant de lui avoir attribué une valeur.

Le nom `spam_missing_both` existe à la fois dans la portée globale et non locale.
Cela peut être assez déroutant et n’est pas recommandé.
Selon la variable à laquelle vous vouliez vous référer, vous deviez ajouter

    global spam_missing_both

ou

    nonlocal spam_missing_both

comme la première ligne à l’intérieur de votre fonction.

L'exécution s'est arrêtée à la ligne 63 du fichier TESTS:\runtime\test_unbound_local_error.py

   61: def test_Missing_both():
   62:     try:
--&gt;63:         outer_missing_both()
               ^^^^^^^^^^^^^^^^^^^^
   64:     except UnboundLocalError as e:

        global outer_missing_both:  &lt;function outer_missing_both&gt;

Exception levée à la ligne 21 du fichier TESTS:\runtime\test_unbound_local_error.py.

   20:     def inner():
--&gt;21:         spam_missing_both += 1

        global spam_missing_both:  1
</pre></div>
</div>
</section>
<section id="missing-global">
<h3>Missing global<a class="headerlink" href="#missing-global" title="Permalink to this headline">¶</a></h3>
<div class="highlight-none notranslate"><div class="highlight"><pre><span></span>Traceback (most recent call last):
  File "TESTS:\runtime\test_unbound_local_error.py", line 27, in test_Missing_global
    outer_missing_global()
  File "TESTS:\runtime\test_unbound_local_error.py", line 10, in outer_missing_global
    inner()
  File "TESTS:\runtime\test_unbound_local_error.py", line 9, in inner
    spam_missing_global += 1
UnboundLocalError: local variable 'spam_missing_global' referenced before assignment

    Avez-vous oublié d’ajouter `global spam_missing_global` ?

En Python, les variables utilisées à l’intérieur d’une fonction sont appelées
variables «locales».
Avant d’utiliser une variable locale, une valeur doit lui être attribuée.
Une variable utilisée avant l’attribution d’une valeur est supposée
être définie en dehors de cette fonction;
elle est connu comme une variable «globale» (`global` ou parfois `nonlocal`).
Vous ne pouvez pas assigner une valeur à une telle variable globale
à l’intérieur d’une fonction sans d’abord confirmer à python
qu’il s’agit d’une variable globale, sinon vous verrez une exception `UnboundLocalError`.

Vous essayez d'utiliser le nom `spam_missing_global` identifié par Python comme se trouvant
dans la portée locale d'une fonction avant de lui avoir attribué une valeur.

Le nom `spam_missing_global` existe dans la portée global.
Peut-être la déclaration

    global spam_missing_global

aurait dû être incluse comme première ligne à l’intérieur de votre fonction.

L'exécution s'est arrêtée à la ligne 27 du fichier TESTS:\runtime\test_unbound_local_error.py

   25: def test_Missing_global():
   26:     try:
--&gt;27:         outer_missing_global()
               ^^^^^^^^^^^^^^^^^^^^^^
   28:     except UnboundLocalError as e:

        global outer_missing_global:  &lt;function outer_missing_global&gt;

Exception levée à la ligne 9 du fichier TESTS:\runtime\test_unbound_local_error.py.

   8:     def inner():
--&gt;9:         spam_missing_global += 1

        global spam_missing_global:  1
</pre></div>
</div>
</section>
<section id="missing-nonlocal">
<h3>Missing nonlocal<a class="headerlink" href="#missing-nonlocal" title="Permalink to this headline">¶</a></h3>
<div class="highlight-none notranslate"><div class="highlight"><pre><span></span>Traceback (most recent call last):
  File "TESTS:\runtime\test_unbound_local_error.py", line 45, in test_Missing_nonlocal
    outer_missing_nonlocal()
  File "TESTS:\runtime\test_unbound_local_error.py", line 16, in outer_missing_nonlocal
    inner()
  File "TESTS:\runtime\test_unbound_local_error.py", line 15, in inner
    spam_missing_nonlocal += 1
UnboundLocalError: local variable 'spam_missing_nonlocal' referenced before assignment

    Avez-vous oublié d’ajouter `nonlocal spam_missing_nonlocal` ?

En Python, les variables utilisées à l’intérieur d’une fonction sont appelées
variables «locales».
Avant d’utiliser une variable locale, une valeur doit lui être attribuée.
Une variable utilisée avant l’attribution d’une valeur est supposée
être définie en dehors de cette fonction;
elle est connu comme une variable «globale» (`global` ou parfois `nonlocal`).
Vous ne pouvez pas assigner une valeur à une telle variable globale
à l’intérieur d’une fonction sans d’abord confirmer à python
qu’il s’agit d’une variable globale, sinon vous verrez une exception `UnboundLocalError`.

Vous essayez d'utiliser le nom `spam_missing_nonlocal` identifié par Python comme se trouvant
dans la portée locale d'une fonction avant de lui avoir attribué une valeur.

Le nom `spam_missing_nonlocal` existe dans la portée nonlocal.
Peut-être la déclaration

    nonlocal spam_missing_nonlocal

aurait dû être incluse comme première ligne à l’intérieur de votre fonction.

L'exécution s'est arrêtée à la ligne 45 du fichier TESTS:\runtime\test_unbound_local_error.py

   43: def test_Missing_nonlocal():
   44:     try:
--&gt;45:         outer_missing_nonlocal()
               ^^^^^^^^^^^^^^^^^^^^^^^^
   46:     except UnboundLocalError as e:

        global outer_missing_nonlocal:  &lt;function outer_missing_nonlocal&gt;

Exception levée à la ligne 15 du fichier TESTS:\runtime\test_unbound_local_error.py.

   14:     def inner():
--&gt;15:         spam_missing_nonlocal += 1
</pre></div>
</div>
</section>
<section id="typo-in-local">
<h3>Typo in local<a class="headerlink" href="#typo-in-local" title="Permalink to this headline">¶</a></h3>
<div class="highlight-none notranslate"><div class="highlight"><pre><span></span>Traceback (most recent call last):
  File "TESTS:\runtime\test_unbound_local_error.py", line 101, in test_Typo_in_local
    test2()
  File "TESTS:\runtime\test_unbound_local_error.py", line 98, in test2
    alpha3 += 1
UnboundLocalError: local variable 'alpha3' referenced before assignment

    Vouliez-vous dire `alpha1` ?

En Python, les variables utilisées à l’intérieur d’une fonction sont appelées
variables «locales».
Avant d’utiliser une variable locale, une valeur doit lui être attribuée.
Une variable utilisée avant l’attribution d’une valeur est supposée
être définie en dehors de cette fonction;
elle est connu comme une variable «globale» (`global` ou parfois `nonlocal`).
Vous ne pouvez pas assigner une valeur à une telle variable globale
à l’intérieur d’une fonction sans d’abord confirmer à python
qu’il s’agit d’une variable globale, sinon vous verrez une exception `UnboundLocalError`.

Au lieu d’écrire `alpha3`, peut-être que vous vouliez écrire l'un des noms suivants :
*    Portée locale : `alpha1`, `alpha2`

L'exécution s'est arrêtée à la ligne 101 du fichier TESTS:\runtime\test_unbound_local_error.py

    97:         alpha2 = 1
    98:         alpha3 += 1
   100:     try:
--&gt;101:         test2()
                ^^^^^^^
   102:     except UnboundLocalError as e:

        test2:  &lt;function test2&gt; defined in &lt;function test_Typo_in_local&gt;

Exception levée à la ligne 98 du fichier TESTS:\runtime\test_unbound_local_error.py.

   95:     def test2():
   96:         alpha1 = 1
   97:         alpha2 = 1
--&gt;98:         alpha3 += 1
</pre></div>
</div>
</section>
<section id="using-name-of-builtin">
<h3>Using name of builtin<a class="headerlink" href="#using-name-of-builtin" title="Permalink to this headline">¶</a></h3>
<div class="highlight-none notranslate"><div class="highlight"><pre><span></span>Traceback (most recent call last):
  File "TESTS:\runtime\test_unbound_local_error.py", line 121, in test_Using_name_of_builtin
    dist([])
  File "TESTS:\runtime\test_unbound_local_error.py", line 117, in dist
    max = max(points)
UnboundLocalError: local variable 'max' referenced before assignment

En Python, les variables utilisées à l’intérieur d’une fonction sont appelées
variables «locales».
Avant d’utiliser une variable locale, une valeur doit lui être attribuée.
Une variable utilisée avant l’attribution d’une valeur est supposée
être définie en dehors de cette fonction;
elle est connu comme une variable «globale» (`global` ou parfois `nonlocal`).
Vous ne pouvez pas assigner une valeur à une telle variable globale
à l’intérieur d’une fonction sans d’abord confirmer à python
qu’il s’agit d’une variable globale, sinon vous verrez une exception `UnboundLocalError`.

`max` est une fonction Python de type 'builtin'.
Vous avez essayé d'attribuer une valeur à `max` dans une fonction
tout en utilisant sa signification originale dans cette même fonction.

Notez que ce n'est généralement pas une bonne idée de donner à une variable locale
le même nom qu'une fonction Python de type 'builtin' (comme `max`).

L'exécution s'est arrêtée à la ligne 121 du fichier TESTS:\runtime\test_unbound_local_error.py

   118:         min = min(points)
   119:         return max - min
   120:     try:
--&gt;121:         dist([])
                ^^^^^^^^
   122:     except UnboundLocalError as e:

        dist:  &lt;function dist&gt; defined in &lt;function test_Using_name_of_builtin&gt;

Exception levée à la ligne 117 du fichier TESTS:\runtime\test_unbound_local_error.py.

   116:     def dist(points):
--&gt;117:         max = max(points)
                ^^^
   118:         min = min(points)

        max:  &lt;builtin function max&gt;
</pre></div>
</div>
</section>
</section>
<section id="unknownerror">
<h2>UnknownError<a class="headerlink" href="#unknownerror" title="Permalink to this headline">¶</a></h2>
<section id="id8">
<h3>Generic<a class="headerlink" href="#id8" title="Permalink to this headline">¶</a></h3>
<div class="highlight-none notranslate"><div class="highlight"><pre><span></span>Traceback (most recent call last):
  File "TESTS:\runtime\test_unknown_error.py", line 12, in test_Generic
    raise UnknownException("Some informative message about an unknown exception.")
UnknownException: Some informative message about an unknown exception.

Aucune information n’est disponible au sujet de cette exception.
Veuillez signaler cet exemple à
https://github.com/friendly-traceback/friendly-traceback/issues/new
Si vous utilisez un REPL, utilisez `www('bug')` pour le faire.

Si vous utilisez la console Friendly, utilisez `www()` pour
faire une recherche sur Internet pour ce cas particulier.

Exception levée à la ligne 12 du fichier TESTS:\runtime\test_unknown_error.py.

    9:     old_debug = friendly_traceback.debug_helper.DEBUG
   10:     friendly_traceback.debug_helper.DEBUG = False
   11:     try:
--&gt;12:         raise UnknownException("Some informative message about an unknown exception.")
   13:     except Exception as e:

        global UnknownException:  &lt;class test_unknown_error.UnknownException&gt;
</pre></div>
</div>
</section>
</section>
<section id="valueerror">
<h2>ValueError<a class="headerlink" href="#valueerror" title="Permalink to this headline">¶</a></h2>
<section id="convert-to-int">
<h3>Convert to int<a class="headerlink" href="#convert-to-int" title="Permalink to this headline">¶</a></h3>
<div class="highlight-none notranslate"><div class="highlight"><pre><span></span>Traceback (most recent call last):
  File "TESTS:\runtime\test_value_error.py", line 187, in test_Convert_to_int
    int('13a')
ValueError: invalid literal for int() with base 10: '13a'

Une exception `ValueError` indique qu'une fonction ou une opération
a reçu un argument du bon type, mais une valeur inappropriée.

`'13a'` est un argument invalide pour `int()` dans la base `10`.
En base `10`, `int()` est le plus souvent utilisé pour convertir une chaîne de caractères
contenant les chiffres `0` à `9` en un nombre entier.
Les caractères suivants ne sont pas permis : `a`.

Exception levée à la ligne 187 du fichier TESTS:\runtime\test_value_error.py.

   183:     if english:
   184:         assert "needs to be first converted using `float()`" in result
   186:     try:
--&gt;187:         int('13a')
                ^^^^^^^^^^
   188:     except ValueError as e:

        int:  &lt;class int&gt;
</pre></div>
</div>
</section>
<section id="could-not-convert-to-float">
<h3>Could not convert to float<a class="headerlink" href="#could-not-convert-to-float" title="Permalink to this headline">¶</a></h3>
<div class="highlight-none notranslate"><div class="highlight"><pre><span></span>Traceback (most recent call last):
  File "TESTS:\runtime\test_value_error.py", line 88, in test_Could_not_convert_to_float
    float("42b")
ValueError: could not convert string to float: '42b'

Une exception `ValueError` indique qu'une fonction ou une opération
a reçu un argument du bon type, mais une valeur inappropriée.

La chaîne `42b` ne peut pas être convertie en un nombre décimal (`float`).

Exception levée à la ligne 88 du fichier TESTS:\runtime\test_value_error.py.

   86: def test_Could_not_convert_to_float():
   87:     try:
--&gt;88:         float("42b")
               ^^^^^^^^^^^^
   89:     except ValueError as e:

        float:  &lt;class float&gt;
</pre></div>
</div>
</section>
<section id="date-invalid-month">
<h3>Date invalid month<a class="headerlink" href="#date-invalid-month" title="Permalink to this headline">¶</a></h3>
<div class="highlight-none notranslate"><div class="highlight"><pre><span></span>Traceback (most recent call last):
  File "TESTS:\runtime\test_value_error.py", line 58, in test_Date_invalid_month
    d = date(2021, 13, 1)
ValueError: month must be in 1..12

    Avez-vous spécifié un mois inexistant ?

Une exception `ValueError` indique qu'une fonction ou une opération
a reçu un argument du bon type, mais une valeur inappropriée.

Je crois que vous avez indiqué une valeur non valide pour le mois
dans un objet de type `date`. Les valeurs valides sont les entiers de 1 à 12.

Exception levée à la ligne 58 du fichier TESTS:\runtime\test_value_error.py.

   55: def test_Date_invalid_month():
   56:     from datetime import date
   57:     try:
--&gt;58:         d = date(2021, 13, 1)
                   ^^^^^^^^^^^^^^^^^
   59:     except ValueError as e:

        date:  &lt;class datetime.date&gt;
</pre></div>
</div>
</section>
<section id="not-enough-values-to-unpack">
<h3>Not enough values to unpack<a class="headerlink" href="#not-enough-values-to-unpack" title="Permalink to this headline">¶</a></h3>
<div class="highlight-none notranslate"><div class="highlight"><pre><span></span>Traceback (most recent call last):
  File "TESTS:\runtime\test_value_error.py", line 28, in test_Not_enough_values_to_unpack
    a, b, c = d
ValueError: not enough values to unpack (expected 3, got 2)

Une exception `ValueError` indique qu'une fonction ou une opération
a reçu un argument du bon type, mais une valeur inappropriée.

Le dépaquetage ('unpack') est un moyen pratique d’attribuer un nom
à chaque élément d’un itérable.
Dans ce cas-ci, il y a plus de noms (3)
que la longueur de l’itérable, une chaîne de caractères (`str`) de longueur 2.

Exception levée à la ligne 28 du fichier TESTS:\runtime\test_value_error.py.

   24:     assert "ValueError: not enough values to unpack (expected 3, got 2)" in result
   26:     d = "ab"
   27:     try:
--&gt;28:         a, b, c = d
   29:     except ValueError as e:

        d:  'ab'
</pre></div>
</div>
</section>
<section id="pow-third-arg-cannot-be-zero">
<h3>Pow third arg cannot be zero<a class="headerlink" href="#pow-third-arg-cannot-be-zero" title="Permalink to this headline">¶</a></h3>
<div class="highlight-none notranslate"><div class="highlight"><pre><span></span>Traceback (most recent call last):
  File "TESTS:\runtime\test_value_error.py", line 103, in test_Pow_third_arg_cannot_be_zero
    pow(2, 4, a)
ValueError: pow() 3rd argument cannot be 0

Une exception `ValueError` indique qu'une fonction ou une opération
a reçu un argument du bon type, mais une valeur inappropriée.

Le troisième argument de la fonction `pow()` ne peut pas être zéro.

Exception levée à la ligne 103 du fichier TESTS:\runtime\test_value_error.py.

   100: def test_Pow_third_arg_cannot_be_zero():
   101:     a = 0
   102:     try:
--&gt;103:         pow(2, 4, a)
                ^^^^^^^^^^^^
   104:     except ValueError as e:

        a:  0
        pow:  &lt;builtin function pow&gt;
</pre></div>
</div>
</section>
<section id="slots-conflicts-with-class-variable">
<h3>Slots conflicts with class variable<a class="headerlink" href="#slots-conflicts-with-class-variable" title="Permalink to this headline">¶</a></h3>
<div class="highlight-none notranslate"><div class="highlight"><pre><span></span>Traceback (most recent call last):
  File "TESTS:\runtime\test_value_error.py", line 72, in test_Slots_conflicts_with_class_variable
    class F:
ValueError: 'a' in __slots__ conflicts with class variable

Une exception `ValueError` indique qu'une fonction ou une opération
a reçu un argument du bon type, mais une valeur inappropriée.

Le nom `a` est utilisé à la fois comme nom d'une variable de classe
et comme élément de chaîne de caractères dans l'attribut `__slots__` d'une classe ;
ceci n'est pas autorisé.

Exception levée à la ligne 72 du fichier TESTS:\runtime\test_value_error.py.

   70: def test_Slots_conflicts_with_class_variable():
   71:     try:
--&gt;72:         class F:
   73:             __slots__ = ["a", "b"]
</pre></div>
</div>
</section>
<section id="too-many-values-to-unpack">
<h3>Too many values to unpack<a class="headerlink" href="#too-many-values-to-unpack" title="Permalink to this headline">¶</a></h3>
<div class="highlight-none notranslate"><div class="highlight"><pre><span></span>Traceback (most recent call last):
  File "TESTS:\runtime\test_value_error.py", line 43, in test_Too_many_values_to_unpack
    a, b = c
ValueError: too many values to unpack (expected 2)

Une exception `ValueError` indique qu'une fonction ou une opération
a reçu un argument du bon type, mais une valeur inappropriée.

Le dépaquetage ('unpack') est un moyen pratique d’attribuer un nom
à chaque élément d’un itérable.
Dans ce cas-ci, il y a moins de noms (2)
que la longueur de l’itérable, une liste (`list`) de longueur 3.

Exception levée à la ligne 43 du fichier TESTS:\runtime\test_value_error.py.

   40: def test_Too_many_values_to_unpack():
   41:     c = [1, 2, 3]
   42:     try:
--&gt;43:         a, b = c
   44:     except ValueError as e:

        c:  [1, 2, 3]
</pre></div>
</div>
</section>
<section id="int-base-not-in-range">
<h3>int base not in range<a class="headerlink" href="#int-base-not-in-range" title="Permalink to this headline">¶</a></h3>
<div class="highlight-none notranslate"><div class="highlight"><pre><span></span>Traceback (most recent call last):
  File "TESTS:\runtime\test_value_error.py", line 201, in test_int_base_not_in_range
    int('18', base=37)
ValueError: int() base must be &gt;= 2 and &lt;= 36, or 0

Une exception `ValueError` indique qu'une fonction ou une opération
a reçu un argument du bon type, mais une valeur inappropriée.

L'argument `base` de `int()` doit être soit zéro
ou un nombre entier de 2 à 36.
Vous avez écrit 37, ce qui n'est pas valide.

Exception levée à la ligne 201 du fichier TESTS:\runtime\test_value_error.py.

   199: def test_int_base_not_in_range():
   200:     try:
--&gt;201:         int('18', base=37)
                ^^^^^^^^^^^^^^^^^^
   202:     except ValueError as e:

        int:  &lt;class int&gt;
</pre></div>
</div>
</section>
<section id="time-strptime-incorrect-format">
<h3>time strptime incorrect format<a class="headerlink" href="#time-strptime-incorrect-format" title="Permalink to this headline">¶</a></h3>
<div class="highlight-none notranslate"><div class="highlight"><pre><span></span>Traceback (most recent call last):
  File "TESTS:\runtime\test_value_error.py", line 127, in test_time_strptime_incorrect_format
    time.strptime("2020-01-01", "%d %m %Y")
ValueError: time data '2020-01-01' does not match format '%d %m %Y'

Une exception `ValueError` indique qu'une fonction ou une opération
a reçu un argument du bon type, mais une valeur inappropriée.

La valeur que vous avez donnée pour l'heure n'est pas dans le format que vous avez spécifié.
Veillez à utiliser le même séparateur entre les éléments
(par exemple, entre le jour et le mois) et conservez le même ordre
dans les données fournies et dans le format que vous avez spécifié.
Le tableau suivant pourrait vous être utile :
https://docs.python.org/fr/3/library/time.html#time.strftime
Le site suivant peut également être utile : https://www.strfti.me/ (anglais seulement).

Exception levée à la ligne 127 du fichier TESTS:\runtime\test_value_error.py.

   123:         return
   125:     import time
   126:     try:
--&gt;127:         time.strptime("2020-01-01", "%d %m %Y")
                ^^^^^^^^^^^^^^^^^^^^^^^^^^^^^^^^^^^^^^^
   128:     except ValueError as e:

        time:  &lt;module time (builtin)&gt;
        time.strptime:  &lt;builtin function strptime&gt;
</pre></div>
</div>
</section>
</section>
<section id="zerodivisionerror">
<h2>ZeroDivisionError<a class="headerlink" href="#zerodivisionerror" title="Permalink to this headline">¶</a></h2>
<section id="complex-division">
<h3>Complex division<a class="headerlink" href="#complex-division" title="Permalink to this headline">¶</a></h3>
<div class="highlight-none notranslate"><div class="highlight"><pre><span></span>Traceback (most recent call last):
  File "TESTS:\runtime\test_zero_division_error.py", line 155, in test_Complex_division
    1 / zero
ZeroDivisionError: complex division by zero

Une exception de type `ZeroDivisionError` se produit lorsque vous essayez de diviser une valeur
par zéro soit directement ou en utilisant une autre opération mathématique.

Vous divisez par le terme suivant

     zero

qui est égal à zéro.

Exception levée à la ligne 155 du fichier TESTS:\runtime\test_zero_division_error.py.

   152: def test_Complex_division():
   153:     zero = 0j
   154:     try:
--&gt;155:         1 / zero
                ^^^^^^^^
   156:     except ZeroDivisionError as e:

        zero:  0j
</pre></div>
</div>
</section>
<section id="division-by-zero-literal">
<h3>Division by zero literal<a class="headerlink" href="#division-by-zero-literal" title="Permalink to this headline">¶</a></h3>
<div class="highlight-none notranslate"><div class="highlight"><pre><span></span>Traceback (most recent call last):
  File "TESTS:\runtime\test_zero_division_error.py", line 199, in test_Division_by_zero_literal
    1. / 0
ZeroDivisionError: float division by zero

Une exception de type `ZeroDivisionError` se produit lorsque vous essayez de diviser une valeur
par zéro soit directement ou en utilisant une autre opération mathématique.

Vous divisez par zéro.

Exception levée à la ligne 199 du fichier TESTS:\runtime\test_zero_division_error.py.

   194:     if friendly_traceback.get_lang() == "en":
   195:         assert "Using the modulo operator, you are dividing by zero" in result
   198:     try:
--&gt;199:         1. / 0
                ^^^^^^
   200:     except ZeroDivisionError as e:
</pre></div>
</div>
</section>
<section id="division-operator">
<h3>Division operator<a class="headerlink" href="#division-operator" title="Permalink to this headline">¶</a></h3>
<div class="highlight-none notranslate"><div class="highlight"><pre><span></span>Traceback (most recent call last):
  File "TESTS:\runtime\test_zero_division_error.py", line 17, in test_Division_operator
    1 / zero
ZeroDivisionError: division by zero

Une exception de type `ZeroDivisionError` se produit lorsque vous essayez de diviser une valeur
par zéro soit directement ou en utilisant une autre opération mathématique.

Vous divisez par le terme suivant

     zero

qui est égal à zéro.

Exception levée à la ligne 17 du fichier TESTS:\runtime\test_zero_division_error.py.

   13:     if friendly_traceback.get_lang() == "en":
   14:         assert "The following mathematical expression includes a division by zero" in result
   16:     try:
--&gt;17:         1 / zero
               ^^^^^^^^
   18:     except ZeroDivisionError as e:

        zero:  0
</pre></div>
</div>
</section>
<section id="divmod">
<h3>Divmod<a class="headerlink" href="#divmod" title="Permalink to this headline">¶</a></h3>
<div class="highlight-none notranslate"><div class="highlight"><pre><span></span>Traceback (most recent call last):
  File "TESTS:\runtime\test_zero_division_error.py", line 82, in test_Divmod
    divmod(1, zero)
ZeroDivisionError: integer division or modulo by zero

Une exception de type `ZeroDivisionError` se produit lorsque vous essayez de diviser une valeur
par zéro soit directement ou en utilisant une autre opération mathématique.

Le deuxième argument de la fonction `divmod()` est égal à zéro.

Exception levée à la ligne 82 du fichier TESTS:\runtime\test_zero_division_error.py.

   79: def test_Divmod():
   80:     zero = 0
   81:     try:
--&gt;82:         divmod(1, zero)
               ^^^^^^^^^^^^^^^
   83:     except ZeroDivisionError as e:

        zero:  0
        divmod:  &lt;builtin function divmod&gt;
</pre></div>
</div>
</section>
<section id="float-division">
<h3>Float division<a class="headerlink" href="#float-division" title="Permalink to this headline">¶</a></h3>
<div class="highlight-none notranslate"><div class="highlight"><pre><span></span>Traceback (most recent call last):
  File "TESTS:\runtime\test_zero_division_error.py", line 125, in test_Float_division
    1 / zero
ZeroDivisionError: float division by zero

Une exception de type `ZeroDivisionError` se produit lorsque vous essayez de diviser une valeur
par zéro soit directement ou en utilisant une autre opération mathématique.

Vous divisez par le terme suivant

     zero

qui est égal à zéro.

Exception levée à la ligne 125 du fichier TESTS:\runtime\test_zero_division_error.py.

   122: def test_Float_division():
   123:     zero = 0.
   124:     try:
--&gt;125:         1 / zero
                ^^^^^^^^
   126:     except ZeroDivisionError as e:

        zero:  0.0
</pre></div>
</div>
</section>
<section id="float-divmod">
<h3>Float divmod<a class="headerlink" href="#float-divmod" title="Permalink to this headline">¶</a></h3>
<div class="highlight-none notranslate"><div class="highlight"><pre><span></span>Traceback (most recent call last):
  File "TESTS:\runtime\test_zero_division_error.py", line 140, in test_Float_divmod
    divmod(1, zero)
ZeroDivisionError: float divmod()

Une exception de type `ZeroDivisionError` se produit lorsque vous essayez de diviser une valeur
par zéro soit directement ou en utilisant une autre opération mathématique.

Le deuxième argument de la fonction `divmod()` est égal à zéro.

Exception levée à la ligne 140 du fichier TESTS:\runtime\test_zero_division_error.py.

   137: def test_Float_divmod():
   138:     zero = 0.
   139:     try:
--&gt;140:         divmod(1, zero)
                ^^^^^^^^^^^^^^^
   141:     except ZeroDivisionError as e:

        zero:  0.0
        divmod:  &lt;builtin function divmod&gt;
</pre></div>
</div>
</section>
<section id="float-modulo">
<h3>Float modulo<a class="headerlink" href="#float-modulo" title="Permalink to this headline">¶</a></h3>
<div class="highlight-none notranslate"><div class="highlight"><pre><span></span>Traceback (most recent call last):
  File "TESTS:\runtime\test_zero_division_error.py", line 110, in test_Float_modulo
    1 % zero
ZeroDivisionError: float modulo

Une exception de type `ZeroDivisionError` se produit lorsque vous essayez de diviser une valeur
par zéro soit directement ou en utilisant une autre opération mathématique.

En utilisant l’opérateur modulo, vous divisez par le terme suivant

     zero

qui est égal à zéro.

Exception levée à la ligne 110 du fichier TESTS:\runtime\test_zero_division_error.py.

   106:         assert "The following mathematical expression includes a division by zero" in result
   107:         assert "done using the modulo operator" in result
   109:     try:
--&gt;110:         1 % zero
                ^^^^^^^^
   111:     except ZeroDivisionError as e:

        zero:  0.0
</pre></div>
</div>
</section>
<section id="integer-division-operator">
<h3>Integer division operator<a class="headerlink" href="#integer-division-operator" title="Permalink to this headline">¶</a></h3>
<div class="highlight-none notranslate"><div class="highlight"><pre><span></span>Traceback (most recent call last):
  File "TESTS:\runtime\test_zero_division_error.py", line 42, in test_Integer_division_operator
    1 // zero
ZeroDivisionError: integer division or modulo by zero

Une exception de type `ZeroDivisionError` se produit lorsque vous essayez de diviser une valeur
par zéro soit directement ou en utilisant une autre opération mathématique.

Vous divisez par le terme suivant

     zero

qui est égal à zéro.

Exception levée à la ligne 42 du fichier TESTS:\runtime\test_zero_division_error.py.

   38:     if friendly_traceback.get_lang() == "en":
   39:         assert "The following mathematical expression includes a division by zero" in result
   41:     try:
--&gt;42:         1 // zero
               ^^^^^^^^^
   43:     except ZeroDivisionError as e:

        zero:  0
</pre></div>
</div>
</section>
<section id="mixed-operations">
<h3>Mixed operations<a class="headerlink" href="#mixed-operations" title="Permalink to this headline">¶</a></h3>
<div class="highlight-none notranslate"><div class="highlight"><pre><span></span>Traceback (most recent call last):
  File "TESTS:\runtime\test_zero_division_error.py", line 212, in test_Mixed_operations
    a = divmod(8, 1 // 2)
ZeroDivisionError: integer division or modulo by zero

Une exception de type `ZeroDivisionError` se produit lorsque vous essayez de diviser une valeur
par zéro soit directement ou en utilisant une autre opération mathématique.

L’expression mathématique suivante inclut une division par zéro :

    divmod(8, 1 // 2)

Exception levée à la ligne 212 du fichier TESTS:\runtime\test_zero_division_error.py.

   210: def test_Mixed_operations():
   211:     try:
--&gt;212:         a = divmod(8, 1 // 2)
                    ^^^^^^^^^^^^^^^^^
   213:     except ZeroDivisionError as e:

        divmod:  &lt;builtin function divmod&gt;
        1 // 2:  0
</pre></div>
</div>
</section>
<section id="modulo-operator">
<h3>Modulo operator<a class="headerlink" href="#modulo-operator" title="Permalink to this headline">¶</a></h3>
<div class="highlight-none notranslate"><div class="highlight"><pre><span></span>Traceback (most recent call last):
  File "TESTS:\runtime\test_zero_division_error.py", line 67, in test_Modulo_operator
    1 % zero
ZeroDivisionError: integer division or modulo by zero

Une exception de type `ZeroDivisionError` se produit lorsque vous essayez de diviser une valeur
par zéro soit directement ou en utilisant une autre opération mathématique.

En utilisant l’opérateur modulo, vous divisez par le terme suivant

     zero

qui est égal à zéro.

Exception levée à la ligne 67 du fichier TESTS:\runtime\test_zero_division_error.py.

   63:     if friendly_traceback.get_lang() == "en":
   64:         assert "The following mathematical expression includes a division by zero" in result
   66:     try:
--&gt;67:         1 % zero
               ^^^^^^^^
   68:     except ZeroDivisionError as e:

        zero:  0
</pre></div>
</div>
</section>
<section id="raise-zero-negative-power">
<h3>Raise zero negative power<a class="headerlink" href="#raise-zero-negative-power" title="Permalink to this headline">¶</a></h3>
<div class="highlight-none notranslate"><div class="highlight"><pre><span></span>Traceback (most recent call last):
  File "TESTS:\runtime\test_zero_division_error.py", line 170, in test_Raise_zero_negative_power
    zero ** -1
ZeroDivisionError: 0.0 cannot be raised to a negative power

Une exception de type `ZeroDivisionError` se produit lorsque vous essayez de diviser une valeur
par zéro soit directement ou en utilisant une autre opération mathématique.

Vous essayez d'élever le nombre 0 à une puissance négative
ce qui équivaut à diviser par zéro.

Exception levée à la ligne 170 du fichier TESTS:\runtime\test_zero_division_error.py.

   167: def test_Raise_zero_negative_power():
   168:     zero = 0
   169:     try:
--&gt;170:         zero ** -1
                ^^^^^^^^^^
   171:     except ZeroDivisionError as e:

        zero:  0
</pre></div>
</div>
</section>
</section>
</section>

        </article>
      </div>
      <footer>
        
        <div class="related-pages">
          <a class="next-page" href="syntax_tracebacks_fr.html">
              <div class="page-info">
                <div class="context">
                  <span>Next</span>
                </div>
                <div class="title"> Friendly SyntaxError tracebacks - en Français</div>
              </div>
              <svg><use href="#svg-arrow-right"></use></svg>
            </a>
          <a class="prev-page" href="syntax_tracebacks_es.html">
              <svg><use href="#svg-arrow-right"></use></svg>
              <div class="page-info">
                <div class="context">
                  <span>Previous</span>
                </div>
                
                <div class="title">Friendly SyntaxError tracebacks - en español</div>
                
              </div>
            </a>
        </div>

        <div class="related-information">
              Copyright &#169; André Roberge |
          Created using <a href="https://www.sphinx-doc.org/">Sphinx</a> and <a class="muted-link" href="https://pradyunsg.me">@pradyunsg</a>'s
          <a href="https://github.com/pradyunsg/furo">Furo theme</a>.
            | <a class="muted-link" href="_sources/tracebacks_fr.rst.txt"
               rel="nofollow">
              Show Source
            </a>
        </div>
        
      </footer>
    </div>
    <aside class="toc-drawer">
      
      
      <div class="toc-sticky toc-scroll">
        <div class="toc-title-container">
          <span class="toc-title">
            Contents
          </span>
        </div>
        <div class="toc-tree-container">
          <div class="toc-tree">
            <ul>
<li><a class="reference internal" href="#"> Friendly tracebacks - en Français</a><ul>
<li><a class="reference internal" href="#arithmeticerror">ArithmeticError</a><ul>
<li><a class="reference internal" href="#generic">Generic</a></li>
</ul>
</li>
<li><a class="reference internal" href="#assertionerror">AssertionError</a><ul>
<li><a class="reference internal" href="#id1">Generic</a></li>
</ul>
</li>
<li><a class="reference internal" href="#attributeerror">AttributeError</a><ul>
<li><a class="reference internal" href="#attribute-from-other-module">Attribute from other module</a></li>
<li><a class="reference internal" href="#builtin-function">Builtin function</a></li>
<li><a class="reference internal" href="#builtin-module-with-no-file">Builtin module with no file</a></li>
<li><a class="reference internal" href="#circular-import">Circular import</a></li>
<li><a class="reference internal" href="#circular-import-b">Circular import b</a></li>
<li><a class="reference internal" href="#id2">Generic</a></li>
<li><a class="reference internal" href="#generic-different-frame">Generic different frame</a></li>
<li><a class="reference internal" href="#generic-instance">Generic instance</a></li>
<li><a class="reference internal" href="#module-attribute-typo">Module attribute typo</a></li>
<li><a class="reference internal" href="#nonetype">Nonetype</a></li>
<li><a class="reference internal" href="#object-attribute-typo">Object attribute typo</a></li>
<li><a class="reference internal" href="#perhaps-comma">Perhaps comma</a></li>
<li><a class="reference internal" href="#read-only">Read only</a></li>
<li><a class="reference internal" href="#shadow-stdlib-module">Shadow stdlib module</a></li>
<li><a class="reference internal" href="#tuple-by-accident">Tuple by accident</a></li>
<li><a class="reference internal" href="#use-builtin">Use builtin</a></li>
<li><a class="reference internal" href="#use-join-with-str">Use join with str</a></li>
<li><a class="reference internal" href="#use-synonym">Use synonym</a></li>
<li><a class="reference internal" href="#using-slots">Using slots</a></li>
</ul>
</li>
<li><a class="reference internal" href="#filenotfounderror">FileNotFoundError</a><ul>
<li><a class="reference internal" href="#directory-not-found">Directory not found</a></li>
<li><a class="reference internal" href="#filename-not-found">Filename not found</a></li>
<li><a class="reference internal" href="#filename-not-found-2">Filename not found 2</a></li>
<li><a class="reference internal" href="#filename-not-found-3">Filename not found 3</a></li>
</ul>
</li>
<li><a class="reference internal" href="#importerror">ImportError</a><ul>
<li><a class="reference internal" href="#id3">Circular import</a></li>
<li><a class="reference internal" href="#simple-import-error">Simple import error</a></li>
</ul>
</li>
<li><a class="reference internal" href="#indexerror">IndexError</a><ul>
<li><a class="reference internal" href="#assignment">Assignment</a></li>
<li><a class="reference internal" href="#empty">Empty</a></li>
<li><a class="reference internal" href="#long-list">Long list</a></li>
<li><a class="reference internal" href="#short-tuple">Short tuple</a></li>
</ul>
</li>
<li><a class="reference internal" href="#keyerror">KeyError</a><ul>
<li><a class="reference internal" href="#chainmap">ChainMap</a></li>
<li><a class="reference internal" href="#forgot-to-convert-to-string">Forgot to convert to string</a></li>
<li><a class="reference internal" href="#generic-key-error">Generic key error</a></li>
<li><a class="reference internal" href="#popitem-empty-chainmap">Popitem empty ChainMap</a></li>
<li><a class="reference internal" href="#popitem-empty-dict">Popitem empty dict</a></li>
<li><a class="reference internal" href="#similar-names">Similar names</a></li>
<li><a class="reference internal" href="#string-by-mistake">String by mistake</a></li>
</ul>
</li>
<li><a class="reference internal" href="#lookuperror">LookupError</a><ul>
<li><a class="reference internal" href="#id4">Generic</a></li>
</ul>
</li>
<li><a class="reference internal" href="#modulenotfounderror">ModuleNotFoundError</a><ul>
<li><a class="reference internal" href="#need-to-install-module">Need to install module</a></li>
<li><a class="reference internal" href="#not-a-package">Not a package</a></li>
<li><a class="reference internal" href="#not-a-package-similar-name">Not a package similar name</a></li>
<li><a class="reference internal" href="#object-not-module">Object not module</a></li>
<li><a class="reference internal" href="#similar-object-not-module">Similar object not module</a></li>
<li><a class="reference internal" href="#standard-library-module">Standard library module</a></li>
<li><a class="reference internal" href="#no-curses">no curses</a></li>
</ul>
</li>
<li><a class="reference internal" href="#nameerror">NameError</a><ul>
<li><a class="reference internal" href="#annotated-variable">Annotated variable</a></li>
<li><a class="reference internal" href="#custom-name">Custom name</a></li>
<li><a class="reference internal" href="#free-variable-referenced">Free variable referenced</a></li>
<li><a class="reference internal" href="#id5">Generic</a></li>
<li><a class="reference internal" href="#missing-import">Missing import</a></li>
<li><a class="reference internal" href="#missing-module-name">Missing module name</a></li>
<li><a class="reference internal" href="#missing-self-1">Missing self 1</a></li>
<li><a class="reference internal" href="#missing-self-2">Missing self 2</a></li>
<li><a class="reference internal" href="#synonym">Synonym</a></li>
<li><a class="reference internal" href="#missing-import2">missing import2</a></li>
<li><a class="reference internal" href="#missing-import3">missing import3</a></li>
</ul>
</li>
<li><a class="reference internal" href="#oserror">OsError</a><ul>
<li><a class="reference internal" href="#urllib-error">Urllib error</a></li>
<li><a class="reference internal" href="#invalid-argument">invalid argument</a></li>
<li><a class="reference internal" href="#no-information">no information</a></li>
</ul>
</li>
<li><a class="reference internal" href="#overflowerror">OverflowError</a><ul>
<li><a class="reference internal" href="#id6">Generic</a></li>
</ul>
</li>
<li><a class="reference internal" href="#recursionerror">RecursionError</a><ul>
<li><a class="reference internal" href="#id7">Generic</a></li>
</ul>
</li>
<li><a class="reference internal" href="#typeerror">TypeError</a><ul>
<li><a class="reference internal" href="#bad-type-for-unary-operator">Bad type for unary operator</a></li>
<li><a class="reference internal" href="#builtin-has-no-len">Builtin has no len</a></li>
<li><a class="reference internal" href="#can-only-concatenate">Can only concatenate</a></li>
<li><a class="reference internal" href="#cannot-convert-dictionary-update-sequence">Cannot convert dictionary update sequence</a></li>
<li><a class="reference internal" href="#cannot-multiply-by-non-int">Cannot multiply by non int</a></li>
<li><a class="reference internal" href="#cannot-unpack-non-iterable-object">Cannot unpack non iterable object</a></li>
<li><a class="reference internal" href="#comparison-not-supported">Comparison not supported</a></li>
<li><a class="reference internal" href="#derive-from-baseexception">Derive from BaseException</a></li>
<li><a class="reference internal" href="#indices-must-be-integers-or-slices">Indices must be integers or slices</a></li>
<li><a class="reference internal" href="#not-an-integer">Not an integer</a></li>
<li><a class="reference internal" href="#not-callable">Not callable</a></li>
<li><a class="reference internal" href="#object-is-not-iterable">Object is not iterable</a></li>
<li><a class="reference internal" href="#object-is-not-subscriptable">Object is not subscriptable</a></li>
<li><a class="reference internal" href="#slice-indices-must-be-integers-or-none">Slice indices must be integers or None</a></li>
<li><a class="reference internal" href="#too-few-positional-argument">Too few positional argument</a></li>
<li><a class="reference internal" href="#too-many-positional-argument">Too many positional argument</a></li>
<li><a class="reference internal" href="#tuple-no-item-assignment">Tuple no item assignment</a></li>
<li><a class="reference internal" href="#unhachable-type">Unhachable type</a></li>
<li><a class="reference internal" href="#unsupported-operand-types">Unsupported operand types</a></li>
<li><a class="reference internal" href="#function-got-multiple-argument">function got multiple argument</a></li>
<li><a class="reference internal" href="#function-has-no-len">function has no len</a></li>
<li><a class="reference internal" href="#getattr-attribute-name-must-be-string">getattr attribute name must be string</a></li>
<li><a class="reference internal" href="#method-got-multiple-argument">method got multiple argument</a></li>
<li><a class="reference internal" href="#vars-arg-must-have-dict">vars arg must have dict</a></li>
</ul>
</li>
<li><a class="reference internal" href="#unboundlocalerror">UnboundLocalError</a><ul>
<li><a class="reference internal" href="#missing-both">Missing both</a></li>
<li><a class="reference internal" href="#missing-global">Missing global</a></li>
<li><a class="reference internal" href="#missing-nonlocal">Missing nonlocal</a></li>
<li><a class="reference internal" href="#typo-in-local">Typo in local</a></li>
<li><a class="reference internal" href="#using-name-of-builtin">Using name of builtin</a></li>
</ul>
</li>
<li><a class="reference internal" href="#unknownerror">UnknownError</a><ul>
<li><a class="reference internal" href="#id8">Generic</a></li>
</ul>
</li>
<li><a class="reference internal" href="#valueerror">ValueError</a><ul>
<li><a class="reference internal" href="#convert-to-int">Convert to int</a></li>
<li><a class="reference internal" href="#could-not-convert-to-float">Could not convert to float</a></li>
<li><a class="reference internal" href="#date-invalid-month">Date invalid month</a></li>
<li><a class="reference internal" href="#not-enough-values-to-unpack">Not enough values to unpack</a></li>
<li><a class="reference internal" href="#pow-third-arg-cannot-be-zero">Pow third arg cannot be zero</a></li>
<li><a class="reference internal" href="#slots-conflicts-with-class-variable">Slots conflicts with class variable</a></li>
<li><a class="reference internal" href="#too-many-values-to-unpack">Too many values to unpack</a></li>
<li><a class="reference internal" href="#int-base-not-in-range">int base not in range</a></li>
<li><a class="reference internal" href="#time-strptime-incorrect-format">time strptime incorrect format</a></li>
</ul>
</li>
<li><a class="reference internal" href="#zerodivisionerror">ZeroDivisionError</a><ul>
<li><a class="reference internal" href="#complex-division">Complex division</a></li>
<li><a class="reference internal" href="#division-by-zero-literal">Division by zero literal</a></li>
<li><a class="reference internal" href="#division-operator">Division operator</a></li>
<li><a class="reference internal" href="#divmod">Divmod</a></li>
<li><a class="reference internal" href="#float-division">Float division</a></li>
<li><a class="reference internal" href="#float-divmod">Float divmod</a></li>
<li><a class="reference internal" href="#float-modulo">Float modulo</a></li>
<li><a class="reference internal" href="#integer-division-operator">Integer division operator</a></li>
<li><a class="reference internal" href="#mixed-operations">Mixed operations</a></li>
<li><a class="reference internal" href="#modulo-operator">Modulo operator</a></li>
<li><a class="reference internal" href="#raise-zero-negative-power">Raise zero negative power</a></li>
</ul>
</li>
</ul>
</li>
</ul>

          </div>
        </div>
      </div>
      
      
    </aside>
  </div>
</div><script data-url_root="./" id="documentation_options" src="_static/documentation_options.js"></script>
    <script src="_static/jquery.js"></script>
    <script src="_static/underscore.js"></script>
    <script src="_static/doctools.js"></script>
    <script src="_static/scripts/furo.js"></script>
    <script src="_static/tabs.js"></script>
    <script src="_static/clipboard.min.js"></script>
    <script src="_static/copybutton.js"></script>
    </body>
</html>