<!doctype html>
<html class="no-js">
  <head><meta charset="utf-8"/>
    <meta name="viewport" content="width=device-width,initial-scale=1"/>
    <meta name="color-scheme" content="light dark"><link rel="index" title="Index" href="genindex.html" /><link rel="search" title="Search" href="search.html" /><link rel="next" title="Friendly SyntaxError tracebacks - in English" href="syntax_tracebacks_en_3.11.html" /><link rel="prev" title="Friendly SyntaxError tracebacks - in English" href="syntax_tracebacks_en_3.10.html" />

    <meta name="generator" content="sphinx-4.1.2, furo 2021.08.17.beta43"/>
        <title>Friendly tracebacks - in English - friendly-traceback 0.4.78</title>
      <link rel="stylesheet" type="text/css" href="_static/pygments.css" />
    <link rel="stylesheet" type="text/css" href="_static/styles/furo.css?digest=910ac4ccc9d7c023151c34010d7b500fb9777a51" />
    <link rel="stylesheet" type="text/css" href="_static/tabs.css" />
    <link rel="stylesheet" type="text/css" href="_static/copybutton.css" />
    <link rel="stylesheet" type="text/css" href="_static/styles/furo-extensions.css?digest=16fb25fabf47304eee183a5e9af80b1ba98259b1" />
    <link rel="stylesheet" type="text/css" href="_static/custom.css" />
    
    


<style>
  body {
    --color-code-background: #FFFFFF;
  --color-code-foreground: #101010;
  
  }
  body[data-theme="dark"] {
    --color-code-background: #101010;
  --color-code-foreground: #F4F0EC;
  
  }
  @media (prefers-color-scheme: dark) {
    body:not([data-theme="light"]) {
      --color-code-background: #101010;
  --color-code-foreground: #F4F0EC;
  
    }
  }
</style>
    <link media="(prefers-color-scheme: dark)" rel="stylesheet" href="_static/pygments_dark.css"></head>
  <body>
    
<svg xmlns="http://www.w3.org/2000/svg" style="display: none;">
  <symbol id="svg-toc" viewBox="0 0 24 24">
    <title>Contents</title>
    <svg xmlns="http://www.w3.org/2000/svg" width="24" height="24" viewBox="0 0 24 24" fill="none" stroke="currentColor"
      stroke-width="1.5" stroke-linecap="round" stroke-linejoin="round">
      <path stroke="none" d="M0 0h24v24H0z" />
      <line x1="4" y1="6" x2="20" y2="6" />
      <line x1="10" y1="12" x2="20" y2="12" />
      <line x1="6" y1="18" x2="20" y2="18" />
    </svg>
  </symbol>
  <symbol id="svg-menu" viewBox="0 0 24 24">
    <title>Menu</title>
    <svg xmlns="http://www.w3.org/2000/svg" width="24" height="24" viewBox="0 0 24 24" fill="none" stroke="currentColor"
      stroke-width="2" stroke-linecap="round" stroke-linejoin="round" class="feather-menu">
      <line x1="3" y1="12" x2="21" y2="12"></line>
      <line x1="3" y1="6" x2="21" y2="6"></line>
      <line x1="3" y1="18" x2="21" y2="18"></line>
    </svg>
  </symbol>
  <symbol id="svg-arrow-right" viewBox="0 0 24 24">
    <title>Expand</title>
    <svg xmlns="http://www.w3.org/2000/svg" width="24" height="24" viewBox="0 0 24 24" fill="none" stroke="currentColor"
      stroke-width="2" stroke-linecap="round" stroke-linejoin="round" class="feather-chevron-right">
      <polyline points="9 18 15 12 9 6"></polyline>
    </svg>
  </symbol>
  <symbol id="svg-sun" viewBox="0 0 24 24">
    <title>Light mode</title>
    <svg xmlns="http://www.w3.org/2000/svg" width="24" height="24" viewBox="0 0 24 24" fill="none" stroke="currentColor"
      stroke-width="1.5" stroke-linecap="round" stroke-linejoin="round" class="feather-sun">
      <circle cx="12" cy="12" r="5"></circle>
      <line x1="12" y1="1" x2="12" y2="3"></line>
      <line x1="12" y1="21" x2="12" y2="23"></line>
      <line x1="4.22" y1="4.22" x2="5.64" y2="5.64"></line>
      <line x1="18.36" y1="18.36" x2="19.78" y2="19.78"></line>
      <line x1="1" y1="12" x2="3" y2="12"></line>
      <line x1="21" y1="12" x2="23" y2="12"></line>
      <line x1="4.22" y1="19.78" x2="5.64" y2="18.36"></line>
      <line x1="18.36" y1="5.64" x2="19.78" y2="4.22"></line>
    </svg>
  </symbol>
  <symbol id="svg-moon" viewBox="0 0 24 24">
    <title>Dark mode</title>
    <svg xmlns="http://www.w3.org/2000/svg" width="24" height="24" viewBox="0 0 24 24" fill="none" stroke="currentColor"
      stroke-width="1.5" stroke-linecap="round" stroke-linejoin="round" class="icon-tabler-moon">
      <path stroke="none" d="M0 0h24v24H0z" fill="none" />
      <path d="M12 3c.132 0 .263 0 .393 0a7.5 7.5 0 0 0 7.92 12.446a9 9 0 1 1 -8.313 -12.454z" />
    </svg>
  </symbol>
  <symbol id="svg-sun-half" viewBox="0 0 24 24">
    <title>Auto light/dark mode</title>
    <svg xmlns="http://www.w3.org/2000/svg" width="24" height="24" viewBox="0 0 24 24" fill="none" stroke="currentColor"
      stroke-width="1.5" stroke-linecap="round" stroke-linejoin="round" class="icon-tabler-shadow">
      <path stroke="none" d="M0 0h24v24H0z" fill="none"/>
      <circle cx="12" cy="12" r="9" />
      <path d="M13 12h5" />
      <path d="M13 15h4" />
      <path d="M13 18h1" />
      <path d="M13 9h4" />
      <path d="M13 6h1" />
    </svg>
  </symbol>
</svg>

<input type="checkbox" class="sidebar-toggle" name="__navigation" id="__navigation">
<input type="checkbox" class="sidebar-toggle" name="__toc" id="__toc">
<label class="overlay sidebar-overlay" for="__navigation">
  <div class="visually-hidden">Hide navigation sidebar</div>
</label>
<label class="overlay toc-overlay" for="__toc">
  <div class="visually-hidden">Hide table of contents sidebar</div>
</label>



<div class="page">
  <header class="mobile-header">
    <div class="header-left">
      <label class="nav-overlay-icon" for="__navigation">
        <div class="visually-hidden">Toggle site navigation sidebar</div>
        <i class="icon"><svg><use href="#svg-menu"></use></svg></i>
      </label>
    </div>
    <div class="header-center">
      <a href="index.html"><div class="brand">friendly-traceback 0.4.78</div></a>
    </div>
    <div class="header-right">
      <div class="theme-toggle-container theme-toggle-header">
        <button class="theme-toggle">
          <div class="visually-hidden">Toggle Light / Dark / Auto color theme</div>
          <svg class="theme-icon-when-auto"><use href="#svg-sun-half"></use></svg>
          <svg class="theme-icon-when-dark"><use href="#svg-moon"></use></svg>
          <svg class="theme-icon-when-light"><use href="#svg-sun"></use></svg>
        </button>
      </div>
      <label class="toc-overlay-icon toc-header-icon" for="__toc">
        <div class="visually-hidden">Toggle table of contents sidebar</div>
        <i class="icon"><svg><use href="#svg-toc"></use></svg></i>
      </label>
    </div>
  </header>
  <aside class="sidebar-drawer">
    <div class="sidebar-container">
      
      <div class="sidebar-sticky"><a class="sidebar-brand centered" href="index.html">
  
  <div class="sidebar-logo-container">
    <img class="sidebar-logo" src="_static/friendly_logo.png" alt="Logo"/>
  </div>
  
  <span class="sidebar-brand-text">friendly-traceback 0.4.78</span>
  
</a><form class="sidebar-search-container" method="get" action="search.html" role="search">
  <input class="sidebar-search" placeholder=Search name="q" aria-label="Search">
  <input type="hidden" name="check_keywords" value="yes">
  <input type="hidden" name="area" value="default">
</form>
<div id="searchbox"></div><div class="sidebar-scroll"><div class="sidebar-tree">
  <p class="caption" role="heading"><span class="caption-text">Begin here</span></p>
<ul>
<li class="toctree-l1"><a class="reference internal" href="beginner.html">Useful information for beginners</a></li>
<li class="toctree-l1"><a class="reference internal" href="install.html">Getting Friendly</a></li>
<li class="toctree-l1"><a class="reference internal" href="usage.html">Basic usage</a></li>
<li class="toctree-l1"><a class="reference internal" href="usage_adv.html">Other details for advanced users</a></li>
</ul>
<p class="caption" role="heading"><span class="caption-text">friendly console</span></p>
<ul>
<li class="toctree-l1"><a class="reference internal" href="repl.html">Console basics</a></li>
<li class="toctree-l1"><a class="reference internal" href="why.html">why()</a></li>
<li class="toctree-l1"><a class="reference internal" href="what.html">what()</a></li>
<li class="toctree-l1"><a class="reference internal" href="where.html">where()</a></li>
<li class="toctree-l1"><a class="reference internal" href="explain.html">explain()</a></li>
<li class="toctree-l1"><a class="reference internal" href="www.html">www()</a></li>
<li class="toctree-l1"><a class="reference internal" href="history.html">history() and back()</a></li>
<li class="toctree-l1"><a class="reference internal" href="friendly_object.html">Friendly object</a></li>
<li class="toctree-l1"><a class="reference internal" href="repl_api.html">Everything about the friendly console</a></li>
<li class="toctree-l1"><a class="reference internal" href="about_warnings.html">One last thing</a></li>
</ul>
<p class="caption" role="heading"><span class="caption-text">Why import *?</span></p>
<ul>
<li class="toctree-l1"><a class="reference internal" href="import_all.html">Why <code class="docutils literal notranslate"><span class="pre">import</span> <span class="pre">*</span></code>?</a></li>
</ul>
<p class="caption" role="heading"><span class="caption-text">IDLE</span></p>
<ul>
<li class="toctree-l1"><a class="reference internal" href="idle.html">About IDLE</a></li>
<li class="toctree-l1"><a class="reference internal" href="idle_repl.html">IDLE’s shell</a></li>
<li class="toctree-l1"><a class="reference internal" href="idle_run.html">IDLE: using the editor</a></li>
</ul>
<p class="caption" role="heading"><span class="caption-text">Mu</span></p>
<ul>
<li class="toctree-l1"><a class="reference internal" href="mu_about.html">About Mu</a></li>
<li class="toctree-l1"><a class="reference internal" href="mu_install.html">Using with Mu: installation</a></li>
<li class="toctree-l1"><a class="reference internal" href="mu_repl.html">Mu’s REPL</a></li>
<li class="toctree-l1"><a class="reference internal" href="mu_run.html">Mu: executing a program</a></li>
</ul>
<p class="caption" role="heading"><span class="caption-text">Other consoles</span></p>
<ul>
<li class="toctree-l1"><a class="reference internal" href="pyrepl.html">Using another REPL</a></li>
<li class="toctree-l1"><a class="reference internal" href="vs_code_repl.html">Visual Studio Code’s terminal</a></li>
<li class="toctree-l1"><a class="reference internal" href="ipython_repl.html">IPython’s console</a></li>
<li class="toctree-l1"><a class="reference internal" href="other_repl.html">Other repl</a></li>
</ul>
<p class="caption" role="heading"><span class="caption-text">Editors and Notebooks</span></p>
<ul>
<li class="toctree-l1"><a class="reference internal" href="install_thonny.html">Information for Thonny</a></li>
<li class="toctree-l1"><a class="reference internal" href="editor.html">Using with an editor or IDE</a></li>
<li class="toctree-l1"><a class="reference internal" href="jupyter.html">Jupyter notebooks and JupyterLab</a></li>
<li class="toctree-l1"><a class="reference internal" href="vs_code.html">Visual Studio Code</a></li>
<li class="toctree-l1"><a class="reference internal" href="colab.html">Google’s colab</a></li>
</ul>
<p class="caption" role="heading"><span class="caption-text">Thoughts on design</span></p>
<ul>
<li class="toctree-l1"><a class="reference internal" href="design.html">Some thoughts on the design of friendly</a></li>
<li class="toctree-l1"><a class="reference internal" href="themes.html">Themes, Styles, and Colours</a></li>
<li class="toctree-l1"><a class="reference internal" href="multiple_tracebacks.html">Multiple tracebacks</a></li>
<li class="toctree-l1"><a class="reference internal" href="friendly_tb.html">friendly tracebacks</a></li>
<li class="toctree-l1"><a class="reference internal" href="ipython_tb.html">IPython tracebacks</a></li>
<li class="toctree-l1"><a class="reference internal" href="jupyter_tb.html">IPython tracebacks</a></li>
<li class="toctree-l1"><a class="reference internal" href="numbered_prompt.html">Numbered prompt</a></li>
<li class="toctree-l1"><a class="reference internal" href="idle_colours.html">IDLE’s colours</a></li>
</ul>
<p class="caption" role="heading"><span class="caption-text">Use in your project</span></p>
<ul>
<li class="toctree-l1"><a class="reference internal" href="api.html">Public API</a></li>
<li class="toctree-l1"><a class="reference internal" href="formatter.html">Custom formatter</a></li>
<li class="toctree-l1"><a class="reference internal" href="custom_errors.html">Registering custom error types</a></li>
<li class="toctree-l1"><a class="reference internal" href="plugins.html">Editor plugins</a></li>
</ul>
<p class="caption" role="heading"><span class="caption-text">Contribute</span></p>
<ul>
<li class="toctree-l1"><a class="reference internal" href="suggest.html">Suggest an addition</a></li>
<li class="toctree-l1"><a class="reference internal" href="translation_notes.html">Notes on translations - using gettext</a></li>
</ul>
<p class="caption" role="heading"><span class="caption-text">All the tracebacks!</span></p>
<ul class="current">
<li class="toctree-l1"><a class="reference internal" href="known.html">Generic information about various exceptions</a></li>
<li class="toctree-l1"><a class="reference internal" href="tracebacks_en_3.6.html">friendly tracebacks - Python 3.6 in English</a></li>
<li class="toctree-l1"><a class="reference internal" href="syntax_tracebacks_en_3.6.html">SyntaxError - Python 3.6 in English</a></li>
<li class="toctree-l1"><a class="reference internal" href="tracebacks_en_3.7.html">friendly tracebacks - Python 3.7 in English</a></li>
<li class="toctree-l1"><a class="reference internal" href="syntax_tracebacks_en_3.7.html">SyntaxError - Python 3.7 in English</a></li>
<li class="toctree-l1"><a class="reference internal" href="tracebacks_en_3.8.html">friendly tracebacks - Python 3.8 in English</a></li>
<li class="toctree-l1"><a class="reference internal" href="syntax_tracebacks_en_3.8.html">SyntaxError - Python 3.8 in English</a></li>
<li class="toctree-l1"><a class="reference internal" href="tracebacks_en_3.9.html">friendly tracebacks - Python 3.9 in English</a></li>
<li class="toctree-l1"><a class="reference internal" href="syntax_tracebacks_en_3.9.html">SyntaxError - Python 3.9 in English</a></li>
<li class="toctree-l1"><a class="reference internal" href="tracebacks_en_3.10.html">friendly tracebacks - Python 3.10 in English</a></li>
<li class="toctree-l1"><a class="reference internal" href="syntax_tracebacks_en_3.10.html">SyntaxError - Python 3.10 in English</a></li>
<li class="toctree-l1 current current-page"><a class="current reference internal" href="#">friendly tracebacks - Python 3.11 in English</a></li>
<li class="toctree-l1"><a class="reference internal" href="syntax_tracebacks_en_3.11.html">SyntaxError - Python 3.11 in English</a></li>
<li class="toctree-l1"><a class="reference internal" href="compare_exceptions.html">Comparing Exception messages between Python versions</a></li>
<li class="toctree-l1"><a class="reference internal" href="compare.html">Comparison between Python versions: SyntaxErrors</a></li>
</ul>
<p class="caption" role="heading"><span class="caption-text">En español</span></p>
<ul>
<li class="toctree-l1"><a class="reference internal" href="tracebacks_es.html">Friendly tracebacks - en español</a></li>
<li class="toctree-l1"><a class="reference internal" href="syntax_tracebacks_es.html">Friendly SyntaxError tracebacks - en español</a></li>
</ul>
<p class="caption" role="heading"><span class="caption-text">En français</span></p>
<ul>
<li class="toctree-l1"><a class="reference internal" href="tracebacks_fr.html"> Friendly tracebacks - en Français</a></li>
<li class="toctree-l1"><a class="reference internal" href="syntax_tracebacks_fr.html"> Friendly SyntaxError tracebacks - en Français</a></li>
</ul>

</div>
</div>
      </div>
      
    </div>
  </aside>
  <div class="main">
    <div class="content">
      <article role="main">
        <div class="content-icon-container">
          <div class="theme-toggle-container theme-toggle-content">
            <button class="theme-toggle">
              <div class="visually-hidden">Toggle Light / Dark / Auto color theme</div>
              <svg class="theme-icon-when-auto"><use href="#svg-sun-half"></use></svg>
              <svg class="theme-icon-when-dark"><use href="#svg-moon"></use></svg>
              <svg class="theme-icon-when-light"><use href="#svg-sun"></use></svg>
            </button>
          </div>
          <label class="toc-overlay-icon toc-content-icon" for="__toc">
            <div class="visually-hidden">Toggle table of contents sidebar</div>
            <i class="icon"><svg><use href="#svg-toc"></use></svg></i>
          </label>
        </div>
        <div class="section" id="friendly-tracebacks-in-english">
<h1>Friendly tracebacks - in English<a class="headerlink" href="#friendly-tracebacks-in-english" title="Permalink to this headline">¶</a></h1>
<p>Friendly aims to provide friendlier feedback when an exception
is raised than what is done by Python.
Below, we can find some examples. SyntaxError cases, as well as TabError and
IndentationError cases, are shown in a separate page.
Not all cases handled by friendly are included here.</p>
<div class="admonition note">
<p class="admonition-title">Note</p>
<p>The content of this page is generated by running
<cite>trb_english.py</cite> located in the <code class="docutils literal notranslate"><span class="pre">tests/</span></code> directory.
This needs to be done explicitly, independently of updating the
documentation using Sphinx.</p>
</div>
<p>Friendly-traceback version: 0.4.78
Python version: 3.11.0a2</p>
<div class="section" id="arithmeticerror">
<h2>ArithmeticError<a class="headerlink" href="#arithmeticerror" title="Permalink to this headline">¶</a></h2>
<div class="section" id="generic">
<h3>Generic<a class="headerlink" href="#generic" title="Permalink to this headline">¶</a></h3>
<div class="highlight-none notranslate"><div class="highlight"><pre><span></span>Traceback (most recent call last):
  File "TESTS:\runtime\test_arithmetic_error.py", line 9, in test_Generic
    raise ArithmeticError('error')
ArithmeticError: error

`ArithmeticError` is the base class for those built-in exceptions
that are raised for various arithmetic errors.
It is unusual that you are seeing this exception;
normally, a more specific exception should have been raised.

Exception raised on line 9 of file TESTS:\runtime\test_arithmetic_error.py.

    4: def test_Generic():
    5:     try:
    6:         # I am not aware of any way in which this error is raised directly
    7:         # Usually, a subclass such as ZeroDivisionError, etc., would
    8:         # likely be raised.
--&gt; 9:         raise ArithmeticError('error')
   10:     except ArithmeticError as e:

        ArithmeticError:  &lt;class ArithmeticError&gt;
</pre></div>
</div>
</div>
</div>
<div class="section" id="assertionerror">
<h2>AssertionError<a class="headerlink" href="#assertionerror" title="Permalink to this headline">¶</a></h2>
<div class="section" id="id1">
<h3>Generic<a class="headerlink" href="#id1" title="Permalink to this headline">¶</a></h3>
<div class="highlight-none notranslate"><div class="highlight"><pre><span></span>Traceback (most recent call last):
  File "TESTS:\runtime\test_assertion_error.py", line 8, in test_Generic
    raise AssertionError("Fake message")
AssertionError: Fake message

In Python, the keyword `assert` is used in statements of the form
`assert condition`, to confirm that `condition` is not `False`,
nor equivalent to `False` such as an empty list, etc.

If `condition` is `False` or equivalent, an `AssertionError` is raised.

Exception raised on line 8 of file TESTS:\runtime\test_assertion_error.py.

   4: def test_Generic():
   5:     try:
   6:         # We raise it explicitly, rather than with the keyword assert, since
   7:         # we don't want pytest to rewrite out test.
--&gt;8:         raise AssertionError("Fake message")
   9:     except AssertionError as e:

        AssertionError:  &lt;class AssertionError&gt;
</pre></div>
</div>
</div>
</div>
<div class="section" id="attributeerror">
<h2>AttributeError<a class="headerlink" href="#attributeerror" title="Permalink to this headline">¶</a></h2>
<div class="section" id="attribute-from-other-module">
<h3>Attribute from other module<a class="headerlink" href="#attribute-from-other-module" title="Permalink to this headline">¶</a></h3>
<div class="highlight-none notranslate"><div class="highlight"><pre><span></span>Traceback (most recent call last):
  File "TESTS:\runtime\test_attribute_error.py", line 323, in test_Attribute_from_other_module
    keyword.pi
AttributeError: module 'keyword' has no attribute 'pi'

    Did you mean one of the following modules: `math, cmath`?
An `AttributeError` occurs when the code contains something like
    `object.x`
and `x` is not a method or attribute (variable) belonging to `object`.

Instead of the module `keyword`, perhaps you wanted to use
the attribute `pi` of one of the following modules:
`math, cmath`.

Exception raised on line 323 of file TESTS:\runtime\test_attribute_error.py.

   319:         assert "Did you mean `math`?" in result
   321:     import cmath
   322:     try:
--&gt;323:         keyword.pi
   324:     except AttributeError as e:

        keyword:  &lt;module keyword&gt; from PYTHON_LIB:\keyword.py
</pre></div>
</div>
</div>
<div class="section" id="builtin-function">
<h3>Builtin function<a class="headerlink" href="#builtin-function" title="Permalink to this headline">¶</a></h3>
<div class="highlight-none notranslate"><div class="highlight"><pre><span></span>Traceback (most recent call last):
  File "TESTS:\runtime\test_attribute_error.py", line 221, in test_Builtin_function
    len.text
AttributeError: 'builtin_function_or_method' object has no attribute 'text'

    Did you mean `len(text)`?

An `AttributeError` occurs when the code contains something like
    `object.x`
and `x` is not a method or attribute (variable) belonging to `object`.

`len` is a function. Perhaps you meant to write
`len(text)`

Exception raised on line 221 of file TESTS:\runtime\test_attribute_error.py.

   218: def test_Builtin_function():
   219:     text = 'Hello world!'
   220:     try:
--&gt;221:         len.text
   222:     except AttributeError as e:

        text:  'Hello world!'
        len:  &lt;builtin function len&gt;
</pre></div>
</div>
</div>
<div class="section" id="builtin-module-with-no-file">
<h3>Builtin module with no file<a class="headerlink" href="#builtin-module-with-no-file" title="Permalink to this headline">¶</a></h3>
<div class="highlight-none notranslate"><div class="highlight"><pre><span></span>Traceback (most recent call last):
  File "TESTS:\runtime\test_attribute_error.py", line 238, in test_Builtin_module_with_no_file
    sys.foo
AttributeError: module 'sys' has no attribute 'foo'

An `AttributeError` occurs when the code contains something like
    `object.x`
and `x` is not a method or attribute (variable) belonging to `object`.

Python tells us that no object with name `foo` is
found in module `sys`.

Exception raised on line 238 of file TESTS:\runtime\test_attribute_error.py.

   234:     """Issue 116"""
   235:     import sys
   237:     try:
--&gt;238:         sys.foo
   239:     except AttributeError as e:

        sys:  &lt;module sys (builtin)&gt;
</pre></div>
</div>
</div>
<div class="section" id="circular-import">
<h3>Circular import<a class="headerlink" href="#circular-import" title="Permalink to this headline">¶</a></h3>
<div class="highlight-none notranslate"><div class="highlight"><pre><span></span>Traceback (most recent call last):
  File "TESTS:\runtime\test_attribute_error.py", line 353, in test_Circular_import
    import my_turtle1
  File "TESTS:\my_turtle1.py", line 4, in &lt;module&gt;
    a = my_turtle1.something
AttributeError: partially initialized module 'my_turtle1' has no attribute 'something' (most likely due to a circular import)

    Did you give your program the same name as a Python module?

An `AttributeError` occurs when the code contains something like
    `object.x`
and `x` is not a method or attribute (variable) belonging to `object`.

I suspect that you used the name `my_turtle1.py` for your program
and that you also wanted to import a module with the same name
from Python's standard library.
If so, you should use a different name for your program.

Execution stopped on line 353 of file TESTS:\runtime\test_attribute_error.py.

   350:     from friendly_traceback.runtime_errors import stdlib_modules
   351:     stdlib_modules.names.append("my_turtle1")
   352:     try:
--&gt;353:        import my_turtle1
   354:     except AttributeError as e:

Exception raised on line 4 of file TESTS:\my_turtle1.py.

   1: """To test attribute error of partially initialized module."""
   2: import my_turtle1
--&gt;4: a = my_turtle1.something
          ^^^^^^^^^^^^^^^^^^^^

        my_turtle1:  &lt;module my_turtle1&gt; from TESTS:\my_turtle1.py
</pre></div>
</div>
</div>
<div class="section" id="circular-import-b">
<h3>Circular import b<a class="headerlink" href="#circular-import-b" title="Permalink to this headline">¶</a></h3>
<div class="highlight-none notranslate"><div class="highlight"><pre><span></span>Traceback (most recent call last):
  File "TESTS:\runtime\test_attribute_error.py", line 370, in test_Circular_import_b
    import circular_c
  File "TESTS:\circular_c.py", line 4, in &lt;module&gt;
    a = circular_c.something
AttributeError: partially initialized module 'circular_c' has no attribute 'something' (most likely due to a circular import)

    You have a circular import.

An `AttributeError` occurs when the code contains something like
    `object.x`
and `x` is not a method or attribute (variable) belonging to `object`.

Python indicated that the module `{module}` was not fully imported.
This can occur if, during the execution of the code in module `circular_c`
an attempt is made to import the same module again.

Execution stopped on line 370 of file TESTS:\runtime\test_attribute_error.py.

   368: def test_Circular_import_b():
   369:     try:
--&gt;370:         import circular_c
   371:     except AttributeError as e:

Exception raised on line 4 of file TESTS:\circular_c.py.

   1: # Attribute error for partially initialize module
   2: import circular_c
--&gt;4: a = circular_c.something
          ^^^^^^^^^^^^^^^^^^^^

        circular_c:  &lt;module circular_c&gt; from TESTS:\circular_c.py
</pre></div>
</div>
</div>
<div class="section" id="id2">
<h3>Generic<a class="headerlink" href="#id2" title="Permalink to this headline">¶</a></h3>
<div class="highlight-none notranslate"><div class="highlight"><pre><span></span>Traceback (most recent call last):
  File "TESTS:\runtime\test_attribute_error.py", line 24, in test_Generic
    A.x  # testing type
AttributeError: type object 'A' has no attribute 'x'

An `AttributeError` occurs when the code contains something like
    `object.x`
and `x` is not a method or attribute (variable) belonging to `object`.

The object `A` has no attribute named `x`.

Exception raised on line 24 of file TESTS:\runtime\test_attribute_error.py.

   20:     class A:
   21:         pass
   23:     try:
--&gt;24:         A.x  # testing type
   25:     except AttributeError as e:

        A:  &lt;class A&gt; defined in &lt;function test_attribute_error.test_Generic&gt;
</pre></div>
</div>
</div>
<div class="section" id="generic-different-frame">
<h3>Generic different frame<a class="headerlink" href="#generic-different-frame" title="Permalink to this headline">¶</a></h3>
<div class="highlight-none notranslate"><div class="highlight"><pre><span></span>Traceback (most recent call last):
  File "TESTS:\runtime\test_attribute_error.py", line 47, in test_Generic_different_frame
    a.attr
AttributeError: 'A' object has no attribute 'attr'

    Did you mean `attr2`?

An `AttributeError` occurs when the code contains something like
    `object.x`
and `x` is not a method or attribute (variable) belonging to `object`.

The object `a` has no attribute named `attr`.
Perhaps you meant to write `a.attr2` instead of `a.attr`

Exception raised on line 47 of file TESTS:\runtime\test_attribute_error.py.

   43:         return A()
   45:     a = f()
   46:     try:
--&gt;47:         a.attr
   48:     except AttributeError as e:

        a:  &lt;A object&gt;
            defined in &lt;function test_attribute_error.test_Generic_different_frame.&lt;locals&gt;.f&gt;
</pre></div>
</div>
</div>
<div class="section" id="generic-instance">
<h3>Generic instance<a class="headerlink" href="#generic-instance" title="Permalink to this headline">¶</a></h3>
<div class="highlight-none notranslate"><div class="highlight"><pre><span></span>Traceback (most recent call last):
  File "TESTS:\runtime\test_attribute_error.py", line 65, in test_Generic_instance
    a.x
AttributeError: 'A' object has no attribute 'x'

An `AttributeError` occurs when the code contains something like
    `object.x`
and `x` is not a method or attribute (variable) belonging to `object`.

The object `a` has no attribute named `x`.

Exception raised on line 65 of file TESTS:\runtime\test_attribute_error.py.

   62:         pass
   63:     a = A()
   64:     try:
--&gt;65:         a.x
   66:     except AttributeError as e:

        a:  &lt;A object&gt;
            defined in &lt;function test_attribute_error.test_Generic_instance&gt;
</pre></div>
</div>
</div>
<div class="section" id="module-attribute-typo">
<h3>Module attribute typo<a class="headerlink" href="#module-attribute-typo" title="Permalink to this headline">¶</a></h3>
<div class="highlight-none notranslate"><div class="highlight"><pre><span></span>Traceback (most recent call last):
  File "TESTS:\runtime\test_attribute_error.py", line 142, in test_Module_attribute_typo
    math.cost
AttributeError: module 'math' has no attribute 'cost'

    Did you mean `cos`?

An `AttributeError` occurs when the code contains something like
    `object.x`
and `x` is not a method or attribute (variable) belonging to `object`.

Instead of writing `math.cost`, perhaps you meant to write one of
the following names which are attributes of module `math`:
`cos, cosh, acos`

Exception raised on line 142 of file TESTS:\runtime\test_attribute_error.py.

   137:         assert "Did you mean `ascii_lowercase`" in result
   139:     import math
   141:     try:
--&gt;142:         math.cost
   143:     except AttributeError as e:

        math:  &lt;module math (builtin)&gt;
</pre></div>
</div>
</div>
<div class="section" id="nonetype">
<h3>Nonetype<a class="headerlink" href="#nonetype" title="Permalink to this headline">¶</a></h3>
<div class="highlight-none notranslate"><div class="highlight"><pre><span></span>Traceback (most recent call last):
  File "TESTS:\runtime\test_attribute_error.py", line 181, in test_Nonetype
    a.b
AttributeError: 'NoneType' object has no attribute 'b'

An `AttributeError` occurs when the code contains something like
    `object.x`
and `x` is not a method or attribute (variable) belonging to `object`.

You are attempting to access the attribute `b`
for a variable whose value is `None`.
Exception raised on line 181 of file TESTS:\runtime\test_attribute_error.py.

   178: def test_Nonetype():
   179:     a = None
   180:     try:
--&gt;181:         a.b
   182:     except AttributeError as e:

        a:  None
</pre></div>
</div>
</div>
<div class="section" id="object-attribute-typo">
<h3>Object attribute typo<a class="headerlink" href="#object-attribute-typo" title="Permalink to this headline">¶</a></h3>
<div class="highlight-none notranslate"><div class="highlight"><pre><span></span>Traceback (most recent call last):
  File "TESTS:\runtime\test_attribute_error.py", line 81, in test_Object_attribute_typo
    a.appendh(4)
AttributeError: 'list' object has no attribute 'appendh'

    Did you mean `append`?

An `AttributeError` occurs when the code contains something like
    `object.x`
and `x` is not a method or attribute (variable) belonging to `object`.

The object `a` has no attribute named `appendh`.
Perhaps you meant to write `a.append` instead of `a.appendh`

Exception raised on line 81 of file TESTS:\runtime\test_attribute_error.py.

   77: def test_Object_attribute_typo():
   78:     #
   79:     try:
   80:         a = [1, 2, 3]
--&gt;81:         a.appendh(4)
               ^^^^^^^^^
   82:     except AttributeError as e:

        a:  [1, 2, 3]
</pre></div>
</div>
</div>
<div class="section" id="perhaps-comma">
<h3>Perhaps comma<a class="headerlink" href="#perhaps-comma" title="Permalink to this headline">¶</a></h3>
<div class="highlight-none notranslate"><div class="highlight"><pre><span></span>Skipped test
</pre></div>
</div>
</div>
<div class="section" id="read-only">
<h3>Read only<a class="headerlink" href="#read-only" title="Permalink to this headline">¶</a></h3>
<div class="highlight-none notranslate"><div class="highlight"><pre><span></span>Traceback (most recent call last):
  File "TESTS:\runtime\test_attribute_error.py", line 278, in test_Read_only
    f.b = 1
AttributeError: 'F' object attribute 'b' is read-only

An `AttributeError` occurs when the code contains something like
    `object.x`
and `x` is not a method or attribute (variable) belonging to `object`.

Object `f` uses `__slots__` to specify which attributes can
be changed. The value of attribute `f.b` cannot be changed.
The only attribute of `f` whose value can be changed is`a`.

Exception raised on line 278 of file TESTS:\runtime\test_attribute_error.py.

   274:         b = 2
   276:     f = F()
   277:     try:
--&gt;278:         f.b = 1
   279:     except AttributeError as e:

        f:  &lt;F object&gt;
            defined in &lt;function test_attribute_error.test_Read_only&gt;
        f.b:  2
</pre></div>
</div>
</div>
<div class="section" id="shadow-stdlib-module">
<h3>Shadow stdlib module<a class="headerlink" href="#shadow-stdlib-module" title="Permalink to this headline">¶</a></h3>
<div class="highlight-none notranslate"><div class="highlight"><pre><span></span>Traceback (most recent call last):
  File "TESTS:\runtime\test_attribute_error.py", line 163, in test_Shadow_stdlib_module
    turtle.Pen
AttributeError: module 'turtle' has no attribute 'Pen'

    Did you give your program the same name as a Python module?

An `AttributeError` occurs when the code contains something like
    `object.x`
and `x` is not a method or attribute (variable) belonging to `object`.

You imported a module named `turtle` from `TESTS:\turtle.py`.
There is also a module named `turtle` in Python's standard library.
Perhaps you need to rename your module.

Exception raised on line 163 of file TESTS:\runtime\test_attribute_error.py.

   159: def test_Shadow_stdlib_module():
   160:     import turtle
   162:     try:
--&gt;163:         turtle.Pen
   164:     except AttributeError as e:

        turtle:  &lt;module turtle&gt; from TESTS:\turtle.py
</pre></div>
</div>
</div>
<div class="section" id="tuple-by-accident">
<h3>Tuple by accident<a class="headerlink" href="#tuple-by-accident" title="Permalink to this headline">¶</a></h3>
<div class="highlight-none notranslate"><div class="highlight"><pre><span></span>Traceback (most recent call last):
  File "TESTS:\runtime\test_attribute_error.py", line 293, in test_Tuple_by_accident
    something.upper()
AttributeError: 'tuple' object has no attribute 'upper'

    Did you write a comma by mistake?

An `AttributeError` occurs when the code contains something like
    `object.x`
and `x` is not a method or attribute (variable) belonging to `object`.

`something` is a tuple that contains a single item
which does have `'upper'` as an attribute.
Perhaps you added a trailing comma by mistake at the end of the line
where you defined `something`.

Exception raised on line 293 of file TESTS:\runtime\test_attribute_error.py.

   290: def test_Tuple_by_accident():
   291:     something = "abc",  # note trailing comma
   292:     try:
--&gt;293:         something.upper()
                ^^^^^^^^^^^^^^^
   294:     except AttributeError as e:

        something:  ('abc',)
</pre></div>
</div>
</div>
<div class="section" id="use-builtin">
<h3>Use builtin<a class="headerlink" href="#use-builtin" title="Permalink to this headline">¶</a></h3>
<div class="highlight-none notranslate"><div class="highlight"><pre><span></span>Traceback (most recent call last):
  File "TESTS:\runtime\test_attribute_error.py", line 97, in test_Use_builtin
    a.length()
AttributeError: 'list' object has no attribute 'length'

    Did you mean `len(a)`?

An `AttributeError` occurs when the code contains something like
    `object.x`
and `x` is not a method or attribute (variable) belonging to `object`.

The object `a` has no attribute named `length`.
Perhaps you can use the Python builtin function `len` instead:
`len(a)`.
Exception raised on line 97 of file TESTS:\runtime\test_attribute_error.py.

   93: def test_Use_builtin():
   94:     #
   95:     try:
   96:         a = [1, 2, 3]
--&gt;97:         a.length()
               ^^^^^^^^
   98:     except AttributeError as e:

        a:  [1, 2, 3]
</pre></div>
</div>
</div>
<div class="section" id="use-join-with-str">
<h3>Use join with str<a class="headerlink" href="#use-join-with-str" title="Permalink to this headline">¶</a></h3>
<div class="highlight-none notranslate"><div class="highlight"><pre><span></span>Traceback (most recent call last):
  File "TESTS:\runtime\test_attribute_error.py", line 337, in test_Use_join_with_str
    a = ['a', '2'].join('abc') + ['b', '3'].join('\n')
AttributeError: 'list' object has no attribute 'join'

    Did you mean `'abc'.join(['a', '2'])`?

An `AttributeError` occurs when the code contains something like
    `object.x`
and `x` is not a method or attribute (variable) belonging to `object`.

The object `['a', '2']` has no attribute named `join`.
Perhaps you wanted something like `'abc'.join(['a', '2'])`.

Exception raised on line 337 of file TESTS:\runtime\test_attribute_error.py.

   335: def test_Use_join_with_str():
   336:     try:
--&gt;337:         a = ['a', '2'].join('abc') + ['b', '3'].join('\n')
                    ^^^^^^^^^^^^^^^
   338:     except AttributeError as e:
</pre></div>
</div>
</div>
<div class="section" id="use-synonym">
<h3>Use synonym<a class="headerlink" href="#use-synonym" title="Permalink to this headline">¶</a></h3>
<div class="highlight-none notranslate"><div class="highlight"><pre><span></span>Traceback (most recent call last):
  File "TESTS:\runtime\test_attribute_error.py", line 113, in test_Use_synonym
    a.add(4)
AttributeError: 'list' object has no attribute 'add'

    Did you mean `append`?

An `AttributeError` occurs when the code contains something like
    `object.x`
and `x` is not a method or attribute (variable) belonging to `object`.

The object `a` has no attribute named `add`.
However, `a` has the following attributes with similar meanings:
`append, extend, insert`.

Exception raised on line 113 of file TESTS:\runtime\test_attribute_error.py.

   109: def test_Use_synonym():
   110:     #
   111:     try:
   112:         a = [1, 2, 3]
--&gt;113:         a.add(4)
                ^^^^^
   114:     except AttributeError as e:

        a:  [1, 2, 3]
</pre></div>
</div>
</div>
<div class="section" id="using-slots">
<h3>Using slots<a class="headerlink" href="#using-slots" title="Permalink to this headline">¶</a></h3>
<div class="highlight-none notranslate"><div class="highlight"><pre><span></span>Traceback (most recent call last):
  File "TESTS:\runtime\test_attribute_error.py", line 258, in test_Using_slots
    f.b = 1
AttributeError: 'F' object has no attribute 'b'

An `AttributeError` occurs when the code contains something like
    `object.x`
and `x` is not a method or attribute (variable) belonging to `object`.

The object `f` has no attribute named `b`.
Note that object `f` uses `__slots__` which prevents
the creation of new attributes.
The following are some of its known attributes:
`a`.
Exception raised on line 258 of file TESTS:\runtime\test_attribute_error.py.

   254:         __slots__ = ["a"]
   256:     f = F()
   257:     try:
--&gt;258:         f.b = 1
   259:     except AttributeError as e:

        f:  &lt;F object&gt;
            defined in &lt;function test_attribute_error.test_Using_slots&gt;
</pre></div>
</div>
</div>
</div>
<div class="section" id="filenotfounderror">
<h2>FileNotFoundError<a class="headerlink" href="#filenotfounderror" title="Permalink to this headline">¶</a></h2>
<div class="section" id="directory-not-found">
<h3>Directory not found<a class="headerlink" href="#directory-not-found" title="Permalink to this headline">¶</a></h3>
<div class="highlight-none notranslate"><div class="highlight"><pre><span></span>Traceback (most recent call last):
  File "TESTS:\runtime\test_file_not_found_error.py", line 70, in test_Directory_not_found
    open("does_not_exist/file.txt")
FileNotFoundError: [Errno 2] No such file or directory: 'does_not_exist/file.txt'

A `FileNotFoundError` exception indicates that you
are trying to open a file that cannot be found by Python.
This could be because you misspelled the name of the file.

In your program, the name of the
file that cannot be found is `file.txt`.
does_not_exist
is not a valid directory.

Exception raised on line 70 of file TESTS:\runtime\test_file_not_found_error.py.

   68: def test_Directory_not_found():
   69:     try:
--&gt;70:         open("does_not_exist/file.txt")
   71:     except FileNotFoundError as e:

        open:  &lt;builtin function open&gt;
</pre></div>
</div>
</div>
<div class="section" id="filename-not-found">
<h3>Filename not found<a class="headerlink" href="#filename-not-found" title="Permalink to this headline">¶</a></h3>
<div class="highlight-none notranslate"><div class="highlight"><pre><span></span>Traceback (most recent call last):
  File "TESTS:\runtime\test_file_not_found_error.py", line 7, in test_Filename_not_found
    open("does_not_exist")
FileNotFoundError: [Errno 2] No such file or directory: 'does_not_exist'

A `FileNotFoundError` exception indicates that you
are trying to open a file that cannot be found by Python.
This could be because you misspelled the name of the file.

In your program, the name of the
file that cannot be found is `does_not_exist`.
It was expected to be found in the
`C:\Users\andre\friendly-traceback\friendly-traceback\tests` directory.
I have no additional information for you.

Exception raised on line 7 of file TESTS:\runtime\test_file_not_found_error.py.

   5: def test_Filename_not_found():
   6:     try:
--&gt;7:         open("does_not_exist")
   8:     except FileNotFoundError as e:

        open:  &lt;builtin function open&gt;
</pre></div>
</div>
</div>
<div class="section" id="filename-not-found-2">
<h3>Filename not found 2<a class="headerlink" href="#filename-not-found-2" title="Permalink to this headline">¶</a></h3>
<div class="highlight-none notranslate"><div class="highlight"><pre><span></span>Traceback (most recent call last):
  File "TESTS:\runtime\test_file_not_found_error.py", line 30, in test_Filename_not_found_2
    open("setupp.py")
FileNotFoundError: [Errno 2] No such file or directory: 'setupp.py'

    Did you mean `setup.py`?

A `FileNotFoundError` exception indicates that you
are trying to open a file that cannot be found by Python.
This could be because you misspelled the name of the file.

In your program, the name of the
file that cannot be found is `setupp.py`.
It was expected to be found in the
`C:\Users\andre\friendly-traceback\friendly-traceback` directory.
The file `setup.py` has a similar name.

Exception raised on line 30 of file TESTS:\runtime\test_file_not_found_error.py.

   26:     if chdir:
   27:         os.chdir("..")
   29:     try:
--&gt;30:         open("setupp.py")
   31:     except FileNotFoundError as e:

        open:  &lt;builtin function open&gt;
</pre></div>
</div>
</div>
<div class="section" id="filename-not-found-3">
<h3>Filename not found 3<a class="headerlink" href="#filename-not-found-3" title="Permalink to this headline">¶</a></h3>
<div class="highlight-none notranslate"><div class="highlight"><pre><span></span>Traceback (most recent call last):
  File "TESTS:\runtime\test_file_not_found_error.py", line 52, in test_Filename_not_found_3
    open("setup.pyg")
FileNotFoundError: [Errno 2] No such file or directory: 'setup.pyg'

    Did you mean `setup.py`?

A `FileNotFoundError` exception indicates that you
are trying to open a file that cannot be found by Python.
This could be because you misspelled the name of the file.

In your program, the name of the
file that cannot be found is `setup.pyg`.
It was expected to be found in the
`C:\Users\andre\friendly-traceback\friendly-traceback` directory.
Perhaps you meant one of the following files with similar names:
`setup.py`, `setup.cfg`

Exception raised on line 52 of file TESTS:\runtime\test_file_not_found_error.py.

   49:     if chdir:
   50:         os.chdir("..")
   51:     try:
--&gt;52:         open("setup.pyg")
   53:     except FileNotFoundError as e:

        open:  &lt;builtin function open&gt;
</pre></div>
</div>
</div>
</div>
<div class="section" id="importerror">
<h2>ImportError<a class="headerlink" href="#importerror" title="Permalink to this headline">¶</a></h2>
<div class="section" id="id3">
<h3>Circular import<a class="headerlink" href="#id3" title="Permalink to this headline">¶</a></h3>
<div class="highlight-none notranslate"><div class="highlight"><pre><span></span>Traceback (most recent call last):
  File "TESTS:\runtime\test_import_error.py", line 58, in test_Circular_import
    import circular_a
  File "TESTS:\circular_a.py", line 2, in &lt;module&gt;
    import circular_b
  File "TESTS:\circular_b.py", line 2, in &lt;module&gt;
    from circular_a import a
ImportError: cannot import name 'a' from partially initialized module 'circular_a' (most likely due to a circular import) (C:\Users\andre\friendly-traceback\friendly-traceback\tests\circular_a.py)

An `ImportError` exception indicates that a certain object could not
be imported from a module or package. Most often, this is
because the name of the object is not spelled correctly.

The object that could not be imported is `a`.
The module or package where it was
expected to be found is `circular_a`.

The problem was likely caused by what is known as a 'circular import'.
First, Python imported and started executing the code in file
   'TESTS:\runtime\test_import_error.py'.
which imports module `circular_a`.
During this process, the code in another file,
   'TESTS:\circular_b.py'
was executed. However in this last file, an attempt was made
to import the original module `circular_a`
a second time, before Python had completed the first import.

Execution stopped on line 58 of file TESTS:\runtime\test_import_error.py.

   56: def test_Circular_import():
   57:     try:
--&gt;58:         import circular_a
   59:     except ImportError as e:

Exception raised on line 2 of file TESTS:\circular_b.py.

   1: """File used in for test_circular_import() in test_import_error.py"""
--&gt;2: from circular_a import a
</pre></div>
</div>
</div>
<div class="section" id="simple-import-error">
<h3>Simple import error<a class="headerlink" href="#simple-import-error" title="Permalink to this headline">¶</a></h3>
<div class="highlight-none notranslate"><div class="highlight"><pre><span></span>Traceback (most recent call last):
  File "TESTS:\runtime\test_import_error.py", line 44, in test_Simple_import_error
    from math import Pi
ImportError: cannot import name 'Pi' from 'math' (unknown location)

    Did you mean `pi`?

An `ImportError` exception indicates that a certain object could not
be imported from a module or package. Most often, this is
because the name of the object is not spelled correctly.

Perhaps you meant to import `pi` (from `math`) instead of `Pi`

Exception raised on line 44 of file TESTS:\runtime\test_import_error.py.

   40:     no_suggestion()
   41:     multiple_import_on_same_line()
   43:     try:
--&gt;44:         from math import Pi
   45:     except ImportError as e:
</pre></div>
</div>
</div>
</div>
<div class="section" id="indexerror">
<h2>IndexError<a class="headerlink" href="#indexerror" title="Permalink to this headline">¶</a></h2>
<div class="section" id="assignment">
<h3>Assignment<a class="headerlink" href="#assignment" title="Permalink to this headline">¶</a></h3>
<div class="highlight-none notranslate"><div class="highlight"><pre><span></span>Traceback (most recent call last):
  File "TESTS:\runtime\test_index_error.py", line 76, in test_Assignment
    a[13] = 1
IndexError: list assignment index out of range

An `IndexError` occurs when you try to get an item from a list,
a tuple, or a similar object (sequence), and use an index which
does not exist; typically, this happens because the index you give
is greater than the length of the sequence.

You have tried to assign a value to index `13` of `a`,
a `list` of length `10`.
The valid index values of `a` are integers ranging from
`-10` to `9`.

Exception raised on line 76 of file TESTS:\runtime\test_index_error.py.

   72:         assert "You have tried to assign a value to index `1` of `b`," in result
   73:         assert "a `list` which contains no item." in result
   75:     try:
--&gt;76:         a[13] = 1
   77:     except IndexError as e:

        a:  [0, 1, 2, 3, 4, 5, 6, 7, 8, 9]
</pre></div>
</div>
</div>
<div class="section" id="empty">
<h3>Empty<a class="headerlink" href="#empty" title="Permalink to this headline">¶</a></h3>
<div class="highlight-none notranslate"><div class="highlight"><pre><span></span>Traceback (most recent call last):
  File "TESTS:\runtime\test_index_error.py", line 38, in test_Empty
    c = a[1]
IndexError: list index out of range

    `a` contains no item.

An `IndexError` occurs when you try to get an item from a list,
a tuple, or a similar object (sequence), and use an index which
does not exist; typically, this happens because the index you give
is greater than the length of the sequence.

You have tried to get the item with index `1` of `a`,
a `list` which contains no item.

Exception raised on line 38 of file TESTS:\runtime\test_index_error.py.

   35: def test_Empty():
   36:     a = []
   37:     try:
--&gt;38:         c = a[1]
                   ^^^^
   39:     except IndexError as e:

        a:  []
</pre></div>
</div>
</div>
<div class="section" id="long-list">
<h3>Long list<a class="headerlink" href="#long-list" title="Permalink to this headline">¶</a></h3>
<div class="highlight-none notranslate"><div class="highlight"><pre><span></span>Traceback (most recent call last):
  File "TESTS:\runtime\test_index_error.py", line 24, in test_Long_list
    print(a[60], b[0])
IndexError: list index out of range

An `IndexError` occurs when you try to get an item from a list,
a tuple, or a similar object (sequence), and use an index which
does not exist; typically, this happens because the index you give
is greater than the length of the sequence.

You have tried to get the item with index `60` of `a`,
a `list` of length `40`.
The valid index values of `a` are integers ranging from
`-40` to `39`.

Exception raised on line 24 of file TESTS:\runtime\test_index_error.py.

   21:     a = list(range(40))
   22:     b = tuple(range(50))
   23:     try:
--&gt;24:         print(a[60], b[0])
                     ^^^^^
   25:     except IndexError as e:

        a:  [0, 1, 2, 3, 4, 5, 6, 7, 8, 9, 10, 11, 12, 13, 14, 15, 16, 17, 18, ...]
            len(a): 40
</pre></div>
</div>
</div>
<div class="section" id="short-tuple">
<h3>Short tuple<a class="headerlink" href="#short-tuple" title="Permalink to this headline">¶</a></h3>
<div class="highlight-none notranslate"><div class="highlight"><pre><span></span>Traceback (most recent call last):
  File "TESTS:\runtime\test_index_error.py", line 8, in test_Short_tuple
    print(a[3], b[2])
IndexError: tuple index out of range

    Remember: the first item of a `tuple` is not at index 1 but at index 0.

An `IndexError` occurs when you try to get an item from a list,
a tuple, or a similar object (sequence), and use an index which
does not exist; typically, this happens because the index you give
is greater than the length of the sequence.

You have tried to get the item with index `3` of `a`,
a `tuple` of length `3`.
The valid index values of `a` are integers ranging from
`-3` to `2`.

Exception raised on line 8 of file TESTS:\runtime\test_index_error.py.

   5:     a = (1, 2, 3)
   6:     b = [1, 2, 3]
   7:     try:
--&gt;8:         print(a[3], b[2])
                    ^^^^
   9:     except IndexError as e:

        a:  (1, 2, 3)
</pre></div>
</div>
</div>
</div>
<div class="section" id="keyerror">
<h2>KeyError<a class="headerlink" href="#keyerror" title="Permalink to this headline">¶</a></h2>
<div class="section" id="chainmap">
<h3>ChainMap<a class="headerlink" href="#chainmap" title="Permalink to this headline">¶</a></h3>
<div class="highlight-none notranslate"><div class="highlight"><pre><span></span>Traceback (most recent call last):
  File "PYTHON_LIB:\collections\__init__.py", line 1060, in pop
    return self.maps[0].pop(key, *args)
           ^^^^^^^^^^^^^^^^^^^^^^^^^^^^
KeyError: 42

    During handling of the above exception, another exception occurred:

Traceback (most recent call last):
  File "TESTS:\runtime\test_key_error.py", line 62, in test_ChainMap
    d.pop(42)
KeyError: 'Key not found in the first mapping: 42'

A `KeyError` is raised when a value is not found as a
key in a Python dict or in a similar object.

The key `42` cannot be found in `d`, an object of type `ChainMap`.

Exception raised on line 62 of file TESTS:\runtime\test_key_error.py.

   59:     from collections import ChainMap
   60:     d = ChainMap({}, {})
   61:     try:
--&gt;62:         d.pop(42)
   63:     except KeyError as e:

        d:  ChainMap({}, {})
        d.pop:  &lt;bound method ChainMap.pop&gt; of ChainMap({}, {})
</pre></div>
</div>
</div>
<div class="section" id="forgot-to-convert-to-string">
<h3>Forgot to convert to string<a class="headerlink" href="#forgot-to-convert-to-string" title="Permalink to this headline">¶</a></h3>
<div class="highlight-none notranslate"><div class="highlight"><pre><span></span>Traceback (most recent call last):
  File "TESTS:\runtime\test_key_error.py", line 115, in test_Forgot_to_convert_to_string
    print(squares[2])
KeyError: 2

    Did you forget to convert `2` into a string?

A `KeyError` is raised when a value is not found as a
key in a Python dict or in a similar object.

The key `2` cannot be found in the dict `squares`.
`squares` contains a string key which is identical to `str(2)`.
Perhaps you forgot to convert the key into a string.

Exception raised on line 115 of file TESTS:\runtime\test_key_error.py.

   112: def test_Forgot_to_convert_to_string():
   113:     squares = {"1": 1, "2": 4, "3": 9}
   114:     try:
--&gt;115:         print(squares[2])
                      ^^^^^^^^^^
   116:     except KeyError as e:

        squares:  {'1': 1, '2': 4, '3': 9}
</pre></div>
</div>
</div>
<div class="section" id="generic-key-error">
<h3>Generic key error<a class="headerlink" href="#generic-key-error" title="Permalink to this headline">¶</a></h3>
<div class="highlight-none notranslate"><div class="highlight"><pre><span></span>Traceback (most recent call last):
  File "TESTS:\runtime\test_key_error.py", line 44, in test_Generic_key_error
    d["c"]
KeyError: 'c'

A `KeyError` is raised when a value is not found as a
key in a Python dict or in a similar object.

The key `'c'` cannot be found in the dict `d`.

Exception raised on line 44 of file TESTS:\runtime\test_key_error.py.

   41: def test_Generic_key_error():
   42:     d = {"a": 1, "b": 2}
   43:     try:
--&gt;44:         d["c"]
   45:     except KeyError as e:

        d:  {'a': 1, 'b': 2}
</pre></div>
</div>
</div>
<div class="section" id="popitem-empty-chainmap">
<h3>Popitem empty ChainMap<a class="headerlink" href="#popitem-empty-chainmap" title="Permalink to this headline">¶</a></h3>
<div class="highlight-none notranslate"><div class="highlight"><pre><span></span>Traceback (most recent call last):
  File "PYTHON_LIB:\collections\__init__.py", line 1053, in popitem
    return self.maps[0].popitem()
           ^^^^^^^^^^^^^^^^^^^^^^
KeyError: 'popitem(): dictionary is empty'

    During handling of the above exception, another exception occurred:

Traceback (most recent call last):
  File "TESTS:\runtime\test_key_error.py", line 26, in test_Popitem_empty_ChainMap
    alpha.popitem()
KeyError: 'No keys found in the first mapping.'

    `alpha` is an empty `ChainMap`.

A `KeyError` is raised when a value is not found as a
key in a Python dict or in a similar object.

You tried to retrieve an item from `alpha` which is an empty `ChainMap`.

Exception raised on line 26 of file TESTS:\runtime\test_key_error.py.

   23:     from collections import ChainMap
   24:     alpha = ChainMap({}, {})
   25:     try:
--&gt;26:         alpha.popitem()
   27:     except KeyError as e:

        alpha:  ChainMap({}, {})
        alpha.popitem:  &lt;bound method ChainMap.popitem&gt; of ChainMap({}, {})
</pre></div>
</div>
</div>
<div class="section" id="popitem-empty-dict">
<h3>Popitem empty dict<a class="headerlink" href="#popitem-empty-dict" title="Permalink to this headline">¶</a></h3>
<div class="highlight-none notranslate"><div class="highlight"><pre><span></span>Traceback (most recent call last):
  File "TESTS:\runtime\test_key_error.py", line 8, in test_Popitem_empty_dict
    d.popitem()
KeyError: 'popitem(): dictionary is empty'

    `d` is an empty `dict`.

A `KeyError` is raised when a value is not found as a
key in a Python dict or in a similar object.

You tried to retrieve an item from `d` which is an empty `dict`.

Exception raised on line 8 of file TESTS:\runtime\test_key_error.py.

   5: def test_Popitem_empty_dict():
   6:     d = {}
   7:     try:
--&gt;8:         d.popitem()
   9:     except KeyError as e:

        d:  {}
        d.popitem:  &lt;builtin method popitem of dict object&gt;
</pre></div>
</div>
</div>
<div class="section" id="similar-names">
<h3>Similar names<a class="headerlink" href="#similar-names" title="Permalink to this headline">¶</a></h3>
<div class="highlight-none notranslate"><div class="highlight"><pre><span></span>Traceback (most recent call last):
  File "TESTS:\runtime\test_key_error.py", line 145, in test_Similar_names
    a = second["alpha"]
KeyError: 'alpha'

    Did you mean `'alpha0'`?

A `KeyError` is raised when a value is not found as a
key in a Python dict or in a similar object.

The key `'alpha'` cannot be found in the dict `second`.
`second` has some keys similar to `'alpha'` including:
`'alpha0', 'alpha12', 'alpha11'`.

Exception raised on line 145 of file TESTS:\runtime\test_key_error.py.

   141:         assert ok, diff
   143:     second = {"alpha0": 1, "alpha11": 2, "alpha12": 3}
   144:     try:
--&gt;145:         a = second["alpha"]
                    ^^^^^^^^^^^^^^^
   146:     except KeyError as e:

        second:  {'alpha0': 1, 'alpha11': 2, 'alpha12': 3}
</pre></div>
</div>
</div>
<div class="section" id="string-by-mistake">
<h3>String by mistake<a class="headerlink" href="#string-by-mistake" title="Permalink to this headline">¶</a></h3>
<div class="highlight-none notranslate"><div class="highlight"><pre><span></span>Traceback (most recent call last):
  File "TESTS:\runtime\test_key_error.py", line 98, in test_String_by_mistake
    d["(0, 0)"]
KeyError: '(0, 0)'

    Did you convert `(0, 0)` into a string by mistake?

A `KeyError` is raised when a value is not found as a
key in a Python dict or in a similar object.

The key `'(0, 0)'` cannot be found in the dict `d`.
`'(0, 0)'` is a string.
There is a key of `d` whose string representation
is identical to `'(0, 0)'`.

Exception raised on line 98 of file TESTS:\runtime\test_key_error.py.

   94:     chain_map_string_by_mistake()  # do not show in docs
   96:     d = {(0, 0): "origin"}
   97:     try:
--&gt;98:         d["(0, 0)"]
   99:     except KeyError as e:

        d:  {(0, 0): 'origin'}
</pre></div>
</div>
</div>
</div>
<div class="section" id="lookuperror">
<h2>LookupError<a class="headerlink" href="#lookuperror" title="Permalink to this headline">¶</a></h2>
<div class="section" id="id4">
<h3>Generic<a class="headerlink" href="#id4" title="Permalink to this headline">¶</a></h3>
<div class="highlight-none notranslate"><div class="highlight"><pre><span></span>Traceback (most recent call last):
  File "TESTS:\runtime\test_lookup_error.py", line 10, in test_Generic
    raise LookupError("Fake message")
LookupError: Fake message

`LookupError` is the base class for the exceptions that are raised
when a key or index used on a mapping or sequence is invalid.
It can also be raised directly by codecs.lookup().

Exception raised on line 10 of file TESTS:\runtime\test_lookup_error.py.

    4: def test_Generic():
    5:     try:
    6:         # LookupError is the base class for KeyError and IndexError.
    7:         # It should normally not be raised by user code,
    8:         # other than possibly codecs.lookup(), which is why we raise
    9:         # it directly here for our example.
--&gt;10:         raise LookupError("Fake message")
   11:     except LookupError as e:

        LookupError:  &lt;class LookupError&gt;
</pre></div>
</div>
</div>
</div>
<div class="section" id="modulenotfounderror">
<h2>ModuleNotFoundError<a class="headerlink" href="#modulenotfounderror" title="Permalink to this headline">¶</a></h2>
<div class="section" id="need-to-install-module">
<h3>Need to install module<a class="headerlink" href="#need-to-install-module" title="Permalink to this headline">¶</a></h3>
<div class="highlight-none notranslate"><div class="highlight"><pre><span></span>Traceback (most recent call last):
  File "TESTS:\runtime\test_module_not_found_error.py", line 76, in test_Need_to_install_module
    import alphabet
ModuleNotFoundError: No module named 'alphabet'

A `ModuleNotFoundError` exception indicates that you
are trying to import a module that cannot be found by Python.
This could be because you misspelled the name of the module
or because it is not installed on your computer.

No module named `alphabet` can be imported.
Perhaps you need to install it.

Exception raised on line 76 of file TESTS:\runtime\test_module_not_found_error.py.

   74: def test_Need_to_install_module():
   75:     try:
--&gt;76:         import alphabet
   77:     except ModuleNotFoundError as e:
</pre></div>
</div>
</div>
<div class="section" id="not-a-package">
<h3>Not a package<a class="headerlink" href="#not-a-package" title="Permalink to this headline">¶</a></h3>
<div class="highlight-none notranslate"><div class="highlight"><pre><span></span>Traceback (most recent call last):
  File "TESTS:\runtime\test_module_not_found_error.py", line 22, in test_Not_a_package
    import os.xxx
ModuleNotFoundError: No module named 'os.xxx'; 'os' is not a package

A `ModuleNotFoundError` exception indicates that you
are trying to import a module that cannot be found by Python.
This could be because you misspelled the name of the module
or because it is not installed on your computer.

`xxx` cannot be imported from `os`.

Exception raised on line 22 of file TESTS:\runtime\test_module_not_found_error.py.

   19: def test_Not_a_package():
   21:     try:
--&gt;22:         import os.xxx
   23:     except ModuleNotFoundError as e:
</pre></div>
</div>
</div>
<div class="section" id="not-a-package-similar-name">
<h3>Not a package similar name<a class="headerlink" href="#not-a-package-similar-name" title="Permalink to this headline">¶</a></h3>
<div class="highlight-none notranslate"><div class="highlight"><pre><span></span>Traceback (most recent call last):
  File "TESTS:\runtime\test_module_not_found_error.py", line 36, in test_Not_a_package_similar_name
    import os.pathh
ModuleNotFoundError: No module named 'os.pathh'; 'os' is not a package

    Did you mean `import os.path`?

A `ModuleNotFoundError` exception indicates that you
are trying to import a module that cannot be found by Python.
This could be because you misspelled the name of the module
or because it is not installed on your computer.

Perhaps you meant `import os.path`.
`path` is a name similar to `pathh` and is a module that
can be imported from `os`.
Other objects with similar names that are part of
 `os` include `fspath`.

Exception raised on line 36 of file TESTS:\runtime\test_module_not_found_error.py.

   34: def test_Not_a_package_similar_name():
   35:     try:
--&gt;36:         import os.pathh
   37:     except ModuleNotFoundError as e:
</pre></div>
</div>
</div>
<div class="section" id="object-not-module">
<h3>Object not module<a class="headerlink" href="#object-not-module" title="Permalink to this headline">¶</a></h3>
<div class="highlight-none notranslate"><div class="highlight"><pre><span></span>Traceback (most recent call last):
  File "TESTS:\runtime\test_module_not_found_error.py", line 49, in test_Object_not_module
    import os.open
ModuleNotFoundError: No module named 'os.open'; 'os' is not a package

    Did you mean `from os import open`?

A `ModuleNotFoundError` exception indicates that you
are trying to import a module that cannot be found by Python.
This could be because you misspelled the name of the module
or because it is not installed on your computer.

`open` is not a separate module but an object that is part of `os`.

Exception raised on line 49 of file TESTS:\runtime\test_module_not_found_error.py.

   47: def test_Object_not_module():
   48:     try:
--&gt;49:         import os.open
   50:     except ModuleNotFoundError as e:

        open:  &lt;builtin function open&gt;
</pre></div>
</div>
</div>
<div class="section" id="similar-object-not-module">
<h3>Similar object not module<a class="headerlink" href="#similar-object-not-module" title="Permalink to this headline">¶</a></h3>
<div class="highlight-none notranslate"><div class="highlight"><pre><span></span>Traceback (most recent call last):
  File "TESTS:\runtime\test_module_not_found_error.py", line 62, in test_Similar_object_not_module
    import os.opend
ModuleNotFoundError: No module named 'os.opend'; 'os' is not a package

    Did you mean `from os import open`?

A `ModuleNotFoundError` exception indicates that you
are trying to import a module that cannot be found by Python.
This could be because you misspelled the name of the module
or because it is not installed on your computer.

Perhaps you meant `from os import open`.
`open` is a name similar to `opend` and is an object that
can be imported from `os`.
Other objects with similar names that are part of
 `os` include `popen, fdopen`.

Exception raised on line 62 of file TESTS:\runtime\test_module_not_found_error.py.

   60: def test_Similar_object_not_module():
   61:     try:
--&gt;62:         import os.opend
   63:     except ModuleNotFoundError as e:
</pre></div>
</div>
</div>
<div class="section" id="standard-library-module">
<h3>Standard library module<a class="headerlink" href="#standard-library-module" title="Permalink to this headline">¶</a></h3>
<div class="highlight-none notranslate"><div class="highlight"><pre><span></span>Traceback (most recent call last):
  File "TESTS:\runtime\test_module_not_found_error.py", line 7, in test_Standard_library_module
    import Tkinter
ModuleNotFoundError: No module named 'Tkinter'

    Did you mean `tkinter`?

A `ModuleNotFoundError` exception indicates that you
are trying to import a module that cannot be found by Python.
This could be because you misspelled the name of the module
or because it is not installed on your computer.

No module named `Tkinter` can be imported.
Perhaps you need to install it.
The following existing modules have names that are similar
to the module you tried to import: `tkinter, _tkinter`

Exception raised on line 7 of file TESTS:\runtime\test_module_not_found_error.py.

   5: def test_Standard_library_module():
   6:     try:
--&gt;7:         import Tkinter
   8:     except ModuleNotFoundError as e:
</pre></div>
</div>
</div>
<div class="section" id="no-curses">
<h3>no curses<a class="headerlink" href="#no-curses" title="Permalink to this headline">¶</a></h3>
<div class="highlight-none notranslate"><div class="highlight"><pre><span></span>Traceback (most recent call last):
  File "TESTS:\runtime\test_module_not_found_error.py", line 92, in test_no_curses
    import curses
ModuleNotFoundError: No module named '_curses'

    The curses module is rarely installed with Python on Windows.

A `ModuleNotFoundError` exception indicates that you
are trying to import a module that cannot be found by Python.
This could be because you misspelled the name of the module
or because it is not installed on your computer.

You have tried to import the curses module.
The curses module is rarely installed with Python on Windows.

Exception raised on line 92 of file TESTS:\runtime\test_module_not_found_error.py.

   90:     def test_no_curses():
   91:         try:
--&gt;92:             import curses
   93:         except ModuleNotFoundError as e:
</pre></div>
</div>
</div>
</div>
<div class="section" id="nameerror">
<h2>NameError<a class="headerlink" href="#nameerror" title="Permalink to this headline">¶</a></h2>
<div class="section" id="annotated-variable">
<h3>Annotated variable<a class="headerlink" href="#annotated-variable" title="Permalink to this headline">¶</a></h3>
<div class="highlight-none notranslate"><div class="highlight"><pre><span></span>Traceback (most recent call last):
  File "TESTS:\runtime\test_name_error.py", line 24, in test_Annotated_variable
    y = x
NameError: name 'x' is not defined

    Did you use a colon instead of an equal sign?

A `NameError` exception indicates that a variable or
function name is not known to Python.
Most often, this is because there is a spelling mistake.
However, sometimes it is because the name is used
before being defined or given a value.

In your program, no object with the name `x` exists.
A type hint found for `x` in the global scope.
Perhaps you had used a colon instead of an equal sign and wrote

    x : 3

instead of

    x = 3

Exception raised on line 24 of file TESTS:\runtime\test_name_error.py.

   22: def test_Annotated_variable():
   23:     try:
--&gt;24:         y = x
                   ^
   25:     except NameError as e:
</pre></div>
</div>
</div>
<div class="section" id="custom-name">
<h3>Custom name<a class="headerlink" href="#custom-name" title="Permalink to this headline">¶</a></h3>
<div class="highlight-none notranslate"><div class="highlight"><pre><span></span>Traceback (most recent call last):
  File "TESTS:\runtime\test_name_error.py", line 165, in test_Custom_name
    python
NameError: name 'python' is not defined

    You are already using Python!
A `NameError` exception indicates that a variable or
function name is not known to Python.
Most often, this is because there is a spelling mistake.
However, sometimes it is because the name is used
before being defined or given a value.

You are already using Python!
Exception raised on line 165 of file TESTS:\runtime\test_name_error.py.

   163: def test_Custom_name():
   164:     try:
--&gt;165:         python
   166:     except NameError as e:
</pre></div>
</div>
</div>
<div class="section" id="free-variable-referenced">
<h3>Free variable referenced<a class="headerlink" href="#free-variable-referenced" title="Permalink to this headline">¶</a></h3>
<div class="highlight-none notranslate"><div class="highlight"><pre><span></span>Traceback (most recent call last):
  File "TESTS:\runtime\test_name_error.py", line 149, in test_Free_variable_referenced
    outer()
  File "TESTS:\runtime\test_name_error.py", line 145, in outer
    inner()
  File "TESTS:\runtime\test_name_error.py", line 144, in inner
    return var
NameError: cannot access free variable 'var' where it is not associated with a value in enclosing scope

A `NameError` exception indicates that a variable or
function name is not known to Python.
Most often, this is because there is a spelling mistake.
However, sometimes it is because the name is used
before being defined or given a value.

In your program, `var` is an unknown name
that exists in an enclosing scope,
but has not yet been assigned a value.

Execution stopped on line 149 of file TESTS:\runtime\test_name_error.py.

   145:         inner()
   146:         var = 4
   148:     try:
--&gt;149:         outer()
   150:     except NameError as e:

        outer:  &lt;function outer&gt;
            defined in &lt;function test_Free_variable_referenced&gt;

Exception raised on line 144 of file TESTS:\runtime\test_name_error.py.

   143:         def inner():
--&gt;144:             return var
                           ^^^
</pre></div>
</div>
</div>
<div class="section" id="id5">
<h3>Generic<a class="headerlink" href="#id5" title="Permalink to this headline">¶</a></h3>
<div class="highlight-none notranslate"><div class="highlight"><pre><span></span>Traceback (most recent call last):
  File "TESTS:\runtime\test_name_error.py", line 9, in test_Generic
    this = something
NameError: name 'something' is not defined

A `NameError` exception indicates that a variable or
function name is not known to Python.
Most often, this is because there is a spelling mistake.
However, sometimes it is because the name is used
before being defined or given a value.

In your program, no object with the name `something` exists.
I have no additional information for you.

Exception raised on line 9 of file TESTS:\runtime\test_name_error.py.

    7: def test_Generic():
    8:     try:
--&gt; 9:         this = something
                      ^^^^^^^^^
   10:     except NameError as e:
</pre></div>
</div>
</div>
<div class="section" id="missing-import">
<h3>Missing import<a class="headerlink" href="#missing-import" title="Permalink to this headline">¶</a></h3>
<div class="highlight-none notranslate"><div class="highlight"><pre><span></span>Traceback (most recent call last):
  File "TESTS:\runtime\test_name_error.py", line 129, in test_Missing_import
    unicodedata.something
NameError: name 'unicodedata' is not defined

    Did you forget to import `unicodedata`?

A `NameError` exception indicates that a variable or
function name is not known to Python.
Most often, this is because there is a spelling mistake.
However, sometimes it is because the name is used
before being defined or given a value.

The name `unicodedata` is not defined in your program.
Perhaps you forgot to import `unicodedata` which is found
in Python's standard library.

Exception raised on line 129 of file TESTS:\runtime\test_name_error.py.

   125:     if friendly_traceback.get_lang() == "en":
   126:         assert "I have no additional information for you." in result
   128:     try:
--&gt;129:         unicodedata.something
                ^^^^^^^^^^^
   130:     except NameError as e:
</pre></div>
</div>
</div>
<div class="section" id="missing-module-name">
<h3>Missing module name<a class="headerlink" href="#missing-module-name" title="Permalink to this headline">¶</a></h3>
<div class="highlight-none notranslate"><div class="highlight"><pre><span></span>Traceback (most recent call last):
  File "TESTS:\runtime\test_name_error.py", line 249, in test_Missing_module_name
    frame = Frame()
NameError: name 'Frame' is not defined

    Did you forget to add `tkinter.`?

A `NameError` exception indicates that a variable or
function name is not known to Python.
Most often, this is because there is a spelling mistake.
However, sometimes it is because the name is used
before being defined or given a value.

In your program, no object with the name `Frame` exists.

The local object `tkinter`
has an attribute named `Frame`.
Perhaps you should have written `tkinter.Frame`
instead of `Frame`.

Exception raised on line 249 of file TESTS:\runtime\test_name_error.py.

   246: def test_Missing_module_name():
   247:     import tkinter
   248:     try:
--&gt;249:         frame = Frame()
                        ^^^^^
   250:     except NameError as e:
</pre></div>
</div>
</div>
<div class="section" id="missing-self-1">
<h3>Missing self 1<a class="headerlink" href="#missing-self-1" title="Permalink to this headline">¶</a></h3>
<div class="highlight-none notranslate"><div class="highlight"><pre><span></span>Traceback (most recent call last):
  File "TESTS:\runtime\test_name_error.py", line 200, in test_Missing_self_1
    str(a)
  File "TESTS:\runtime\test_name_error.py", line 191, in __str__
    toys_list = add_toy(  # ensure that it can see 'self' on following line
NameError: name 'add_toy' is not defined

    Did you write `self` at the wrong place?

A `NameError` exception indicates that a variable or
function name is not known to Python.
Most often, this is because there is a spelling mistake.
However, sometimes it is because the name is used
before being defined or given a value.

In your program, no object with the name `add_toy` exists.

The local object `&lt;Pet object&gt; defined in &lt;function test_name_error.test_Missing_self_1&gt;`
has an attribute named `add_toy`.
Perhaps you should have written `self.add_toy(...`
instead of `add_toy(self, ...`.

Execution stopped on line 200 of file TESTS:\runtime\test_name_error.py.

   196:                 return "{} has no toys".format(self.name)
   198:     a = Pet('Fido')
   199:     try:
--&gt;200:         str(a)
   201:     except NameError as e:

        a:  &lt;Pet object&gt;
            defined in &lt;function test_name_error.test_Missing_self_1&gt;
        str:  &lt;class str&gt;

Exception raised on line 191 of file TESTS:\runtime\test_name_error.py.

   189:         def __str__(self):
   190:             # self at the wrong place
--&gt;191:             toys_list = add_toy(  # ensure that it can see 'self' on following line
                                ^^^^^^^
   192:                                 self, 'something')
   193:             if self.toys:
</pre></div>
</div>
</div>
<div class="section" id="missing-self-2">
<h3>Missing self 2<a class="headerlink" href="#missing-self-2" title="Permalink to this headline">¶</a></h3>
<div class="highlight-none notranslate"><div class="highlight"><pre><span></span>Traceback (most recent call last):
  File "TESTS:\runtime\test_name_error.py", line 234, in test_Missing_self_2
    str(a)
  File "TESTS:\runtime\test_name_error.py", line 226, in __str__
    toys_list = add_toy('something')
NameError: name 'add_toy' is not defined

    Did you forget to add `self.`?

A `NameError` exception indicates that a variable or
function name is not known to Python.
Most often, this is because there is a spelling mistake.
However, sometimes it is because the name is used
before being defined or given a value.

In your program, no object with the name `add_toy` exists.

A local object, `&lt;Pet object&gt; defined in &lt;function test_name_error.test_Missing_self_2&gt;`,
has an attribute named `add_toy`.
Perhaps you should have written `self.add_toy`
instead of `add_toy`.

Execution stopped on line 234 of file TESTS:\runtime\test_name_error.py.

   230:                 return "{} has no toys".format(self.name)
   232:     a = Pet('Fido')
   233:     try:
--&gt;234:         str(a)
   235:     except NameError as e:

        a:  &lt;Pet object&gt;
            defined in &lt;function test_name_error.test_Missing_self_2&gt;
        str:  &lt;class str&gt;

Exception raised on line 226 of file TESTS:\runtime\test_name_error.py.

   224:         def __str__(self):
   225:             # Missing self.
--&gt;226:             toys_list = add_toy('something')
                                ^^^^^^^
   227:             if self.toys:
</pre></div>
</div>
</div>
<div class="section" id="synonym">
<h3>Synonym<a class="headerlink" href="#synonym" title="Permalink to this headline">¶</a></h3>
<div class="highlight-none notranslate"><div class="highlight"><pre><span></span>Traceback (most recent call last):
  File "TESTS:\runtime\test_name_error.py", line 89, in test_Synonym
    cost  # wrote from math import * above
NameError: name 'cost' is not defined

    Did you mean `cos`?

A `NameError` exception indicates that a variable or
function name is not known to Python.
Most often, this is because there is a spelling mistake.
However, sometimes it is because the name is used
before being defined or given a value.

In your program, no object with the name `cost` exists.
Instead of writing `cost`, perhaps you meant one of the following:
*   Global scope: `cos`, `cosh`, `acos`

Exception raised on line 89 of file TESTS:\runtime\test_name_error.py.

   85:     if friendly_traceback.get_lang() == "en":
   86:         assert "The Python builtin `chr` has a similar name." in result
   88:     try:
--&gt;89:         cost  # wrote from math import * above
   90:     except NameError as e:
</pre></div>
</div>
</div>
</div>
<div class="section" id="oserror">
<h2>OsError<a class="headerlink" href="#oserror" title="Permalink to this headline">¶</a></h2>
<div class="section" id="urllib-error">
<h3>Urllib error<a class="headerlink" href="#urllib-error" title="Permalink to this headline">¶</a></h3>
<div class="highlight-none notranslate"><div class="highlight"><pre><span></span>Traceback (most recent call last):
  File "PYTHON_LIB:\urllib\request.py", line 1348, in do_open
       ... More lines not shown. ...
               ^^^^^^^^^^^^^^^^^^^^^^^^^^^^^^^^^^^^^^^
  File "PYTHON_LIB:\socket.py", line 955, in getaddrinfo
    for res in _socket.getaddrinfo(host, port, family, type, proto, flags):
               ^^^^^^^^^^^^^^^^^^^^^^^^^^^^^^^^^^^^^^^^^^^^^^^^^^^^^^^^^^^
socket.gaierror: [Errno 11001] getaddrinfo failed

    During handling of the above exception, another exception occurred:

Traceback (most recent call last):
  File "TESTS:\runtime\test_os_error.py", line 8, in test_Urllib_error
    request.urlopen("http://does_not_exist")
URLError: &lt;urlopen error [Errno 11001] getaddrinfo failed&gt;

An exception of type `URLError` is a subclass of `OSError`.
An `OSError` exception is usually raised by the Operating System
to indicate that an operation is not allowed or that
a resource is not available.

I suspect that you are trying to connect to a server and
that a connection cannot be made.

If that is the case, check for typos in the URL
and check your internet connectivity.

Exception raised on line 8 of file TESTS:\runtime\test_os_error.py.

   5: def test_Urllib_error():
   6:     from urllib import request, error
   7:     try:
--&gt;8:         request.urlopen("http://does_not_exist")
   9:     except error.URLError as e:

        request:  &lt;module urllib.request&gt; from PYTHON_LIB:\urllib\request.py
        request.urlopen:  &lt;function urlopen&gt;
</pre></div>
</div>
</div>
<div class="section" id="invalid-argument">
<h3>invalid argument<a class="headerlink" href="#invalid-argument" title="Permalink to this headline">¶</a></h3>
<div class="highlight-none notranslate"><div class="highlight"><pre><span></span>Traceback (most recent call last):
  File "TESTS:\runtime\test_os_error.py", line 46, in test_invalid_argument
    open("c:\test.txt")
OSError: [Errno 22] Invalid argument: 'c:\test.txt'

    Perhaps you need to double the backslash characters.

An `OSError` exception is usually raised by the Operating System
to indicate that an operation is not allowed or that
a resource is not available.

I suspect that you wrote a filename or path that contains
at least one backslash character, `\`.
Python likely interpreted this as indicating the beginning of
what is known as an escape sequence.
To solve the problem, either write a so-called 'raw string'
by adding the letter `r` as a prefix in
front of the filename or path, or replace all single backslash
characters, `\`, by double ones: `\\`.

Exception raised on line 46 of file TESTS:\runtime\test_os_error.py.

   43:     if os.name != "nt":
   44:         return "Windows test only", "No result"
   45:     try:
--&gt;46:         open("c:\test.txt")
   47:     except OSError as e:

        open:  &lt;builtin function open&gt;
</pre></div>
</div>
</div>
<div class="section" id="no-information">
<h3>no information<a class="headerlink" href="#no-information" title="Permalink to this headline">¶</a></h3>
<div class="highlight-none notranslate"><div class="highlight"><pre><span></span>Traceback (most recent call last):
  File "TESTS:\runtime\test_os_error.py", line 27, in test_no_information
    raise OSError("Some unknown message")
OSError: Some unknown message

    Friendly-traceback does not know the cause of this error.

An `OSError` exception is usually raised by the Operating System
to indicate that an operation is not allowed or that
a resource is not available.

No information is known about this exception.
Please report this example to
https://github.com/friendly-traceback/friendly-traceback/issues/new
If you are using a REPL, use `www('bug')` to do so.

If you are using the Friendly console, use `www()` to
do an Internet search for this particular case.

Exception raised on line 27 of file TESTS:\runtime\test_os_error.py.

   24:     old_debug = friendly_traceback.debug_helper.DEBUG
   25:     friendly_traceback.debug_helper.DEBUG = False
   26:     try:
--&gt;27:         raise OSError("Some unknown message")
   28:     except OSError as e:

        OSError:  &lt;class OSError&gt;
</pre></div>
</div>
</div>
</div>
<div class="section" id="overflowerror">
<h2>OverflowError<a class="headerlink" href="#overflowerror" title="Permalink to this headline">¶</a></h2>
<div class="section" id="id6">
<h3>Generic<a class="headerlink" href="#id6" title="Permalink to this headline">¶</a></h3>
<div class="highlight-none notranslate"><div class="highlight"><pre><span></span>Traceback (most recent call last):
  File "TESTS:\runtime\test_overflow_error.py", line 6, in test_Generic
    2.0 ** 1600
OverflowError: (34, 'Result too large')

An `OverflowError` is raised when the result of an arithmetic operation
is too large to be handled by the computer's processor.

Exception raised on line 6 of file TESTS:\runtime\test_overflow_error.py.

   4: def test_Generic():
   5:     try:
--&gt;6:         2.0 ** 1600
   7:     except OverflowError as e:
</pre></div>
</div>
</div>
</div>
<div class="section" id="recursionerror">
<h2>RecursionError<a class="headerlink" href="#recursionerror" title="Permalink to this headline">¶</a></h2>
<div class="section" id="id7">
<h3>Generic<a class="headerlink" href="#id7" title="Permalink to this headline">¶</a></h3>
<div class="highlight-none notranslate"><div class="highlight"><pre><span></span>Traceback (most recent call last):
  File "TESTS:\runtime\test_recursion_error.py", line 8, in test_Generic
    a()
       ... More lines not shown. ...
  File "TESTS:\runtime\test_recursion_error.py", line 6, in a
    return a()
  File "TESTS:\runtime\test_recursion_error.py", line 6, in a
    return a()
RecursionError: maximum recursion depth exceeded

A `RecursionError` is raised when a function calls itself,
directly or indirectly, too many times.
It almost always indicates that you made an error in your code
and that your program would never stop.

Execution stopped on line 8 of file TESTS:\runtime\test_recursion_error.py.

   5:     def a():
   6:         return a()
   7:     try:
--&gt;8:         a()
   9:     except RecursionError as e:

        a:  &lt;function a&gt; defined in &lt;function test_Generic&gt;

Exception raised on line 6 of file TESTS:\runtime\test_recursion_error.py.

   5:     def a():
--&gt;6:         return a()
                     ^^^

        a:  &lt;function a&gt; defined in &lt;function test_Generic&gt;
</pre></div>
</div>
</div>
</div>
<div class="section" id="typeerror">
<h2>TypeError<a class="headerlink" href="#typeerror" title="Permalink to this headline">¶</a></h2>
<div class="section" id="bad-type-for-unary-operator">
<h3>Bad type for unary operator<a class="headerlink" href="#bad-type-for-unary-operator" title="Permalink to this headline">¶</a></h3>
<div class="highlight-none notranslate"><div class="highlight"><pre><span></span>Traceback (most recent call last):
  File "TESTS:\runtime\test_type_error.py", line 371, in test_Bad_type_for_unary_operator
    a =+ "def"
TypeError: bad operand type for unary +: 'str'

    Perhaps you meant to write `+=` instead of `=+`
A `TypeError` is usually caused by trying
to combine two incompatible types of objects,
by calling a function with the wrong type of object,
or by trying to do an operation not allowed on a given type of object.

You tried to use the unary operator '+'
with the following type of object: a string (`str`).
This operation is not defined for this type of object.

Perhaps you meant to write `+=` instead of `=+`

Exception raised on line 371 of file TESTS:\runtime\test_type_error.py.

   366:         assert "You tried to use the unary operator '~'" in result
   368:     try:
   369:         # fmt: off
   370:         a = "abc"
--&gt;371:         a =+ "def"
                   ^^^^^^^
   372:         # fmt: on
</pre></div>
</div>
</div>
<div class="section" id="builtin-has-no-len">
<h3>Builtin has no len<a class="headerlink" href="#builtin-has-no-len" title="Permalink to this headline">¶</a></h3>
<div class="highlight-none notranslate"><div class="highlight"><pre><span></span>Traceback (most recent call last):
  File "TESTS:\runtime\test_type_error.py", line 780, in test_Builtin_has_no_len
    len("Hello world".split)
TypeError: object of type 'builtin_function_or_method' has no len()

    Did you forget to call `"Hello world".split`?

A `TypeError` is usually caused by trying
to combine two incompatible types of objects,
by calling a function with the wrong type of object,
or by trying to do an operation not allowed on a given type of object.

I suspect that you forgot to add parentheses to call `"Hello world".split`.
You might have meant to write:
`len("Hello world".split())`

Exception raised on line 780 of file TESTS:\runtime\test_type_error.py.

   778: def test_Builtin_has_no_len():
   779:     try:
--&gt;780:         len("Hello world".split)
   781:     except TypeError as e:

        len:  &lt;builtin function len&gt;
        "Hello world".split:  &lt;builtin method split of str object&gt;
</pre></div>
</div>
</div>
<div class="section" id="can-only-concatenate">
<h3>Can only concatenate<a class="headerlink" href="#can-only-concatenate" title="Permalink to this headline">¶</a></h3>
<div class="highlight-none notranslate"><div class="highlight"><pre><span></span>Traceback (most recent call last):
  File "TESTS:\runtime\test_type_error.py", line 37, in test_Can_only_concatenate
    result = a_tuple + a_list
TypeError: can only concatenate tuple (not "list") to tuple

A `TypeError` is usually caused by trying
to combine two incompatible types of objects,
by calling a function with the wrong type of object,
or by trying to do an operation not allowed on a given type of object.

You tried to concatenate (add) two different types of objects:
a `tuple` and a `list`.

Exception raised on line 37 of file TESTS:\runtime\test_type_error.py.

   34:     try:
   35:         a_tuple = (1, 2, 3)
   36:         a_list = [1, 2, 3]
--&gt;37:         result = a_tuple + a_list
                        ^^^^^^^^^^^^^^^^
   38:     except TypeError as e:

        a_list:  [1, 2, 3]
        a_tuple:  (1, 2, 3)
</pre></div>
</div>
</div>
<div class="section" id="cannot-convert-dictionary-update-sequence">
<h3>Cannot convert dictionary update sequence<a class="headerlink" href="#cannot-convert-dictionary-update-sequence" title="Permalink to this headline">¶</a></h3>
<div class="highlight-none notranslate"><div class="highlight"><pre><span></span>Traceback (most recent call last):
  File "TESTS:\runtime\test_type_error.py", line 766, in test_Cannot_convert_dictionary_update_sequence
    dd.update([1, 2, 3])
TypeError: cannot convert dictionary update sequence element #0 to a sequence

    Perhaps you need to use the `dict.fromkeys()` method.

A `TypeError` is usually caused by trying
to combine two incompatible types of objects,
by calling a function with the wrong type of object,
or by trying to do an operation not allowed on a given type of object.

`dict.update()` does not accept a sequence as an argument.
Instead of writing `dd.update([1, 2, 3])`
perhaps you should use the `dict.fromkeys()` method: `dd.update( dict.fromkeys([1, 2, 3]) )`.

Exception raised on line 766 of file TESTS:\runtime\test_type_error.py.

   762:         assert "you should use the `dict.fromkeys()`" in result
   764:     dd = {"a": "a"}
   765:     try:
--&gt;766:         dd.update([1, 2, 3])
   767:     except TypeError as e:

        dd:  {'a': 'a'}
        dd.update:  &lt;builtin method update of dict object&gt;
</pre></div>
</div>
</div>
<div class="section" id="cannot-multiply-by-non-int">
<h3>Cannot multiply by non int<a class="headerlink" href="#cannot-multiply-by-non-int" title="Permalink to this headline">¶</a></h3>
<div class="highlight-none notranslate"><div class="highlight"><pre><span></span>Traceback (most recent call last):
  File "TESTS:\runtime\test_type_error.py", line 570, in test_Cannot_multiply_by_non_int
    "a" * "2"
TypeError: can't multiply sequence by non-int of type 'str'

    Did you forget to convert `"2"` into an integer?

A `TypeError` is usually caused by trying
to combine two incompatible types of objects,
by calling a function with the wrong type of object,
or by trying to do an operation not allowed on a given type of object.

You can only multiply sequences, such as list, tuples,
 strings, etc., by integers.
Perhaps you forgot to convert `"2"` into an integer.

Exception raised on line 570 of file TESTS:\runtime\test_type_error.py.

   566:     if friendly_traceback.get_lang() == "en":
   567:         assert "Did you forget to convert `c` into an integer?" in result
   569:     try:
--&gt;570:         "a" * "2"
   571:     except TypeError as e:
</pre></div>
</div>
</div>
<div class="section" id="cannot-unpack-non-iterable-object">
<h3>Cannot unpack non iterable object<a class="headerlink" href="#cannot-unpack-non-iterable-object" title="Permalink to this headline">¶</a></h3>
<div class="highlight-none notranslate"><div class="highlight"><pre><span></span>Traceback (most recent call last):
  File "TESTS:\runtime\test_type_error.py", line 738, in test_Cannot_unpack_non_iterable_object
    a, b = 42.0
TypeError: cannot unpack non-iterable float object

A `TypeError` is usually caused by trying
to combine two incompatible types of objects,
by calling a function with the wrong type of object,
or by trying to do an operation not allowed on a given type of object.

Unpacking is a convenient way to assign a name,
to each item of an iterable.
An iterable is an object capable of returning its members one at a time.
Python containers (`list, tuple, dict`, etc.) are iterables,
but not objects of type `float`.

Exception raised on line 738 of file TESTS:\runtime\test_type_error.py.

   736: def test_Cannot_unpack_non_iterable_object():
   737:     try:
--&gt;738:         a, b = 42.0
   739:     except TypeError as e:
</pre></div>
</div>
</div>
<div class="section" id="comparison-not-supported">
<h3>Comparison not supported<a class="headerlink" href="#comparison-not-supported" title="Permalink to this headline">¶</a></h3>
<div class="highlight-none notranslate"><div class="highlight"><pre><span></span>Traceback (most recent call last):
  File "TESTS:\runtime\test_type_error.py", line 320, in test_Comparison_not_supported
    b &gt;= a
TypeError: '&gt;=' not supported between instances of 'int' and 'str'

    Did you forget to convert the string `a` into an integer (`int`)?

A `TypeError` is usually caused by trying
to combine two incompatible types of objects,
by calling a function with the wrong type of object,
or by trying to do an operation not allowed on a given type of object.

You tried to do an order comparison (&gt;=)
between two incompatible types of objects:
an integer (`int`) and a string (`str`).
Perhaps you forgot to convert the string `a` into an integer (`int`).

Exception raised on line 320 of file TESTS:\runtime\test_type_error.py.

   317:     try:
   318:         a = "2"
   319:         b = 42
--&gt;320:         b &gt;= a
   321:     except TypeError as e:

        a:  '2'
        b:  42
</pre></div>
</div>
</div>
<div class="section" id="derive-from-baseexception">
<h3>Derive from BaseException<a class="headerlink" href="#derive-from-baseexception" title="Permalink to this headline">¶</a></h3>
<div class="highlight-none notranslate"><div class="highlight"><pre><span></span>Traceback (most recent call last):
  File "TESTS:\runtime\test_type_error.py", line 513, in test_Derive_from_BaseException
    raise "exception"  # noqa
TypeError: exceptions must derive from BaseException

A `TypeError` is usually caused by trying
to combine two incompatible types of objects,
by calling a function with the wrong type of object,
or by trying to do an operation not allowed on a given type of object.

In Python 3, exceptions must be derived from BaseException.

Exception raised on line 513 of file TESTS:\runtime\test_type_error.py.

   511: def test_Derive_from_BaseException():
   512:     try:
--&gt;513:         raise "exception"  # noqa
   514:     except TypeError as e:
</pre></div>
</div>
</div>
<div class="section" id="indices-must-be-integers-or-slices">
<h3>Indices must be integers or slices<a class="headerlink" href="#indices-must-be-integers-or-slices" title="Permalink to this headline">¶</a></h3>
<div class="highlight-none notranslate"><div class="highlight"><pre><span></span>Traceback (most recent call last):
  File "TESTS:\runtime\test_type_error.py", line 652, in test_Indices_must_be_integers_or_slices
    [1, 2, 3]["2"]
TypeError: list indices must be integers or slices, not str

    Did you forget to convert `"2"` into an integer?

A `TypeError` is usually caused by trying
to combine two incompatible types of objects,
by calling a function with the wrong type of object,
or by trying to do an operation not allowed on a given type of object.

In the expression `[1, 2, 3]["2"]`
what is included between the square brackets, `[...]`,
must be either an integer or a slice
(`start:stop` or `start:stop:step`)
and you have used a string (`str`) instead.

Perhaps you forgot to convert `"2"` into an integer.

Exception raised on line 652 of file TESTS:\runtime\test_type_error.py.

   648:     if friendly_traceback.get_lang() == "en":
   649:         assert "Perhaps you forgot to convert `2.0` into an integer." in result
   651:     try:
--&gt;652:         [1, 2, 3]["2"]
   653:     except TypeError as e:
</pre></div>
</div>
</div>
<div class="section" id="not-an-integer">
<h3>Not an integer<a class="headerlink" href="#not-an-integer" title="Permalink to this headline">¶</a></h3>
<div class="highlight-none notranslate"><div class="highlight"><pre><span></span>Traceback (most recent call last):
  File "TESTS:\runtime\test_type_error.py", line 615, in test_Not_an_integer
    range(c, d)
TypeError: 'str' object cannot be interpreted as an integer

    Did you forget to convert `c, d` into integers?

A `TypeError` is usually caused by trying
to combine two incompatible types of objects,
by calling a function with the wrong type of object,
or by trying to do an operation not allowed on a given type of object.

You wrote an object of type `str` where an integer was expected.
Perhaps you forgot to convert `c, d` into integers.
Exception raised on line 615 of file TESTS:\runtime\test_type_error.py.

   611:         assert "Perhaps you forgot to convert `1.0" in result
   613:     c, d = "2", "3"
   614:     try:
--&gt;615:         range(c, d)
   616:     except TypeError as e:

        c:  '2'
        d:  '3'
        range:  &lt;class range&gt;
</pre></div>
</div>
</div>
<div class="section" id="not-callable">
<h3>Not callable<a class="headerlink" href="#not-callable" title="Permalink to this headline">¶</a></h3>
<div class="highlight-none notranslate"><div class="highlight"><pre><span></span>Traceback (most recent call last):
  File "TESTS:\runtime\test_type_error.py", line 500, in test_Not_callable
    _ = [1, 2](a + b)
TypeError: 'list' object is not callable

    Did you mean `[1, 2][a + b]`?

A `TypeError` is usually caused by trying
to combine two incompatible types of objects,
by calling a function with the wrong type of object,
or by trying to do an operation not allowed on a given type of object.

Because of the surrounding parenthesis, `(a + b)`
is interpreted by Python as indicating a function call for
`[1, 2]`, which is an object of type `list`
which cannot be called.

However, `[1, 2]` is a sequence.
Perhaps you meant to use `[]` instead of `()` and write
`[1, 2][a + b]`

Exception raised on line 500 of file TESTS:\runtime\test_type_error.py.

   496:         assert "b.a_list[3]" in result
   498:     try:
   499:         a, b = 3, 7
--&gt;500:         _ = [1, 2](a + b)
                    ^^^^^^^^^^^^^
   501:     except TypeError as e:

        a:  3
        b:  7
        a + b:  10
</pre></div>
</div>
</div>
<div class="section" id="object-is-not-iterable">
<h3>Object is not iterable<a class="headerlink" href="#object-is-not-iterable" title="Permalink to this headline">¶</a></h3>
<div class="highlight-none notranslate"><div class="highlight"><pre><span></span>Traceback (most recent call last):
  File "TESTS:\runtime\test_type_error.py", line 724, in test_Object_is_not_iterable
    list(42)
TypeError: 'int' object is not iterable

A `TypeError` is usually caused by trying
to combine two incompatible types of objects,
by calling a function with the wrong type of object,
or by trying to do an operation not allowed on a given type of object.

An iterable is an object capable of returning its members one at a time.
Python containers (`list, tuple, dict`, etc.) are iterables.
An iterable is required here.

Exception raised on line 724 of file TESTS:\runtime\test_type_error.py.

   722: def test_Object_is_not_iterable():
   723:     try:
--&gt;724:         list(42)
   725:     except TypeError as e:

        list:  &lt;class list&gt;
</pre></div>
</div>
</div>
<div class="section" id="object-is-not-subscriptable">
<h3>Object is not subscriptable<a class="headerlink" href="#object-is-not-subscriptable" title="Permalink to this headline">¶</a></h3>
<div class="highlight-none notranslate"><div class="highlight"><pre><span></span>Traceback (most recent call last):
  File "TESTS:\runtime\test_type_error.py", line 710, in test_Object_is_not_subscriptable
    a = f[1]
TypeError: 'function' object is not subscriptable

    Did you mean `f(1)`?

A `TypeError` is usually caused by trying
to combine two incompatible types of objects,
by calling a function with the wrong type of object,
or by trying to do an operation not allowed on a given type of object.

Subscriptable objects are typically containers from which
you can retrieve item using the notation `[...]`.

Perhaps you meant to write `f(1)`.

Exception raised on line 710 of file TESTS:\runtime\test_type_error.py.

   706:     def f():
   707:         pass
   709:     try:
--&gt;710:         a = f[1]
                    ^^^^
   711:     except TypeError as e:

        f:  &lt;function f&gt;
            defined in &lt;function test_Object_is_not_subscriptable&gt;
</pre></div>
</div>
</div>
<div class="section" id="slice-indices-must-be-integers-or-none">
<h3>Slice indices must be integers or None<a class="headerlink" href="#slice-indices-must-be-integers-or-none" title="Permalink to this headline">¶</a></h3>
<div class="highlight-none notranslate"><div class="highlight"><pre><span></span>Traceback (most recent call last):
  File "TESTS:\runtime\test_type_error.py", line 666, in test_Slice_indices_must_be_integers_or_None
    [1, 2, 3][1.0:2.0]
TypeError: slice indices must be integers or None or have an __index__ method

A `TypeError` is usually caused by trying
to combine two incompatible types of objects,
by calling a function with the wrong type of object,
or by trying to do an operation not allowed on a given type of object.

When using a slice to extract a range of elements
from a sequence, that is something like
`[start:stop]` or `[start:stop:step]`
each of `start`, `stop`, `step` must be either an integer, `None`,
or possibly some other object having an `__index__` method.

Exception raised on line 666 of file TESTS:\runtime\test_type_error.py.

   664: def test_Slice_indices_must_be_integers_or_None():
   665:     try:
--&gt;666:         [1, 2, 3][1.0:2.0]
   667:     except TypeError as e:
</pre></div>
</div>
</div>
<div class="section" id="too-few-positional-argument">
<h3>Too few positional argument<a class="headerlink" href="#too-few-positional-argument" title="Permalink to this headline">¶</a></h3>
<div class="highlight-none notranslate"><div class="highlight"><pre><span></span>Traceback (most recent call last):
  File "TESTS:\runtime\test_type_error.py", line 441, in test_Too_few_positional_argument
    fn(1)
TypeError: test_Too_few_positional_argument.&lt;locals&gt;.fn() missing 2 required positional arguments: 'b' and 'c'

A `TypeError` is usually caused by trying
to combine two incompatible types of objects,
by calling a function with the wrong type of object,
or by trying to do an operation not allowed on a given type of object.

You apparently have called the function 'test_Too_few_positional_argument.&lt;locals&gt;.fn()' with
fewer positional arguments than it requires (2 missing).

Exception raised on line 441 of file TESTS:\runtime\test_type_error.py.

   437:     def fn(a, b, c):
   438:         pass
   440:     try:
--&gt;441:         fn(1)
   442:     except TypeError as e:

        fn:  &lt;function fn&gt;
            defined in &lt;function test_Too_few_positional_argument&gt;
</pre></div>
</div>
</div>
<div class="section" id="too-many-positional-argument">
<h3>Too many positional argument<a class="headerlink" href="#too-many-positional-argument" title="Permalink to this headline">¶</a></h3>
<div class="highlight-none notranslate"><div class="highlight"><pre><span></span>Traceback (most recent call last):
  File "TESTS:\runtime\test_type_error.py", line 422, in test_Too_many_positional_argument
    A().f(1)
TypeError: test_Too_many_positional_argument.&lt;locals&gt;.A.f() takes 1 positional argument but 2 were given

    Perhaps you forgot `self` when defining `A.f`.

A `TypeError` is usually caused by trying
to combine two incompatible types of objects,
by calling a function with the wrong type of object,
or by trying to do an operation not allowed on a given type of object.

You apparently have called the function `A.f` with
2 positional argument(s) while it requires 1
such positional argument(s).
Perhaps you forgot `self` when defining `A.f`.

Exception raised on line 422 of file TESTS:\runtime\test_type_error.py.

   418:         def f(x):
   419:             pass
   421:     try:
--&gt;422:         A().f(1)
   423:     except TypeError as e:

        A:  &lt;class A&gt;
            defined in &lt;function test_type_error.test_Too_many_positional_argument&gt;
</pre></div>
</div>
</div>
<div class="section" id="tuple-no-item-assignment">
<h3>Tuple no item assignment<a class="headerlink" href="#tuple-no-item-assignment" title="Permalink to this headline">¶</a></h3>
<div class="highlight-none notranslate"><div class="highlight"><pre><span></span>Traceback (most recent call last):
  File "TESTS:\runtime\test_type_error.py", line 389, in test_Tuple_no_item_assignment
    a[0] = 0
TypeError: 'tuple' object does not support item assignment

    Did you mean to use a list?

A `TypeError` is usually caused by trying
to combine two incompatible types of objects,
by calling a function with the wrong type of object,
or by trying to do an operation not allowed on a given type of object.

In Python, some objects are known as immutable:
once defined, their value cannot be changed.
You tried change part of such an immutable object: a `tuple`,
most likely by using an indexing operation.
Perhaps you meant to use a list instead.

Exception raised on line 389 of file TESTS:\runtime\test_type_error.py.

   386: def test_Tuple_no_item_assignment():
   387:     a = (1, 2, 3)
   388:     try:
--&gt;389:         a[0] = 0
   390:     except TypeError as e:

        a:  (1, 2, 3)
        a[0]:  1
</pre></div>
</div>
</div>
<div class="section" id="unhachable-type">
<h3>Unhachable type<a class="headerlink" href="#unhachable-type" title="Permalink to this headline">¶</a></h3>
<div class="highlight-none notranslate"><div class="highlight"><pre><span></span>Traceback (most recent call last):
  File "TESTS:\runtime\test_type_error.py", line 683, in test_Unhachable_type
    {[1, 2]: 1}
TypeError: unhashable type: 'list'

A `TypeError` is usually caused by trying
to combine two incompatible types of objects,
by calling a function with the wrong type of object,
or by trying to do an operation not allowed on a given type of object.

Only hashable objects can be used
as elements of `set` or keys of `dict`.
Hashable objects are objects that do not change value
once they have been created.Instead of using a `list`, consider using a `tuple`.

Exception raised on line 683 of file TESTS:\runtime\test_type_error.py.

   681: def test_Unhachable_type():
   682:     try:
--&gt;683:         {[1, 2]: 1}
   684:     except TypeError as e:
</pre></div>
</div>
</div>
<div class="section" id="unsupported-operand-types">
<h3>Unsupported operand types<a class="headerlink" href="#unsupported-operand-types" title="Permalink to this headline">¶</a></h3>
<div class="highlight-none notranslate"><div class="highlight"><pre><span></span>Traceback (most recent call last):
  File "TESTS:\runtime\test_type_error.py", line 283, in test_Unsupported_operand_types
    a @= b
TypeError: unsupported operand type(s) for @=: 'str' and 'int'

A `TypeError` is usually caused by trying
to combine two incompatible types of objects,
by calling a function with the wrong type of object,
or by trying to do an operation not allowed on a given type of object.

You tried to use the operator @=
using two incompatible types of objects:
a string (`str`) and an integer (`int`).
This operator is normally used only
for multiplication of matrices.

Exception raised on line 283 of file TESTS:\runtime\test_type_error.py.

   280:     try:
   281:         a = "a"
   282:         b = 2
--&gt;283:         a @= b
   284:     except TypeError as e:

        a:  'a'
        b:  2
</pre></div>
</div>
</div>
<div class="section" id="function-got-multiple-argument">
<h3>function got multiple argument<a class="headerlink" href="#function-got-multiple-argument" title="Permalink to this headline">¶</a></h3>
<div class="highlight-none notranslate"><div class="highlight"><pre><span></span>Traceback (most recent call last):
  File "TESTS:\runtime\test_type_error.py", line 872, in test_function_got_multiple_argument
    fn2(0, a=1)
TypeError: test_function_got_multiple_argument.&lt;locals&gt;.fn2() got multiple values for argument 'a'

A `TypeError` is usually caused by trying
to combine two incompatible types of objects,
by calling a function with the wrong type of object,
or by trying to do an operation not allowed on a given type of object.

You have specified the value of argument `a` more than once
when calling the function named `fn2`.
This function has the following arguments:
`a, b=1`

Exception raised on line 872 of file TESTS:\runtime\test_type_error.py.

   868:     def fn2(a, b=1):
   869:         pass
   871:     try:
--&gt;872:         fn2(0, a=1)
   873:     except TypeError as e:

        fn2:  &lt;function fn2&gt;
            defined in &lt;function test_function_got_multiple_argument&gt;
</pre></div>
</div>
</div>
<div class="section" id="function-has-no-len">
<h3>function has no len<a class="headerlink" href="#function-has-no-len" title="Permalink to this headline">¶</a></h3>
<div class="highlight-none notranslate"><div class="highlight"><pre><span></span>Traceback (most recent call last):
  File "TESTS:\runtime\test_type_error.py", line 797, in test_function_has_no_len
    len(bad)
TypeError: object of type 'function' has no len()

    Did you forget to call `bad`?

A `TypeError` is usually caused by trying
to combine two incompatible types of objects,
by calling a function with the wrong type of object,
or by trying to do an operation not allowed on a given type of object.

I suspect that you forgot to add parentheses to call `bad`.
You might have meant to write:
`len(bad())`

Exception raised on line 797 of file TESTS:\runtime\test_type_error.py.

   793:     def bad():
   794:         pass
   796:     try:
--&gt;797:         len(bad)
   798:     except TypeError as e:

        bad:  &lt;function bad&gt; defined in &lt;function test_function_has_no_len&gt;
        len:  &lt;builtin function len&gt;
</pre></div>
</div>
</div>
<div class="section" id="getattr-attribute-name-must-be-string">
<h3>getattr attribute name must be string<a class="headerlink" href="#getattr-attribute-name-must-be-string" title="Permalink to this headline">¶</a></h3>
<div class="highlight-none notranslate"><div class="highlight"><pre><span></span>Traceback (most recent call last):
  File "TESTS:\runtime\test_type_error.py", line 918, in test_getattr_attribute_name_must_be_string
    getattr("__repr__", 1)  # as reported in issue #77
TypeError: getattr(): attribute name must be string

A `TypeError` is usually caused by trying
to combine two incompatible types of objects,
by calling a function with the wrong type of object,
or by trying to do an operation not allowed on a given type of object.

The second argument of the function `getattr()` must be a string.

Exception raised on line 918 of file TESTS:\runtime\test_type_error.py.

   911:     if friendly_traceback.get_lang() == "en":
   912:         assert (
   913:             "The second argument of the function `hasattr()` must be a string."
   914:             in result
   915:         )
   917:     try:
--&gt;918:         getattr("__repr__", 1)  # as reported in issue #77
   919:     except TypeError as e:

        getattr:  &lt;builtin function getattr&gt;
</pre></div>
</div>
</div>
<div class="section" id="method-got-multiple-argument">
<h3>method got multiple argument<a class="headerlink" href="#method-got-multiple-argument" title="Permalink to this headline">¶</a></h3>
<div class="highlight-none notranslate"><div class="highlight"><pre><span></span>Traceback (most recent call last):
  File "TESTS:\runtime\test_type_error.py", line 891, in test_method_got_multiple_argument
    t.some_method(0, a=1)
TypeError: test_method_got_multiple_argument.&lt;locals&gt;.T.some_method() got multiple values for argument 'a'

A `TypeError` is usually caused by trying
to combine two incompatible types of objects,
by calling a function with the wrong type of object,
or by trying to do an operation not allowed on a given type of object.

You have specified the value of argument `a` more than once
when calling the function named `t.some_method`.
This function has only one argument: `a`

Exception raised on line 891 of file TESTS:\runtime\test_type_error.py.

   887:             pass
   889:     t = T()
   890:     try:
--&gt;891:         t.some_method(0, a=1)
   892:     except TypeError as e:

        t:  &lt;T object&gt;
            defined in &lt;function test_type_error.test_method_got_multiple_argument&gt;
        t.some_method:  &lt;bound method T.some_method&gt;
            of &lt;T object&gt;
            defined in &lt;function test_type_error.test_method_got_multiple_argument&gt;
</pre></div>
</div>
</div>
<div class="section" id="vars-arg-must-have-dict">
<h3>vars arg must have dict<a class="headerlink" href="#vars-arg-must-have-dict" title="Permalink to this headline">¶</a></h3>
<div class="highlight-none notranslate"><div class="highlight"><pre><span></span>Traceback (most recent call last):
  File "TESTS:\runtime\test_type_error.py", line 841, in test_vars_arg_must_have_dict
    vars(f)
TypeError: vars() argument must have __dict__ attribute

A `TypeError` is usually caused by trying
to combine two incompatible types of objects,
by calling a function with the wrong type of object,
or by trying to do an operation not allowed on a given type of object.

The function `vars` is used to list the content of the
`__dict__` attribute of an object.
Object `f` uses `__slots__` instead of `__dict__`.

Exception raised on line 841 of file TESTS:\runtime\test_type_error.py.

   837:         assert no_slots not in result
   838:         assert use_slots not in result
   840:     try:
--&gt;841:         vars(f)
   842:     except TypeError as e:

        f:  &lt;F object&gt;
            defined in &lt;function test_type_error.test_vars_arg_must_have_dict&gt;
        vars:  &lt;builtin function vars&gt;
</pre></div>
</div>
</div>
</div>
<div class="section" id="unboundlocalerror">
<h2>UnboundLocalError<a class="headerlink" href="#unboundlocalerror" title="Permalink to this headline">¶</a></h2>
<div class="section" id="missing-both">
<h3>Missing both<a class="headerlink" href="#missing-both" title="Permalink to this headline">¶</a></h3>
<div class="highlight-none notranslate"><div class="highlight"><pre><span></span>Traceback (most recent call last):
  File "TESTS:\runtime\test_unbound_local_error.py", line 63, in test_Missing_both
    outer_missing_both()
  File "TESTS:\runtime\test_unbound_local_error.py", line 22, in outer_missing_both
    inner()
  File "TESTS:\runtime\test_unbound_local_error.py", line 21, in inner
    spam_missing_both += 1
UnboundLocalError: cannot access local variable 'spam_missing_both' where it is not associated with a value

    Did you forget to add either `global spam_missing_both` or
    `nonlocal spam_missing_both`?

In Python, variables that are used inside a function are known as
local variables. Before they are used, they must be assigned a value.
A variable that is used before it is assigned a value is assumed to
be defined outside that function; it is known as a `global`
(or sometimes `nonlocal`) variable. You cannot assign a value to such
a global variable inside a function without first indicating to
Python that this is a global variable, otherwise you will see
an `UnboundLocalError`.

The name `spam_missing_both` exists in both the global and nonlocal scope.
This can be rather confusing and is not recommended.
Depending on which variable you wanted to refer to, you needed to add either

    global spam_missing_both

or

    nonlocal spam_missing_both

as the first line inside your function.

Execution stopped on line 63 of file TESTS:\runtime\test_unbound_local_error.py.

   61: def test_Missing_both():
   62:     try:
--&gt;63:         outer_missing_both()
   64:     except UnboundLocalError as e:

        global outer_missing_both:  &lt;function outer_missing_both&gt;

Exception raised on line 21 of file TESTS:\runtime\test_unbound_local_error.py.

   20:     def inner():
--&gt;21:         spam_missing_both += 1

        global spam_missing_both:  1
</pre></div>
</div>
</div>
<div class="section" id="missing-global">
<h3>Missing global<a class="headerlink" href="#missing-global" title="Permalink to this headline">¶</a></h3>
<div class="highlight-none notranslate"><div class="highlight"><pre><span></span>Traceback (most recent call last):
  File "TESTS:\runtime\test_unbound_local_error.py", line 27, in test_Missing_global
    outer_missing_global()
  File "TESTS:\runtime\test_unbound_local_error.py", line 10, in outer_missing_global
    inner()
  File "TESTS:\runtime\test_unbound_local_error.py", line 9, in inner
    spam_missing_global += 1
UnboundLocalError: cannot access local variable 'spam_missing_global' where it is not associated with a value

    Did you forget to add `global spam_missing_global`?

In Python, variables that are used inside a function are known as
local variables. Before they are used, they must be assigned a value.
A variable that is used before it is assigned a value is assumed to
be defined outside that function; it is known as a `global`
(or sometimes `nonlocal`) variable. You cannot assign a value to such
a global variable inside a function without first indicating to
Python that this is a global variable, otherwise you will see
an `UnboundLocalError`.

The name `spam_missing_global` exists in the global scope.
Perhaps the statement

    global spam_missing_global

should have been included as the first line inside your function.

Execution stopped on line 27 of file TESTS:\runtime\test_unbound_local_error.py.

   25: def test_Missing_global():
   26:     try:
--&gt;27:         outer_missing_global()
   28:     except UnboundLocalError as e:

        global outer_missing_global:  &lt;function outer_missing_global&gt;

Exception raised on line 9 of file TESTS:\runtime\test_unbound_local_error.py.

   8:     def inner():
--&gt;9:         spam_missing_global += 1

        global spam_missing_global:  1
</pre></div>
</div>
</div>
<div class="section" id="missing-nonlocal">
<h3>Missing nonlocal<a class="headerlink" href="#missing-nonlocal" title="Permalink to this headline">¶</a></h3>
<div class="highlight-none notranslate"><div class="highlight"><pre><span></span>Traceback (most recent call last):
  File "TESTS:\runtime\test_unbound_local_error.py", line 45, in test_Missing_nonlocal
    outer_missing_nonlocal()
  File "TESTS:\runtime\test_unbound_local_error.py", line 16, in outer_missing_nonlocal
    inner()
  File "TESTS:\runtime\test_unbound_local_error.py", line 15, in inner
    spam_missing_nonlocal += 1
UnboundLocalError: cannot access local variable 'spam_missing_nonlocal' where it is not associated with a value

    Did you forget to add `nonlocal spam_missing_nonlocal`?

In Python, variables that are used inside a function are known as
local variables. Before they are used, they must be assigned a value.
A variable that is used before it is assigned a value is assumed to
be defined outside that function; it is known as a `global`
(or sometimes `nonlocal`) variable. You cannot assign a value to such
a global variable inside a function without first indicating to
Python that this is a global variable, otherwise you will see
an `UnboundLocalError`.

The name `spam_missing_nonlocal` exists in the nonlocal scope.
Perhaps the statement

    nonlocal spam_missing_nonlocal

should have been included as the first line inside your function.

Execution stopped on line 45 of file TESTS:\runtime\test_unbound_local_error.py.

   43: def test_Missing_nonlocal():
   44:     try:
--&gt;45:         outer_missing_nonlocal()
   46:     except UnboundLocalError as e:

        global outer_missing_nonlocal:  &lt;function outer_missing_nonlocal&gt;

Exception raised on line 15 of file TESTS:\runtime\test_unbound_local_error.py.

   14:     def inner():
--&gt;15:         spam_missing_nonlocal += 1
</pre></div>
</div>
</div>
<div class="section" id="typo-in-local">
<h3>Typo in local<a class="headerlink" href="#typo-in-local" title="Permalink to this headline">¶</a></h3>
<div class="highlight-none notranslate"><div class="highlight"><pre><span></span>Traceback (most recent call last):
  File "TESTS:\runtime\test_unbound_local_error.py", line 101, in test_Typo_in_local
    test2()
  File "TESTS:\runtime\test_unbound_local_error.py", line 98, in test2
    alpha3 += 1
UnboundLocalError: cannot access local variable 'alpha3' where it is not associated with a value

    Did you mean `alpha2`?

In Python, variables that are used inside a function are known as
local variables. Before they are used, they must be assigned a value.
A variable that is used before it is assigned a value is assumed to
be defined outside that function; it is known as a `global`
(or sometimes `nonlocal`) variable. You cannot assign a value to such
a global variable inside a function without first indicating to
Python that this is a global variable, otherwise you will see
an `UnboundLocalError`.

Instead of writing `alpha3`, perhaps you meant one of the following:
*   Local scope: `alpha2`, `alpha1`

Execution stopped on line 101 of file TESTS:\runtime\test_unbound_local_error.py.

    97:         alpha2 = 1
    98:         alpha3 += 1
   100:     try:
--&gt;101:         test2()
   102:     except UnboundLocalError as e:

        test2:  &lt;function test2&gt; defined in &lt;function test_Typo_in_local&gt;

Exception raised on line 98 of file TESTS:\runtime\test_unbound_local_error.py.

   95:     def test2():
   96:         alpha1 = 1
   97:         alpha2 = 1
--&gt;98:         alpha3 += 1
</pre></div>
</div>
</div>
<div class="section" id="using-name-of-builtin">
<h3>Using name of builtin<a class="headerlink" href="#using-name-of-builtin" title="Permalink to this headline">¶</a></h3>
<div class="highlight-none notranslate"><div class="highlight"><pre><span></span>Traceback (most recent call last):
  File "TESTS:\runtime\test_unbound_local_error.py", line 121, in test_Using_name_of_builtin
    dist([])
  File "TESTS:\runtime\test_unbound_local_error.py", line 117, in dist
    max = max(points)
UnboundLocalError: cannot access local variable 'max' where it is not associated with a value

In Python, variables that are used inside a function are known as
local variables. Before they are used, they must be assigned a value.
A variable that is used before it is assigned a value is assumed to
be defined outside that function; it is known as a `global`
(or sometimes `nonlocal`) variable. You cannot assign a value to such
a global variable inside a function without first indicating to
Python that this is a global variable, otherwise you will see
an `UnboundLocalError`.

`max` is a Python builtin function.
You have tried to assign a value to `max` inside a function
while also using its original meaning in the function.

Note that it is generally not a good idea to give a local variable
the same name as a Python builtin function (like `max`).

Execution stopped on line 121 of file TESTS:\runtime\test_unbound_local_error.py.

   118:         min = min(points)
   119:         return max - min
   120:     try:
--&gt;121:         dist([])
   122:     except UnboundLocalError as e:

        dist:  &lt;function dist&gt; defined in &lt;function test_Using_name_of_builtin&gt;

Exception raised on line 117 of file TESTS:\runtime\test_unbound_local_error.py.

   116:     def dist(points):
--&gt;117:         max = max(points)
                ^^^
   118:         min = min(points)

        max:  &lt;builtin function max&gt;
</pre></div>
</div>
</div>
</div>
<div class="section" id="unknownerror">
<h2>UnknownError<a class="headerlink" href="#unknownerror" title="Permalink to this headline">¶</a></h2>
<div class="section" id="id8">
<h3>Generic<a class="headerlink" href="#id8" title="Permalink to this headline">¶</a></h3>
<div class="highlight-none notranslate"><div class="highlight"><pre><span></span>Traceback (most recent call last):
  File "TESTS:\runtime\test_unknown_error.py", line 12, in test_Generic
    raise UnknownException("Some informative message about an unknown exception.")
UnknownException: Some informative message about an unknown exception.

No information is known about this exception.
Please report this example to
https://github.com/friendly-traceback/friendly-traceback/issues/new
If you are using a REPL, use `www('bug')` to do so.

If you are using the Friendly console, use `www()` to
do an Internet search for this particular case.

Exception raised on line 12 of file TESTS:\runtime\test_unknown_error.py.

    9:     old_debug = friendly_traceback.debug_helper.DEBUG
   10:     friendly_traceback.debug_helper.DEBUG = False
   11:     try:
--&gt;12:         raise UnknownException("Some informative message about an unknown exception.")
   13:     except Exception as e:

        global UnknownException:  &lt;class test_unknown_error.UnknownException&gt;
</pre></div>
</div>
</div>
</div>
<div class="section" id="valueerror">
<h2>ValueError<a class="headerlink" href="#valueerror" title="Permalink to this headline">¶</a></h2>
<div class="section" id="date-invalid-month">
<h3>Date invalid month<a class="headerlink" href="#date-invalid-month" title="Permalink to this headline">¶</a></h3>
<div class="highlight-none notranslate"><div class="highlight"><pre><span></span>Traceback (most recent call last):
  File "TESTS:\runtime\test_value_error.py", line 58, in test_Date_invalid_month
    d = date(2021, 13, 1)
ValueError: month must be in 1..12

    Did you specify an invalid month?

A `ValueError` indicates that a function or an operation
received an argument of the right type, but an inappropriate value.

I am guessing that you specify an invalid value for a month
in a `date` object. Valid values are integers, from 1 to 12.

Exception raised on line 58 of file TESTS:\runtime\test_value_error.py.

   55: def test_Date_invalid_month():
   56:     from datetime import date
   57:     try:
--&gt;58:         d = date(2021, 13, 1)
                   ^^^^^^^^^^^^^^^^^
   59:     except ValueError as e:

        date:  &lt;class datetime.date&gt;
</pre></div>
</div>
</div>
<div class="section" id="not-enough-values-to-unpack">
<h3>Not enough values to unpack<a class="headerlink" href="#not-enough-values-to-unpack" title="Permalink to this headline">¶</a></h3>
<div class="highlight-none notranslate"><div class="highlight"><pre><span></span>Traceback (most recent call last):
  File "TESTS:\runtime\test_value_error.py", line 28, in test_Not_enough_values_to_unpack
    a, b, c = d
ValueError: not enough values to unpack (expected 3, got 2)

A `ValueError` indicates that a function or an operation
received an argument of the right type, but an inappropriate value.

Unpacking is a convenient way to assign a name,
to each item of an iterable.
In this instance, there are more names (3)
than the length of the iterable, a string (`str`) of length 2.

Exception raised on line 28 of file TESTS:\runtime\test_value_error.py.

   24:     assert "ValueError: not enough values to unpack (expected 3, got 2)" in result
   26:     d = "ab"
   27:     try:
--&gt;28:         a, b, c = d
   29:     except ValueError as e:

        d:  'ab'
</pre></div>
</div>
</div>
<div class="section" id="too-many-values-to-unpack">
<h3>Too many values to unpack<a class="headerlink" href="#too-many-values-to-unpack" title="Permalink to this headline">¶</a></h3>
<div class="highlight-none notranslate"><div class="highlight"><pre><span></span>Traceback (most recent call last):
  File "TESTS:\runtime\test_value_error.py", line 43, in test_Too_many_values_to_unpack
    a, b = c
ValueError: too many values to unpack (expected 2)

A `ValueError` indicates that a function or an operation
received an argument of the right type, but an inappropriate value.

Unpacking is a convenient way to assign a name,
to each item of an iterable.
In this instance, there are fewer names (2)
than the length of the iterable, a `list` of length 3.

Exception raised on line 43 of file TESTS:\runtime\test_value_error.py.

   40: def test_Too_many_values_to_unpack():
   41:     c = [1, 2, 3]
   42:     try:
--&gt;43:         a, b = c
   44:     except ValueError as e:

        c:  [1, 2, 3]
</pre></div>
</div>
</div>
<div class="section" id="slots-conflicts-with-class-variable">
<h3>slots conflicts with class variable<a class="headerlink" href="#slots-conflicts-with-class-variable" title="Permalink to this headline">¶</a></h3>
<div class="highlight-none notranslate"><div class="highlight"><pre><span></span>Traceback (most recent call last):
  File "TESTS:\runtime\test_value_error.py", line 72, in test_slots_conflicts_with_class_variable
    class F:
ValueError: 'a' in __slots__ conflicts with class variable

A `ValueError` indicates that a function or an operation
received an argument of the right type, but an inappropriate value.

The name `a` is used both as the name of a class variable
and as a string item in the class `__slots__`;
this is not allowed.

Exception raised on line 72 of file TESTS:\runtime\test_value_error.py.

   70: def test_slots_conflicts_with_class_variable():
   71:     try:
--&gt;72:         class F:
   73:             __slots__ = ["a", "b"]
</pre></div>
</div>
</div>
<div class="section" id="time-strptime-incorrect-format">
<h3>time strptime incorrect format<a class="headerlink" href="#time-strptime-incorrect-format" title="Permalink to this headline">¶</a></h3>
<div class="highlight-none notranslate"><div class="highlight"><pre><span></span>Traceback (most recent call last):
  File "TESTS:\runtime\test_value_error.py", line 98, in test_time_strptime_incorrect_format
    time.strptime("2020-01-01", "%d %m %Y")
ValueError: time data '2020-01-01' does not match format '%d %m %Y'

A `ValueError` indicates that a function or an operation
received an argument of the right type, but an inappropriate value.

The value you gave for the time is not in the format you specified.
Make sure to use the same separator between items
(for example, between day and month) and keep the order the same
in both the data provided and the format you specified.
The following table might be useful:
https://docs.python.org/3/library/time.html#time.strftime
The following site might also be useful: https://www.strfti.me/

Exception raised on line 98 of file TESTS:\runtime\test_value_error.py.

   94:         return
   96:     import time
   97:     try:
--&gt;98:         time.strptime("2020-01-01", "%d %m %Y")
   99:     except ValueError as e:

        time:  &lt;module time (builtin)&gt;
        time.strptime:  &lt;builtin function strptime&gt;
</pre></div>
</div>
</div>
</div>
<div class="section" id="zerodivisionerror">
<h2>ZeroDivisionError<a class="headerlink" href="#zerodivisionerror" title="Permalink to this headline">¶</a></h2>
<div class="section" id="complex-division">
<h3>Complex division<a class="headerlink" href="#complex-division" title="Permalink to this headline">¶</a></h3>
<div class="highlight-none notranslate"><div class="highlight"><pre><span></span>Traceback (most recent call last):
  File "TESTS:\runtime\test_zero_division_error.py", line 155, in test_Complex_division
    1 / zero
ZeroDivisionError: complex division by zero

A `ZeroDivisionError` occurs when you are attempting to divide a value
by zero either directly or by using some other mathematical operation.

You are dividing by the following term

     zero

which is equal to zero.

Exception raised on line 155 of file TESTS:\runtime\test_zero_division_error.py.

   152: def test_Complex_division():
   153:     zero = 0j
   154:     try:
--&gt;155:         1 / zero
   156:     except ZeroDivisionError as e:

        zero:  0j
</pre></div>
</div>
</div>
<div class="section" id="division-by-zero-literal">
<h3>Division by zero literal<a class="headerlink" href="#division-by-zero-literal" title="Permalink to this headline">¶</a></h3>
<div class="highlight-none notranslate"><div class="highlight"><pre><span></span>Traceback (most recent call last):
  File "TESTS:\runtime\test_zero_division_error.py", line 199, in test_Division_by_zero_literal
    1. / 0
ZeroDivisionError: float division by zero

A `ZeroDivisionError` occurs when you are attempting to divide a value
by zero either directly or by using some other mathematical operation.

You are dividing by zero.

Exception raised on line 199 of file TESTS:\runtime\test_zero_division_error.py.

   194:     if friendly_traceback.get_lang() == "en":
   195:         assert "Using the modulo operator, you are dividing by zero" in result
   198:     try:
--&gt;199:         1. / 0
   200:     except ZeroDivisionError as e:
</pre></div>
</div>
</div>
<div class="section" id="division-operator">
<h3>Division operator<a class="headerlink" href="#division-operator" title="Permalink to this headline">¶</a></h3>
<div class="highlight-none notranslate"><div class="highlight"><pre><span></span>Traceback (most recent call last):
  File "TESTS:\runtime\test_zero_division_error.py", line 17, in test_Division_operator
    1 / zero
ZeroDivisionError: division by zero

A `ZeroDivisionError` occurs when you are attempting to divide a value
by zero either directly or by using some other mathematical operation.

You are dividing by the following term

     zero

which is equal to zero.

Exception raised on line 17 of file TESTS:\runtime\test_zero_division_error.py.

   13:     if friendly_traceback.get_lang() == "en":
   14:         assert "The following mathematical expression includes a division by zero" in result
   16:     try:
--&gt;17:         1 / zero
   18:     except ZeroDivisionError as e:

        zero:  0
</pre></div>
</div>
</div>
<div class="section" id="divmod">
<h3>Divmod<a class="headerlink" href="#divmod" title="Permalink to this headline">¶</a></h3>
<div class="highlight-none notranslate"><div class="highlight"><pre><span></span>Traceback (most recent call last):
  File "TESTS:\runtime\test_zero_division_error.py", line 82, in test_Divmod
    divmod(1, zero)
ZeroDivisionError: integer division or modulo by zero

A `ZeroDivisionError` occurs when you are attempting to divide a value
by zero either directly or by using some other mathematical operation.

The second argument of the `divmod()` function is zero.

Exception raised on line 82 of file TESTS:\runtime\test_zero_division_error.py.

   79: def test_Divmod():
   80:     zero = 0
   81:     try:
--&gt;82:         divmod(1, zero)
   83:     except ZeroDivisionError as e:

        zero:  0
        divmod:  &lt;builtin function divmod&gt;
</pre></div>
</div>
</div>
<div class="section" id="float-division">
<h3>Float division<a class="headerlink" href="#float-division" title="Permalink to this headline">¶</a></h3>
<div class="highlight-none notranslate"><div class="highlight"><pre><span></span>Traceback (most recent call last):
  File "TESTS:\runtime\test_zero_division_error.py", line 125, in test_Float_division
    1 / zero
ZeroDivisionError: float division by zero

A `ZeroDivisionError` occurs when you are attempting to divide a value
by zero either directly or by using some other mathematical operation.

You are dividing by the following term

     zero

which is equal to zero.

Exception raised on line 125 of file TESTS:\runtime\test_zero_division_error.py.

   122: def test_Float_division():
   123:     zero = 0.
   124:     try:
--&gt;125:         1 / zero
   126:     except ZeroDivisionError as e:

        zero:  0.0
</pre></div>
</div>
</div>
<div class="section" id="float-divmod">
<h3>Float divmod<a class="headerlink" href="#float-divmod" title="Permalink to this headline">¶</a></h3>
<div class="highlight-none notranslate"><div class="highlight"><pre><span></span>Traceback (most recent call last):
  File "TESTS:\runtime\test_zero_division_error.py", line 140, in test_Float_divmod
    divmod(1, zero)
ZeroDivisionError: float divmod()

A `ZeroDivisionError` occurs when you are attempting to divide a value
by zero either directly or by using some other mathematical operation.

The second argument of the `divmod()` function is equal to zero.

Exception raised on line 140 of file TESTS:\runtime\test_zero_division_error.py.

   137: def test_Float_divmod():
   138:     zero = 0.
   139:     try:
--&gt;140:         divmod(1, zero)
   141:     except ZeroDivisionError as e:

        zero:  0.0
        divmod:  &lt;builtin function divmod&gt;
</pre></div>
</div>
</div>
<div class="section" id="float-modulo">
<h3>Float modulo<a class="headerlink" href="#float-modulo" title="Permalink to this headline">¶</a></h3>
<div class="highlight-none notranslate"><div class="highlight"><pre><span></span>Traceback (most recent call last):
  File "TESTS:\runtime\test_zero_division_error.py", line 110, in test_Float_modulo
    1 % zero
ZeroDivisionError: float modulo

A `ZeroDivisionError` occurs when you are attempting to divide a value
by zero either directly or by using some other mathematical operation.

Using the modulo operator, you are dividing by the following term

     zero

which is equal to zero.

Exception raised on line 110 of file TESTS:\runtime\test_zero_division_error.py.

   106:         assert "The following mathematical expression includes a division by zero" in result
   107:         assert "done using the modulo operator" in result
   109:     try:
--&gt;110:         1 % zero
   111:     except ZeroDivisionError as e:

        zero:  0.0
</pre></div>
</div>
</div>
<div class="section" id="integer-division-operator">
<h3>Integer division operator<a class="headerlink" href="#integer-division-operator" title="Permalink to this headline">¶</a></h3>
<div class="highlight-none notranslate"><div class="highlight"><pre><span></span>Traceback (most recent call last):
  File "TESTS:\runtime\test_zero_division_error.py", line 42, in test_Integer_division_operator
    1 // zero
ZeroDivisionError: integer division or modulo by zero

A `ZeroDivisionError` occurs when you are attempting to divide a value
by zero either directly or by using some other mathematical operation.

You are dividing by the following term

     zero

which is equal to zero.

Exception raised on line 42 of file TESTS:\runtime\test_zero_division_error.py.

   38:     if friendly_traceback.get_lang() == "en":
   39:         assert "The following mathematical expression includes a division by zero" in result
   41:     try:
--&gt;42:         1 // zero
   43:     except ZeroDivisionError as e:

        zero:  0
</pre></div>
</div>
</div>
<div class="section" id="mixed-operations">
<h3>Mixed operations<a class="headerlink" href="#mixed-operations" title="Permalink to this headline">¶</a></h3>
<div class="highlight-none notranslate"><div class="highlight"><pre><span></span>Traceback (most recent call last):
  File "TESTS:\runtime\test_zero_division_error.py", line 212, in test_Mixed_operations
    a = divmod(8, 1 // 2)
ZeroDivisionError: integer division or modulo by zero

A `ZeroDivisionError` occurs when you are attempting to divide a value
by zero either directly or by using some other mathematical operation.

The following mathematical expression includes a division by zero:

    divmod(8, 1 // 2)

Exception raised on line 212 of file TESTS:\runtime\test_zero_division_error.py.

   210: def test_Mixed_operations():
   211:     try:
--&gt;212:         a = divmod(8, 1 // 2)
                    ^^^^^^^^^^^^^^^^^
   213:     except ZeroDivisionError as e:

        divmod:  &lt;builtin function divmod&gt;
        1 // 2:  0
</pre></div>
</div>
</div>
<div class="section" id="modulo-operator">
<h3>Modulo operator<a class="headerlink" href="#modulo-operator" title="Permalink to this headline">¶</a></h3>
<div class="highlight-none notranslate"><div class="highlight"><pre><span></span>Traceback (most recent call last):
  File "TESTS:\runtime\test_zero_division_error.py", line 67, in test_Modulo_operator
    1 % zero
ZeroDivisionError: integer division or modulo by zero

A `ZeroDivisionError` occurs when you are attempting to divide a value
by zero either directly or by using some other mathematical operation.

Using the modulo operator, you are dividing by the following term

     zero

which is equal to zero.

Exception raised on line 67 of file TESTS:\runtime\test_zero_division_error.py.

   63:     if friendly_traceback.get_lang() == "en":
   64:         assert "The following mathematical expression includes a division by zero" in result
   66:     try:
--&gt;67:         1 % zero
   68:     except ZeroDivisionError as e:

        zero:  0
</pre></div>
</div>
</div>
<div class="section" id="raise-zero-negative-power">
<h3>Raise zero negative power<a class="headerlink" href="#raise-zero-negative-power" title="Permalink to this headline">¶</a></h3>
<div class="highlight-none notranslate"><div class="highlight"><pre><span></span>Traceback (most recent call last):
  File "TESTS:\runtime\test_zero_division_error.py", line 170, in test_Raise_zero_negative_power
    zero ** -1
ZeroDivisionError: 0.0 cannot be raised to a negative power

A `ZeroDivisionError` occurs when you are attempting to divide a value
by zero either directly or by using some other mathematical operation.

You are attempting to raise the number 0 to a negative power
which is equivalent to dividing by zero.

Exception raised on line 170 of file TESTS:\runtime\test_zero_division_error.py.

   167: def test_Raise_zero_negative_power():
   168:     zero = 0
   169:     try:
--&gt;170:         zero ** -1
   171:     except ZeroDivisionError as e:

        zero:  0
</pre></div>
</div>
</div>
</div>
</div>

      </article>
      <footer>
        
        <div class="related-pages">
          <a class="next-page" href="syntax_tracebacks_en_3.11.html">
              <div class="page-info">
                <div class="context">
                  <span>Next</span>
                </div>
                <div class="title">Friendly SyntaxError tracebacks - in English</div>
              </div>
              <svg><use href="#svg-arrow-right"></use></svg>
            </a>
          <a class="prev-page" href="syntax_tracebacks_en_3.10.html">
              <svg><use href="#svg-arrow-right"></use></svg>
              <div class="page-info">
                <div class="context">
                  <span>Previous</span>
                </div>
                
                <div class="title">Friendly SyntaxError tracebacks - in English</div>
                
              </div>
            </a>
        </div>

        <div class="related-information">
              Copyright &#169; André Roberge
            |
            Built with <a href="https://www.sphinx-doc.org/">Sphinx</a>
              and
              <a class="muted-link" href="https://pradyunsg.me">@pradyunsg</a>'s
              <a href="https://github.com/pradyunsg/furo">Furo theme</a>.
            |
            <a class="muted-link" href="_sources/tracebacks_en_3.11.rst.txt"
               rel="nofollow">
              Show Source
            </a>
        </div>
        
      </footer>
    </div>
    <aside class="toc-drawer">
      
      
      <div class="toc-sticky toc-scroll">
        <div class="toc-title-container">
          <span class="toc-title">
            Contents
          </span>
        </div>
        <div class="toc-tree-container">
          <div class="toc-tree">
            <ul>
<li><a class="reference internal" href="#">Friendly tracebacks - in English</a><ul>
<li><a class="reference internal" href="#arithmeticerror">ArithmeticError</a><ul>
<li><a class="reference internal" href="#generic">Generic</a></li>
</ul>
</li>
<li><a class="reference internal" href="#assertionerror">AssertionError</a><ul>
<li><a class="reference internal" href="#id1">Generic</a></li>
</ul>
</li>
<li><a class="reference internal" href="#attributeerror">AttributeError</a><ul>
<li><a class="reference internal" href="#attribute-from-other-module">Attribute from other module</a></li>
<li><a class="reference internal" href="#builtin-function">Builtin function</a></li>
<li><a class="reference internal" href="#builtin-module-with-no-file">Builtin module with no file</a></li>
<li><a class="reference internal" href="#circular-import">Circular import</a></li>
<li><a class="reference internal" href="#circular-import-b">Circular import b</a></li>
<li><a class="reference internal" href="#id2">Generic</a></li>
<li><a class="reference internal" href="#generic-different-frame">Generic different frame</a></li>
<li><a class="reference internal" href="#generic-instance">Generic instance</a></li>
<li><a class="reference internal" href="#module-attribute-typo">Module attribute typo</a></li>
<li><a class="reference internal" href="#nonetype">Nonetype</a></li>
<li><a class="reference internal" href="#object-attribute-typo">Object attribute typo</a></li>
<li><a class="reference internal" href="#perhaps-comma">Perhaps comma</a></li>
<li><a class="reference internal" href="#read-only">Read only</a></li>
<li><a class="reference internal" href="#shadow-stdlib-module">Shadow stdlib module</a></li>
<li><a class="reference internal" href="#tuple-by-accident">Tuple by accident</a></li>
<li><a class="reference internal" href="#use-builtin">Use builtin</a></li>
<li><a class="reference internal" href="#use-join-with-str">Use join with str</a></li>
<li><a class="reference internal" href="#use-synonym">Use synonym</a></li>
<li><a class="reference internal" href="#using-slots">Using slots</a></li>
</ul>
</li>
<li><a class="reference internal" href="#filenotfounderror">FileNotFoundError</a><ul>
<li><a class="reference internal" href="#directory-not-found">Directory not found</a></li>
<li><a class="reference internal" href="#filename-not-found">Filename not found</a></li>
<li><a class="reference internal" href="#filename-not-found-2">Filename not found 2</a></li>
<li><a class="reference internal" href="#filename-not-found-3">Filename not found 3</a></li>
</ul>
</li>
<li><a class="reference internal" href="#importerror">ImportError</a><ul>
<li><a class="reference internal" href="#id3">Circular import</a></li>
<li><a class="reference internal" href="#simple-import-error">Simple import error</a></li>
</ul>
</li>
<li><a class="reference internal" href="#indexerror">IndexError</a><ul>
<li><a class="reference internal" href="#assignment">Assignment</a></li>
<li><a class="reference internal" href="#empty">Empty</a></li>
<li><a class="reference internal" href="#long-list">Long list</a></li>
<li><a class="reference internal" href="#short-tuple">Short tuple</a></li>
</ul>
</li>
<li><a class="reference internal" href="#keyerror">KeyError</a><ul>
<li><a class="reference internal" href="#chainmap">ChainMap</a></li>
<li><a class="reference internal" href="#forgot-to-convert-to-string">Forgot to convert to string</a></li>
<li><a class="reference internal" href="#generic-key-error">Generic key error</a></li>
<li><a class="reference internal" href="#popitem-empty-chainmap">Popitem empty ChainMap</a></li>
<li><a class="reference internal" href="#popitem-empty-dict">Popitem empty dict</a></li>
<li><a class="reference internal" href="#similar-names">Similar names</a></li>
<li><a class="reference internal" href="#string-by-mistake">String by mistake</a></li>
</ul>
</li>
<li><a class="reference internal" href="#lookuperror">LookupError</a><ul>
<li><a class="reference internal" href="#id4">Generic</a></li>
</ul>
</li>
<li><a class="reference internal" href="#modulenotfounderror">ModuleNotFoundError</a><ul>
<li><a class="reference internal" href="#need-to-install-module">Need to install module</a></li>
<li><a class="reference internal" href="#not-a-package">Not a package</a></li>
<li><a class="reference internal" href="#not-a-package-similar-name">Not a package similar name</a></li>
<li><a class="reference internal" href="#object-not-module">Object not module</a></li>
<li><a class="reference internal" href="#similar-object-not-module">Similar object not module</a></li>
<li><a class="reference internal" href="#standard-library-module">Standard library module</a></li>
<li><a class="reference internal" href="#no-curses">no curses</a></li>
</ul>
</li>
<li><a class="reference internal" href="#nameerror">NameError</a><ul>
<li><a class="reference internal" href="#annotated-variable">Annotated variable</a></li>
<li><a class="reference internal" href="#custom-name">Custom name</a></li>
<li><a class="reference internal" href="#free-variable-referenced">Free variable referenced</a></li>
<li><a class="reference internal" href="#id5">Generic</a></li>
<li><a class="reference internal" href="#missing-import">Missing import</a></li>
<li><a class="reference internal" href="#missing-module-name">Missing module name</a></li>
<li><a class="reference internal" href="#missing-self-1">Missing self 1</a></li>
<li><a class="reference internal" href="#missing-self-2">Missing self 2</a></li>
<li><a class="reference internal" href="#synonym">Synonym</a></li>
</ul>
</li>
<li><a class="reference internal" href="#oserror">OsError</a><ul>
<li><a class="reference internal" href="#urllib-error">Urllib error</a></li>
<li><a class="reference internal" href="#invalid-argument">invalid argument</a></li>
<li><a class="reference internal" href="#no-information">no information</a></li>
</ul>
</li>
<li><a class="reference internal" href="#overflowerror">OverflowError</a><ul>
<li><a class="reference internal" href="#id6">Generic</a></li>
</ul>
</li>
<li><a class="reference internal" href="#recursionerror">RecursionError</a><ul>
<li><a class="reference internal" href="#id7">Generic</a></li>
</ul>
</li>
<li><a class="reference internal" href="#typeerror">TypeError</a><ul>
<li><a class="reference internal" href="#bad-type-for-unary-operator">Bad type for unary operator</a></li>
<li><a class="reference internal" href="#builtin-has-no-len">Builtin has no len</a></li>
<li><a class="reference internal" href="#can-only-concatenate">Can only concatenate</a></li>
<li><a class="reference internal" href="#cannot-convert-dictionary-update-sequence">Cannot convert dictionary update sequence</a></li>
<li><a class="reference internal" href="#cannot-multiply-by-non-int">Cannot multiply by non int</a></li>
<li><a class="reference internal" href="#cannot-unpack-non-iterable-object">Cannot unpack non iterable object</a></li>
<li><a class="reference internal" href="#comparison-not-supported">Comparison not supported</a></li>
<li><a class="reference internal" href="#derive-from-baseexception">Derive from BaseException</a></li>
<li><a class="reference internal" href="#indices-must-be-integers-or-slices">Indices must be integers or slices</a></li>
<li><a class="reference internal" href="#not-an-integer">Not an integer</a></li>
<li><a class="reference internal" href="#not-callable">Not callable</a></li>
<li><a class="reference internal" href="#object-is-not-iterable">Object is not iterable</a></li>
<li><a class="reference internal" href="#object-is-not-subscriptable">Object is not subscriptable</a></li>
<li><a class="reference internal" href="#slice-indices-must-be-integers-or-none">Slice indices must be integers or None</a></li>
<li><a class="reference internal" href="#too-few-positional-argument">Too few positional argument</a></li>
<li><a class="reference internal" href="#too-many-positional-argument">Too many positional argument</a></li>
<li><a class="reference internal" href="#tuple-no-item-assignment">Tuple no item assignment</a></li>
<li><a class="reference internal" href="#unhachable-type">Unhachable type</a></li>
<li><a class="reference internal" href="#unsupported-operand-types">Unsupported operand types</a></li>
<li><a class="reference internal" href="#function-got-multiple-argument">function got multiple argument</a></li>
<li><a class="reference internal" href="#function-has-no-len">function has no len</a></li>
<li><a class="reference internal" href="#getattr-attribute-name-must-be-string">getattr attribute name must be string</a></li>
<li><a class="reference internal" href="#method-got-multiple-argument">method got multiple argument</a></li>
<li><a class="reference internal" href="#vars-arg-must-have-dict">vars arg must have dict</a></li>
</ul>
</li>
<li><a class="reference internal" href="#unboundlocalerror">UnboundLocalError</a><ul>
<li><a class="reference internal" href="#missing-both">Missing both</a></li>
<li><a class="reference internal" href="#missing-global">Missing global</a></li>
<li><a class="reference internal" href="#missing-nonlocal">Missing nonlocal</a></li>
<li><a class="reference internal" href="#typo-in-local">Typo in local</a></li>
<li><a class="reference internal" href="#using-name-of-builtin">Using name of builtin</a></li>
</ul>
</li>
<li><a class="reference internal" href="#unknownerror">UnknownError</a><ul>
<li><a class="reference internal" href="#id8">Generic</a></li>
</ul>
</li>
<li><a class="reference internal" href="#valueerror">ValueError</a><ul>
<li><a class="reference internal" href="#date-invalid-month">Date invalid month</a></li>
<li><a class="reference internal" href="#not-enough-values-to-unpack">Not enough values to unpack</a></li>
<li><a class="reference internal" href="#too-many-values-to-unpack">Too many values to unpack</a></li>
<li><a class="reference internal" href="#slots-conflicts-with-class-variable">slots conflicts with class variable</a></li>
<li><a class="reference internal" href="#time-strptime-incorrect-format">time strptime incorrect format</a></li>
</ul>
</li>
<li><a class="reference internal" href="#zerodivisionerror">ZeroDivisionError</a><ul>
<li><a class="reference internal" href="#complex-division">Complex division</a></li>
<li><a class="reference internal" href="#division-by-zero-literal">Division by zero literal</a></li>
<li><a class="reference internal" href="#division-operator">Division operator</a></li>
<li><a class="reference internal" href="#divmod">Divmod</a></li>
<li><a class="reference internal" href="#float-division">Float division</a></li>
<li><a class="reference internal" href="#float-divmod">Float divmod</a></li>
<li><a class="reference internal" href="#float-modulo">Float modulo</a></li>
<li><a class="reference internal" href="#integer-division-operator">Integer division operator</a></li>
<li><a class="reference internal" href="#mixed-operations">Mixed operations</a></li>
<li><a class="reference internal" href="#modulo-operator">Modulo operator</a></li>
<li><a class="reference internal" href="#raise-zero-negative-power">Raise zero negative power</a></li>
</ul>
</li>
</ul>
</li>
</ul>

          </div>
        </div>
      </div>
      
      
    </aside>
  </div>
</div><script data-url_root="./" id="documentation_options" src="_static/documentation_options.js"></script>
    <script src="_static/jquery.js"></script>
    <script src="_static/underscore.js"></script>
    <script src="_static/doctools.js"></script>
    <script src="_static/scripts/main.js"></script>
    <script src="_static/tabs.js"></script>
    <script src="_static/clipboard.min.js"></script>
    <script src="_static/copybutton.js"></script>
    </body>
</html>