
Friendly tracebacks - בעברית
======================================

Friendly שואפת לספק משוב ידידותי יותר כאשר מדובר בחריג
מוגדל ממה שנעשה על ידי Python.
(sentence translated by Google Translate).

Below, we can find some examples. SyntaxError cases, as well as TabError and
IndentationError cases, are shown in a separate page.
Not all cases handled by friendly are included here.

.. note::

     The content of this page is generated by running
     `trb_hebrew.py` located in the ``tests/`` directory.
     This needs to be done explicitly, independently of updating the
     documentation using Sphinx.

Friendly-traceback version: 0.7.49
Python version: 3.10.6



ArithmeticError
---------------


Generic
~~~~~~~

.. code-block:: none


    Traceback (most recent call last):
      File "TESTS:\runtime\test_arithmetic_error.py", line 9, in test_Generic
        raise ArithmeticError('error')
    ArithmeticError: error
    
    `ArithmeticError` is the base class for those built-in exceptions
    that are raised for various arithmetic errors.
    
    Exception raised on line `9` of file 'TESTS:\runtime\test_arithmetic_error.py'.
    
        4| def test_Generic():
        5|     try:
        6|         # I am not aware of any way in which this error is raised directly
        7|         # Usually, a subclass such as ZeroDivisionError, etc., would
        8|         # likely be raised.
    --> 9|         raise ArithmeticError('error')
       10|     except ArithmeticError as e:

            ArithmeticError:  <class ArithmeticError>
        


AssertionError
--------------


Generic
~~~~~~~

.. code-block:: none


    Traceback (most recent call last):
      File "TESTS:\runtime\test_assertion_error.py", line 8, in test_Generic
        raise AssertionError("Fake message")
    AssertionError: Fake message
    
    ב-Python, מילת המפתח `assert` משמשת בהצהרות של הטופס
    `assert condition`, כדי לאשר ש`תנאי` אינו `שקר`,
    ולא שווה ערך ל'שקר' כמו רשימה ריקה וכו'.
    
    אם 'תנאי' הוא 'שקר' או שווה ערך, מועלית 'AssertionError'.
    
    Exception raised on line `8` of file 'TESTS:\runtime\test_assertion_error.py'.
    
       4| def test_Generic():
       5|     try:
       6|         # We raise it explicitly, rather than with the keyword assert, since
       7|         # we don't want pytest to rewrite out test.
    -->8|         raise AssertionError("Fake message")
       9|     except AssertionError as e:

            AssertionError:  <class AssertionError>
        


AttributeError
--------------


Attribute from other module
~~~~~~~~~~~~~~~~~~~~~~~~~~~

.. code-block:: none


    Traceback (most recent call last):
      File "TESTS:\runtime\test_attribute_error.py", line 325, in test_Attribute_from_other_module
        keyword.pi
    AttributeError: module 'keyword' has no attribute 'pi'
    
        האם התכוונת לאחד המודולים הבאים: `math, cmath`?
    'AttributeError' מתרחשת כאשר הקוד מכיל משהו כמו
        'object.x'
    ו-'x' אינו שיטה או תכונה (משתנה) השייכת ל-'object'.
    
    במקום המודול `keyword`, אולי רצית להשתמש
    התכונה 'pi' של אחד מהמודולים הבאים:
    `math, cmath`.
    
    Exception raised on line `325` of file 'TESTS:\runtime\test_attribute_error.py'.
    
       321|     assert "Did you mean `math`?" in result
       322| 
       323| import cmath
       324| try:
    -->325|     keyword.pi
                ^^^^^^^^^^
       326| except AttributeError as e:

            keyword:  <module keyword> from PYTHON_LIB:\keyword.py
        


Builtin function
~~~~~~~~~~~~~~~~

.. code-block:: none


    Traceback (most recent call last):
      File "TESTS:\runtime\test_attribute_error.py", line 223, in test_Builtin_function
        len.text
    AttributeError: 'builtin_function_or_method' object has no attribute 'text'
    
        האם התכוונת ל "len (text)"?
        
    'AttributeError' מתרחשת כאשר הקוד מכיל משהו כמו
        'object.x'
    ו-'x' אינו שיטה או תכונה (משתנה) השייכת ל-'object'.
    
    `len` היא פונקציה. אולי התכוונת לכתוב
    `len (text)`
    
    Exception raised on line `223` of file 'TESTS:\runtime\test_attribute_error.py'.
    
       220| def test_Builtin_function():
       221|     text = 'Hello world!'
       222|     try:
    -->223|         len.text
                    ^^^^^^^^
       224|     except AttributeError as e:

            text:  'Hello world!'
            len:  <builtin function len>
        


Builtin module with no file
~~~~~~~~~~~~~~~~~~~~~~~~~~~

.. code-block:: none


    Traceback (most recent call last):
      File "TESTS:\runtime\test_attribute_error.py", line 240, in test_Builtin_module_with_no_file
        sys.foo
    AttributeError: module 'sys' has no attribute 'foo'
    
    'AttributeError' מתרחשת כאשר הקוד מכיל משהו כמו
        'object.x'
    ו-'x' אינו שיטה או תכונה (משתנה) השייכת ל-'object'.
    
    פייתון אומר לנו שאין אובייקט בשם "foo"
    שנמצא במודול `sys`.
    
    Exception raised on line `240` of file 'TESTS:\runtime\test_attribute_error.py'.
    
       236| """Issue 116"""
       237| import sys
       238| 
       239| try:
    -->240|     sys.foo
                ^^^^^^^
       241| except AttributeError as e:

            sys:  <module sys (builtin)>
        


Circular import
~~~~~~~~~~~~~~~

.. code-block:: none


    Traceback (most recent call last):
      File "TESTS:\runtime\test_attribute_error.py", line 355, in test_Circular_import
        import my_turtle1
      File "TESTS:\my_turtle1.py", line 4, in <module>
        a = my_turtle1.something
    AttributeError: partially initialized module 'my_turtle1' has no attribute 'something' (most likely due to a circular import)
    
        האם נתת לתוכנית שלך את אותו שם כמו מודול פייתון?
        
    'AttributeError' מתרחשת כאשר הקוד מכיל משהו כמו
        'object.x'
    ו-'x' אינו שיטה או תכונה (משתנה) השייכת ל-'object'.
    
    אני חושד שהשתמשת בשם 'my_turtle1 .py' עבור התוכנית שלך
    ושאתה גם רוצה לייבא מודול עם אותו שם
    מהספרייה הסטנדרטית של פייתון.
    אם כן, עליך להשתמש בשם אחר לתוכנית שלך.
    
    Execution stopped on line `355` of file 'TESTS:\runtime\test_attribute_error.py'.
    
       352| from friendly_traceback.runtime_errors import stdlib_modules
       353| stdlib_modules.names.add("my_turtle1")
       354| try:
    -->355|    import my_turtle1
       356| except AttributeError as e:

    Exception raised on line `4` of file 'TESTS:\my_turtle1.py'.
    
       1| """To test attribute error of partially initialized module."""
       2| import my_turtle1
       3| 
    -->4| a = my_turtle1.something
              ^^^^^^^^^^^^^^^^^^^^

            my_turtle1:  <module my_turtle1> from TESTS:\my_turtle1.py
        


Circular import b
~~~~~~~~~~~~~~~~~

.. code-block:: none


    Traceback (most recent call last):
      File "TESTS:\runtime\test_attribute_error.py", line 372, in test_Circular_import_b
        import circular_c
      File "TESTS:\circular_c.py", line 4, in <module>
        a = circular_c.something
    AttributeError: partially initialized module 'circular_c' has no attribute 'something' (most likely due to a circular import)
    
        יש לך יבוא מעגלי.
        
    'AttributeError' מתרחשת כאשר הקוד מכיל משהו כמו
        'object.x'
    ו-'x' אינו שיטה או תכונה (משתנה) השייכת ל-'object'.
    
    פייתון ציין כי המודול `{module}` לא יובא במלואו.
    זה יכול לקרות אם במהלך ביצוע הקוד במודול 'circular_c'
    נעשה ניסיון לייבא את אותו מודול שוב.
    
    Execution stopped on line `372` of file 'TESTS:\runtime\test_attribute_error.py'.
    
       370| def test_Circular_import_b():
       371|     try:
    -->372|         import circular_c
       373|     except AttributeError as e:

    Exception raised on line `4` of file 'TESTS:\circular_c.py'.
    
       1| # Attribute error for partially initialize module
       2| import circular_c
       3| 
    -->4| a = circular_c.something
              ^^^^^^^^^^^^^^^^^^^^

            circular_c:  <module circular_c> from TESTS:\circular_c.py
        


Generic
~~~~~~~

.. code-block:: none


    Traceback (most recent call last):
      File "TESTS:\runtime\test_attribute_error.py", line 26, in test_Generic
        A.x  # testing type
    AttributeError: type object 'A' has no attribute 'x'
    
    'AttributeError' מתרחשת כאשר הקוד מכיל משהו כמו
        'object.x'
    ו-'x' אינו שיטה או תכונה (משתנה) השייכת ל-'object'.
    
    לאובייקט 'A' אין תכונה בשם 'x'.
    
    Exception raised on line `26` of file 'TESTS:\runtime\test_attribute_error.py'.
    
       22| class A:
       23|     pass
       24| 
       25| try:
    -->26|     A.x  # testing type
               ^^^
       27| except AttributeError as e:

            A:  <class A> defined in <function test_attribute_error.test_Generic>
        


Generic different frame
~~~~~~~~~~~~~~~~~~~~~~~

.. code-block:: none


    Traceback (most recent call last):
      File "TESTS:\runtime\test_attribute_error.py", line 49, in test_Generic_different_frame
        a.attr
    AttributeError: 'A' object has no attribute 'attr'. Did you mean: 'attr2'?
    
        האם התכוונת ל 'attr2'?
        
    'AttributeError' מתרחשת כאשר הקוד מכיל משהו כמו
        'object.x'
    ו-'x' אינו שיטה או תכונה (משתנה) השייכת ל-'object'.
    
    לאובייקט 'a' אין תכונה בשם 'attr'.
    אולי התכוונת לכתוב 'a. attr2' במקום 'a. attr'
    
    Exception raised on line `49` of file 'TESTS:\runtime\test_attribute_error.py'.
    
       45|     return A()
       46| 
       47| a = f()
       48| try:
    -->49|     a.attr
               ^^^^^^
       50| except AttributeError as e:

            a:  <A object>
                defined in <function test_attribute_error.test_Generic_different_frame.<locals>.f>
        


Generic instance
~~~~~~~~~~~~~~~~

.. code-block:: none


    Traceback (most recent call last):
      File "TESTS:\runtime\test_attribute_error.py", line 67, in test_Generic_instance
        a.x
    AttributeError: 'A' object has no attribute 'x'
    
    'AttributeError' מתרחשת כאשר הקוד מכיל משהו כמו
        'object.x'
    ו-'x' אינו שיטה או תכונה (משתנה) השייכת ל-'object'.
    
    לאובייקט 'a' אין תכונה בשם 'x'.
    
    Exception raised on line `67` of file 'TESTS:\runtime\test_attribute_error.py'.
    
       64|     pass
       65| a = A()
       66| try:
    -->67|     a.x
               ^^^
       68| except AttributeError as e:

            a:  <A object>
                defined in <function test_attribute_error.test_Generic_instance>
        


Module attribute typo
~~~~~~~~~~~~~~~~~~~~~

.. code-block:: none


    Traceback (most recent call last):
      File "TESTS:\runtime\test_attribute_error.py", line 144, in test_Module_attribute_typo
        math.cost
    AttributeError: module 'math' has no attribute 'cost'. Did you mean: 'cos'?
    
        האם התכוונת ל 'cos'?
        
    'AttributeError' מתרחשת כאשר הקוד מכיל משהו כמו
        'object.x'
    ו-'x' אינו שיטה או תכונה (משתנה) השייכת ל-'object'.
    
    Instead of writing `math.cost`, perhaps you meant to write one of 
    the following names which are attributes of module `math`:
    `cos, cosh`
    
    Exception raised on line `144` of file 'TESTS:\runtime\test_attribute_error.py'.
    
       139|     assert "Did you mean `ascii_lowercase`" in result
       140| 
       141| import math
       142| 
       143| try:
    -->144|     math.cost
                ^^^^^^^^^
       145| except AttributeError as e:

            math:  <module math (builtin)>
        


Nonetype
~~~~~~~~

.. code-block:: none


    Traceback (most recent call last):
      File "TESTS:\runtime\test_attribute_error.py", line 183, in test_Nonetype
        a.b
    AttributeError: 'NoneType' object has no attribute 'b'
    
    'AttributeError' מתרחשת כאשר הקוד מכיל משהו כמו
        'object.x'
    ו-'x' אינו שיטה או תכונה (משתנה) השייכת ל-'object'.
    
    אתה מנסה לגשת למאפיין 'b'
    עבור משתנה שערכו 'כלום'(none).
    Exception raised on line `183` of file 'TESTS:\runtime\test_attribute_error.py'.
    
       180| def test_Nonetype():
       181|     a = None
       182|     try:
    -->183|         a.b
                    ^^^
       184|     except AttributeError as e:

            a:  None
        


Object attribute typo
~~~~~~~~~~~~~~~~~~~~~

.. code-block:: none


    Traceback (most recent call last):
      File "TESTS:\runtime\test_attribute_error.py", line 83, in test_Object_attribute_typo
        a.appendh(4)
    AttributeError: 'list' object has no attribute 'appendh'. Did you mean: 'append'?
    
        האם התכוונת ל 'append'?
        
    'AttributeError' מתרחשת כאשר הקוד מכיל משהו כמו
        'object.x'
    ו-'x' אינו שיטה או תכונה (משתנה) השייכת ל-'object'.
    
    לאובייקט 'a' אין תכונה בשם 'appendh'.
    אולי התכוונת לכתוב 'a. append' במקום 'a. appendh'
    
    Exception raised on line `83` of file 'TESTS:\runtime\test_attribute_error.py'.
    
       79| def test_Object_attribute_typo():
       80|     #
       81|     try:
       82|         a = [1, 2, 3]
    -->83|         a.appendh(4)
                   ^^^^^^^^^
       84|     except AttributeError as e:

            a:  [1, 2, 3]
        


Perhaps comma
~~~~~~~~~~~~~

.. code-block:: none

            Skipped test

Read only
~~~~~~~~~

.. code-block:: none


    Traceback (most recent call last):
      File "TESTS:\runtime\test_attribute_error.py", line 280, in test_Read_only
        f.b = 1
    AttributeError: 'F' object attribute 'b' is read-only
    
    'AttributeError' מתרחשת כאשר הקוד מכיל משהו כמו
        'object.x'
    ו-'x' אינו שיטה או תכונה (משתנה) השייכת ל-'object'.
    
    Object `f` uses `__slots__` to specify which attributes can
    be changed. The value of attribute `f.b` cannot be changed.
    The only attribute of `f` whose value can be changed is`a`.
    
    Exception raised on line `280` of file 'TESTS:\runtime\test_attribute_error.py'.
    
       276|     b = 2
       277| 
       278| f = F()
       279| try:
    -->280|     f.b = 1
                ^^^
       281| except AttributeError as e:

            f:  <F object>
                defined in <function test_attribute_error.test_Read_only>
            f.b:  2
        


Shadow stdlib module
~~~~~~~~~~~~~~~~~~~~

.. code-block:: none


    Traceback (most recent call last):
      File "TESTS:\runtime\test_attribute_error.py", line 165, in test_Shadow_stdlib_module
        turtle.Pen
    AttributeError: module 'turtle' has no attribute 'Pen'
    
        האם נתת לתוכנית שלך את אותו שם כמו מודול פייתון?
        
    'AttributeError' מתרחשת כאשר הקוד מכיל משהו כמו
        'object.x'
    ו-'x' אינו שיטה או תכונה (משתנה) השייכת ל-'object'.
    
    You imported a module named `turtle` from `TESTS:\turtle.py`.
    There is also a module named `turtle` in Python's standard library.
    Perhaps you need to rename your module.
    
    Exception raised on line `165` of file 'TESTS:\runtime\test_attribute_error.py'.
    
       161| def test_Shadow_stdlib_module():
       162|     import turtle
       163| 
       164|     try:
    -->165|         turtle.Pen
                    ^^^^^^^^^^
       166|     except AttributeError as e:

            turtle:  <module turtle> from TESTS:\turtle.py
        


Tuple by accident
~~~~~~~~~~~~~~~~~

.. code-block:: none


    Traceback (most recent call last):
      File "TESTS:\runtime\test_attribute_error.py", line 295, in test_Tuple_by_accident
        something.upper()
    AttributeError: 'tuple' object has no attribute 'upper'
    
        כתבת פסיק בטעות?
        
    'AttributeError' מתרחשת כאשר הקוד מכיל משהו כמו
        'object.x'
    ו-'x' אינו שיטה או תכונה (משתנה) השייכת ל-'object'.
    
    `something` הוא צמד (tuple ) המכיל פריט בודד
    אשר אכן מכיל "'upper' 'כתכונה.
    אולי הוספת פסיק נגרר בטעות בסוף השורה
    שם הגדרת את "something".
    
    Exception raised on line `295` of file 'TESTS:\runtime\test_attribute_error.py'.
    
       292| def test_Tuple_by_accident():
       293|     something = "abc",  # note trailing comma
       294|     try:
    -->295|         something.upper()
                    ^^^^^^^^^^^^^^^
       296|     except AttributeError as e:

            something:  ('abc',)
        


Use builtin
~~~~~~~~~~~

.. code-block:: none


    Traceback (most recent call last):
      File "TESTS:\runtime\test_attribute_error.py", line 99, in test_Use_builtin
        a.length()
    AttributeError: 'list' object has no attribute 'length'
    
        האם התכוונת ל 'len(a)'?
        
    'AttributeError' מתרחשת כאשר הקוד מכיל משהו כמו
        'object.x'
    ו-'x' אינו שיטה או תכונה (משתנה) השייכת ל-'object'.
    
    לאובייקט 'a' אין תכונה בשם 'length'.
    אולי תוכל להשתמש בפונקציה הסטנדרטית  של Python `len` במקום:
    `len(a)`.
    Exception raised on line `99` of file 'TESTS:\runtime\test_attribute_error.py'.
    
        95| def test_Use_builtin():
        96|     #
        97|     try:
        98|         a = [1, 2, 3]
    --> 99|         a.length()
                    ^^^^^^^^
       100|     except AttributeError as e:

            a:  [1, 2, 3]
        


Use join with str
~~~~~~~~~~~~~~~~~

.. code-block:: none


    Traceback (most recent call last):
      File "TESTS:\runtime\test_attribute_error.py", line 339, in test_Use_join_with_str
        a = ['a', '2'].join('abc') + ['b', '3'].join('\n')
    AttributeError: 'list' object has no attribute 'join'
    
        האם התכוונת ל ''abc'.join(['a', '2']) `?
        
    'AttributeError' מתרחשת כאשר הקוד מכיל משהו כמו
        'object.x'
    ו-'x' אינו שיטה או תכונה (משתנה) השייכת ל-'object'.
    
    לאובייקט '['a', '2']' אין תכונה בשם 'join'.
    אולי רצית משהו כמו ''abc'.join(['a', '2'])'.
    
    Exception raised on line `339` of file 'TESTS:\runtime\test_attribute_error.py'.
    
       337| def test_Use_join_with_str():
       338|     try:
    -->339|         a = ['a', '2'].join('abc') + ['b', '3'].join('\n')
                        ^^^^^^^^^^^^^^^
       340|     except AttributeError as e:


Use synonym
~~~~~~~~~~~

.. code-block:: none


    Traceback (most recent call last):
      File "TESTS:\runtime\test_attribute_error.py", line 115, in test_Use_synonym
        a.add(4)
    AttributeError: 'list' object has no attribute 'add'
    
        האם התכוונת ל 'append'?
        
    'AttributeError' מתרחשת כאשר הקוד מכיל משהו כמו
        'object.x'
    ו-'x' אינו שיטה או תכונה (משתנה) השייכת ל-'object'.
    
    לאובייקט 'a' אין תכונה בשם 'add'.
    עם זאת, ל- 'a' יש את התכונות הבאות בעלות משמעויות דומות:
    `append, extend, insert`.
    
    Exception raised on line `115` of file 'TESTS:\runtime\test_attribute_error.py'.
    
       111| def test_Use_synonym():
       112|     #
       113|     try:
       114|         a = [1, 2, 3]
    -->115|         a.add(4)
                    ^^^^^
       116|     except AttributeError as e:

            a:  [1, 2, 3]
        


Using slots
~~~~~~~~~~~

.. code-block:: none


    Traceback (most recent call last):
      File "TESTS:\runtime\test_attribute_error.py", line 260, in test_Using_slots
        f.b = 1
    AttributeError: 'F' object has no attribute 'b'
    
    'AttributeError' מתרחשת כאשר הקוד מכיל משהו כמו
        'object.x'
    ו-'x' אינו שיטה או תכונה (משתנה) השייכת ל-'object'.
    
    לאובייקט 'f' אין תכונה בשם 'b'.
    שים לב שהאובייקט `f` משתמש ב- `__slots__` אשר מונע
    יצירת תכונות חדשות.
    להלן כמה מהתכונות הידועות:
    `a`.
    Exception raised on line `260` of file 'TESTS:\runtime\test_attribute_error.py'.
    
       256|     __slots__ = ["a"]
       257| 
       258| f = F()
       259| try:
    -->260|     f.b = 1
                ^^^
       261| except AttributeError as e:

            f:  <F object>
                defined in <function test_attribute_error.test_Using_slots>
        


FileNotFoundError
-----------------


Directory not found
~~~~~~~~~~~~~~~~~~~

.. code-block:: none


    Traceback (most recent call last):
      File "TESTS:\runtime\test_file_not_found_error.py", line 70, in test_Directory_not_found
        open("does_not_exist/file.txt")
    FileNotFoundError: [Errno 2] No such file or directory: 'does_not_exist/file.txt'
    
    חריג של 'FileNotFoundError' מציין
    שמנסים לפתוח קובץ שפייתון לא מצא.
    זה יכול להיות בגלל שגיאת כתיב בשם הקובץ.
    
    בתוכנית שלך, שם ה-
    הקובץ שלא ניתן למצוא הוא 'file.txt'.
    does_not_exist
    is not a valid directory.
    
    Exception raised on line `70` of file 'TESTS:\runtime\test_file_not_found_error.py'.
    
       68| def test_Directory_not_found():
       69|     try:
    -->70|         open("does_not_exist/file.txt")
                   ^^^^^^^^^^^^^^^^^^^^^^^^^^^^^^^
       71|     except FileNotFoundError as e:

            open:  <builtin function open>
        


Filename not found
~~~~~~~~~~~~~~~~~~

.. code-block:: none


    Traceback (most recent call last):
      File "TESTS:\runtime\test_file_not_found_error.py", line 7, in test_Filename_not_found
        open("does_not_exist")
    FileNotFoundError: [Errno 2] No such file or directory: 'does_not_exist'
    
    חריג של 'FileNotFoundError' מציין
    שמנסים לפתוח קובץ שפייתון לא מצא.
    זה יכול להיות בגלל שגיאת כתיב בשם הקובץ.
    
    בתוכנית שלך, שם ה-
    הקובץ שלא ניתן למצוא הוא 'does_not_exist'.
    It was expected to be found in the
    `C:\Users\Andre\github\friendly-traceback\tests` directory.
    אין לי מידע נוסף עבורך.
    
    Exception raised on line `7` of file 'TESTS:\runtime\test_file_not_found_error.py'.
    
       5| def test_Filename_not_found():
       6|     try:
    -->7|         open("does_not_exist")
                  ^^^^^^^^^^^^^^^^^^^^^^
       8|     except FileNotFoundError as e:

            open:  <builtin function open>
        


Filename not found 2
~~~~~~~~~~~~~~~~~~~~

.. code-block:: none


    Traceback (most recent call last):
      File "TESTS:\runtime\test_file_not_found_error.py", line 30, in test_Filename_not_found_2
        open("setupp.py")
    FileNotFoundError: [Errno 2] No such file or directory: 'setupp.py'
    
        האם התכוונת ל`setup.py`?
        
    חריג של 'FileNotFoundError' מציין
    שמנסים לפתוח קובץ שפייתון לא מצא.
    זה יכול להיות בגלל שגיאת כתיב בשם הקובץ.
    
    בתוכנית שלך, שם ה-
    הקובץ שלא ניתן למצוא הוא 'setupp.py'.
    It was expected to be found in the
    `C:\Users\Andre\github\friendly-traceback` directory.
    לקובץ `setup.py` יש שם דומה.
    
    Exception raised on line `30` of file 'TESTS:\runtime\test_file_not_found_error.py'.
    
       26| if chdir:
       27|     os.chdir("..")
       28| 
       29| try:
    -->30|     open("setupp.py")
               ^^^^^^^^^^^^^^^^^
       31| except FileNotFoundError as e:

            open:  <builtin function open>
        


Filename not found 3
~~~~~~~~~~~~~~~~~~~~

.. code-block:: none


    Traceback (most recent call last):
      File "TESTS:\runtime\test_file_not_found_error.py", line 52, in test_Filename_not_found_3
        open("setup.pyg")
    FileNotFoundError: [Errno 2] No such file or directory: 'setup.pyg'
    
        האם התכוונת ל`setup.py`?
        
    חריג של 'FileNotFoundError' מציין
    שמנסים לפתוח קובץ שפייתון לא מצא.
    זה יכול להיות בגלל שגיאת כתיב בשם הקובץ.
    
    בתוכנית שלך, שם ה-
    הקובץ שלא ניתן למצוא הוא 'setup.pyg'.
    It was expected to be found in the
    `C:\Users\Andre\github\friendly-traceback` directory.
    אולי התכוונת לאחד מהקבצים הבאים עם שמות דומים:
    `setup.py`, `setup.cfg`
    
    Exception raised on line `52` of file 'TESTS:\runtime\test_file_not_found_error.py'.
    
       49| if chdir:
       50|     os.chdir("..")
       51| try:
    -->52|     open("setup.pyg")
               ^^^^^^^^^^^^^^^^^
       53| except FileNotFoundError as e:

            open:  <builtin function open>
        


ImportError
-----------


Simple import error
~~~~~~~~~~~~~~~~~~~

.. code-block:: none


    Traceback (most recent call last):
      File "TESTS:\runtime\test_import_error.py", line 56, in test_Simple_import_error
        from math import Pi
    ImportError: cannot import name 'Pi' from 'math' (unknown location)
    
        האם התכוונת ל 'pi'?
        
    חריג של 'ImportError' מציין כי אובייקט מסוים לא יכול היה
    להיות מיובא ממודול או מחבילה. לרוב, זה קורה
    כי שם האובייקט לא מאוית נכון.
    
    אולי התכוונת לייבא 'pi' (מתוך 'math') במקום 'Pi'
    
    Exception raised on line `56` of file 'TESTS:\runtime\test_import_error.py'.
    
       52| multiple_import_on_same_line()
       53| wrong_case()
       54| 
       55| try:
    -->56|     from math import Pi
       57| except ImportError as e:


IndexError
----------


Assignment
~~~~~~~~~~

.. code-block:: none


    Traceback (most recent call last):
      File "TESTS:\runtime\test_index_error.py", line 84, in test_Assignment
        a[13] = 1
    IndexError: list assignment index out of range
    
    'IndexError' מתרחש כשאתה מנסה להשיג פריט מרשימה,
    צמד או אובייקט דומה (רצף), ומשתמש באינדקס אשר
    לא קיים; בדרך כלל, זה קורה מכיוון שהאינדקס שאתה נותן
    גדול מאורך הרצף.
    
    You have tried to assign a value to index `13` of `a`,
    רשימה (`list`) of length `10`.
    ערכי האינדקס התקפים של 'a' הם מספרים שלמים הנעים בין
    `-10` עד `9`.
    
    Exception raised on line `84` of file 'TESTS:\runtime\test_index_error.py'.
    
       80|     assert "You have tried to assign a value to index `1` of `b`," in result
       81|     assert "a `list` which contains no item." in result
       82| 
       83| try:
    -->84|     a[13] = 1
               ^^^^^
       85| except IndexError as e:

            a:  [0, 1, 2, 3, 4, 5, 6, 7, 8, 9]
        


Empty
~~~~~

.. code-block:: none


    Traceback (most recent call last):
      File "TESTS:\runtime\test_index_error.py", line 40, in test_Empty
        c = a[1]
    IndexError: list index out of range
    
        `a` אינו מכיל פריט.
        
    'IndexError' מתרחש כשאתה מנסה להשיג פריט מרשימה,
    צמד או אובייקט דומה (רצף), ומשתמש באינדקס אשר
    לא קיים; בדרך כלל, זה קורה מכיוון שהאינדקס שאתה נותן
    גדול מאורך הרצף.
    
    ניסית לקבל את הפריט עם האינדקס '1' של 'a',
    רשימה (`list`) שאינו מכיל פריט.
    
    Exception raised on line `40` of file 'TESTS:\runtime\test_index_error.py'.
    
       37| def test_Empty():
       38|     a = []
       39|     try:
    -->40|         c = a[1]
                       ^^^^
       41|     except IndexError as e:

            a:  []
        


Long list
~~~~~~~~~

.. code-block:: none


    Traceback (most recent call last):
      File "TESTS:\runtime\test_index_error.py", line 26, in test_Long_list
        print(a[60], b[0])
    IndexError: list index out of range
    
    'IndexError' מתרחש כשאתה מנסה להשיג פריט מרשימה,
    צמד או אובייקט דומה (רצף), ומשתמש באינדקס אשר
    לא קיים; בדרך כלל, זה קורה מכיוון שהאינדקס שאתה נותן
    גדול מאורך הרצף.
    
    ניסית לקבל את הפריט עם האינדקס '60' של 'a',
    רשימה (`list`) של אורך `40`.
    ערכי האינדקס התקפים של 'a' הם מספרים שלמים הנעים בין
    `-40` עד `39`.
    
    Exception raised on line `26` of file 'TESTS:\runtime\test_index_error.py'.
    
       23| a = list(range(40))
       24| b = tuple(range(50))
       25| try:
    -->26|     print(a[60], b[0])
                     ^^^^^
       27| except IndexError as e:

            a:  [0, 1, 2, 3, 4, 5, 6, 7, 8, 9, 10, 11, 12, 13, 14, 15, 16, 17, 18, ...]
                len(a): 40
        
        


Short tuple
~~~~~~~~~~~

.. code-block:: none


    Traceback (most recent call last):
      File "TESTS:\runtime\test_index_error.py", line 10, in test_Short_tuple
        print(a[3], b[2])
    IndexError: tuple index out of range
    
        זכור: הפריט הראשון של צמד ('tuple') אינו באינדקס 1 אלא באינדקס 0.
        
    'IndexError' מתרחש כשאתה מנסה להשיג פריט מרשימה,
    צמד או אובייקט דומה (רצף), ומשתמש באינדקס אשר
    לא קיים; בדרך כלל, זה קורה מכיוון שהאינדקס שאתה נותן
    גדול מאורך הרצף.
    
    ניסית לקבל את הפריט עם האינדקס '3' של 'a',
    צמד ('tuple') של אורך `3`.
    ערכי האינדקס התקפים של 'a' הם מספרים שלמים הנעים בין
    `-3` עד `2`.
    
    Exception raised on line `10` of file 'TESTS:\runtime\test_index_error.py'.
    
        7| a = (1, 2, 3)
        8| b = [1, 2, 3]
        9| try:
    -->10|     print(a[3], b[2])
                     ^^^^
       11| except IndexError as e:

            a:  (1, 2, 3)
        


KeyError
--------


ChainMap
~~~~~~~~

.. code-block:: none


    Traceback (most recent call last):
      File "PYTHON_LIB:\collections\__init__.py", line 1056, in pop
        return self.maps[0].pop(key, *args)
    KeyError: 42
    
        During handling of the above exception, another exception occurred:
    
    Traceback (most recent call last):
      File "TESTS:\runtime\test_key_error.py", line 62, in test_ChainMap
        d.pop(42)
    KeyError: 'Key not found in the first mapping: 42'
    
    'KeyError' נזרק כאשר ערך אינו נמצא כ-
    מפתח במילון או באובייקט דומה.
    
    לא ניתן למצוא את המפתח '42' ב- 'd', אובייקט מסוג 'ChainMap'.
    
    Exception raised on line `62` of file 'TESTS:\runtime\test_key_error.py'.
    
       59| from collections import ChainMap
       60| d = ChainMap({}, {})
       61| try:
    -->62|     d.pop(42)
               ^^^^^^^^^
       63| except KeyError as e:

            d:  ChainMap({}, {})
            d.pop:  <bound method ChainMap.pop> of ChainMap({}, {})
        


Forgot to convert to string
~~~~~~~~~~~~~~~~~~~~~~~~~~~

.. code-block:: none


    Traceback (most recent call last):
      File "TESTS:\runtime\test_key_error.py", line 115, in test_Forgot_to_convert_to_string
        print(squares[2])
    KeyError: 2
    
        שכחת להמיר את '2' למחרוזת?
        
    'KeyError' נזרק כאשר ערך אינו נמצא כ-
    מפתח במילון או באובייקט דומה.
    
    לא ניתן למצוא את המפתח `2` במילון (dict) בשם `squares`.
    `squares` מכיל מפתח מחרוזת שזהה ל- `str(2)`.
    אולי שכחת להמיר את המפתח למחרוזת.
    
    Exception raised on line `115` of file 'TESTS:\runtime\test_key_error.py'.
    
       112| def test_Forgot_to_convert_to_string():
       113|     squares = {"1": 1, "2": 4, "3": 9}
       114|     try:
    -->115|         print(squares[2])
                          ^^^^^^^^^^
       116|     except KeyError as e:

            squares:  {'1': 1, '2': 4, '3': 9}
        


Generic key error
~~~~~~~~~~~~~~~~~

.. code-block:: none


    Traceback (most recent call last):
      File "TESTS:\runtime\test_key_error.py", line 44, in test_Generic_key_error
        d["c"]
    KeyError: 'c'
    
    'KeyError' נזרק כאשר ערך אינו נמצא כ-
    מפתח במילון או באובייקט דומה.
    
    לא ניתן למצוא את המפתח `'c'` במילון (dict) בשם `d`.
    
    Exception raised on line `44` of file 'TESTS:\runtime\test_key_error.py'.
    
       41| def test_Generic_key_error():
       42|     d = {"a": 1, "b": 2}
       43|     try:
    -->44|         d["c"]
                   ^^^^^^
       45|     except KeyError as e:

            d:  {'a': 1, 'b': 2}
        


Popitem empty ChainMap
~~~~~~~~~~~~~~~~~~~~~~

.. code-block:: none


    Traceback (most recent call last):
      File "PYTHON_LIB:\collections\__init__.py", line 1049, in popitem
        return self.maps[0].popitem()
    KeyError: 'popitem(): dictionary is empty'
    
        During handling of the above exception, another exception occurred:
    
    Traceback (most recent call last):
      File "TESTS:\runtime\test_key_error.py", line 26, in test_Popitem_empty_ChainMap
        alpha.popitem()
    KeyError: 'No keys found in the first mapping.'
    
        `alpha` הוא `ChainMap` ריק.
        
    'KeyError' נזרק כאשר ערך אינו נמצא כ-
    מפתח במילון או באובייקט דומה.
    
    ניסית לקבל פריט מתוך 'alpha' שהוא 'ChainMap' ריק.
    
    Exception raised on line `26` of file 'TESTS:\runtime\test_key_error.py'.
    
       23| from collections import ChainMap
       24| alpha = ChainMap({}, {})
       25| try:
    -->26|     alpha.popitem()
               ^^^^^^^^^^^^^^^
       27| except KeyError as e:

            alpha:  ChainMap({}, {})
            alpha.popitem:  <bound method ChainMap.popitem> of ChainMap({}, {})
        


Popitem empty dict
~~~~~~~~~~~~~~~~~~

.. code-block:: none


    Traceback (most recent call last):
      File "TESTS:\runtime\test_key_error.py", line 8, in test_Popitem_empty_dict
        d.popitem()
    KeyError: 'popitem(): dictionary is empty'
    
        'd' הוא מילון ('dict') ריק.
        
    'KeyError' נזרק כאשר ערך אינו נמצא כ-
    מפתח במילון או באובייקט דומה.
    
    ניסית לקבל פריט מתוך 'd' שהוא מילון ('dict') ריק.
    
    Exception raised on line `8` of file 'TESTS:\runtime\test_key_error.py'.
    
       5| def test_Popitem_empty_dict():
       6|     d = {}
       7|     try:
    -->8|         d.popitem()
                  ^^^^^^^^^^^
       9|     except KeyError as e:

            d:  {}
            d.popitem:  <builtin method popitem of dict object>
        


Similar names
~~~~~~~~~~~~~

.. code-block:: none


    Traceback (most recent call last):
      File "TESTS:\runtime\test_key_error.py", line 145, in test_Similar_names
        a = second["alpha"]
    KeyError: 'alpha'
    
        האם התכוונת ל ''alpha0''?
        
    'KeyError' נזרק כאשר ערך אינו נמצא כ-
    מפתח במילון או באובייקט דומה.
    
    לא ניתן למצוא את המפתח `'alpha'` במילון (dict) בשם `second`.
    'second' מכיל כמה מפתחות הדומים ל- ''alpha'' כולל:
    `'alpha0', 'alpha11', 'alpha12'`.
    
    Exception raised on line `145` of file 'TESTS:\runtime\test_key_error.py'.
    
       141|     assert ok, diff
       142| 
       143| second = {"alpha0": 1, "alpha11": 2, "alpha12": 3}
       144| try:
    -->145|     a = second["alpha"]
                    ^^^^^^^^^^^^^^^
       146| except KeyError as e:

            second:  {'alpha0': 1, 'alpha11': 2, 'alpha12': 3}
        


String by mistake
~~~~~~~~~~~~~~~~~

.. code-block:: none


    Traceback (most recent call last):
      File "TESTS:\runtime\test_key_error.py", line 98, in test_String_by_mistake
        d["(0, 0)"]
    KeyError: '(0, 0)'
    
        האם המרת את '(0, 0)' למחרוזת בטעות?
        
    'KeyError' נזרק כאשר ערך אינו נמצא כ-
    מפתח במילון או באובייקט דומה.
    
    לא ניתן למצוא את המפתח `'(0, 0)'` במילון (dict) בשם `d`.
    `'(0, 0)'` היא מחרוזת.
    יש מפתח של 'd' שייצוג המחרוזות שלו
    זהה ל- ''(0, 0)''.
    
    Exception raised on line `98` of file 'TESTS:\runtime\test_key_error.py'.
    
       94| chain_map_string_by_mistake()  # do not show in docs
       95| 
       96| d = {(0, 0): "origin"}
       97| try:
    -->98|     d["(0, 0)"]
               ^^^^^^^^^^^
       99| except KeyError as e:

            d:  {(0, 0): 'origin'}
        


LookupError
-----------


Generic
~~~~~~~

.. code-block:: none


    Traceback (most recent call last):
      File "TESTS:\runtime\test_lookup_error.py", line 10, in test_Generic
        raise LookupError("Fake message")
    LookupError: Fake message
    
    'LookupError' היא מחלקת הבסיס לחריגים שמועלים
    כאשר המפתח או אינדקס שמשתמשים בהם על מפה או רצף (רשימה,צמד וכדומה) אינם תקפים.
    ניתן גם להעלות אותו ישירות על ידי codecs.lookup ().
    
    Exception raised on line `10` of file 'TESTS:\runtime\test_lookup_error.py'.
    
        4| def test_Generic():
        5|     try:
        6|         # LookupError is the base class for KeyError and IndexError.
        7|         # It should normally not be raised by user code,
        8|         # other than possibly codecs.lookup(), which is why we raise
        9|         # it directly here for our example.
    -->10|         raise LookupError("Fake message")
       11|     except LookupError as e:

            LookupError:  <class LookupError>
        


ModuleNotFoundError
-------------------


Need to install module
~~~~~~~~~~~~~~~~~~~~~~

.. code-block:: none


    Traceback (most recent call last):
      File "TESTS:\runtime\test_module_not_found_error.py", line 76, in test_Need_to_install_module
        import alphabet
    ModuleNotFoundError: No module named 'alphabet'
    
    חריג `ModuleNotFoundError` נזרק כאשר
    מנסים לייבא מודול שפייתון לא מצא .
    זה יכול להיות בגלל שגיאת כתיב בשם המודול
    או מכיוון שהוא לא מותקן במחשב שלך.
    
    לא ניתן לייבא מודול בשם 'alphabet'.
    אולי אתה צריך להתקין אותו.
    
    Exception raised on line `76` of file 'TESTS:\runtime\test_module_not_found_error.py'.
    
       74| def test_Need_to_install_module():
       75|     try:
    -->76|         import alphabet
       77|     except ModuleNotFoundError as e:


Not a package
~~~~~~~~~~~~~

.. code-block:: none


    Traceback (most recent call last):
      File "TESTS:\runtime\test_module_not_found_error.py", line 22, in test_Not_a_package
        import os.xxx
    ModuleNotFoundError: No module named 'os.xxx'; 'os' is not a package
    
    חריג `ModuleNotFoundError` נזרק כאשר
    מנסים לייבא מודול שפייתון לא מצא .
    זה יכול להיות בגלל שגיאת כתיב בשם המודול
    או מכיוון שהוא לא מותקן במחשב שלך.
    
    לא ניתן לייבא את 'xxx' מתוך 'os'.
    
    Exception raised on line `22` of file 'TESTS:\runtime\test_module_not_found_error.py'.
    
       19| def test_Not_a_package():
       20| 
       21|     try:
    -->22|         import os.xxx
       23|     except ModuleNotFoundError as e:


Not a package similar name
~~~~~~~~~~~~~~~~~~~~~~~~~~

.. code-block:: none


    Traceback (most recent call last):
      File "TESTS:\runtime\test_module_not_found_error.py", line 36, in test_Not_a_package_similar_name
        import os.pathh
    ModuleNotFoundError: No module named 'os.pathh'; 'os' is not a package
    
        האם התכוונת ל-`import os.path`? ('יבא os.path)' ?
        
    חריג `ModuleNotFoundError` נזרק כאשר
    מנסים לייבא מודול שפייתון לא מצא .
    זה יכול להיות בגלל שגיאת כתיב בשם המודול
    או מכיוון שהוא לא מותקן במחשב שלך.
    
    אולי התכוונת ל'ייבא os. path '.
    'path' הוא שם הדומה ל- 'pathh' והוא מודול ש
    ניתן לייבא מ 'os'.
    
    Exception raised on line `36` of file 'TESTS:\runtime\test_module_not_found_error.py'.
    
       34| def test_Not_a_package_similar_name():
       35|     try:
    -->36|         import os.pathh
       37|     except ModuleNotFoundError as e:


Object not module
~~~~~~~~~~~~~~~~~

.. code-block:: none


    Traceback (most recent call last):
      File "TESTS:\runtime\test_module_not_found_error.py", line 49, in test_Object_not_module
        import os.open
    ModuleNotFoundError: No module named 'os.open'; 'os' is not a package
    
        האם התכוונת ל-`from os import open`? ('מתוך os יבא open)' ?
        
    חריג `ModuleNotFoundError` נזרק כאשר
    מנסים לייבא מודול שפייתון לא מצא .
    זה יכול להיות בגלל שגיאת כתיב בשם המודול
    או מכיוון שהוא לא מותקן במחשב שלך.
    
    'open' אינו מודול נפרד אלא אובייקט שהוא חלק מ- 'os'.
    
    Exception raised on line `49` of file 'TESTS:\runtime\test_module_not_found_error.py'.
    
       47| def test_Object_not_module():
       48|     try:
    -->49|         import os.open
       50|     except ModuleNotFoundError as e:

            open:  <builtin function open>
        


Similar object not module
~~~~~~~~~~~~~~~~~~~~~~~~~

.. code-block:: none


    Traceback (most recent call last):
      File "TESTS:\runtime\test_module_not_found_error.py", line 62, in test_Similar_object_not_module
        import os.opend
    ModuleNotFoundError: No module named 'os.opend'; 'os' is not a package
    
        האם התכוונת ל-`from os import open`? ('מתוך os יבוא open)' ?
        
    חריג `ModuleNotFoundError` נזרק כאשר
    מנסים לייבא מודול שפייתון לא מצא .
    זה יכול להיות בגלל שגיאת כתיב בשם המודול
    או מכיוון שהוא לא מותקן במחשב שלך.
    
    אולי התכוונת ל `from os import open`  (מ- os יבא topen'.
    ')
    `open` הוא שם הדומה ל- `opend` והוא אובייקט ש
    ניתן לייבא מ 'os'.
    אובייקטים אחרים עם שמות דומים שהם חלק מ
      "os" כלול "popen".
    
    Exception raised on line `62` of file 'TESTS:\runtime\test_module_not_found_error.py'.
    
       60| def test_Similar_object_not_module():
       61|     try:
    -->62|         import os.opend
       63|     except ModuleNotFoundError as e:


Standard library module
~~~~~~~~~~~~~~~~~~~~~~~

.. code-block:: none


    Traceback (most recent call last):
      File "TESTS:\runtime\test_module_not_found_error.py", line 7, in test_Standard_library_module
        import Tkinter
    ModuleNotFoundError: No module named 'Tkinter'
    
        האם התכוונת ל 'tkinter'?
        
    חריג `ModuleNotFoundError` נזרק כאשר
    מנסים לייבא מודול שפייתון לא מצא .
    זה יכול להיות בגלל שגיאת כתיב בשם המודול
    או מכיוון שהוא לא מותקן במחשב שלך.
    
    לא ניתן לייבא מודול בשם 'Tkinter'.
    אולי אתה צריך להתקין אותו.
    במודולים הקיימים הבאים יש שמות דומים
    למודול שניסית לייבא: `tkinter, _tkinter`
    
    Exception raised on line `7` of file 'TESTS:\runtime\test_module_not_found_error.py'.
    
       5| def test_Standard_library_module():
       6|     try:
    -->7|         import Tkinter
       8|     except ModuleNotFoundError as e:


no curses
~~~~~~~~~

.. code-block:: none


    Traceback (most recent call last):
      File "TESTS:\runtime\test_module_not_found_error.py", line 92, in test_no_curses
        import curses
    ModuleNotFoundError: No module named '_curses'
    
        המודול "curses" מותקן לעתים רחוקות עם Python ב- Windows.
        
    חריג `ModuleNotFoundError` נזרק כאשר
    מנסים לייבא מודול שפייתון לא מצא .
    זה יכול להיות בגלל שגיאת כתיב בשם המודול
    או מכיוון שהוא לא מותקן במחשב שלך.
    
    ניסית לייבא את המודול "curses ".
    המודול "curses" מותקן לעתים רחוקות עם Python ב- Windows.
    
    Exception raised on line `92` of file 'TESTS:\runtime\test_module_not_found_error.py'.
    
       90| def test_no_curses():
       91|     try:
    -->92|         import curses
       93|     except ModuleNotFoundError as e:


NameError
---------


Annotated variable
~~~~~~~~~~~~~~~~~~

.. code-block:: none


    Traceback (most recent call last):
      File "TESTS:\runtime\test_name_error.py", line 30, in test_Annotated_variable
        y = x
    NameError: name 'x' is not defined
    
        האם השתמשת בנקודותיים במקום בסימן שוויון?
        
    חריג של 'NameError' מציין כי משתנה או
    הפונקציה אינו ידוע לפייתון.
    לרוב, הסיבה לכך היא שיש טעות כתיב.
    עם זאת, לפעמים זה בגלל שהשם משמש
    לפני שמגדירים אותו או נותנים לו ערך.
    
    בתוכנית שלך אין אובייקט בשם "x".
    רמז סוג נמצא עבור 'x' בהיקף global.
    אולי השתמשת בנקודותיים במקום בסימן שווה וכתבת
    
         x: 3
    
    במקום
    
         x = 3
    
    Exception raised on line `30` of file 'TESTS:\runtime\test_name_error.py'.
    
       28| def test_Annotated_variable():
       29|     try:
    -->30|         y = x
                       ^
       31|     except NameError as e:


Custom name
~~~~~~~~~~~

.. code-block:: none


    Traceback (most recent call last):
      File "TESTS:\runtime\test_name_error.py", line 239, in test_Custom_name
        python
    NameError: name 'python' is not defined
    
        אתה כבר משתמש בפייתון!
    חריג של 'NameError' מציין כי משתנה או
    הפונקציה אינו ידוע לפייתון.
    לרוב, הסיבה לכך היא שיש טעות כתיב.
    עם זאת, לפעמים זה בגלל שהשם משמש
    לפני שמגדירים אותו או נותנים לו ערך.
    
    אתה כבר משתמש בפייתון!
    Exception raised on line `239` of file 'TESTS:\runtime\test_name_error.py'.
    
       237| def test_Custom_name():
       238|     try:
    -->239|         python
                    ^^^^^^
       240|     except NameError as e:


Free variable referenced
~~~~~~~~~~~~~~~~~~~~~~~~

.. code-block:: none


    Traceback (most recent call last):
      File "TESTS:\runtime\test_name_error.py", line 223, in test_Free_variable_referenced
        outer()
      File "TESTS:\runtime\test_name_error.py", line 219, in outer
        inner()
      File "TESTS:\runtime\test_name_error.py", line 218, in inner
        return var
    NameError: free variable 'var' referenced before assignment in enclosing scope. Did you mean: 'vars'?
    
    חריג של 'NameError' מציין כי משתנה או
    הפונקציה אינו ידוע לפייתון.
    לרוב, הסיבה לכך היא שיש טעות כתיב.
    עם זאת, לפעמים זה בגלל שהשם משמש
    לפני שמגדירים אותו או נותנים לו ערך.
    
    בתוכנית שלך, 'var' הוא שם לא ידוע
    שקיים בהיקף סגור,
    אך עדיין לא הוקצה לו ערך.
    
    Execution stopped on line `223` of file 'TESTS:\runtime\test_name_error.py'.
    
       219|     inner()
       220|     var = 4
       221| 
       222| try:
    -->223|     outer()
                ^^^^^^^
       224| except NameError as e:

            outer:  <function outer>
                defined in <function test_Free_variable_referenced>
        
    Exception raised on line `218` of file 'TESTS:\runtime\test_name_error.py'.
    
       217| def inner():
    -->218|     return var
                       ^^^


Generic
~~~~~~~

.. code-block:: none


    Traceback (most recent call last):
      File "TESTS:\runtime\test_name_error.py", line 15, in test_Generic
        this = something
    NameError: name 'something' is not defined
    
    חריג של 'NameError' מציין כי משתנה או
    הפונקציה אינו ידוע לפייתון.
    לרוב, הסיבה לכך היא שיש טעות כתיב.
    עם זאת, לפעמים זה בגלל שהשם משמש
    לפני שמגדירים אותו או נותנים לו ערך.
    
    בתוכנית שלך אין אובייקט בשם "something".
    אין לי מידע נוסף עבורך.
    
    Exception raised on line `15` of file 'TESTS:\runtime\test_name_error.py'.
    
       13| def test_Generic():
       14|     try:
    -->15|         this = something
                          ^^^^^^^^^
       16|     except NameError as e:


Missing import
~~~~~~~~~~~~~~

.. code-block:: none


    Traceback (most recent call last):
      File "TESTS:\runtime\test_name_error.py", line 135, in test_Missing_import
        unicodedata.something
    NameError: name 'unicodedata' is not defined
    
        שכחת לייבא את 'unicodedata'?
        
    חריג של 'NameError' מציין כי משתנה או
    הפונקציה אינו ידוע לפייתון.
    לרוב, הסיבה לכך היא שיש טעות כתיב.
    עם זאת, לפעמים זה בגלל שהשם משמש
    לפני שמגדירים אותו או נותנים לו ערך.
    
    
    השם "unicodedata" לא מוגדר בתוכנית שלך.
    אולי שכחת לייבא את 'unicodedata' שנמצא
    בספרייה הסטנדרטית של פייתון.
    
    
    Exception raised on line `135` of file 'TESTS:\runtime\test_name_error.py'.
    
       131| if friendly_traceback.get_lang() == "en":
       132|     assert "I have no additional information for you." in result
       133| 
       134| try:
    -->135|     unicodedata.something
                ^^^^^^^^^^^
       136| except NameError as e:


Missing module name
~~~~~~~~~~~~~~~~~~~

.. code-block:: none


    Traceback (most recent call last):
      File "TESTS:\runtime\test_name_error.py", line 322, in test_Missing_module_name
        frame = Frame()
    NameError: name 'Frame' is not defined. Did you mean: 'frame'?
    
        שכחת להוסיף את `tkinter.`?
        
    חריג של 'NameError' מציין כי משתנה או
    הפונקציה אינו ידוע לפייתון.
    לרוב, הסיבה לכך היא שיש טעות כתיב.
    עם זאת, לפעמים זה בגלל שהשם משמש
    לפני שמגדירים אותו או נותנים לו ערך.
    
    בתוכנית שלך אין אובייקט בשם "Frame".
    
    The global object `tkinter`
    has an attribute named `Frame`.
    Perhaps you should have written `tkinter.Frame`
    instead of `Frame`.
    
    `Frame` is a name found in the following modules:
    tkinter, tracemalloc.
    Perhaps you forgot to import `Frame` from one of these modules.
    
    Exception raised on line `322` of file 'TESTS:\runtime\test_name_error.py'.
    
       319| @pytest.mark.skipif(not tkinter, reason="tkinter not present; likely MacOS")
       320| def test_Missing_module_name():
       321|     try:
    -->322|         frame = Frame()
                            ^^^^^
       323|     except NameError as e:


Missing self 1
~~~~~~~~~~~~~~

.. code-block:: none


    Traceback (most recent call last):
      File "TESTS:\runtime\test_name_error.py", line 274, in test_Missing_self_1
        str(a)
      File "TESTS:\runtime\test_name_error.py", line 265, in __str__
        toys_list = add_toy(  # ensure that it can see 'self' on following line
    NameError: name 'add_toy' is not defined
    
        Did you write `self` at the wrong place?
        
    חריג של 'NameError' מציין כי משתנה או
    הפונקציה אינו ידוע לפייתון.
    לרוב, הסיבה לכך היא שיש טעות כתיב.
    עם זאת, לפעמים זה בגלל שהשם משמש
    לפני שמגדירים אותו או נותנים לו ערך.
    
    בתוכנית שלך אין אובייקט בשם "add_toy".
    
    The local object `<Pet object> defined in <function test_name_error.test_Missing_self_1>`
    has an attribute named `add_toy`.
    Perhaps you should have written `self.add_toy(...`
    instead of `add_toy(self, ...`.
    
    Execution stopped on line `274` of file 'TESTS:\runtime\test_name_error.py'.
    
       270|             return "{} has no toys".format(self.name)
       271| 
       272| a = Pet('Fido')
       273| try:
    -->274|     str(a)
                ^^^^^^
       275| except NameError as e:

            a:  <Pet object>
                defined in <function test_name_error.test_Missing_self_1>
            str:  <class str>
        
    Exception raised on line `265` of file 'TESTS:\runtime\test_name_error.py'.
    
       263| def __str__(self):
       264|     # self at the wrong place
    -->265|     toys_list = add_toy(  # ensure that it can see 'self' on following line
                            ^^^^^^^
       266|                         self, 'something')
       267|     if self.toys:


Missing self 2
~~~~~~~~~~~~~~

.. code-block:: none


    Traceback (most recent call last):
      File "TESTS:\runtime\test_name_error.py", line 308, in test_Missing_self_2
        str(a)
      File "TESTS:\runtime\test_name_error.py", line 300, in __str__
        toys_list = add_toy('something')
    NameError: name 'add_toy' is not defined
    
        Did you forget to add `self.`?
        
    חריג של 'NameError' מציין כי משתנה או
    הפונקציה אינו ידוע לפייתון.
    לרוב, הסיבה לכך היא שיש טעות כתיב.
    עם זאת, לפעמים זה בגלל שהשם משמש
    לפני שמגדירים אותו או נותנים לו ערך.
    
    בתוכנית שלך אין אובייקט בשם "add_toy".
    
    A local object, `<Pet object> defined in <function test_name_error.test_Missing_self_2>`,
    has an attribute named `add_toy`.
    Perhaps you should have written `self.add_toy`
    instead of `add_toy`.
    
    Execution stopped on line `308` of file 'TESTS:\runtime\test_name_error.py'.
    
       304|             return "{} has no toys".format(self.name)
       305| 
       306| a = Pet('Fido')
       307| try:
    -->308|     str(a)
                ^^^^^^
       309| except NameError as e:

            a:  <Pet object>
                defined in <function test_name_error.test_Missing_self_2>
            str:  <class str>
        
    Exception raised on line `300` of file 'TESTS:\runtime\test_name_error.py'.
    
       298| def __str__(self):
       299|     # Missing self.
    -->300|     toys_list = add_toy('something')
                            ^^^^^^^
       301|     if self.toys:


Synonym
~~~~~~~

.. code-block:: none


    Traceback (most recent call last):
      File "TESTS:\runtime\test_name_error.py", line 95, in test_Synonym
        cost  # wrote from math import * above
    NameError: name 'cost' is not defined. Did you mean: 'cos'?
    
        האם התכוונת ל 'cos'?
        
    חריג של 'NameError' מציין כי משתנה או
    הפונקציה אינו ידוע לפייתון.
    לרוב, הסיבה לכך היא שיש טעות כתיב.
    עם זאת, לפעמים זה בגלל שהשם משמש
    לפני שמגדירים אותו או נותנים לו ערך.
    
    בתוכנית שלך אין אובייקט בשם "cost".
    במקום לכתוב 'cost', אולי התכוונת לאחד מהדברים הבאים:
    * היקף גלובלי `cos`, `cosh`
    
    Exception raised on line `95` of file 'TESTS:\runtime\test_name_error.py'.
    
       91| if friendly_traceback.get_lang() == "en":
       92|     assert "The Python builtin `chr` has a similar name." in result
       93| 
       94| try:
    -->95|     cost  # wrote from math import * above
               ^^^^
       96| except NameError as e:


missing import2
~~~~~~~~~~~~~~~

.. code-block:: none


    Traceback (most recent call last):
      File "TESTS:\runtime\test_name_error.py", line 149, in test_missing_import2
        ABCMeta
    NameError: name 'ABCMeta' is not defined
    
    חריג של 'NameError' מציין כי משתנה או
    הפונקציה אינו ידוע לפייתון.
    לרוב, הסיבה לכך היא שיש טעות כתיב.
    עם זאת, לפעמים זה בגלל שהשם משמש
    לפני שמגדירים אותו או נותנים לו ערך.
    
    בתוכנית שלך אין אובייקט בשם "ABCMeta".
    `ABCMeta` is a name found in the following modules:
    selectors, typing, abc, numbers.
    Perhaps you forgot to import `ABCMeta` from one of these modules.
    
    Exception raised on line `149` of file 'TESTS:\runtime\test_name_error.py'.
    
       147| def test_missing_import2():
       148|     try:
    -->149|         ABCMeta
                    ^^^^^^^
       150|     except NameError as e:


missing import3
~~~~~~~~~~~~~~~

.. code-block:: none


    Traceback (most recent call last):
      File "TESTS:\runtime\test_name_error.py", line 163, in test_missing_import3
        AF_APPLETALK
    NameError: name 'AF_APPLETALK' is not defined
    
    חריג של 'NameError' מציין כי משתנה או
    הפונקציה אינו ידוע לפייתון.
    לרוב, הסיבה לכך היא שיש טעות כתיב.
    עם זאת, לפעמים זה בגלל שהשם משמש
    לפני שמגדירים אותו או נותנים לו ערך.
    
    בתוכנית שלך אין אובייקט בשם "AF_APPLETALK".
    `AF_APPLETALK` is a name found in module `socket`.
    Perhaps you forgot to write
    
        from socket import AF_APPLETALK
    
    Exception raised on line `163` of file 'TESTS:\runtime\test_name_error.py'.
    
       161| def test_missing_import3():
       162|     try:
    -->163|         AF_APPLETALK
                    ^^^^^^^^^^^^
       164|     except NameError as e:


missing import from other 1
~~~~~~~~~~~~~~~~~~~~~~~~~~~

.. code-block:: none


    Traceback (most recent call last):
      File "TESTS:\runtime\test_name_error.py", line 177, in test_missing_import_from_other_1
        fake_module_name.something()
    NameError: name 'fake_module_name' is not defined
    
        שכחת לייבא את 'fake_module_name'?
        
    חריג של 'NameError' מציין כי משתנה או
    הפונקציה אינו ידוע לפייתון.
    לרוב, הסיבה לכך היא שיש טעות כתיב.
    עם זאת, לפעמים זה בגלל שהשם משמש
    לפני שמגדירים אותו או נותנים לו ערך.
    
    
    The name `fake_module_name` is not defined in your program.
    Perhaps you forgot to import `fake_module_name` which is a known library.
    
    
    Exception raised on line `177` of file 'TESTS:\runtime\test_name_error.py'.
    
       174| def test_missing_import_from_other_1():
       175|     friendly_traceback.add_other_module_names(["fake_module_name"])
       176|     try:
    -->177|         fake_module_name.something()
                    ^^^^^^^^^^^^^^^^
       178|     except NameError as e:


missing import from other 2
~~~~~~~~~~~~~~~~~~~~~~~~~~~

.. code-block:: none


    Traceback (most recent call last):
      File "TESTS:\runtime\test_name_error.py", line 191, in test_missing_import_from_other_2
        plt.something
    NameError: name 'plt' is not defined
    
        Did you forget to import `matplotlib.pyplot`?
        
    חריג של 'NameError' מציין כי משתנה או
    הפונקציה אינו ידוע לפייתון.
    לרוב, הסיבה לכך היא שיש טעות כתיב.
    עם זאת, לפעמים זה בגלל שהשם משמש
    לפני שמגדירים אותו או נותנים לו ערך.
    
    
    The name `plt` is not defined in your program.
    Perhaps you forgot to write
    
       import matplotlib.pyplot as plt
    
    
    Exception raised on line `191` of file 'TESTS:\runtime\test_name_error.py'.
    
       188| def test_missing_import_from_other_2():
       189|     friendly_traceback.add_other_module_names_synonyms({"plt": "matplotlib.pyplot"})
       190|     try:
    -->191|         plt.something
                    ^^^
       192|     except NameError as e:


missing import from other 3
~~~~~~~~~~~~~~~~~~~~~~~~~~~

.. code-block:: none


    Traceback (most recent call last):
      File "TESTS:\runtime\test_name_error.py", line 204, in test_missing_import_from_other_3
        show()
    NameError: name 'show' is not defined
    
    חריג של 'NameError' מציין כי משתנה או
    הפונקציה אינו ידוע לפייתון.
    לרוב, הסיבה לכך היא שיש טעות כתיב.
    עם זאת, לפעמים זה בגלל שהשם משמש
    לפני שמגדירים אותו או נותנים לו ערך.
    
    בתוכנית שלך אין אובייקט בשם "show".
    `show` is a name found in the following modules:
    mailcap, matplotlib.pyplot, funny.
    Perhaps you forgot to import `show` from one of these modules.
    
    Exception raised on line `204` of file 'TESTS:\runtime\test_name_error.py'.
    
       201| def test_missing_import_from_other_3():
       202|     friendly_traceback.add_other_attribute_names({"show": ["matplotlib.pyplot", "funny"] })
       203|     try:
    -->204|         show()
                    ^^^^
       205|     except NameError as e:


special keyword
~~~~~~~~~~~~~~~

.. code-block:: none


    Traceback (most recent call last):
      File "TESTS:\runtime\test_name_error.py", line 353, in test_special_keyword
        brek
    NameError: name 'brek' is not defined
    
        האם התכוונת ל 'break'?
        
    חריג של 'NameError' מציין כי משתנה או
    הפונקציה אינו ידוע לפייתון.
    לרוב, הסיבה לכך היא שיש טעות כתיב.
    עם זאת, לפעמים זה בגלל שהשם משמש
    לפני שמגדירים אותו או נותנים לו ערך.
    
    I suspect you meant to write the keyword `break` and made a typo.
    
    Exception raised on line `353` of file 'TESTS:\runtime\test_name_error.py'.
    
       350| if friendly_traceback.get_lang() == "en":
       351|     assert "Did you mean `continue`" in result
       352| try:
    -->353|     brek
                ^^^^
       354| except NameError as e:


OsError
-------


Urllib error
~~~~~~~~~~~~

.. code-block:: none


    Traceback (most recent call last):
      File "PYTHON_LIB:\urllib\request.py", line 1348, in do_open
           ... שורות נוספות לא מוצגות. ...
      File "PYTHON_LIB:\socket.py", line 824, in create_connection
        for res in getaddrinfo(host, port, 0, SOCK_STREAM):
      File "PYTHON_LIB:\socket.py", line 955, in getaddrinfo
        for res in _socket.getaddrinfo(host, port, family, type, proto, flags):
    socket.gaierror: [Errno 11001] getaddrinfo failed
    
        During handling of the above exception, another exception occurred:
    
    Traceback (most recent call last):
      File "TESTS:\runtime\test_os_error.py", line 10, in test_Urllib_error
        request.urlopen("http://does_not_exist")
    URLError: <urlopen error [Errno 11001] getaddrinfo failed>
    
    שגיאה מסוג `URLError` היא תת-מחלקה של `OSError`.
    Nothing more specific is known about `URLError`.
    
    בדרך כלל מערכת ההפעלה מעלה חריג של 'OSError'
    כדי לציין שפעולה אסורה או כי
    משאב אינו זמין.
    
    אני חושד שאתה מנסה להתחבר לשרת ו
    שלא ניתן ליצור קשר.
    
    אם זה המצב, בדוק אם יש שגיאות כתיב בכתובת האתר
    ובדוק את חיבור האינטרנט שלך.
    
    Exception raised on line `10` of file 'TESTS:\runtime\test_os_error.py'.
    
        6| @pytest.mark.skipif(random.randint(0, 50) < 59, reason="very long test")
        7| def test_Urllib_error():
        8|     from urllib import request, error
        9|     try:
    -->10|         request.urlopen("http://does_not_exist")
                   ^^^^^^^^^^^^^^^^^^^^^^^^^^^^^^^^^^^^^^^^
       11|     except error.URLError as e:

            request:  <module urllib.request> from PYTHON_LIB:\urllib\request.py
            request.urlopen:  <function urlopen>
        


invalid argument
~~~~~~~~~~~~~~~~

.. code-block:: none


    Traceback (most recent call last):
      File "TESTS:\runtime\test_os_error.py", line 48, in test_invalid_argument
        open("c:\test.txt")
    OSError: [Errno 22] Invalid argument: 'c:\test.txt'
    
        אולי אתה צריך להכפיל את הלוֹכסן האחורי .
        
    בדרך כלל מערכת ההפעלה מעלה חריג של 'OSError'
    כדי לציין שפעולה אסורה או כי
    משאב אינו זמין.
    
    I suspect that you wrote a filename or path that contains
    at least one backslash character, `\`.
    Python likely interpreted this as indicating the beginning of
    what is known as an escape sequence.
    To solve the problem, either write a so-called 'raw string'
    by adding the letter `r` as a prefix in
    front of the filename or path, or replace all single backslash
    characters, `\`, by double ones: `\\`.
    
    Exception raised on line `48` of file 'TESTS:\runtime\test_os_error.py'.
    
       45| if os.name != "nt":
       46|     return "Windows test only", "No result"
       47| try:
    -->48|     open("c:\test.txt")
               ^^^^^^^^^^^^^^^^^^^
       49| except OSError as e:

            open:  <builtin function open>
        


no information
~~~~~~~~~~~~~~

.. code-block:: none


    Traceback (most recent call last):
      File "TESTS:\runtime\test_os_error.py", line 29, in test_no_information
        raise OSError("Some unknown message")
    OSError: Some unknown message
    
        מקור השגיאה לא ידוע.
        
    בדרך כלל מערכת ההפעלה מעלה חריג של 'OSError'
    כדי לציין שפעולה אסורה או כי
    משאב אינו זמין.
    
    אין מידע על חריג זה.
    Please report this example to
    https://github.com/friendly-traceback/friendly-traceback/issues/new
    If you are using a REPL, use `www('bug')` to do so.
    
    אם אתה משתמש במסוף ידידותי, השתמש ב- 'www ()' כדי
    חפש באינטרנט את המקרה הספציפי הזה.
    
    Exception raised on line `29` of file 'TESTS:\runtime\test_os_error.py'.
    
       26| old_debug = friendly_traceback.debug_helper.DEBUG
       27| friendly_traceback.debug_helper.DEBUG = False
       28| try:
    -->29|     raise OSError("Some unknown message")
       30| except OSError as e:

            OSError:  <class OSError>
        


OverflowError
-------------


Generic
~~~~~~~

.. code-block:: none


    Traceback (most recent call last):
      File "TESTS:\runtime\test_overflow_error.py", line 6, in test_Generic
        2.0 ** 1600
    OverflowError: (34, 'Result too large')
    
    'OverflowError' מוגבה כאשר התוצאה של פעולה חשבונית
    הוא גדול מכדי שניתן יהיה לטפל בו במעבד המחשב.
    
    Exception raised on line `6` of file 'TESTS:\runtime\test_overflow_error.py'.
    
       4| def test_Generic():
       5|     try:
    -->6|         2.0 ** 1600
                  ^^^^^^^^^^^
       7|     except OverflowError as e:


Huge lenght
~~~~~~~~~~~

.. code-block:: none


    Traceback (most recent call last):
      File "TESTS:\runtime\test_overflow_error.py", line 24, in test_Huge_lenght
        len(huge)
    OverflowError: Python int too large to convert to C ssize_t
    
    'OverflowError' מוגבה כאשר התוצאה של פעולה חשבונית
    הוא גדול מכדי שניתן יהיה לטפל בו במעבד המחשב.
    
    Exception raised on line `24` of file 'TESTS:\runtime\test_overflow_error.py'.
    
       21| def test_Huge_lenght():
       22|     huge = range(1<<10000)
       23|     try:
    -->24|         len(huge)
                   ^^^^^^^^^
       25|     except OverflowError as e:

            huge:  range(0, ...)
                   len(huge): Object too large to be processed by Python.
        
            len:  <builtin function len>
        


RecursionError
--------------


Generic
~~~~~~~

.. code-block:: none


    Traceback (most recent call last):
      File "TESTS:\runtime\test_recursion_error.py", line 8, in test_Generic
        a()
           ... שורות נוספות לא מוצגות. ...
      File "TESTS:\runtime\test_recursion_error.py", line 6, in a
        return a()
      File "TESTS:\runtime\test_recursion_error.py", line 6, in a
        return a()
    RecursionError: maximum recursion depth exceeded
    
    "RecursionError" מועלה כאשר פונקציה קוראת לעצמה,
    במישרין או בעקיפין, פעמים רבות מדי.
    זה כמעט תמיד מציין שעשית שגיאה בקוד שלך
    ושהתוכנית שלך לעולם לא תפסיק.
    
    Execution stopped on line `8` of file 'TESTS:\runtime\test_recursion_error.py'.
    
       5| def a():
       6|     return a()
       7| try:
    -->8|     a()
              ^^^
       9| except RecursionError as e:

            a:  <function a> defined in <function test_Generic>
        
    Exception raised on line `6` of file 'TESTS:\runtime\test_recursion_error.py'.
    
       5| def a():
    -->6|     return a()
                     ^^^

            a:  <function a> defined in <function test_Generic>
        


TypeError
---------


Argument of object is not iterable
~~~~~~~~~~~~~~~~~~~~~~~~~~~~~~~~~~

.. code-block:: none


    Traceback (most recent call last):
      File "TESTS:\runtime\test_type_error.py", line 794, in test_Argument_of_object_is_not_iterable
        a in b
    TypeError: argument of type 'object' is not iterable
    
    'TypeError' נגרמת בדרך כלל על ידי ניסיון
    לשלב שני סוגי אובייקטים שאינם תואמים,
    על ידי קריאה לפונקציה עם סוג האובייקט הלא נכון,
    או על ידי ניסיון לבצע פעולה שאינה מותרת בסוג נתון של אובייקט.
    
    An iterable is an object capable of returning its members one at a time.
    Python containers (`list, tuple, dict`, etc.) are iterables.
    'b' is not a container. A container is required here.
    
    Exception raised on line `794` of file 'TESTS:\runtime\test_type_error.py'.
    
       791| a = object()
       792| b = object()
       793| try:
    -->794|     a in b
                ^^^^^^
       795| except TypeError as e:

            a:  <object object>
            b:  <object object>
        


Bad type for unary operator
~~~~~~~~~~~~~~~~~~~~~~~~~~~

.. code-block:: none


    Traceback (most recent call last):
      File "TESTS:\runtime\test_type_error.py", line 410, in test_Bad_type_for_unary_operator
        a =+ "def"
    TypeError: bad operand type for unary +: 'str'
    
        אולי התכוונת לכתוב `+=` במקום `=+`
    'TypeError' נגרמת בדרך כלל על ידי ניסיון
    לשלב שני סוגי אובייקטים שאינם תואמים,
    על ידי קריאה לפונקציה עם סוג האובייקט הלא נכון,
    או על ידי ניסיון לבצע פעולה שאינה מותרת בסוג נתון של אובייקט.
    
    ניסית להשתמש באופרטור האנורי '+'
    עם סוג האובייקט הבא: מחרוזת (`str`).
    פעולה זו אינה מוגדרת עבור אובייקט מסוג זה.
    
    אולי התכוונת לכתוב `+=` במקום `=+`
    
    Exception raised on line `410` of file 'TESTS:\runtime\test_type_error.py'.
    
       405|     assert "You tried to use the unary operator '~'" in result
       406| 
       407| try:
       408|     # fmt: off
       409|     a = "abc"
    -->410|     a =+ "def"
                   ^^^^^^^
       411|     # fmt: on


Builtin has no len
~~~~~~~~~~~~~~~~~~

.. code-block:: none


    Traceback (most recent call last):
      File "TESTS:\runtime\test_type_error.py", line 849, in test_Builtin_has_no_len
        len("Hello world".split)
    TypeError: object of type 'builtin_function_or_method' has no len()
    
        שכחת לקרוא ל '"Hello world".split'?
        
    'TypeError' נגרמת בדרך כלל על ידי ניסיון
    לשלב שני סוגי אובייקטים שאינם תואמים,
    על ידי קריאה לפונקציה עם סוג האובייקט הלא נכון,
    או על ידי ניסיון לבצע פעולה שאינה מותרת בסוג נתון של אובייקט.
    
    אני חושד ששכחת להוסיף סוגריים כדי לקרוא '"Hello world".split'.
    אולי התכוונת לכתוב:
    `len("Hello world".split())`
    
    Exception raised on line `849` of file 'TESTS:\runtime\test_type_error.py'.
    
       847| def test_Builtin_has_no_len():
       848|     try:
    -->849|         len("Hello world".split)
                    ^^^^^^^^^^^^^^^^^^^^^^^^
       850|     except TypeError as e:

            len:  <builtin function len>
            "Hello world".split:  <builtin method split of str object>
        


Can only concatenate
~~~~~~~~~~~~~~~~~~~~

.. code-block:: none


    Traceback (most recent call last):
      File "TESTS:\runtime\test_type_error.py", line 39, in test_Can_only_concatenate
        result = a_tuple + a_list
    TypeError: can only concatenate tuple (not "list") to tuple
    
    'TypeError' נגרמת בדרך כלל על ידי ניסיון
    לשלב שני סוגי אובייקטים שאינם תואמים,
    על ידי קריאה לפונקציה עם סוג האובייקט הלא נכון,
    או על ידי ניסיון לבצע פעולה שאינה מותרת בסוג נתון של אובייקט.
    
    ניסית לחבר  (להוסיף) שני סוגים שונים של אובייקטים:
    צמד ('tuple') ו- רשימה (`list`).
    
    Exception raised on line `39` of file 'TESTS:\runtime\test_type_error.py'.
    
       36| try:
       37|     a_tuple = (1, 2, 3)
       38|     a_list = [1, 2, 3]
    -->39|     result = a_tuple + a_list
                        ^^^^^^^^^^^^^^^^
       40| except TypeError as e:

            a_list:  [1, 2, 3]
            a_tuple:  (1, 2, 3)
        


Cannot convert dictionary update sequence
~~~~~~~~~~~~~~~~~~~~~~~~~~~~~~~~~~~~~~~~~

.. code-block:: none


    Traceback (most recent call last):
      File "TESTS:\runtime\test_type_error.py", line 835, in test_Cannot_convert_dictionary_update_sequence
        dd.update([1, 2, 3])
    TypeError: cannot convert dictionary update sequence element #0 to a sequence
    
        Perhaps you need to use the `dict.fromkeys()` method.
        
    'TypeError' נגרמת בדרך כלל על ידי ניסיון
    לשלב שני סוגי אובייקטים שאינם תואמים,
    על ידי קריאה לפונקציה עם סוג האובייקט הלא נכון,
    או על ידי ניסיון לבצע פעולה שאינה מותרת בסוג נתון של אובייקט.
    
    `dict.update()` אינו מקבל רצף כארגומנט.
    במקום לכתוב 'dd.update([1, 2, 3])'
    אולי כדאי להשתמש בשיטת 'dict.fromkeys ()': "dd.update( dict.fromkeys([1, 2, 3]) )". (מילון.מהמפתחות(...))
    
    Exception raised on line `835` of file 'TESTS:\runtime\test_type_error.py'.
    
       831|     assert "you should use the `dict.fromkeys()`" in result
       832| 
       833| dd = {"a": "a"}
       834| try:
    -->835|     dd.update([1, 2, 3])
                ^^^^^^^^^^^^^^^^^^^^
       836| except TypeError as e:

            dd:  {'a': 'a'}
            dd.update:  <builtin method update of dict object>
        


Cannot multiply by non int
~~~~~~~~~~~~~~~~~~~~~~~~~~

.. code-block:: none


    Traceback (most recent call last):
      File "TESTS:\runtime\test_type_error.py", line 610, in test_Cannot_multiply_by_non_int
        "a" * "2"
    TypeError: can't multiply sequence by non-int of type 'str'
    
        שכחת להמיר את '"2"' למספר שלם?
        
    'TypeError' נגרמת בדרך כלל על ידי ניסיון
    לשלב שני סוגי אובייקטים שאינם תואמים,
    על ידי קריאה לפונקציה עם סוג האובייקט הלא נכון,
    או על ידי ניסיון לבצע פעולה שאינה מותרת בסוג נתון של אובייקט.
    
    אתה יכול רק להכפיל רצפים, כגון רשימה, זוגות,
      מחרוזות וכו ', לפי מספרים שלמים.
    אולי שכחת להמיר את '"2"' למספר שלם.
    
    Exception raised on line `610` of file 'TESTS:\runtime\test_type_error.py'.
    
       606| if friendly_traceback.get_lang() == "en":
       607|     assert "Did you forget to convert `c` into an integer?" in result
       608| 
       609| try:
    -->610|     "a" * "2"
                ^^^^^^^^^
       611| except TypeError as e:


Cannot unpack non iterable object
~~~~~~~~~~~~~~~~~~~~~~~~~~~~~~~~~

.. code-block:: none


    Traceback (most recent call last):
      File "TESTS:\runtime\test_type_error.py", line 807, in test_Cannot_unpack_non_iterable_object
        a, b = 42.0
    TypeError: cannot unpack non-iterable float object
    
    'TypeError' נגרמת בדרך כלל על ידי ניסיון
    לשלב שני סוגי אובייקטים שאינם תואמים,
    על ידי קריאה לפונקציה עם סוג האובייקט הלא נכון,
    או על ידי ניסיון לבצע פעולה שאינה מותרת בסוג נתון של אובייקט.
    
    פריקה היא דרך נוחה להקצות שם,
    לכל פריט של חוזר.
    חוזר הוא אובייקט המסוגל להחזיר את פרטיו,אחד בכל פעם.
    מכולות (`רשימה, tuple, dict`, וכו ') הם רכיבים חוזרים.
    אבל לא אובייקטים מהסוג `float`.
    
    Exception raised on line `807` of file 'TESTS:\runtime\test_type_error.py'.
    
       805| def test_Cannot_unpack_non_iterable_object():
       806|     try:
    -->807|         a, b = 42.0
       808|     except TypeError as e:


Comparison not supported
~~~~~~~~~~~~~~~~~~~~~~~~

.. code-block:: none


    Traceback (most recent call last):
      File "TESTS:\runtime\test_type_error.py", line 359, in test_Comparison_not_supported
        b >= a
    TypeError: '>=' not supported between instances of 'int' and 'str'
    
        שכחת להמיר את המחרוזת "a" ל- מספר שלם (`int`)?
        
    'TypeError' נגרמת בדרך כלל על ידי ניסיון
    לשלב שני סוגי אובייקטים שאינם תואמים,
    על ידי קריאה לפונקציה עם סוג האובייקט הלא נכון,
    או על ידי ניסיון לבצע פעולה שאינה מותרת בסוג נתון של אובייקט.
    
    ניסית לבצע השוואת סדר (>=)
    בין שני סוגי אובייקטים לא תואמים:
    מספר שלם (`int`) ו- מחרוזת (`str`).
    אולי שכחת להמיר את המחרוזת "a" ל- מספר שלם (`int`).
    
    Exception raised on line `359` of file 'TESTS:\runtime\test_type_error.py'.
    
       356| try:
       357|     a = "2"
       358|     b = 42
    -->359|     b >= a
                ^^^^^^
       360| except TypeError as e:

            a:  '2'
            b:  42
        


Derive from BaseException
~~~~~~~~~~~~~~~~~~~~~~~~~

.. code-block:: none


    Traceback (most recent call last):
      File "TESTS:\runtime\test_type_error.py", line 553, in test_Derive_from_BaseException
        raise "exception"  # noqa
    TypeError: exceptions must derive from BaseException
    
    'TypeError' נגרמת בדרך כלל על ידי ניסיון
    לשלב שני סוגי אובייקטים שאינם תואמים,
    על ידי קריאה לפונקציה עם סוג האובייקט הלא נכון,
    או על ידי ניסיון לבצע פעולה שאינה מותרת בסוג נתון של אובייקט.
    
    ב- Python 3 יש לגזור חריגים מ- BaseException.
    
    Exception raised on line `553` of file 'TESTS:\runtime\test_type_error.py'.
    
       551| def test_Derive_from_BaseException():
       552|     try:
    -->553|         raise "exception"  # noqa
       554|     except TypeError as e:


Generator has no len
~~~~~~~~~~~~~~~~~~~~

.. code-block:: none


    Traceback (most recent call last):
      File "TESTS:\runtime\test_type_error.py", line 1004, in test_Generator_has_no_len
        nb = len(letter
    TypeError: object of type 'generator' has no len()
    
        You likely need to build a list first.
        
    'TypeError' נגרמת בדרך כלל על ידי ניסיון
    לשלב שני סוגי אובייקטים שאינם תואמים,
    על ידי קריאה לפונקציה עם סוג האובייקט הלא נכון,
    או על ידי ניסיון לבצע פעולה שאינה מותרת בסוג נתון של אובייקט.
    
    I am guessing that you were trying to count the number of elements
    produced by a generator expression. You first need to capture them
    in a list:
    
        len([letter                 for letter in "word"])?
    
    Exception raised on line `1004` of file 'TESTS:\runtime\test_type_error.py'.
    
       1002| def test_Generator_has_no_len():
       1003|     try:
    -->1004|         nb = len(letter
                          ^^^^^^^^^^
       1005|                  for letter in "word")
                              ^^^^^^^^^^^^^^^^^^^^^
       1006|     except TypeError as e:

            len:  <builtin function len>
        


Indices must be integers or slices
~~~~~~~~~~~~~~~~~~~~~~~~~~~~~~~~~~

.. code-block:: none


    Traceback (most recent call last):
      File "TESTS:\runtime\test_type_error.py", line 692, in test_Indices_must_be_integers_or_slices
        [1, 2, 3]["2"]
    TypeError: list indices must be integers or slices, not str
    
        שכחת להמיר את '"2"' למספר שלם?
        
    'TypeError' נגרמת בדרך כלל על ידי ניסיון
    לשלב שני סוגי אובייקטים שאינם תואמים,
    על ידי קריאה לפונקציה עם סוג האובייקט הלא נכון,
    או על ידי ניסיון לבצע פעולה שאינה מותרת בסוג נתון של אובייקט.
    
    בביטוי `[1, 2, 3]["2"]`
    מה כלול בין הסוגריים המרובעים, '[...]',
    חייב להיות מספר שלם או פרוסה
    (`התחל: עצור` או` התחל: עצור: שלב`)
    והשתמשת במקום זאת ב- מחרוזת (`str`).
    
    אולי שכחת להמיר את '"2"' למספר שלם.
    
    Exception raised on line `692` of file 'TESTS:\runtime\test_type_error.py'.
    
       688| if friendly_traceback.get_lang() == "en":
       689|     assert "Perhaps you forgot to convert `2.0` into an integer." in result
       690| 
       691| try:
    -->692|     [1, 2, 3]["2"]
                ^^^^^^^^^^^^^^
       693| except TypeError as e:


Not an integer
~~~~~~~~~~~~~~

.. code-block:: none


    Traceback (most recent call last):
      File "TESTS:\runtime\test_type_error.py", line 655, in test_Not_an_integer
        range(c, d)
    TypeError: 'str' object cannot be interpreted as an integer
    
        האם שכחת להמיר את 'c, d' למספרים שלמים?
        
    'TypeError' נגרמת בדרך כלל על ידי ניסיון
    לשלב שני סוגי אובייקטים שאינם תואמים,
    על ידי קריאה לפונקציה עם סוג האובייקט הלא נכון,
    או על ידי ניסיון לבצע פעולה שאינה מותרת בסוג נתון של אובייקט.
    
    כתבת אובייקט מסוג 'str' שבו צפוי מספר שלם.
    Perhaps you forgot to convert `c, d` into integers.
    Exception raised on line `655` of file 'TESTS:\runtime\test_type_error.py'.
    
       651|     assert "Perhaps you forgot to convert `1.0" in result
       652| 
       653| c, d = "2", "3"
       654| try:
    -->655|     range(c, d)
                ^^^^^^^^^^^
       656| except TypeError as e:

            c:  '2'
            d:  '3'
            range:  <class range>
        


Not callable
~~~~~~~~~~~~

.. code-block:: none


    Traceback (most recent call last):
      File "TESTS:\runtime\test_type_error.py", line 540, in test_Not_callable
        _ = [1, 2](a + b)
    TypeError: 'list' object is not callable
    
        האם התכוונת ל '[1, 2] [a + b]'?
        
    'TypeError' נגרמת בדרך כלל על ידי ניסיון
    לשלב שני סוגי אובייקטים שאינם תואמים,
    על ידי קריאה לפונקציה עם סוג האובייקט הלא נכון,
    או על ידי ניסיון לבצע פעולה שאינה מותרת בסוג נתון של אובייקט.
    
    בגלל הסוגריים שמסביב, '(a + b)'
    מתפרש על ידי פייתון כמעיד על קריאה לפונקציה
    `[1, 2]`, שהוא אובייקט מסוג 'list'
    שלא ניתן לקרוא לה.
    עם זאת, '[1, 2]' הוא רצף.
    אולי התכוונת להשתמש ב- [] במקום במקום () ולכתוב
    `[1, 2] [a + b]`
    
    Exception raised on line `540` of file 'TESTS:\runtime\test_type_error.py'.
    
       536|     assert "b.a_list[3]" in result
       537| 
       538| try:
       539|     a, b = 3, 7
    -->540|     _ = [1, 2](a + b)
                    ^^^^^^^^^^^^^
       541| except TypeError as e:

            a:  3
            b:  7
            a + b:  10
        


Object is not iterable
~~~~~~~~~~~~~~~~~~~~~~

.. code-block:: none


    Traceback (most recent call last):
      File "TESTS:\runtime\test_type_error.py", line 778, in test_Object_is_not_iterable
        list(42)
    TypeError: 'int' object is not iterable
    
    'TypeError' נגרמת בדרך כלל על ידי ניסיון
    לשלב שני סוגי אובייקטים שאינם תואמים,
    על ידי קריאה לפונקציה עם סוג האובייקט הלא נכון,
    או על ידי ניסיון לבצע פעולה שאינה מותרת בסוג נתון של אובייקט.
    
    חוזר הוא אובייקט המסוגל להחזיר את פרטיו,אחד בכל פעם.
    מכולות (`רשימה, tuple, dict`, וכו ') הם רכיבים חוזרים.
    דרוש כאן חזרה.
    
    Exception raised on line `778` of file 'TESTS:\runtime\test_type_error.py'.
    
       776| def test_Object_is_not_iterable():
       777|     try:
    -->778|         list(42)
                    ^^^^^^^^
       779|     except TypeError as e:

            list:  <class list>
        


Object is not subscriptable
~~~~~~~~~~~~~~~~~~~~~~~~~~~

.. code-block:: none


    Traceback (most recent call last):
      File "TESTS:\runtime\test_type_error.py", line 764, in test_Object_is_not_subscriptable
        a = f[1]
    TypeError: 'function' object is not subscriptable
    
        האם התכוונת ל "f(1)"?
        
    'TypeError' נגרמת בדרך כלל על ידי ניסיון
    לשלב שני סוגי אובייקטים שאינם תואמים,
    על ידי קריאה לפונקציה עם סוג האובייקט הלא נכון,
    או על ידי ניסיון לבצע פעולה שאינה מותרת בסוג נתון של אובייקט.
    
    אובייקטים הרשמים הם בדרך כלל מיכלים מהם
    אתה יכול לאחזר פריט באמצעות הסימון '[...]'.
    
    אולי התכוונת לכתוב 'f(1)'.
    
    Exception raised on line `764` of file 'TESTS:\runtime\test_type_error.py'.
    
       760| def f():
       761|     pass
       762| 
       763| try:
    -->764|     a = f[1]
                    ^^^^
       765| except TypeError as e:

            f:  <function f>
                defined in <function test_Object_is_not_subscriptable>
        


Slice indices must be integers or None
~~~~~~~~~~~~~~~~~~~~~~~~~~~~~~~~~~~~~~

.. code-block:: none


    Traceback (most recent call last):
      File "TESTS:\runtime\test_type_error.py", line 706, in test_Slice_indices_must_be_integers_or_None
        [1, 2, 3][1.0:2.0]
    TypeError: slice indices must be integers or None or have an __index__ method
    
    'TypeError' נגרמת בדרך כלל על ידי ניסיון
    לשלב שני סוגי אובייקטים שאינם תואמים,
    על ידי קריאה לפונקציה עם סוג האובייקט הלא נכון,
    או על ידי ניסיון לבצע פעולה שאינה מותרת בסוג נתון של אובייקט.
    
    בעת שימוש בפרוס (slice) לחילוץ מגוון אלמנטים
    מרצף, זה משהו כמו
    `[start: stop]` או `[start: stop: step]`
    כל אחד מ'התחלה ',' עצירה ',' שלב 'חייב להיות מספר שלם,' אין ',
    או אולי אובייקט אחר בעל שיטת '__index__'.
    
    Exception raised on line `706` of file 'TESTS:\runtime\test_type_error.py'.
    
       704| def test_Slice_indices_must_be_integers_or_None():
       705|     try:
    -->706|         [1, 2, 3][1.0:2.0]
                    ^^^^^^^^^^^^^^^^^^
       707|     except TypeError as e:


Too few positional argument
~~~~~~~~~~~~~~~~~~~~~~~~~~~

.. code-block:: none


    Traceback (most recent call last):
      File "TESTS:\runtime\test_type_error.py", line 480, in test_Too_few_positional_argument
        fn(1)
    TypeError: test_Too_few_positional_argument.<locals>.fn() missing 2 required positional arguments: 'b' and 'c'
    
    'TypeError' נגרמת בדרך כלל על ידי ניסיון
    לשלב שני סוגי אובייקטים שאינם תואמים,
    על ידי קריאה לפונקציה עם סוג האובייקט הלא נכון,
    או על ידי ניסיון לבצע פעולה שאינה מותרת בסוג נתון של אובייקט.
    
    כנראה קראת לפונקציה 'test_Too_few_positional_argument.<locals>.fn()' עם
    פחות ארגומנטים מיקוםיים ממה שהוא דורש (חסר 2).
    
    Exception raised on line `480` of file 'TESTS:\runtime\test_type_error.py'.
    
       476| def fn(a, b, c):
       477|     pass
       478| 
       479| try:
    -->480|     fn(1)
                ^^^^^
       481| except TypeError as e:

            fn:  <function fn>
                defined in <function test_Too_few_positional_argument>
        


Too many positional argument
~~~~~~~~~~~~~~~~~~~~~~~~~~~~

.. code-block:: none


    Traceback (most recent call last):
      File "TESTS:\runtime\test_type_error.py", line 461, in test_Too_many_positional_argument
        A().f(1)
    TypeError: test_Too_many_positional_argument.<locals>.A.f() takes 1 positional argument but 2 were given
    
        אולי שכחת את 'self'(עצמי) בהגדרת 'A.f'.
        
    'TypeError' נגרמת בדרך כלל על ידי ניסיון
    לשלב שני סוגי אובייקטים שאינם תואמים,
    על ידי קריאה לפונקציה עם סוג האובייקט הלא נכון,
    או על ידי ניסיון לבצע פעולה שאינה מותרת בסוג נתון של אובייקט.
    
    כנראה קראת לפונקציה 'A.f' עם
    2 ארגומנטים בזמן שהוא דורש 1
    ארגומנטים כאלה.
    אולי שכחת את 'self'(עצמי) בהגדרת 'A.f'.
    
    Exception raised on line `461` of file 'TESTS:\runtime\test_type_error.py'.
    
       457|     def f(x):
       458|         pass
       459| 
       460| try:
    -->461|     A().f(1)
                ^^^^^^^^
       462| except TypeError as e:

            A:  <class A>
                defined in <function test_type_error.test_Too_many_positional_argument>
        


Tuple no item assignment
~~~~~~~~~~~~~~~~~~~~~~~~

.. code-block:: none


    Traceback (most recent call last):
      File "TESTS:\runtime\test_type_error.py", line 428, in test_Tuple_no_item_assignment
        a[0] = 0
    TypeError: 'tuple' object does not support item assignment
    
        האם התכוונת להשתמש ברשימה?
        
    'TypeError' נגרמת בדרך כלל על ידי ניסיון
    לשלב שני סוגי אובייקטים שאינם תואמים,
    על ידי קריאה לפונקציה עם סוג האובייקט הלא נכון,
    או על ידי ניסיון לבצע פעולה שאינה מותרת בסוג נתון של אובייקט.
    
    בפייתון כמה אובייקטים ידועים כבלתי משתנים:
    לאחר שהוגדר, לא ניתן לשנות את ערכם.
    ניסית לשנות חלק מאובייקט בלתי משתנה כזה: צמד ('tuple'),
    סביר להניח על ידי שימוש בפעולת אינדקס.
    אולי התכוונת להשתמש ברשימה במקום זאת.
    
    Exception raised on line `428` of file 'TESTS:\runtime\test_type_error.py'.
    
       425| def test_Tuple_no_item_assignment():
       426|     a = (1, 2, 3)
       427|     try:
    -->428|         a[0] = 0
                    ^^^^
       429|     except TypeError as e:

            a:  (1, 2, 3)
            a[0]:  1
        


Unhachable type
~~~~~~~~~~~~~~~

.. code-block:: none


    Traceback (most recent call last):
      File "TESTS:\runtime\test_type_error.py", line 723, in test_Unhachable_type
        {[1, 2]: 1}
    TypeError: unhashable type: 'list'
    
    'TypeError' נגרמת בדרך כלל על ידי ניסיון
    לשלב שני סוגי אובייקטים שאינם תואמים,
    על ידי קריאה לפונקציה עם סוג האובייקט הלא נכון,
    או על ידי ניסיון לבצע פעולה שאינה מותרת בסוג נתון של אובייקט.
    
    ניתן להשתמש רק באובייקטים הניתנים לגיבוש
    כאלמנטים של 'סט' או כמקשים של 'dict'.
    אובייקטים ניתנים לגיבוש הם אובייקטים שאינם משנים ערך
    ברגע שהם נוצרו.במקום להשתמש ב- רשימה (`list`), שקול להשתמש ב- צמד ('tuple').
    
    Exception raised on line `723` of file 'TESTS:\runtime\test_type_error.py'.
    
       721| def test_Unhachable_type():
       722|     try:
    -->723|         {[1, 2]: 1}
       724|     except TypeError as e:


Unsupported operand types
~~~~~~~~~~~~~~~~~~~~~~~~~

.. code-block:: none


    Traceback (most recent call last):
      File "TESTS:\runtime\test_type_error.py", line 310, in test_Unsupported_operand_types
        a @= b
    TypeError: unsupported operand type(s) for @=: 'str' and 'int'
    
    'TypeError' נגרמת בדרך כלל על ידי ניסיון
    לשלב שני סוגי אובייקטים שאינם תואמים,
    על ידי קריאה לפונקציה עם סוג האובייקט הלא נכון,
    או על ידי ניסיון לבצע פעולה שאינה מותרת בסוג נתון של אובייקט.
    
    ניסית להשתמש באופרטור @=
    שימוש בשני סוגים של אובייקטים לא תואמים:
    מחרוזת (`str`) ו- מספר שלם (`int`).
    מפעיל זה משמש בדרך כלל בלבד
    לריבוי מטריצות.
    
    Exception raised on line `310` of file 'TESTS:\runtime\test_type_error.py'.
    
       307| try:
       308|     a = "a"
       309|     b = 2
    -->310|     a @= b
       311| except TypeError as e:

            a:  'a'
            b:  2
        


divmod
~~~~~~

.. code-block:: none


    Traceback (most recent call last):
      File "TESTS:\runtime\test_type_error.py", line 55, in test_divmod
        result = divmod(a, b)
    TypeError: unsupported operand type(s) for divmod(): 'int' and 'complex'
    
    'TypeError' נגרמת בדרך כלל על ידי ניסיון
    לשלב שני סוגי אובייקטים שאינם תואמים,
    על ידי קריאה לפונקציה עם סוג האובייקט הלא נכון,
    או על ידי ניסיון לבצע פעולה שאינה מותרת בסוג נתון של אובייקט.
    
    The arguments of `divmod` must be integers (`int`) or real (`float`) numbers.
    At least one of the arguments was a complex number.
    
    Exception raised on line `55` of file 'TESTS:\runtime\test_type_error.py'.
    
       52| a = 2
       53| b = 3 + 2j
       54| try:
    -->55|     result = divmod(a, b)
                        ^^^^^^^^^^^^
       56| except TypeError as e:

            a:  2
            b:  (3+2j)
            divmod:  <builtin function divmod>
        


function got multiple argument
~~~~~~~~~~~~~~~~~~~~~~~~~~~~~~

.. code-block:: none


    Traceback (most recent call last):
      File "TESTS:\runtime\test_type_error.py", line 941, in test_function_got_multiple_argument
        fn2(0, a=1)
    TypeError: test_function_got_multiple_argument.<locals>.fn2() got multiple values for argument 'a'
    
    'TypeError' נגרמת בדרך כלל על ידי ניסיון
    לשלב שני סוגי אובייקטים שאינם תואמים,
    על ידי קריאה לפונקציה עם סוג האובייקט הלא נכון,
    או על ידי ניסיון לבצע פעולה שאינה מותרת בסוג נתון של אובייקט.
    
    You have specified the value of argument `a` more than once
    when calling the function named `fn2`.
    This function has the following arguments:
    `a, b=1`
    
    Exception raised on line `941` of file 'TESTS:\runtime\test_type_error.py'.
    
       937| def fn2(a, b=1):
       938|     pass
       939| 
       940| try:
    -->941|     fn2(0, a=1)
                ^^^^^^^^^^^
       942| except TypeError as e:

            fn2:  <function fn2>
                defined in <function test_function_got_multiple_argument>
        


function has no len
~~~~~~~~~~~~~~~~~~~

.. code-block:: none


    Traceback (most recent call last):
      File "TESTS:\runtime\test_type_error.py", line 866, in test_function_has_no_len
        len(bad)
    TypeError: object of type 'function' has no len()
    
        שכחת לקרוא ל 'bad'?
        
    'TypeError' נגרמת בדרך כלל על ידי ניסיון
    לשלב שני סוגי אובייקטים שאינם תואמים,
    על ידי קריאה לפונקציה עם סוג האובייקט הלא נכון,
    או על ידי ניסיון לבצע פעולה שאינה מותרת בסוג נתון של אובייקט.
    
    אני חושד ששכחת להוסיף סוגריים כדי לקרוא 'bad'.
    אולי התכוונת לכתוב:
    `len(bad())`
    
    Exception raised on line `866` of file 'TESTS:\runtime\test_type_error.py'.
    
       862| def bad():
       863|     pass
       864| 
       865| try:
    -->866|     len(bad)
                ^^^^^^^^
       867| except TypeError as e:

            bad:  <function bad> defined in <function test_function_has_no_len>
            len:  <builtin function len>
        


getattr attribute name must be string
~~~~~~~~~~~~~~~~~~~~~~~~~~~~~~~~~~~~~

.. code-block:: none


    Traceback (most recent call last):
      File "TESTS:\runtime\test_type_error.py", line 987, in test_getattr_attribute_name_must_be_string
        getattr("__repr__", 1)  # as reported in issue #77
    TypeError: getattr(): attribute name must be string
    
    'TypeError' נגרמת בדרך כלל על ידי ניסיון
    לשלב שני סוגי אובייקטים שאינם תואמים,
    על ידי קריאה לפונקציה עם סוג האובייקט הלא נכון,
    או על ידי ניסיון לבצע פעולה שאינה מותרת בסוג נתון של אובייקט.
    
    The second argument of the function `getattr()` must be a string.
    
    Exception raised on line `987` of file 'TESTS:\runtime\test_type_error.py'.
    
       980| if friendly_traceback.get_lang() == "en":
       981|     assert (
       982|         "The second argument of the function `hasattr()` must be a string."
       983|         in result
       984|     )
       985| 
       986| try:
    -->987|     getattr("__repr__", 1)  # as reported in issue #77
                ^^^^^^^^^^^^^^^^^^^^^^
       988| except TypeError as e:

            getattr:  <builtin function getattr>
        


method got multiple argument
~~~~~~~~~~~~~~~~~~~~~~~~~~~~

.. code-block:: none


    Traceback (most recent call last):
      File "TESTS:\runtime\test_type_error.py", line 960, in test_method_got_multiple_argument
        t.some_method(0, a=1)
    TypeError: test_method_got_multiple_argument.<locals>.T.some_method() got multiple values for argument 'a'
    
    'TypeError' נגרמת בדרך כלל על ידי ניסיון
    לשלב שני סוגי אובייקטים שאינם תואמים,
    על ידי קריאה לפונקציה עם סוג האובייקט הלא נכון,
    או על ידי ניסיון לבצע פעולה שאינה מותרת בסוג נתון של אובייקט.
    
    You have specified the value of argument `a` more than once
    when calling the function named `t.some_method`.
    This function has only one argument: `a`
    
    Exception raised on line `960` of file 'TESTS:\runtime\test_type_error.py'.
    
       956|         pass
       957| 
       958| t = T()
       959| try:
    -->960|     t.some_method(0, a=1)
                ^^^^^^^^^^^^^^^^^^^^^
       961| except TypeError as e:

            t:  <T object>
                defined in <function test_type_error.test_method_got_multiple_argument>
            t.some_method:  <bound method T.some_method>
                of <T object>
                defined in <function test_type_error.test_method_got_multiple_argument>
        


vars arg must have dict
~~~~~~~~~~~~~~~~~~~~~~~

.. code-block:: none


    Traceback (most recent call last):
      File "TESTS:\runtime\test_type_error.py", line 910, in test_vars_arg_must_have_dict
        vars(f)
    TypeError: vars() argument must have __dict__ attribute
    
    'TypeError' נגרמת בדרך כלל על ידי ניסיון
    לשלב שני סוגי אובייקטים שאינם תואמים,
    על ידי קריאה לפונקציה עם סוג האובייקט הלא נכון,
    או על ידי ניסיון לבצע פעולה שאינה מותרת בסוג נתון של אובייקט.
    
    The function `vars` is used to list the content of the
    `__dict__` attribute of an object.
    Object `f` uses `__slots__` instead of `__dict__`.
    
    Exception raised on line `910` of file 'TESTS:\runtime\test_type_error.py'.
    
       906|     assert no_slots not in result
       907|     assert use_slots not in result
       908| 
       909| try:
    -->910|     vars(f)
                ^^^^^^^
       911| except TypeError as e:

            f:  <F object>
                defined in <function test_type_error.test_vars_arg_must_have_dict>
            vars:  <builtin function vars>
        


UnboundLocalError
-----------------


Missing both
~~~~~~~~~~~~

.. code-block:: none


    Traceback (most recent call last):
      File "TESTS:\runtime\test_unbound_local_error.py", line 63, in test_Missing_both
        outer_missing_both()
      File "TESTS:\runtime\test_unbound_local_error.py", line 22, in outer_missing_both
        inner()
      File "TESTS:\runtime\test_unbound_local_error.py", line 21, in inner
        spam_missing_both += 1
    UnboundLocalError: local variable 'spam_missing_both' referenced before assignment
    
        שכחת להוסיף את 'global spam_missing_both' או
        `לא -מקומי spam_missing_both`?
        
    ב-Python, משתנים המשמשים בתוך פונקציה ידועים בשם
    משתנים מקומיים. לפני השימוש בהם, יש להקצות להם ערך.
    מניחים למשתנה שמשתמשים בו לפני שהוקצה לו ערך
    להיות מוגדר מחוץ לפונקציה זו; זה ידוע בתור 'גלובלי'
    (או לפעמים 'לא מקומי'). אתה לא יכול להקצות ערך לכאלה
    משתנה גלובלי בתוך פונקציה מבלי לציין תחילה ל
    פייתון שזה משתנה גלובלי, אחרת תראה
    'UnboundLocalError'.
    
    You're trying to use the name `spam_missing_both` identified by Python as being
    in the local scope of a function before having assigned it a value.
    
    השם "spam_missing_both" קיים גם בתחום הגלובלי וגם הלא -מקומי.
    זה יכול להיות די מבלבל ואינו מומלץ.
    תלוי לאיזה משתנה אתה רוצה להתייחס, היית צריך להוסיף את זה
    
         spam_missing_both גלובלי
    
    אוֹ
    
         spam_missing_both לא -מקומי
    
    כשורה הראשונה בתוך הפונקציה שלך.
    
    Execution stopped on line `63` of file 'TESTS:\runtime\test_unbound_local_error.py'.
    
       61| def test_Missing_both():
       62|     try:
    -->63|         outer_missing_both()
                   ^^^^^^^^^^^^^^^^^^^^
       64|     except UnboundLocalError as e:

            global outer_missing_both:  <function outer_missing_both>
        
    Exception raised on line `21` of file 'TESTS:\runtime\test_unbound_local_error.py'.
    
       20| def inner():
    -->21|     spam_missing_both += 1

            global spam_missing_both:  1
        


Missing global
~~~~~~~~~~~~~~

.. code-block:: none


    Traceback (most recent call last):
      File "TESTS:\runtime\test_unbound_local_error.py", line 27, in test_Missing_global
        outer_missing_global()
      File "TESTS:\runtime\test_unbound_local_error.py", line 10, in outer_missing_global
        inner()
      File "TESTS:\runtime\test_unbound_local_error.py", line 9, in inner
        spam_missing_global += 1
    UnboundLocalError: local variable 'spam_missing_global' referenced before assignment
    
        שכחת להוסיף את 'global spam_missing_global'?
        
    ב-Python, משתנים המשמשים בתוך פונקציה ידועים בשם
    משתנים מקומיים. לפני השימוש בהם, יש להקצות להם ערך.
    מניחים למשתנה שמשתמשים בו לפני שהוקצה לו ערך
    להיות מוגדר מחוץ לפונקציה זו; זה ידוע בתור 'גלובלי'
    (או לפעמים 'לא מקומי'). אתה לא יכול להקצות ערך לכאלה
    משתנה גלובלי בתוך פונקציה מבלי לציין תחילה ל
    פייתון שזה משתנה גלובלי, אחרת תראה
    'UnboundLocalError'.
    
    You're trying to use the name `spam_missing_global` identified by Python as being
    in the local scope of a function before having assigned it a value.
    
    The name `spam_missing_global` exists in the global scope.
    Perhaps the statement
    
        global spam_missing_global
    
    should have been included as the first line inside your function.
    
    Execution stopped on line `27` of file 'TESTS:\runtime\test_unbound_local_error.py'.
    
       25| def test_Missing_global():
       26|     try:
    -->27|         outer_missing_global()
                   ^^^^^^^^^^^^^^^^^^^^^^
       28|     except UnboundLocalError as e:

            global outer_missing_global:  <function outer_missing_global>
        
    Exception raised on line `9` of file 'TESTS:\runtime\test_unbound_local_error.py'.
    
       8| def inner():
    -->9|     spam_missing_global += 1

            global spam_missing_global:  1
        


Missing nonlocal
~~~~~~~~~~~~~~~~

.. code-block:: none


    Traceback (most recent call last):
      File "TESTS:\runtime\test_unbound_local_error.py", line 45, in test_Missing_nonlocal
        outer_missing_nonlocal()
      File "TESTS:\runtime\test_unbound_local_error.py", line 16, in outer_missing_nonlocal
        inner()
      File "TESTS:\runtime\test_unbound_local_error.py", line 15, in inner
        spam_missing_nonlocal += 1
    UnboundLocalError: local variable 'spam_missing_nonlocal' referenced before assignment
    
        שכחת להוסיף את 'nonlocal spam_missing_nonlocal'?
        
    ב-Python, משתנים המשמשים בתוך פונקציה ידועים בשם
    משתנים מקומיים. לפני השימוש בהם, יש להקצות להם ערך.
    מניחים למשתנה שמשתמשים בו לפני שהוקצה לו ערך
    להיות מוגדר מחוץ לפונקציה זו; זה ידוע בתור 'גלובלי'
    (או לפעמים 'לא מקומי'). אתה לא יכול להקצות ערך לכאלה
    משתנה גלובלי בתוך פונקציה מבלי לציין תחילה ל
    פייתון שזה משתנה גלובלי, אחרת תראה
    'UnboundLocalError'.
    
    You're trying to use the name `spam_missing_nonlocal` identified by Python as being
    in the local scope of a function before having assigned it a value.
    
    The name `spam_missing_nonlocal` exists in the nonlocal scope.
    Perhaps the statement
    
        nonlocal spam_missing_nonlocal
    
    should have been included as the first line inside your function.
    
    Execution stopped on line `45` of file 'TESTS:\runtime\test_unbound_local_error.py'.
    
       43| def test_Missing_nonlocal():
       44|     try:
    -->45|         outer_missing_nonlocal()
                   ^^^^^^^^^^^^^^^^^^^^^^^^
       46|     except UnboundLocalError as e:

            global outer_missing_nonlocal:  <function outer_missing_nonlocal>
        
    Exception raised on line `15` of file 'TESTS:\runtime\test_unbound_local_error.py'.
    
       14| def inner():
    -->15|     spam_missing_nonlocal += 1


Typo in local
~~~~~~~~~~~~~

.. code-block:: none


    Traceback (most recent call last):
      File "TESTS:\runtime\test_unbound_local_error.py", line 101, in test_Typo_in_local
        test2()
      File "TESTS:\runtime\test_unbound_local_error.py", line 98, in test2
        alpha3 += 1
    UnboundLocalError: local variable 'alpha3' referenced before assignment
    
        האם התכוונת ל 'alpha1'?
        
    ב-Python, משתנים המשמשים בתוך פונקציה ידועים בשם
    משתנים מקומיים. לפני השימוש בהם, יש להקצות להם ערך.
    מניחים למשתנה שמשתמשים בו לפני שהוקצה לו ערך
    להיות מוגדר מחוץ לפונקציה זו; זה ידוע בתור 'גלובלי'
    (או לפעמים 'לא מקומי'). אתה לא יכול להקצות ערך לכאלה
    משתנה גלובלי בתוך פונקציה מבלי לציין תחילה ל
    פייתון שזה משתנה גלובלי, אחרת תראה
    'UnboundLocalError'.
    
    במקום לכתוב 'alpha3', אולי התכוונת לאחד מהדברים הבאים:
    * היקף מקומי `alpha1`, `alpha2`
    
    Execution stopped on line `101` of file 'TESTS:\runtime\test_unbound_local_error.py'.
    
        97|     alpha2 = 1
        98|     alpha3 += 1
        99| 
       100| try:
    -->101|     test2()
                ^^^^^^^
       102| except UnboundLocalError as e:

            test2:  <function test2> defined in <function test_Typo_in_local>
        
    Exception raised on line `98` of file 'TESTS:\runtime\test_unbound_local_error.py'.
    
       95| def test2():
       96|     alpha1 = 1
       97|     alpha2 = 1
    -->98|     alpha3 += 1


Using name of builtin
~~~~~~~~~~~~~~~~~~~~~

.. code-block:: none


    Traceback (most recent call last):
      File "TESTS:\runtime\test_unbound_local_error.py", line 121, in test_Using_name_of_builtin
        dist([])
      File "TESTS:\runtime\test_unbound_local_error.py", line 117, in dist
        max = max(points)
    UnboundLocalError: local variable 'max' referenced before assignment
    
    ב-Python, משתנים המשמשים בתוך פונקציה ידועים בשם
    משתנים מקומיים. לפני השימוש בהם, יש להקצות להם ערך.
    מניחים למשתנה שמשתמשים בו לפני שהוקצה לו ערך
    להיות מוגדר מחוץ לפונקציה זו; זה ידוע בתור 'גלובלי'
    (או לפעמים 'לא מקומי'). אתה לא יכול להקצות ערך לכאלה
    משתנה גלובלי בתוך פונקציה מבלי לציין תחילה ל
    פייתון שזה משתנה גלובלי, אחרת תראה
    'UnboundLocalError'.
    
    `max` is a Python builtin function.
    You have tried to assign a value to `max` inside a function
    while also using its original meaning in the function.
    
    Note that it is generally not a good idea to give a local variable
    the same name as a Python builtin function (like `max`).
    
    Execution stopped on line `121` of file 'TESTS:\runtime\test_unbound_local_error.py'.
    
       118|     min = min(points)
       119|     return max - min
       120| try:
    -->121|     dist([])
                ^^^^^^^^
       122| except UnboundLocalError as e:

            dist:  <function dist> defined in <function test_Using_name_of_builtin>
        
    Exception raised on line `117` of file 'TESTS:\runtime\test_unbound_local_error.py'.
    
       116| def dist(points):
    -->117|     max = max(points)
                      ^^^
       118|     min = min(points)

            max:  <builtin function max>
        


UnknownError
------------


Generic
~~~~~~~

.. code-block:: none


    Traceback (most recent call last):
      File "TESTS:\runtime\test_unknown_error.py", line 24, in test_Generic
        raise UnknownException("Some informative message about an unknown exception.")
    UnknownException: Some informative message about an unknown exception.
    
    שגיאה מסוג `UnknownException` היא תת-מחלקה של `Exception`.
    Nothing more specific is known about `UnknownException`.
    
    All built-in exceptions defined by Python are derived from `Exception`.
    All user-defined exceptions should also be derived from this class.
    
    Exception raised on line `24` of file 'TESTS:\runtime\test_unknown_error.py'.
    
       20| result = friendly_traceback.get_output()
       21| assert "UnknownException -> Exception" in result
       22| 
       23| try:
    -->24|     raise UnknownException("Some informative message about an unknown exception.")
       25| except Exception as e:

            global UnknownException:  <class test_unknown_error.UnknownException>
        


ValueError
----------


Convert to int
~~~~~~~~~~~~~~

.. code-block:: none


    Traceback (most recent call last):
      File "TESTS:\runtime\test_value_error.py", line 187, in test_Convert_to_int
        int('13a')
    ValueError: invalid literal for int() with base 10: '13a'
    
    'ValueError' מציין כי פונקציה או פעולה
    קיבל ערך מהסוג הנכון, אך בעל ערך לא נכון.
    
    `'13a'` הוא ארגומנט לא חוקי עבור `int (שלם)` בבסיס `10`.
    בבסיס '10', 'int (שלם)' משמש לרוב להמרת מחרוזת
    המכיל את הספרות '0' עד '9' למספר שלם.
    The following characters are not allowed: `a`.
    
    Exception raised on line `187` of file 'TESTS:\runtime\test_value_error.py'.
    
       183| if english:
       184|     assert "needs to be first converted using `float()`" in result
       185| 
       186| try:
    -->187|     int('13a')
                ^^^^^^^^^^
       188| except ValueError as e:

            int:  <class int>
        


Could not convert to float
~~~~~~~~~~~~~~~~~~~~~~~~~~

.. code-block:: none


    Traceback (most recent call last):
      File "TESTS:\runtime\test_value_error.py", line 88, in test_Could_not_convert_to_float
        float("42b")
    ValueError: could not convert string to float: '42b'
    
    'ValueError' מציין כי פונקציה או פעולה
    קיבל ערך מהסוג הנכון, אך בעל ערך לא נכון.
    
    The string `42b` cannot be converted to a `float`
    as it does not represent a number.
    
    Exception raised on line `88` of file 'TESTS:\runtime\test_value_error.py'.
    
       86| def test_Could_not_convert_to_float():
       87|     try:
    -->88|         float("42b")
                   ^^^^^^^^^^^^
       89|     except ValueError as e:

            float:  <class float>
        


Date invalid month
~~~~~~~~~~~~~~~~~~

.. code-block:: none


    Traceback (most recent call last):
      File "TESTS:\runtime\test_value_error.py", line 58, in test_Date_invalid_month
        d = date(2021, 13, 1)
    ValueError: month must be in 1..12
    
        האם ציינת חודש לא חוקי?
        
    'ValueError' מציין כי פונקציה או פעולה
    קיבל ערך מהסוג הנכון, אך בעל ערך לא נכון.
    
    אני מנחש שאתה מציין ערך לא חוקי למשך חודש
    באובייקט `תאריך`. ערכים חוקיים הם מספרים שלמים, מ -1 עד 12.
    
    Exception raised on line `58` of file 'TESTS:\runtime\test_value_error.py'.
    
       55| def test_Date_invalid_month():
       56|     from datetime import date
       57|     try:
    -->58|         d = date(2021, 13, 1)
                       ^^^^^^^^^^^^^^^^^
       59|     except ValueError as e:

            date:  <class datetime.date>
        


Not enough values to unpack
~~~~~~~~~~~~~~~~~~~~~~~~~~~

.. code-block:: none


    Traceback (most recent call last):
      File "TESTS:\runtime\test_value_error.py", line 28, in test_Not_enough_values_to_unpack
        a, b, c = d
    ValueError: not enough values to unpack (expected 3, got 2)
    
    'ValueError' מציין כי פונקציה או פעולה
    קיבל ערך מהסוג הנכון, אך בעל ערך לא נכון.
    
    פריקה היא דרך נוחה להקצות שם,
    לכל פריט של חוזר.
    במקרה זה, ישנם שמות נוספים (3)
    מאשר אורך ה- iterable, מחרוזת (`str`) של אורך 2.
    
    Exception raised on line `28` of file 'TESTS:\runtime\test_value_error.py'.
    
       24| assert "ValueError: not enough values to unpack (expected 3, got 2)" in result
       25| 
       26| d = "ab"
       27| try:
    -->28|     a, b, c = d
       29| except ValueError as e:

            d:  'ab'
        


Pow third arg cannot be zero
~~~~~~~~~~~~~~~~~~~~~~~~~~~~

.. code-block:: none


    Traceback (most recent call last):
      File "TESTS:\runtime\test_value_error.py", line 103, in test_Pow_third_arg_cannot_be_zero
        pow(2, 4, a)
    ValueError: pow() 3rd argument cannot be 0
    
    'ValueError' מציין כי פונקציה או פעולה
    קיבל ערך מהסוג הנכון, אך בעל ערך לא נכון.
    
    The third argument of the function `pow()` cannot be zero.
    
    Exception raised on line `103` of file 'TESTS:\runtime\test_value_error.py'.
    
       100| def test_Pow_third_arg_cannot_be_zero():
       101|     a = 0
       102|     try:
    -->103|         pow(2, 4, a)
                    ^^^^^^^^^^^^
       104|     except ValueError as e:

            a:  0
            pow:  <builtin function pow>
        


Slots conflicts with class variable
~~~~~~~~~~~~~~~~~~~~~~~~~~~~~~~~~~~

.. code-block:: none


    Traceback (most recent call last):
      File "TESTS:\runtime\test_value_error.py", line 72, in test_Slots_conflicts_with_class_variable
        class F:
    ValueError: 'a' in __slots__ conflicts with class variable
    
    'ValueError' מציין כי פונקציה או פעולה
    קיבל ערך מהסוג הנכון, אך בעל ערך לא נכון.
    
    The name `a` is used both as the name of a class variable
    and as a string item in the class `__slots__`;
    this is not allowed.
    
    Exception raised on line `72` of file 'TESTS:\runtime\test_value_error.py'.
    
       70| def test_Slots_conflicts_with_class_variable():
       71|     try:
    -->72|         class F:
       73|             __slots__ = ["a", "b"]


Too many values to unpack
~~~~~~~~~~~~~~~~~~~~~~~~~

.. code-block:: none


    Traceback (most recent call last):
      File "TESTS:\runtime\test_value_error.py", line 43, in test_Too_many_values_to_unpack
        a, b = c
    ValueError: too many values to unpack (expected 2)
    
    'ValueError' מציין כי פונקציה או פעולה
    קיבל ערך מהסוג הנכון, אך בעל ערך לא נכון.
    
    פריקה היא דרך נוחה להקצות שם,
    לכל פריט של חוזר.
    במקרה זה, יש פחות שמות (2)
    מאשר אורך ה- iterable, רשימה (`list`) של אורך 3.
    
    Exception raised on line `43` of file 'TESTS:\runtime\test_value_error.py'.
    
       40| def test_Too_many_values_to_unpack():
       41|     c = [1, 2, 3]
       42|     try:
    -->43|         a, b = c
       44|     except ValueError as e:

            c:  [1, 2, 3]
        


int base not in range
~~~~~~~~~~~~~~~~~~~~~

.. code-block:: none


    Traceback (most recent call last):
      File "TESTS:\runtime\test_value_error.py", line 201, in test_int_base_not_in_range
        int('18', base=37)
    ValueError: int() base must be >= 2 and <= 36, or 0
    
    'ValueError' מציין כי פונקציה או פעולה
    קיבל ערך מהסוג הנכון, אך בעל ערך לא נכון.
    
    The argument `base` of `int()` must be either zero
    or any integer from 2 to 36.
    You wrote 37 which is not allowed.
    
    Exception raised on line `201` of file 'TESTS:\runtime\test_value_error.py'.
    
       199| def test_int_base_not_in_range():
       200|     try:
    -->201|         int('18', base=37)
                    ^^^^^^^^^^^^^^^^^^
       202|     except ValueError as e:

            int:  <class int>
        


remove item not in list
~~~~~~~~~~~~~~~~~~~~~~~

.. code-block:: none


    Traceback (most recent call last):
      File "TESTS:\runtime\test_value_error.py", line 227, in test_remove_item_not_in_list
        a_list.remove(b)
    ValueError: list.remove(x): x not in list
    
    'ValueError' מציין כי פונקציה או פעולה
    קיבל ערך מהסוג הנכון, אך בעל ערך לא נכון.
    
    You have attempted to remove `b` from the list `a_list`.
    However, `a_list` does not contain `b`.
    
    Exception raised on line `227` of file 'TESTS:\runtime\test_value_error.py'.
    
       224| a_list = [1, 2, 3]
       225| b = 4
       226| try:
    -->227|     a_list.remove(b)
                ^^^^^^^^^^^^^^^^
       228| except ValueError as e:

            a_list:  [1, 2, 3]
            b:  4
            a_list.remove:  <builtin method remove of list object>
        


time strptime incorrect format
~~~~~~~~~~~~~~~~~~~~~~~~~~~~~~

.. code-block:: none


    Traceback (most recent call last):
      File "TESTS:\runtime\test_value_error.py", line 127, in test_time_strptime_incorrect_format
        time.strptime("2020-01-01", "%d %m %Y")
    ValueError: time data '2020-01-01' does not match format '%d %m %Y'
    
    'ValueError' מציין כי פונקציה או פעולה
    קיבל ערך מהסוג הנכון, אך בעל ערך לא נכון.
    
    The value you gave for the time is not in the format you specified.
    Make sure to use the same separator between items
    (for example, between day and month) and keep the order the same
    in both the data provided and the format you specified.
    The following table might be useful:
    https://docs.python.org/3/library/time.html#time.strftime
    The following site might also be useful: https://www.strfti.me/
    
    Exception raised on line `127` of file 'TESTS:\runtime\test_value_error.py'.
    
       123|     return
       124| 
       125| import time
       126| try:
    -->127|     time.strptime("2020-01-01", "%d %m %Y")
                ^^^^^^^^^^^^^^^^^^^^^^^^^^^^^^^^^^^^^^^
       128| except ValueError as e:

            time:  <module time (builtin)>
            time.strptime:  <builtin function strptime>
        


ZeroDivisionError
-----------------


Complex division
~~~~~~~~~~~~~~~~

.. code-block:: none


    Traceback (most recent call last):
      File "TESTS:\runtime\test_zero_division_error.py", line 173, in test_Complex_division
        1 / zero
    ZeroDivisionError: complex division by zero
    
    'ZeroDivisionError' מתרחש כאשר אתה מנסה לחלק ערך
    באפס ישירות או באמצעות פעולה מתמטית אחרת.
    
    את\ה מחלק\תבמונח הבא
    
          zero
    
    שהוא שווה לאפס.
    
    Exception raised on line `173` of file 'TESTS:\runtime\test_zero_division_error.py'.
    
       170| def test_Complex_division():
       171|     zero = 0j
       172|     try:
    -->173|         1 / zero
                    ^^^^^^^^
       174|     except ZeroDivisionError as e:

            zero:  0j
        


Division by zero literal
~~~~~~~~~~~~~~~~~~~~~~~~

.. code-block:: none


    Traceback (most recent call last):
      File "TESTS:\runtime\test_zero_division_error.py", line 220, in test_Division_by_zero_literal
        1.0 / 0
    ZeroDivisionError: float division by zero
    
    'ZeroDivisionError' מתרחש כאשר אתה מנסה לחלק ערך
    באפס ישירות או באמצעות פעולה מתמטית אחרת.
    
    את\ה מחלק\ת באפס.
    
    Exception raised on line `220` of file 'TESTS:\runtime\test_zero_division_error.py'.
    
       216| if friendly_traceback.get_lang() == "en":
       217|     assert "Using the modulo operator, you are dividing by zero" in result
       218| 
       219| try:
    -->220|     1.0 / 0
                ^^^^^^^
       221| except ZeroDivisionError as e:


Division operator
~~~~~~~~~~~~~~~~~

.. code-block:: none


    Traceback (most recent call last):
      File "TESTS:\runtime\test_zero_division_error.py", line 20, in test_Division_operator
        1 / zero
    ZeroDivisionError: division by zero
    
    'ZeroDivisionError' מתרחש כאשר אתה מנסה לחלק ערך
    באפס ישירות או באמצעות פעולה מתמטית אחרת.
    
    את\ה מחלק\תבמונח הבא
    
          zero
    
    שהוא שווה לאפס.
    
    Exception raised on line `20` of file 'TESTS:\runtime\test_zero_division_error.py'.
    
       13| if friendly_traceback.get_lang() == "en":
       14|     assert (
       15|         "The following mathematical expression includes a division by zero"
       16|         in result
       17|     )
       18| 
       19| try:
    -->20|     1 / zero
               ^^^^^^^^
       21| except ZeroDivisionError as e:

            zero:  0
        


Divmod
~~~~~~

.. code-block:: none


    Traceback (most recent call last):
      File "TESTS:\runtime\test_zero_division_error.py", line 97, in test_Divmod
        divmod(1, zero)
    ZeroDivisionError: integer division or modulo by zero
    
    'ZeroDivisionError' מתרחש כאשר אתה מנסה לחלק ערך
    באפס ישירות או באמצעות פעולה מתמטית אחרת.
    
    הטיעון השני של הפונקציה `divmod(חלוקה)` הוא אפס.
    
    Exception raised on line `97` of file 'TESTS:\runtime\test_zero_division_error.py'.
    
       94| def test_Divmod():
       95|     zero = 0
       96|     try:
    -->97|         divmod(1, zero)
                   ^^^^^^^^^^^^^^^
       98|     except ZeroDivisionError as e:

            zero:  0
            divmod:  <builtin function divmod>
        


Float division
~~~~~~~~~~~~~~

.. code-block:: none


    Traceback (most recent call last):
      File "TESTS:\runtime\test_zero_division_error.py", line 143, in test_Float_division
        1 / zero
    ZeroDivisionError: float division by zero
    
    'ZeroDivisionError' מתרחש כאשר אתה מנסה לחלק ערך
    באפס ישירות או באמצעות פעולה מתמטית אחרת.
    
    את\ה מחלק\תבמונח הבא
    
          zero
    
    שהוא שווה לאפס.
    
    Exception raised on line `143` of file 'TESTS:\runtime\test_zero_division_error.py'.
    
       140| def test_Float_division():
       141|     zero = 0.0
       142|     try:
    -->143|         1 / zero
                    ^^^^^^^^
       144|     except ZeroDivisionError as e:

            zero:  0.0
        


Float divmod
~~~~~~~~~~~~

.. code-block:: none


    Traceback (most recent call last):
      File "TESTS:\runtime\test_zero_division_error.py", line 158, in test_Float_divmod
        divmod(1, zero)
    ZeroDivisionError: float divmod()
    
    'ZeroDivisionError' מתרחש כאשר אתה מנסה לחלק ערך
    באפס ישירות או באמצעות פעולה מתמטית אחרת.
    
    הטיעון השני של הפונקציה `divmod(חלוקה)` שווה אפס.
    
    Exception raised on line `158` of file 'TESTS:\runtime\test_zero_division_error.py'.
    
       155| def test_Float_divmod():
       156|     zero = 0.0
       157|     try:
    -->158|         divmod(1, zero)
                    ^^^^^^^^^^^^^^^
       159|     except ZeroDivisionError as e:

            zero:  0.0
            divmod:  <builtin function divmod>
        


Float modulo
~~~~~~~~~~~~

.. code-block:: none


    Traceback (most recent call last):
      File "TESTS:\runtime\test_zero_division_error.py", line 128, in test_Float_modulo
        1 % zero
    ZeroDivisionError: float modulo
    
    'ZeroDivisionError' מתרחש כאשר אתה מנסה לחלק ערך
    באפס ישירות או באמצעות פעולה מתמטית אחרת.
    
    באמצעות אופרטור המודולו, את\ה מחלק\ת במונח הבא
    
          zero
    
    שהוא שווה לאפס.
    
    Exception raised on line `128` of file 'TESTS:\runtime\test_zero_division_error.py'.
    
       121|     assert (
       122|         "The following mathematical expression includes a division by zero"
       123|         in result
       124|     )
       125|     assert "done using the modulo operator" in result
       126| 
       127| try:
    -->128|     1 % zero
                ^^^^^^^^
       129| except ZeroDivisionError as e:

            zero:  0.0
        


Integer division operator
~~~~~~~~~~~~~~~~~~~~~~~~~

.. code-block:: none


    Traceback (most recent call last):
      File "TESTS:\runtime\test_zero_division_error.py", line 48, in test_Integer_division_operator
        1 // zero
    ZeroDivisionError: integer division or modulo by zero
    
    'ZeroDivisionError' מתרחש כאשר אתה מנסה לחלק ערך
    באפס ישירות או באמצעות פעולה מתמטית אחרת.
    
    את\ה מחלק\תבמונח הבא
    
          zero
    
    שהוא שווה לאפס.
    
    Exception raised on line `48` of file 'TESTS:\runtime\test_zero_division_error.py'.
    
       41| if friendly_traceback.get_lang() == "en":
       42|     assert (
       43|         "The following mathematical expression includes a division by zero"
       44|         in result
       45|     )
       46| 
       47| try:
    -->48|     1 // zero
               ^^^^^^^^^
       49| except ZeroDivisionError as e:

            zero:  0
        


Mixed operations
~~~~~~~~~~~~~~~~

.. code-block:: none


    Traceback (most recent call last):
      File "TESTS:\runtime\test_zero_division_error.py", line 233, in test_Mixed_operations
        a = divmod(8, 1 // 2)
    ZeroDivisionError: integer division or modulo by zero
    
    'ZeroDivisionError' מתרחש כאשר אתה מנסה לחלק ערך
    באפס ישירות או באמצעות פעולה מתמטית אחרת.
    
    הביטוי המתמטי הבא כולל חלוקה באפס:
    
         divmod(8, 1 // 2)
    
    Exception raised on line `233` of file 'TESTS:\runtime\test_zero_division_error.py'.
    
       231| def test_Mixed_operations():
       232|     try:
    -->233|         a = divmod(8, 1 // 2)
                        ^^^^^^^^^^^^^^^^^
       234|     except ZeroDivisionError as e:

            divmod:  <builtin function divmod>
            1 // 2:  0
        


Modulo operator
~~~~~~~~~~~~~~~

.. code-block:: none


    Traceback (most recent call last):
      File "TESTS:\runtime\test_zero_division_error.py", line 79, in test_Modulo_operator
        1 % zero
    ZeroDivisionError: integer division or modulo by zero
    
    'ZeroDivisionError' מתרחש כאשר אתה מנסה לחלק ערך
    באפס ישירות או באמצעות פעולה מתמטית אחרת.
    
    באמצעות אופרטור המודולו, את\ה מחלק\ת במונח הבא
    
          zero
    
    שהוא שווה לאפס.
    
    Exception raised on line `79` of file 'TESTS:\runtime\test_zero_division_error.py'.
    
       72| if friendly_traceback.get_lang() == "en":
       73|     assert (
       74|         "The following mathematical expression includes a division by zero"
       75|         in result
       76|     )
       77| 
       78| try:
    -->79|     1 % zero
               ^^^^^^^^
       80| except ZeroDivisionError as e:

            zero:  0
        


Raise zero negative power
~~~~~~~~~~~~~~~~~~~~~~~~~

.. code-block:: none


    Traceback (most recent call last):
      File "TESTS:\runtime\test_zero_division_error.py", line 188, in test_Raise_zero_negative_power
        zero**-1
    ZeroDivisionError: 0.0 cannot be raised to a negative power
    
    'ZeroDivisionError' מתרחש כאשר אתה מנסה לחלק ערך
    באפס ישירות או באמצעות פעולה מתמטית אחרת.
    
    את\ה מנסה להעלות את המספר 0 בחזקת מספר שלילי
    זה מקביל לחלוקה באפס.
    
    Exception raised on line `188` of file 'TESTS:\runtime\test_zero_division_error.py'.
    
       185| def test_Raise_zero_negative_power():
       186|     zero = 0
       187|     try:
    -->188|         zero**-1
                    ^^^^^^^^
       189|     except ZeroDivisionError as e:

            zero:  0
        

